File: plots/rawdata/Figure1c_circle.txt
# strain (%), stress (GPa)
7.40040000 4.82396531
7.40120000 4.82427637
7.40200000 4.82443021
7.40280000 4.82466736
7.40360000 4.82496325
7.40440000 4.82534508
7.40520000 4.82580146
7.40600000 4.82617348
7.40680000 4.82664553
7.40760000 4.82727740
7.40840000 4.82790278
7.40920000 4.82852854
7.41000000 4.82918496
7.41080000 4.82955378
7.41160000 4.82999801
7.41240000 4.83043738
7.41320000 4.83090586
7.41400000 4.83138463
7.41480000 4.83184734
7.41560000 4.83235538
7.41640000 4.83282778
7.41720000 4.83328060
7.41800000 4.83374395
7.41880000 4.83420202
7.41960000 4.83465160
7.42040000 4.83505282
7.42120000 4.83531058
7.42200000 4.83565145
7.42280000 4.83595810
7.42360000 4.83626758
7.42440000 4.83676447
7.42520000 4.83731304
7.42600000 4.83786444
7.42680000 4.83818932
7.42760000 4.83852260
7.42840000 4.83898305
7.42920000 4.83942827
7.43000000 4.83982201
7.43080000 4.84007532
7.43160000 4.84040973
7.43240000 4.84081704
7.43320000 4.84124181
7.43400000 4.84167297
7.43480000 4.84192926
7.43560000 4.84230710
7.43640000 4.84276444
7.43720000 4.84320699
7.43800000 4.84360199
7.43880000 4.84410352
7.43960000 4.84447224
7.44040000 4.84471270
7.44120000 4.84496531
7.44200000 4.84534496
7.44280000 4.84562923
7.44360000 4.84600133
7.44440000 4.84631607
7.44520000 4.84638220
7.44600000 4.84657218
7.44680000 4.84674155
7.44760000 4.84681308
7.44840000 4.84679902
7.44920000 4.84686368
7.45000000 4.84695502
7.45080000 4.84716221
7.45160000 4.84717902
7.45240000 4.84736257
7.45320000 4.84760709
7.45400000 4.84778821
7.45480000 4.84798438
7.45560000 4.84802143
7.45640000 4.84803737
7.45720000 4.84817672
7.45800000 4.84835096
7.45880000 4.84856161
7.45960000 4.84854876
7.46040000 4.84853927
7.46120000 4.84856820
7.46200000 4.84857017
7.46280000 4.84863072
7.46360000 4.84871088
7.46440000 4.84877165
7.46520000 4.84880807
7.46600000 4.84870297
7.46680000 4.84860904
7.46760000 4.84855536
7.46840000 4.84850687
7.46920000 4.84844688
7.47000000 4.84830977
7.47080000 4.84817542
7.47160000 4.84801303
7.47240000 4.84770266
7.47320000 4.84748382
7.47400000 4.84724161
7.47480000 4.84683495
7.47560000 4.84632047
7.47640000 4.84591249
7.47720000 4.84562225
7.47800000 4.84538435
7.47880000 4.84523727
7.47960000 4.84522705
7.48040000 4.84511145
7.48120000 4.84498273
7.48200000 4.84485675
7.48280000 4.84471788
7.48360000 4.84453637
7.48440000 4.84440559
7.48520000 4.84442506
7.48600000 4.84427924
7.48680000 4.84414918
7.48760000 4.84403628
7.48840000 4.84401576
7.48920000 4.84404099
7.49000000 4.84400530
7.49080000 4.84390187
7.49160000 4.84400598
7.49240000 4.84390028
7.49320000 4.84370341
7.49400000 4.84357256
7.49480000 4.84347901
7.49560000 4.84335363
7.49640000 4.84330684
7.49720000 4.84327031
7.49800000 4.84308411
7.49880000 4.84297321
7.49960000 4.84305408
7.50040000 4.84318255
7.50120000 4.84334677
7.50200000 4.84338067
7.50280000 4.84340195
7.50360000 4.84342822
7.50440000 4.84336974
7.50520000 4.84333727
7.50600000 4.84349529
7.50680000 4.84371003
7.50760000 4.84384885
7.50840000 4.84383756
7.50920000 4.84391033
7.51000000 4.84402275
7.51080000 4.84417428
7.51160000 4.84435824
7.51240000 4.84465029
7.51320000 4.84493099
7.51400000 4.84525166
7.51480000 4.84567207
7.51560000 4.84607531
7.51640000 4.84637191
7.51720000 4.84672791
7.51800000 4.84707662
7.51880000 4.84728740
7.51960000 4.84756594
7.52040000 4.84790540
7.52120000 4.84815872
7.52200000 4.84838821
7.52280000 4.84862869
7.52360000 4.84878307
7.52440000 4.84909779
7.52520000 4.84962134
7.52600000 4.85023552
7.52680000 4.85078474
7.52760000 4.85133764
7.52840000 4.85179877
7.52920000 4.85213386
7.53000000 4.85249282
7.53080000 4.85297308
7.53160000 4.85352767
7.53240000 4.85409827
7.53320000 4.85465620
7.53400000 4.85519601
7.53480000 4.85563880
7.53560000 4.85617975
7.53640000 4.85670723
7.53720000 4.85720142
7.53800000 4.85780315
7.53880000 4.85835086
7.53960000 4.85885181
7.54040000 4.85923596
7.54120000 4.85952233
7.54200000 4.85982005
7.54280000 4.86018545
7.54360000 4.86052909
7.54440000 4.86088367
7.54520000 4.86127970
7.54600000 4.86160376
7.54680000 4.86184383
7.54760000 4.86218093
7.54840000 4.86267553
7.54920000 4.86299146
7.55000000 4.86329009
7.55080000 4.86355738
7.55160000 4.86382230
7.55240000 4.86408738
7.55320000 4.86433464
7.55400000 4.86453381
7.55480000 4.86477936
7.55560000 4.86503405
7.55640000 4.86550726
7.55720000 4.86598376
7.55800000 4.86650782
7.55880000 4.86698110
7.55960000 4.86744292
7.56040000 4.86790845
7.56120000 4.86846265
7.56200000 4.86908545
7.56280000 4.86969192
7.56360000 4.87027967
7.56440000 4.87069888
7.56520000 4.87102539
7.56600000 4.87132972
7.56680000 4.87170663
7.56760000 4.87209204
7.56840000 4.87261084
7.56920000 4.87307601
7.57000000 4.87339112
7.57080000 4.87365532
7.57160000 4.87388909
7.57240000 4.87413817
7.57320000 4.87429807
7.57400000 4.87447892
7.57480000 4.87474085
7.57560000 4.87493373
7.57640000 4.87484063
7.57720000 4.87474261
7.57800000 4.87461784
7.57880000 4.87438171
7.57960000 4.87428423
7.58040000 4.87427986
7.58120000 4.87431087
7.58200000 4.87444525
7.58280000 4.87442507
7.58360000 4.87434472
7.58440000 4.87432664
7.58520000 4.87426110
7.58600000 4.87417978
7.58680000 4.87419237
7.58760000 4.87428577
7.58840000 4.87434198
7.58920000 4.87456566
7.59000000 4.87479392
7.59080000 4.87495758
7.59160000 4.87513629
7.59240000 4.87537581
7.59320000 4.87560199
7.59400000 4.87579930
7.59480000 4.87597105
7.59560000 4.87617166
7.59640000 4.87605980
7.59720000 4.87574761
7.59800000 4.87562795
7.59880000 4.87556212
7.59960000 4.87549943
7.60040000 4.87536922
7.60120000 4.87527954
7.60200000 4.87517196
7.60280000 4.87515954
7.60360000 4.87518293
7.60440000 4.87520202
7.60520000 4.87508409
7.60600000 4.87490241
7.60680000 4.87465607
7.60760000 4.87439141
7.60840000 4.87405398
7.60920000 4.87378219
7.61000000 4.87365773
7.61080000 4.87355177
7.61160000 4.87345043
7.61240000 4.87334426
7.61320000 4.87331208
7.61400000 4.87324742
7.61480000 4.87318647
7.61560000 4.87323253
7.61640000 4.87351079
7.61720000 4.87374394
7.61800000 4.87382194
7.61880000 4.87394962
7.61960000 4.87411812
7.62040000 4.87437163
7.62120000 4.87449553
7.62200000 4.87462322
7.62280000 4.87496480
7.62360000 4.87535600
7.62440000 4.87559575
7.62520000 4.87594921
7.62600000 4.87638501
7.62680000 4.87691734
7.62760000 4.87722934
7.62840000 4.87751185
7.62920000 4.87773870
7.63000000 4.87801582
7.63080000 4.87841004
7.63160000 4.87869854
7.63240000 4.87891491
7.63320000 4.87917894
7.63400000 4.87951394
7.63480000 4.88012785
7.63560000 4.88079488
7.63640000 4.88150734
7.63720000 4.88216332
7.63800000 4.88256983
7.63880000 4.88303560
7.63960000 4.88351117
7.64040000 4.88413275
7.64120000 4.88467397
7.64200000 4.88510304
7.64280000 4.88546600
7.64360000 4.88573536
7.64440000 4.88603305
7.64520000 4.88628501
7.64600000 4.88656816
7.64680000 4.88687145
7.64760000 4.88740337
7.64840000 4.88788579
7.64920000 4.88833696
7.65000000 4.88884833
7.65080000 4.88928910
7.65160000 4.88967612
7.65240000 4.89010181
7.65320000 4.89052971
7.65400000 4.89115237
7.65480000 4.89164727
7.65560000 4.89207830
7.65640000 4.89263595
7.65720000 4.89311505
7.65800000 4.89380402
7.65880000 4.89448561
7.65960000 4.89508477
7.66040000 4.89556651
7.66120000 4.89617984
7.66200000 4.89677062
7.66280000 4.89717239
7.66360000 4.89762612
7.66440000 4.89826959
7.66520000 4.89873230
7.66600000 4.89907842
7.66680000 4.89925781
7.66760000 4.89953976
7.66840000 4.89983679
7.66920000 4.90034926
7.67000000 4.90078120
7.67080000 4.90098071
7.67160000 4.90124206
7.67240000 4.90150589
7.67320000 4.90178113
7.67400000 4.90197123
7.67480000 4.90191591
7.67560000 4.90184045
7.67640000 4.90184733
7.67720000 4.90205095
7.67800000 4.90230975
7.67880000 4.90271311
7.67960000 4.90304041
7.68040000 4.90332892
7.68120000 4.90365687
7.68200000 4.90407083
7.68280000 4.90453006
7.68360000 4.90491110
7.68440000 4.90524108
7.68520000 4.90562375
7.68600000 4.90610536
7.68680000 4.90669670
7.68760000 4.90708244
7.68840000 4.90739326
7.68920000 4.90785463
7.69000000 4.90820696
7.69080000 4.90864394
7.69160000 4.90892821
7.69240000 4.90915524
7.69320000 4.90938429
7.69400000 4.90947175
7.69480000 4.90972045
7.69560000 4.91018303
7.69640000 4.91040926
7.69720000 4.91073351
7.69800000 4.91101226
7.69880000 4.91135642
7.69960000 4.91166814
7.70040000 4.91188721
7.70120000 4.91196996
7.70200000 4.91201208
7.70280000 4.91208582
7.70360000 4.91208168
7.70440000 4.91213722
7.70520000 4.91229199
7.70600000 4.91247846
7.70680000 4.91267562
7.70760000 4.91290798
7.70840000 4.91321627
7.70920000 4.91335487
7.71000000 4.91360171
7.71080000 4.91406088
7.71160000 4.91445695
7.71240000 4.91475117
7.71320000 4.91501632
7.71400000 4.91538036
7.71480000 4.91583690
7.71560000 4.91614192
7.71640000 4.91636016
7.71720000 4.91662518
7.71800000 4.91683525
7.71880000 4.91682904
7.71960000 4.91686569
7.72040000 4.91696441
7.72120000 4.91719851
7.72200000 4.91734182
7.72280000 4.91748480
7.72360000 4.91769419
7.72440000 4.91789806
7.72520000 4.91809132
7.72600000 4.91831517
7.72680000 4.91848214
7.72760000 4.91860619
7.72840000 4.91882867
7.72920000 4.91904998
7.73000000 4.91917575
7.73080000 4.91932799
7.73160000 4.91977675
7.73240000 4.92025119
7.73320000 4.92080682
7.73400000 4.92136647
7.73480000 4.92182265
7.73560000 4.92206996
7.73640000 4.92233145
7.73720000 4.92263809
7.73800000 4.92292210
7.73880000 4.92304192
7.73960000 4.92327823
7.74040000 4.92354058
7.74120000 4.92386787
7.74200000 4.92408694
7.74280000 4.92447966
7.74360000 4.92490097
7.74440000 4.92520872
7.74520000 4.92552018
7.74600000 4.92583944
7.74680000 4.92618688
7.74760000 4.92641115
7.74840000 4.92659931
7.74920000 4.92697903
7.75000000 4.92715557
7.75080000 4.92733830
7.75160000 4.92763168
7.75240000 4.92798250
7.75320000 4.92851081
7.75400000 4.92895576
7.75480000 4.92923847
7.75560000 4.92957914
7.75640000 4.93001304
7.75720000 4.93041534
7.75800000 4.93088587
7.75880000 4.93136918
7.75960000 4.93171616
7.76040000 4.93193943
7.76120000 4.93206561
7.76200000 4.93230346
7.76280000 4.93254525
7.76360000 4.93292770
7.76440000 4.93329697
7.76520000 4.93380890
7.76600000 4.93430937
7.76680000 4.93476185
7.76760000 4.93528479
7.76840000 4.93580988
7.76920000 4.93618806
7.77000000 4.93671750
7.77080000 4.93708593
7.77160000 4.93720920
7.77240000 4.93723036
7.77320000 4.93730648
7.77400000 4.93727729
7.77480000 4.93732807
7.77560000 4.93733620
7.77640000 4.93747783
7.77720000 4.93758301
7.77800000 4.93766155
7.77880000 4.93796869
7.77960000 4.93816780
7.78040000 4.93843867
7.78120000 4.93868796
7.78200000 4.93913556
7.78280000 4.93953563
7.78360000 4.93987122
7.78440000 4.94011695
7.78520000 4.94033257
7.78600000 4.94062542
7.78680000 4.94092669
7.78760000 4.94139190
7.78840000 4.94169790
7.78920000 4.94176974
7.79000000 4.94199051
7.79080000 4.94226724
7.79160000 4.94249910
7.79240000 4.94279186
7.79320000 4.94301119
7.79400000 4.94335866
7.79480000 4.94378496
7.79560000 4.94417338
7.79640000 4.94465149
7.79720000 4.94502642
7.79800000 4.94534648
7.79880000 4.94566328
7.79960000 4.94608520
7.80040000 4.94666372
7.80120000 4.94709481
7.80200000 4.94749437
7.80280000 4.94777329
7.80360000 4.94817063
7.80440000 4.94864055
7.80520000 4.94898194
7.80600000 4.94927311
7.80680000 4.94957066
7.80760000 4.94984816
7.80840000 4.95019930
7.80920000 4.95057803
7.81000000 4.95085089
7.81080000 4.95126424
7.81160000 4.95170991
7.81240000 4.95230827
7.81320000 4.95272167
7.81400000 4.95324348
7.81480000 4.95374693
7.81560000 4.95437464
7.81640000 4.95492134
7.81720000 4.95542907
7.81800000 4.95585476
7.81880000 4.95619707
7.81960000 4.95655517
7.82040000 4.95696705
7.82120000 4.95753508
7.82200000 4.95801383
7.82280000 4.95829694
7.82360000 4.95875571
7.82440000 4.95932259
7.82520000 4.95992482
7.82600000 4.96046247
7.82680000 4.96087920
7.82760000 4.96124898
7.82840000 4.96161364
7.82920000 4.96185846
7.83000000 4.96203506
7.83080000 4.96216989
7.83160000 4.96225347
7.83240000 4.96225541
7.83320000 4.96219383
7.83400000 4.96200366
7.83480000 4.96179232
7.83560000 4.96153189
7.83640000 4.96106870
7.83720000 4.96067887
7.83800000 4.96036610
7.83880000 4.96009749
7.83960000 4.96000785
7.84040000 4.95998530
7.84120000 4.96008205
7.84200000 4.96014151
7.84280000 4.96025326
7.84360000 4.96009681
7.84440000 4.95993639
7.84520000 4.95979677
7.84600000 4.95960947
7.84680000 4.95943960
7.84760000 4.95931983
7.84840000 4.95915575
7.84920000 4.95898422
7.85000000 4.95879589
7.85080000 4.95870212
7.85160000 4.95860518
7.85240000 4.95844868
7.85320000 4.95847191
7.85400000 4.95857471
7.85480000 4.95859576
7.85560000 4.95841326
7.85640000 4.95836715
7.85720000 4.95839937
7.85800000 4.95860601
7.85880000 4.95876011
7.85960000 4.95897836
7.86040000 4.95904192
7.86120000 4.95885337
7.86200000 4.95866941
7.86280000 4.95864460
7.86360000 4.95852871
7.86440000 4.95831038
7.86520000 4.95795479
7.86600000 4.95765180
7.86680000 4.95750627
7.86760000 4.95730218
7.86840000 4.95737697
7.86920000 4.95768087
7.87000000 4.95789676
7.87080000 4.95799297
7.87160000 4.95809254
7.87240000 4.95828975
7.87320000 4.95852575
7.87400000 4.95875219
7.87480000 4.95896754
7.87560000 4.95932432
7.87640000 4.95972927
7.87720000 4.96016196
7.87800000 4.96067282
7.87880000 4.96110295
7.87960000 4.96139288
7.88040000 4.96158773
7.88120000 4.96166349
7.88200000 4.96154802
7.88280000 4.96139710
7.88360000 4.96138917
7.88440000 4.96134322
7.88520000 4.96131089
7.88600000 4.96123946
7.88680000 4.96112051
7.88760000 4.96089348
7.88840000 4.96082084
7.88920000 4.96084983
7.89000000 4.96095950
7.89080000 4.96092246
7.89160000 4.96107433
7.89240000 4.96110509
7.89320000 4.96102802
7.89400000 4.96092466
7.89480000 4.96085310
7.89560000 4.96092030
7.89640000 4.96088830
7.89720000 4.96084557
7.89800000 4.96080920
7.89880000 4.96074966
7.89960000 4.96057580
7.90040000 4.96054487
7.90120000 4.96063657
7.90200000 4.96074466
7.90280000 4.96085768
7.90360000 4.96101892
7.90440000 4.96111553
7.90520000 4.96126776
7.90600000 4.96149560
7.90680000 4.96167894
7.90760000 4.96203316
7.90840000 4.96210033
7.90920000 4.96214967
7.91000000 4.96233899
7.91080000 4.96270790
7.91160000 4.96316119
7.91240000 4.96354554
7.91320000 4.96381844
7.91400000 4.96422599
7.91480000 4.96474446
7.91560000 4.96511927
7.91640000 4.96552472
7.91720000 4.96596782
7.91800000 4.96620854
7.91880000 4.96644932
7.91960000 4.96658464
7.92040000 4.96664773
7.92120000 4.96692238
7.92200000 4.96738167
7.92280000 4.96792099
7.92360000 4.96834804
7.92440000 4.96887340
7.92520000 4.96941139
7.92600000 4.97008079
7.92680000 4.97073413
7.92760000 4.97140171
7.92840000 4.97188998
7.92920000 4.97230287
7.93000000 4.97272423
7.93080000 4.97322681
7.93160000 4.97361706
7.93240000 4.97404763
7.93320000 4.97448040
7.93400000 4.97483485
7.93480000 4.97519822
7.93560000 4.97562202
7.93640000 4.97622824
7.93720000 4.97683372
7.93800000 4.97730301
7.93880000 4.97776633
7.93960000 4.97825615
7.94040000 4.97871859
7.94120000 4.97930367
7.94200000 4.97998956
7.94280000 4.98048014
7.94360000 4.98086188
7.94440000 4.98142638
7.94520000 4.98207045
7.94600000 4.98258080
7.94680000 4.98313078
7.94760000 4.98341585
7.94840000 4.98372407
7.94920000 4.98401687
7.95000000 4.98430624
7.95080000 4.98451103
7.95160000 4.98474608
7.95240000 4.98500531
7.95320000 4.98528343
7.95400000 4.98548525
7.95480000 4.98551391
7.95560000 4.98562915
7.95640000 4.98585517
7.95720000 4.98589929
7.95800000 4.98607935
7.95880000 4.98636223
7.95960000 4.98676207
7.96040000 4.98719355
7.96120000 4.98749288
7.96200000 4.98771306
7.96280000 4.98795476
7.96360000 4.98817412
7.96440000 4.98836981
7.96520000 4.98845033
7.96600000 4.98848539
7.96680000 4.98859202
7.96760000 4.98879618
7.96840000 4.98909126
7.96920000 4.98935043
7.97000000 4.98953858
7.97080000 4.98963979
7.97160000 4.98978901
7.97240000 4.98993565
7.97320000 4.99017415
7.97400000 4.99047080
7.97480000 4.99078496
7.97560000 4.99106106
7.97640000 4.99129693
7.97720000 4.99147290
7.97800000 4.99163880
7.97880000 4.99180070
7.97960000 4.99203495
7.98040000 4.99224018
7.98120000 4.99241231
7.98200000 4.99241256
7.98280000 4.99260269
7.98360000 4.99286863
7.98440000 4.99306536
7.98520000 4.99315568
7.98600000 4.99340410
7.98680000 4.99366751
7.98760000 4.99402922
7.98840000 4.99436663
7.98920000 4.99463651
7.99000000 4.99492933
7.99080000 4.99530771
7.99160000 4.99560579
7.99240000 4.99587700
7.99320000 4.99610472
7.99400000 4.99633713
7.99480000 4.99663704
7.99560000 4.99696430
7.99640000 4.99710974
7.99720000 4.99739888
7.99800000 4.99776523
7.99880000 4.99819422
7.99960000 4.99845061
8.00040000 4.99868231
8.00120000 4.99898349
8.00200000 4.99959334
8.00280000 5.00010076
8.00360000 5.00052308
8.00440000 5.00088508
8.00520000 5.00137464
8.00600000 5.00181637
8.00680000 5.00227267
8.00760000 5.00260827
8.00840000 5.00293645
8.00920000 5.00332017
8.01000000 5.00378036
8.01080000 5.00413242
8.01160000 5.00443741
8.01240000 5.00487196
8.01320000 5.00535832
8.01400000 5.00575642
8.01480000 5.00591428
8.01560000 5.00619281
8.01640000 5.00621212
8.01720000 5.00633771
8.01800000 5.00666412
8.01880000 5.00702604
8.01960000 5.00727255
8.02040000 5.00749048
8.02120000 5.00777238
8.02200000 5.00815842
8.02280000 5.00845936
8.02360000 5.00883009
8.02440000 5.00909655
8.02520000 5.00949971
8.02600000 5.00980522
8.02680000 5.01003516
8.02760000 5.01027793
8.02840000 5.01057996
8.02920000 5.01095542
8.03000000 5.01132794
8.03080000 5.01172433
8.03160000 5.01209836
8.03240000 5.01247285
8.03320000 5.01283805
8.03400000 5.01316351
8.03480000 5.01361162
8.03560000 5.01407249
8.03640000 5.01447245
8.03720000 5.01497648
8.03800000 5.01524163
8.03880000 5.01544719
8.03960000 5.01572819
8.04040000 5.01594015
8.04120000 5.01610586
8.04200000 5.01615561
8.04280000 5.01626876
8.04360000 5.01656233
8.04440000 5.01689735
8.04520000 5.01716867
8.04600000 5.01754813
8.04680000 5.01788461
8.04760000 5.01832283
8.04840000 5.01866877
8.04920000 5.01894256
8.05000000 5.01922542
8.05080000 5.01968803
8.05160000 5.02003056
8.05240000 5.02031250
8.05320000 5.02040355
8.05400000 5.02054307
8.05480000 5.02086161
8.05560000 5.02097373
8.05640000 5.02125880
8.05720000 5.02150311
8.05800000 5.02152420
8.05880000 5.02158207
8.05960000 5.02184896
8.06040000 5.02220061
8.06120000 5.02245766
8.06200000 5.02266153
8.06280000 5.02280779
8.06360000 5.02291044
8.06440000 5.02323466
8.06520000 5.02338804
8.06600000 5.02354093
8.06680000 5.02354586
8.06760000 5.02359628
8.06840000 5.02382412
8.06920000 5.02399176
8.07000000 5.02418686
8.07080000 5.02438326
8.07160000 5.02465013
8.07240000 5.02481831
8.07320000 5.02508318
8.07400000 5.02528500
8.07480000 5.02533754
8.07560000 5.02540947
8.07640000 5.02575461
8.07720000 5.02604202
8.07800000 5.02633576
8.07880000 5.02653110
8.07960000 5.02678432
8.08040000 5.02706849
8.08120000 5.02736187
8.08200000 5.02753144
8.08280000 5.02781959
8.08360000 5.02818785
8.08440000 5.02850414
8.08520000 5.02878156
8.08600000 5.02889387
8.08680000 5.02911527
8.08760000 5.02930878
8.08840000 5.02964592
8.08920000 5.03001332
8.09000000 5.03032616
8.09080000 5.03051069
8.09160000 5.03070284
8.09240000 5.03093533
8.09320000 5.03105332
8.09400000 5.03125254
8.09480000 5.03149440
8.09560000 5.03175944
8.09640000 5.03203355
8.09720000 5.03229033
8.09800000 5.03254361
8.09880000 5.03288943
8.09960000 5.03304943
8.10040000 5.03311780
8.10120000 5.03313765
8.10200000 5.03320522
8.10280000 5.03340358
8.10360000 5.03357366
8.10440000 5.03370126
8.10520000 5.03397826
8.10600000 5.03421697
8.10680000 5.03455662
8.10760000 5.03490333
8.10840000 5.03521838
8.10920000 5.03563281
8.11000000 5.03595145
8.11080000 5.03609875
8.11160000 5.03618842
8.11240000 5.03647785
8.11320000 5.03666251
8.11400000 5.03694165
8.11480000 5.03712365
8.11560000 5.03747205
8.11640000 5.03769389
8.11720000 5.03773118
8.11800000 5.03794460
8.11880000 5.03823020
8.11960000 5.03843977
8.12040000 5.03871678
8.12120000 5.03910221
8.12200000 5.03935297
8.12280000 5.03915735
8.12360000 5.03885668
8.12440000 5.03851878
8.12520000 5.03807350
8.12600000 5.03777829
8.12680000 5.03744112
8.12760000 5.03704027
8.12840000 5.03654896
8.12920000 5.03605344
8.13000000 5.03559019
8.13080000 5.03522088
8.13160000 5.03503045
8.13240000 5.03478017
8.13320000 5.03464396
8.13400000 5.03439261
8.13480000 5.03419417
8.13560000 5.03408309
8.13640000 5.03394026
8.13720000 5.03387823
8.13800000 5.03407582
8.13880000 5.03403378
8.13960000 5.03407156
8.14040000 5.03411061
8.14120000 5.03429706
8.14200000 5.03438223
8.14280000 5.03439212
8.14360000 5.03424556
8.14440000 5.03405388
8.14520000 5.03360997
8.14600000 5.03320105
8.14680000 5.03299988
8.14760000 5.03286854
8.14840000 5.03264812
8.14920000 5.03240971
8.15000000 5.03224840
8.15080000 5.03214311
8.15160000 5.03201963
8.15240000 5.03174633
8.15320000 5.03158392
8.15400000 5.03141615
8.15480000 5.03145718
8.15560000 5.03137095
8.15640000 5.03116937
8.15720000 5.03100570
8.15800000 5.03085321
8.15880000 5.03062000
8.15960000 5.03044002
8.16040000 5.03033778
8.16120000 5.03006379
8.16200000 5.03005107
8.16280000 5.03034272
8.16360000 5.03045584
8.16440000 5.03068841
8.16520000 5.03104867
8.16600000 5.03124038
8.16680000 5.03145073
8.16760000 5.03182271
8.16840000 5.03220711
8.16920000 5.03260504
8.17000000 5.03306506
8.17080000 5.03338732
8.17160000 5.03361663
8.17240000 5.03382959
8.17320000 5.03411245
8.17400000 5.03442104
8.17480000 5.03462839
8.17560000 5.03483812
8.17640000 5.03502346
8.17720000 5.03529763
8.17800000 5.03513682
8.17880000 5.03502400
8.17960000 5.03495278
8.18040000 5.03470901
8.18120000 5.03442048
8.18200000 5.03420414
8.18280000 5.03389305
8.18360000 5.03376029
8.18440000 5.03355361
8.18520000 5.03358105
8.18600000 5.03358315
8.18680000 5.03350982
8.18760000 5.03326684
8.18840000 5.03313664
8.18920000 5.03304718
8.19000000 5.03293851
8.19080000 5.03284048
8.19160000 5.03281679
8.19240000 5.03281909
8.19320000 5.03268075
8.19400000 5.03257051
8.19480000 5.03241396
8.19560000 5.03226706
8.19640000 5.03223363
8.19720000 5.03220099
8.19800000 5.03203157
8.19880000 5.03190952
8.19960000 5.03183091
8.20040000 5.03171074
8.20120000 5.03164026
8.20200000 5.03132233
8.20280000 5.03101553
8.20360000 5.03093899
8.20440000 5.03092090
8.20520000 5.03100899
8.20600000 5.03104107
8.20680000 5.03098718
8.20760000 5.03081633
8.20840000 5.03065238
8.20920000 5.03053762
8.21000000 5.03033799
8.21080000 5.03018877
8.21160000 5.03013848
8.21240000 5.02999244
8.21320000 5.02970762
8.21400000 5.02950501
8.21480000 5.02926967
8.21560000 5.02882536
8.21640000 5.02838294
8.21720000 5.02775657
8.21800000 5.02744960
8.21880000 5.02715154
8.21960000 5.02674655
8.22040000 5.02644947
8.22120000 5.02620101
8.22200000 5.02594870
8.22280000 5.02580951
8.22360000 5.02562867
8.22440000 5.02551130
8.22520000 5.02550089
8.22600000 5.02551407
8.22680000 5.02548039
8.22760000 5.02550515
8.22840000 5.02530178
8.22920000 5.02509634
8.23000000 5.02486958
8.23080000 5.02460458
8.23160000 5.02425461
8.23240000 5.02410782
8.23320000 5.02410553
8.23400000 5.02406078
8.23480000 5.02406651
8.23560000 5.02394589
8.23640000 5.02374027
8.23720000 5.02357797
8.23800000 5.02345139
8.23880000 5.02334025
8.23960000 5.02320518
8.24040000 5.02301623
8.24120000 5.02289548
8.24200000 5.02291254
8.24280000 5.02294522
8.24360000 5.02291219
8.24440000 5.02279277
8.24520000 5.02257311
8.24600000 5.02247325
8.24680000 5.02240747
8.24760000 5.02234519
8.24840000 5.02224499
8.24920000 5.02213755
8.25000000 5.02203928
8.25080000 5.02204488
8.25160000 5.02194595
8.25240000 5.02199282
8.25320000 5.02219710
8.25400000 5.02230290
8.25480000 5.02246252
8.25560000 5.02280439
8.25640000 5.02322046
8.25720000 5.02366834
8.25800000 5.02409018
8.25880000 5.02460584
8.25960000 5.02516216
8.26040000 5.02585387
8.26120000 5.02643825
8.26200000 5.02693569
8.26280000 5.02750083
8.26360000 5.02800919
8.26440000 5.02854167
8.26520000 5.02889781
8.26600000 5.02920083
8.26680000 5.02954455
8.26760000 5.02992350
8.26840000 5.03046537
8.26920000 5.03089647
8.27000000 5.03131040
8.27080000 5.03177252
8.27160000 5.03220957
8.27240000 5.03252560
8.27320000 5.03282243
8.27400000 5.03315942
8.27480000 5.03343278
8.27560000 5.03377534
8.27640000 5.03425490
8.27720000 5.03467990
8.27800000 5.03511725
8.27880000 5.03556517
8.27960000 5.03604715
8.28040000 5.03649963
8.28120000 5.03698008
8.28200000 5.03739106
8.28280000 5.03775124
8.28360000 5.03809778
8.28440000 5.03839290
8.28520000 5.03865104
8.28600000 5.03897768
8.28680000 5.03927486
8.28760000 5.03950985
8.28840000 5.03972403
8.28920000 5.03996596
8.29000000 5.04017705
8.29080000 5.04048497
8.29160000 5.04078796
8.29240000 5.04100286
8.29320000 5.04120845
8.29400000 5.04142376
8.29480000 5.04163331
8.29560000 5.04183429
8.29640000 5.04200058
8.29720000 5.04216953
8.29800000 5.04219255
8.29880000 5.04219888
8.29960000 5.04223893
8.30040000 5.04222371
8.30120000 5.04221784
8.30200000 5.04226752
8.30280000 5.04228630
8.30360000 5.04238584
8.30440000 5.04247445
8.30520000 5.04254238
8.30600000 5.04277227
8.30680000 5.04294187
8.30760000 5.04301811
8.30840000 5.04313846
8.30920000 5.04330705
8.31000000 5.04353983
8.31080000 5.04371185
8.31160000 5.04398455
8.31240000 5.04419874
8.31320000 5.04434604
8.31400000 5.04448212
8.31480000 5.04460806
8.31560000 5.04469360
8.31640000 5.04469302
8.31720000 5.04474626
8.31800000 5.04484654
8.31880000 5.04494231
8.31960000 5.04499851
8.32040000 5.04507867
8.32120000 5.04510089
8.32200000 5.04529967
8.32280000 5.04562474
8.32360000 5.04589678
8.32440000 5.04617507
8.32520000 5.04658800
8.32600000 5.04690163
8.32680000 5.04739002
8.32760000 5.04797182
8.32840000 5.04845994
8.32920000 5.04881988
8.33000000 5.04922099
8.33080000 5.04960743
8.33160000 5.04992504
8.33240000 5.05033609
8.33320000 5.05070666
8.33400000 5.05108416
8.33480000 5.05147449
8.33560000 5.05182393
8.33640000 5.05206935
8.33720000 5.05235416
8.33800000 5.05277847
8.33880000 5.05314411
8.33960000 5.05342646
8.34040000 5.05376261
8.34120000 5.05397907
8.34200000 5.05427421
8.34280000 5.05451773
8.34360000 5.05478053
8.34440000 5.05499411
8.34520000 5.05522349
8.34600000 5.05532008
8.34680000 5.05540650
8.34760000 5.05555832
8.34840000 5.05559924
8.34920000 5.05563631
8.35000000 5.05571075
8.35080000 5.05579066
8.35160000 5.05586111
8.35240000 5.05587208
8.35320000 5.05593011
8.35400000 5.05602912
8.35480000 5.05608514
8.35560000 5.05615778
8.35640000 5.05635369
8.35720000 5.05641190
8.35800000 5.05643331
8.35880000 5.05638817
8.35960000 5.05630738
8.36040000 5.05628493
8.36120000 5.05624253
8.36200000 5.05618979
8.36280000 5.05596205
8.36360000 5.05578523
8.36440000 5.05562272
8.36520000 5.05532774
8.36600000 5.05518158
8.36680000 5.05489797
8.36760000 5.05450534
8.36840000 5.05428964
8.36920000 5.05415707
8.37000000 5.05402647
8.37080000 5.05348260
8.37160000 5.05303090
8.37240000 5.05264925
8.37320000 5.05234170
8.37400000 5.05204657
8.37480000 5.05177123
8.37560000 5.05150294
8.37640000 5.05131087
8.37720000 5.05108972
8.37800000 5.05083338
8.37880000 5.05067508
8.37960000 5.05059032
8.38040000 5.05046433
8.38120000 5.05052848
8.38200000 5.05052121
8.38280000 5.05050243
8.38360000 5.05042916
8.38440000 5.05028691
8.38520000 5.05018956
8.38600000 5.05001319
8.38680000 5.04989109
8.38760000 5.04972483
8.38840000 5.04958897
8.38920000 5.04952372
8.39000000 5.04940357
8.39080000 5.04931716
8.39160000 5.04909784
8.39240000 5.04902708
8.39320000 5.04903970
8.39400000 5.04890780
8.39480000 5.04881118
8.39560000 5.04876483
8.39640000 5.04868205
8.39720000 5.04874603
8.39800000 5.04877705
8.39880000 5.04892109
8.39960000 5.04916164
8.40040000 5.04936038
8.40120000 5.04949381
8.40200000 5.04949933
8.40280000 5.04965404
8.40360000 5.04981536
8.40440000 5.05002448
8.40520000 5.05025430
8.40600000 5.05042969
8.40680000 5.05052387
8.40760000 5.05067568
8.40840000 5.05061196
8.40920000 5.05047503
8.41000000 5.05040265
8.41080000 5.05075125
8.41160000 5.05104585
8.41240000 5.05117161
8.41320000 5.05118102
8.41400000 5.05116855
8.41480000 5.05121580
8.41560000 5.05115988
8.41640000 5.05108250
8.41720000 5.05108106
8.41800000 5.05107685
8.41880000 5.05100127
8.41960000 5.05093618
8.42040000 5.05084888
8.42120000 5.05065086
8.42200000 5.05050736
8.42280000 5.05038418
8.42360000 5.05033744
8.42440000 5.05041683
8.42520000 5.05053511
8.42600000 5.05068076
8.42680000 5.05082863
8.42760000 5.05105228
8.42840000 5.05119420
8.42920000 5.05123136
8.43000000 5.05130665
8.43080000 5.05137373
8.43160000 5.05154867
8.43240000 5.05163537
8.43320000 5.05158832
8.43400000 5.05161905
8.43480000 5.05168726
8.43560000 5.05164665
8.43640000 5.05142666
8.43720000 5.05129396
8.43800000 5.05128309
8.43880000 5.05117073
8.43960000 5.05112453
8.44040000 5.05102315
8.44120000 5.05102811
8.44200000 5.05097124
8.44280000 5.05078728
8.44360000 5.05066699
8.44440000 5.05045084
8.44520000 5.05023389
8.44600000 5.05000142
8.44680000 5.04984838
8.44760000 5.04973814
8.44840000 5.04982171
8.44920000 5.05002706
8.45000000 5.05014715
8.45080000 5.05018934
8.45160000 5.05030196
8.45240000 5.05055857
8.45320000 5.05087244
8.45400000 5.05120910
8.45480000 5.05139924
8.45560000 5.05170650
8.45640000 5.05206331
8.45720000 5.05231726
8.45800000 5.05254322
8.45880000 5.05284073
8.45960000 5.05312661
8.46040000 5.05345639
8.46120000 5.05385541
8.46200000 5.05422520
8.46280000 5.05456784
8.46360000 5.05488744
8.46440000 5.05522476
8.46520000 5.05562748
8.46600000 5.05604226
8.46680000 5.05636858
8.46760000 5.05654646
8.46840000 5.05678087
8.46920000 5.05704477
8.47000000 5.05730248
8.47080000 5.05761971
8.47160000 5.05794274
8.47240000 5.05821488
8.47320000 5.05850258
8.47400000 5.05890946
8.47480000 5.05932754
8.47560000 5.05977579
8.47640000 5.06034828
8.47720000 5.06087659
8.47800000 5.06139620
8.47880000 5.06190450
8.47960000 5.06222104
8.48040000 5.06255018
8.48120000 5.06285687
8.48200000 5.06330341
8.48280000 5.06380360
8.48360000 5.06422180
8.48440000 5.06467899
8.48520000 5.06519416
8.48600000 5.06573999
8.48680000 5.06630172
8.48760000 5.06675494
8.48840000 5.06726565
8.48920000 5.06765148
8.49000000 5.06807899
8.49080000 5.06846999
8.49160000 5.06881833
8.49240000 5.06914348
8.49320000 5.06955417
8.49400000 5.06994999
8.49480000 5.07041762
8.49560000 5.07095931
8.49640000 5.07154688
8.49720000 5.07217156
8.49800000 5.07269562
8.49880000 5.07319125
8.49960000 5.07369007
8.50040000 5.07414933
8.50120000 5.07456868
8.50200000 5.07503012
8.50280000 5.07556231
8.50360000 5.07603822
8.50440000 5.07649365
8.50520000 5.07681743
8.50600000 5.07715282
8.50680000 5.07763453
8.50760000 5.07817962
8.50840000 5.07874943
8.50920000 5.07932329
8.51000000 5.07983712
8.51080000 5.08028089
8.51160000 5.08073567
8.51240000 5.08128309
8.51320000 5.08185145
8.51400000 5.08233074
8.51480000 5.08279939
8.51560000 5.08336268
8.51640000 5.08389703
8.51720000 5.08440252
8.51800000 5.08486820
8.51880000 5.08536249
8.51960000 5.08581688
8.52040000 5.08628311
8.52120000 5.08671339
8.52200000 5.08719550
8.52280000 5.08768751
8.52360000 5.08817164
8.52440000 5.08863045
8.52520000 5.08905186
8.52600000 5.08950754
8.52680000 5.08991773
8.52760000 5.09033869
8.52840000 5.09062346
8.52920000 5.09091519
8.53000000 5.09124988
8.53080000 5.09158846
8.53160000 5.09189975
8.53240000 5.09219779
8.53320000 5.09244519
8.53400000 5.09281169
8.53480000 5.09325025
8.53560000 5.09359422
8.53640000 5.09380238
8.53720000 5.09392803
8.53800000 5.09420762
8.53880000 5.09452218
8.53960000 5.09479299
8.54040000 5.09512376
8.54120000 5.09551235
8.54200000 5.09585421
8.54280000 5.09617764
8.54360000 5.09646691
8.54440000 5.09674024
8.54520000 5.09700912
8.54600000 5.09724394
8.54680000 5.09739665
8.54760000 5.09760904
8.54840000 5.09784869
8.54920000 5.09796223
8.55000000 5.09816374
8.55080000 5.09833836
8.55160000 5.09850164
8.55240000 5.09870737
8.55320000 5.09899891
8.55400000 5.09926967
8.55480000 5.09945030
8.55560000 5.09962326
8.55640000 5.09983833
8.55720000 5.10002892
8.55800000 5.10020737
8.55880000 5.10033672
8.55960000 5.10064741
8.56040000 5.10098107
8.56120000 5.10137356
8.56200000 5.10179522
8.56280000 5.10218383
8.56360000 5.10260776
8.56440000 5.10299073
8.56520000 5.10335147
8.56600000 5.10363370
8.56680000 5.10394240
8.56760000 5.10426129
8.56840000 5.10469145
8.56920000 5.10527762
8.57000000 5.10576196
8.57080000 5.10617055
8.57160000 5.10661889
8.57240000 5.10709900
8.57320000 5.10759582
8.57400000 5.10806008
8.57480000 5.10842786
8.57560000 5.10866617
8.57640000 5.10899882
8.57720000 5.10940525
8.57800000 5.10989935
8.57880000 5.11032725
8.57960000 5.11067934
8.58040000 5.11100413
8.58120000 5.11133753
8.58200000 5.11166345
8.58280000 5.11184151
8.58360000 5.11204116
8.58440000 5.11223932
8.58520000 5.11244823
8.58600000 5.11277143
8.58680000 5.11307341
8.58760000 5.11333071
8.58840000 5.11358381
8.58920000 5.11396484
8.59000000 5.11429387
8.59080000 5.11462797
8.59160000 5.11502094
8.59240000 5.11544900
8.59320000 5.11581636
8.59400000 5.11617399
8.59480000 5.11664415
8.59560000 5.11722320
8.59640000 5.11771933
8.59720000 5.11815125
8.59800000 5.11857258
8.59880000 5.11909870
8.59960000 5.11963679