File: plots/rawdata/Figure2-15K.txt
# strain(%), strain_el(%), stress(GPa)
0.00000000 -0.00013068 0.00000000
0.00080000 0.00196821 0.00162734
0.00160000 0.00263076 0.00214104
0.00240000 0.00223484 0.00183407
0.00320000 0.00571427 0.00453180
0.00400000 0.00679829 0.00537228
0.00480000 0.00467350 0.00372485
0.00560000 0.00669569 0.00529273
0.00640000 0.00731186 0.00577047
0.00720000 0.00819381 0.00645428
0.00800000 0.00894183 0.00703425
0.00880000 0.00844749 0.00665097
0.00960000 0.01282737 0.01004685
0.01040000 0.00990405 0.00778029
0.01120000 0.01229060 0.00963067
0.01200000 0.01455979 0.01139006
0.01280000 0.01606250 0.01255516
0.01360000 0.01403868 0.01098602
0.01440000 0.01430071 0.01118918
0.01520000 0.01491298 0.01166390
0.01600000 0.01865910 0.01456840
0.01680000 0.01998355 0.01559529
0.01760000 0.02080496 0.01623216
0.01840000 0.02125478 0.01658093
0.01920000 0.01908037 0.01489502
0.02000000 0.01958097 0.01528316
0.02080000 0.02331440 0.01817783
0.02160000 0.02506628 0.01953612
0.02240000 0.02498780 0.01947528
0.02320000 0.02395648 0.01867566
0.02400000 0.02509050 0.01955490
0.02480000 0.02726741 0.02124274
0.02560000 0.02870330 0.02235604
0.02640000 0.02995475 0.02332633
0.02720000 0.03064799 0.02386383
0.02800000 0.03104023 0.02416795
0.02880000 0.03149453 0.02452018
0.02960000 0.03212022 0.02500530
0.03040000 0.03300856 0.02569407
0.03120000 0.03483490 0.02711009
0.03200000 0.03502349 0.02725631
0.03280000 0.03545355 0.02758976
0.03360000 0.03639980 0.02832341
0.03440000 0.03399065 0.02645551
0.03520000 0.03490095 0.02716130
0.03600000 0.03654783 0.02843819
0.03680000 0.03649855 0.02839998
0.03760000 0.03851572 0.02996396
0.03840000 0.03810975 0.02964921
0.03920000 0.04224852 0.03285814
0.04000000 0.04250454 0.03305665
0.04080000 0.04335159 0.03371339
0.04160000 0.04224556 0.03285585
0.04240000 0.04209198 0.03273677
0.04320000 0.04385724 0.03410544
0.04400000 0.04362768 0.03392746
0.04480000 0.04434430 0.03448307
0.04560000 0.04506546 0.03504222
0.04640000 0.04896606 0.03806650
0.04720000 0.04970060 0.03863602
0.04800000 0.04746205 0.03690038
0.04880000 0.04849255 0.03769937
0.04960000 0.04920315 0.03825032
0.05040000 0.05003231 0.03889320
0.05120000 0.05069833 0.03940959
0.05200000 0.05176908 0.04023978
0.05280000 0.05227754 0.04063401
0.05360000 0.05632795 0.04377444
0.05440000 0.05739448 0.04460136
0.05520000 0.05854028 0.04548974
0.05600000 0.05906525 0.04589677
0.05680000 0.06001633 0.04663418
0.05760000 0.05733311 0.04455378
0.05840000 0.05839918 0.04538034
0.05920000 0.05872289 0.04563132
0.06000000 0.05955055 0.04627304
0.06080000 0.06035687 0.04689821
0.06160000 0.06120849 0.04755850
0.06240000 0.06191753 0.04810824
0.06320000 0.06275999 0.04876144
0.06400000 0.06725484 0.05224646
0.06480000 0.06882651 0.05346503
0.06560000 0.06522927 0.05067596
0.06640000 0.06688774 0.05196183
0.06720000 0.06678909 0.05188535
0.06800000 0.07145192 0.05550061
0.06880000 0.07261259 0.05640052
0.06960000 0.07234665 0.05619433
0.07040000 0.07297926 0.05668481
0.07120000 0.07369232 0.05723767
0.07200000 0.07507966 0.05831333
0.07280000 0.07608714 0.05909446
0.07360000 0.07695126 0.05976444
0.07440000 0.07701407 0.05981315
0.07520000 0.07796310 0.06054897
0.07600000 0.07883496 0.06122495
0.07680000 0.07961444 0.06182931
0.07760000 0.08012367 0.06222413
0.07840000 0.08104912 0.06294167
0.07920000 0.08181379 0.06353454
0.08000000 0.08253075 0.06409043
0.08080000 0.08350470 0.06484557
0.08160000 0.08112049 0.06299700
0.08240000 0.08200354 0.06368166
0.08320000 0.08251046 0.06407470
0.08400000 0.08712422 0.06765192
0.08480000 0.08731354 0.06779871
0.08560000 0.08849627 0.06871572
0.08640000 0.08578401 0.06661281
0.08720000 0.08660732 0.06725114
0.08800000 0.09089746 0.07057745
0.08880000 0.09226729 0.07163953
0.08960000 0.08895332 0.06907009
0.09040000 0.08980049 0.06972693
0.09120000 0.09332627 0.07246060
0.09200000 0.09575635 0.07434472
0.09280000 0.09213687 0.07153841
0.09360000 0.09288846 0.07212115
0.09440000 0.09376928 0.07280407
0.09520000 0.09520109 0.07391421
0.09600000 0.09519663 0.07391075
0.09680000 0.09939465 0.07716563
0.09760000 0.10141080 0.07872882
0.09840000 0.10138140 0.07870603
0.09920000 0.10182528 0.07905018
0.10000000 0.10266609 0.07970209
0.10080000 0.10388370 0.08064615
0.10160000 0.10494600 0.08146979
0.10240000 0.10500794 0.08151782
0.10320000 0.10582447 0.08215090
0.10400000 0.10661601 0.08276461
0.10480000 0.10807562 0.08389630
0.10560000 0.10873564 0.08440805
0.10640000 0.10950229 0.08500246
0.10720000 0.10978107 0.08521861
0.10800000 0.10716743 0.08319215
0.10880000 0.10814053 0.08394663
0.10960000 0.10932709 0.08486661
0.11040000 0.10955222 0.08504117
0.11120000 0.11045884 0.08574410
0.11200000 0.11132694 0.08641717
0.11280000 0.11544110 0.08960703
0.11360000 0.11618346 0.09018261
0.11440000 0.11373734 0.08828604
0.11520000 0.11443678 0.08882834
0.11600000 0.11857035 0.09203325
0.11680000 0.11952820 0.09277591
0.11760000 0.11679605 0.09065757
0.11840000 0.11804581 0.09162655
0.11920000 0.11852181 0.09199562
0.12000000 0.11912839 0.09246592
0.12080000 0.11999635 0.09313889
0.12160000 0.12080390 0.09376501
0.12240000 0.12168092 0.09444499
0.12320000 0.12255619 0.09512362
0.12400000 0.12349249 0.09584957
0.12480000 0.12385369 0.09612962
0.12560000 0.12487993 0.09692530
0.12640000 0.12573171 0.09758572
0.12720000 0.12670129 0.09833747
0.12800000 0.12727744 0.09878418
0.12880000 0.12803717 0.09937322
0.12960000 0.12889770 0.10004042
0.13040000 0.12983345 0.10076595
0.13120000 0.13421490 0.10416305
0.13200000 0.13468442 0.10452708
0.13280000 0.13187196 0.10234648
0.13360000 0.13242903 0.10277839
0.13440000 0.13356860 0.10366195
0.13520000 0.13427095 0.10420651
0.13600000 0.13498539 0.10476044
0.13680000 0.13606035 0.10559389
0.13760000 0.13648343 0.10592192
0.13840000 0.13771917 0.10688003
0.13920000 0.13831689 0.10734347
0.14000000 0.13899738 0.10787107
0.14080000 0.13993643 0.10859916
0.14160000 0.14422061 0.11192084
0.14240000 0.14488030 0.11243232
0.14320000 0.14227146 0.11040959
0.14400000 0.14337089 0.11126202
0.14480000 0.14766840 0.11459404
0.14560000 0.14820274 0.11500833
0.14640000 0.14550483 0.11291654
0.14720000 0.14605219 0.11334093
0.14800000 0.15050353 0.11679221
0.14880000 0.15161416 0.11765333
0.14960000 0.14854991 0.11527750
0.15040000 0.14960200 0.11609323
0.15120000 0.15040890 0.11671885
0.15200000 0.15118082 0.11731734
0.15280000 0.15544511 0.12062360
0.15360000 0.15602519 0.12107336
0.15440000 0.15343857 0.11906786
0.15520000 0.15404720 0.11953975
0.15600000 0.15525443 0.12047577
0.15680000 0.15579308 0.12089340
0.15760000 0.15711509 0.12191840
0.15840000 0.15743343 0.12216522
0.15920000 0.15822438 0.12277847
0.16000000 0.15897540 0.12336077
0.16080000 0.15982269 0.12401770
0.16160000 0.16426890 0.12746501
0.16240000 0.16139267 0.12523497
0.16320000 0.16232073 0.12595452
0.16400000 0.16655195 0.12923515
0.16480000 0.16741043 0.12990076
0.16560000 0.16808172 0.13042123
0.16640000 0.16538106 0.12832731
0.16720000 0.16608399 0.12887232
0.16800000 0.16674423 0.12938422
0.16880000 0.16782469 0.13022195
0.16960000 0.16866910 0.13087665
0.17040000 0.16917659 0.13127012
0.17120000 0.17376075 0.13482439
0.17200000 0.17464302 0.13550845
0.17280000 0.17172203 0.13324370
0.17360000 0.17236644 0.13374333
0.17440000 0.17320355 0.13439237
0.17520000 0.17436390 0.13529204
0.17600000 0.17503328 0.13581103
0.17680000 0.17565568 0.13629360
0.17760000 0.17678821 0.13717169
0.17840000 0.17717417 0.13747094
0.17920000 0.18142697 0.14076829
0.18000000 0.18253904 0.14163052
0.18080000 0.17988680 0.13957414
0.18160000 0.18051666 0.14006249
0.18240000 0.18152992 0.14084811
0.18320000 0.18214760 0.14132703
0.18400000 0.18277440 0.14181300
0.18480000 0.18377919 0.14259205
0.18560000 0.18820927 0.14602686
0.18640000 0.18524923 0.14373183
0.18720000 0.18584302 0.14419222
0.18800000 0.18675171 0.14489676
0.18880000 0.19189659 0.14888577
0.18960000 0.19205244 0.14900661
0.19040000 0.18918709 0.14678499
0.19120000 0.18983206 0.14728507
0.19200000 0.19455008 0.15094312
0.19280000 0.19541208 0.15161146
0.19360000 0.19208443 0.14903141
0.19440000 0.19319407 0.14989176
0.19520000 0.19447960 0.15088847
0.19600000 0.19463222 0.15100681
0.19680000 0.19555222 0.15172011
0.19760000 0.19660265 0.15253455
0.19840000 0.19701935 0.15285764
0.19920000 0.19811026 0.15370346
0.20000000 0.20251015 0.15711485
0.20080000 0.19960251 0.15486046
0.20160000 0.20020853 0.15533033
0.20240000 0.20174607 0.15652243
0.20320000 0.20181880 0.15657882
0.20400000 0.20295695 0.15746127
0.20480000 0.20337606 0.15778622
0.20560000 0.20819330 0.16152121
0.20640000 0.20903124 0.16217089
0.20720000 0.20600951 0.15982804
0.20800000 0.20649413 0.16020378
0.20880000 0.21142984 0.16403061
0.20960000 0.20839319 0.16167619
0.21040000 0.20918028 0.16228645
0.21120000 0.20989116 0.16283762
0.21200000 0.21062207 0.16340432
0.21280000 0.21508095 0.16686146
0.21360000 0.21628675 0.16779635
0.21440000 0.21292607 0.16519070
0.21520000 0.21344045 0.16558951
0.21600000 0.21430377 0.16625888
0.21680000 0.21552306 0.16720424
0.21760000 0.21630214 0.16780829
0.21840000 0.21712006 0.16844245
0.21920000 0.21821184 0.16928895
0.22000000 0.21840801 0.16944105
0.22080000 0.21936842 0.17018569
0.22160000 0.22037592 0.17096684
0.22240000 0.22112760 0.17154964
0.22320000 0.22158983 0.17190803
0.22400000 0.22275414 0.17281076
0.22480000 0.22340262 0.17331355
0.22560000 0.22741772 0.17642661
0.22640000 0.22872430 0.17743965
0.22720000 0.22566721 0.17506937
0.22800000 0.22628504 0.17554840
0.22880000 0.23063658 0.17892230
0.22960000 0.23185079 0.17986372
0.23040000 0.23267889 0.18050579
0.23120000 0.23310137 0.18083335
0.23200000 0.23040819 0.17874523
0.23280000 0.23111528 0.17929346
0.23360000 0.23594225 0.18303599
0.23440000 0.23632735 0.18333457
0.23520000 0.23397846 0.18151338
0.23600000 0.23432411 0.18178138
0.23680000 0.23903909 0.18543708
0.23760000 0.24012939 0.18628243
0.23840000 0.23696461 0.18382866
0.23920000 0.23735648 0.18413249
0.24000000 0.23812772 0.18473046
0.24080000 0.23952507 0.18581388
0.24160000 0.24028380 0.18640215
0.24240000 0.24438584 0.18958261
0.24320000 0.24561275 0.19053388
0.24400000 0.24263137 0.18822230
0.24480000 0.24303910 0.18853843
0.24560000 0.24422557 0.18945835
0.24640000 0.24498391 0.19004631
0.24720000 0.24590926 0.19076377
0.24800000 0.24978118 0.19376581
0.24880000 0.25107459 0.19476865
0.24960000 0.24817140 0.19251769
0.25040000 0.24841098 0.19270345
0.25120000 0.24928523 0.19338128
0.25200000 0.25028541 0.19415676
0.25280000 0.25106683 0.19476263
0.25360000 0.25166374 0.19522543
0.25440000 0.25263488 0.19597839
0.25520000 0.25315654 0.19638286
0.25600000 0.25444316 0.19738042
0.25680000 0.25507184 0.19786786
0.25760000 0.25564145 0.19830950
0.25840000 0.25689653 0.19928261
0.25920000 0.25709254 0.19943458
0.26000000 0.25829950 0.20037038
0.26080000 0.25902976 0.20093658
0.26160000 0.25986695 0.20158568
0.26240000 0.26061373 0.20216469
0.26320000 0.26112236 0.20255905
0.26400000 0.26239226 0.20354365
0.26480000 0.26304177 0.20404723
0.26560000 0.26372450 0.20457658
0.26640000 0.26461508 0.20526708
0.26720000 0.26546366 0.20592502
0.26800000 0.26582751 0.20620712
0.26880000 0.27035477 0.20971727
0.26960000 0.27193225 0.21094035
0.27040000 0.27215761 0.21111508
0.27120000 0.26940448 0.20898048
0.27200000 0.26986746 0.20933944
0.27280000 0.27109452 0.21029083
0.27360000 0.27177948 0.21082190
0.27440000 0.27251112 0.21138917
0.27520000 0.27335705 0.21204505
0.27600000 0.27390739 0.21247175
0.27680000 0.27472138 0.21310286
0.27760000 0.27548245 0.21369295
0.27840000 0.27618774 0.21423979
0.27920000 0.27700332 0.21487214
0.28000000 0.27785108 0.21552944
0.28080000 0.27877565 0.21624629
0.28160000 0.27938785 0.21672095
0.28240000 0.28013034 0.21729663
0.28320000 0.28127195 0.21818176
0.28400000 0.28206197 0.21879429
0.28480000 0.28632129 0.22209670
0.28560000 0.28350632 0.21991415
0.28640000 0.28449260 0.22067885
0.28720000 0.28887550 0.22407707
0.28800000 0.28943461 0.22451057
0.28880000 0.28700755 0.22262878
0.28960000 0.28736980 0.22290965
0.29040000 0.29176561 0.22631788
0.29120000 0.28898504 0.22416200
0.29200000 0.29002353 0.22496718
0.29280000 0.29070859 0.22549834
0.29360000 0.29152901 0.22613444
0.29440000 0.29231117 0.22674088
0.29520000 0.29296187 0.22724538
0.29600000 0.29381346 0.22790565
0.29680000 0.29463990 0.22854643
0.29760000 0.29549103 0.22920633
0.29840000 0.29611576 0.22969071
0.29920000 0.29695383 0.23034050
0.30000000 0.29777748 0.23097911
0.30080000 0.29885495 0.23181450
0.30160000 0.29943962 0.23226782
0.30240000 0.30011613 0.23279235
0.30320000 0.30093857 0.23343001
0.30400000 0.30162856 0.23396499
0.30480000 0.30220113 0.23440892
0.30560000 0.30330005 0.23526096
0.30640000 0.30412613 0.23590144
0.30720000 0.30545330 0.23693045
0.30800000 0.30954308 0.24010141
0.30880000 0.31022945 0.24063357
0.30960000 0.30714245 0.23824011
0.31040000 0.30786486 0.23880022
0.31120000 0.30874211 0.23948038
0.31200000 0.30921496 0.23984700
0.31280000 0.31070544 0.24100262
0.31360000 0.31103133 0.24125530
0.31440000 0.31184040 0.24188260
0.31520000 0.31289482 0.24270013
0.31600000 0.31393310 0.24350515
0.31680000 0.31404645 0.24359303
0.31760000 0.31495459 0.24429714
0.31840000 0.31614717 0.24522179
0.31920000 0.31689980 0.24580534
0.32000000 0.31753191 0.24629544
0.32080000 0.31803850 0.24668821
0.32160000 0.31963806 0.24792841
0.32240000 0.31999019 0.24820143
0.32320000 0.32047225 0.24857519
0.32400000 0.32168907 0.24951863
0.32480000 0.32245461 0.25011218
0.32560000 0.32312471 0.25063174
0.32640000 0.32758912 0.25409316
0.32720000 0.32495731 0.25205262
0.32800000 0.32602281 0.25287874
0.32880000 0.32603952 0.25289170
0.32960000 0.32749651 0.25402136
0.33040000 0.32783135 0.25428097
0.33120000 0.32891202 0.25511885
0.33200000 0.32923175 0.25536675
0.33280000 0.33054975 0.25638865
0.33360000 0.32637300 0.25315026
0.33440000 0.33187957 0.25741970
0.33520000 0.33244106 0.25785504
0.33600000 0.33331577 0.25853324
0.33680000 0.33026043 0.25616433
0.33760000 0.33530472 0.26007535
0.33840000 0.33552742 0.26024801
0.33920000 0.33681907 0.26124948
0.34000000 0.33253999 0.25793175
0.34080000 0.33811441 0.26225380
0.34160000 0.33921338 0.26310587
0.34240000 0.33960830 0.26341207
0.34320000 0.34014423 0.26382760
0.34400000 0.34127731 0.26470612
0.34480000 0.34230998 0.26550678
0.34560000 0.34291754 0.26597785
0.34640000 0.34337505 0.26633257
0.34720000 0.34462657 0.26730292
0.34800000 0.34553663 0.26800852
0.34880000 0.34616790 0.26849797
0.34960000 0.34649864 0.26875440
0.35040000 0.34791975 0.26985624
0.35120000 0.34420326 0.26697471
0.35200000 0.34601243 0.26837742
0.35280000 0.35003887 0.27149927
0.35360000 0.35053628 0.27188493
0.35440000 0.35133192 0.27250182
0.35520000 0.35247231 0.27338601
0.35600000 0.35340984 0.27411291
0.35680000 0.34956930 0.27113519
0.35760000 0.34937124 0.27098164
0.35840000 0.35602896 0.27614361
0.35920000 0.35669071 0.27665669
0.36000000 0.35733827 0.27715876
0.36080000 0.35268943 0.27355435
0.36160000 0.35364577 0.27429583
0.36240000 0.35540659 0.27566106
0.36320000 0.36002779 0.27924405
0.36400000 0.36081247 0.27985244
0.36480000 0.35866316 0.27818600
0.36560000 0.35806778 0.27772438
0.36640000 0.36375690 0.28213537
0.36720000 0.36439702 0.28263167
0.36800000 0.36531467 0.28334316
0.36880000 0.36176498 0.28059096
0.36960000 0.36165057 0.28050225
0.37040000 0.36212536 0.28087037
0.37120000 0.36287990 0.28145539
0.37200000 0.36890808 0.28612926
0.37280000 0.36985219 0.28686126
0.37360000 0.37103064 0.28777496
0.37440000 0.37178516 0.28835997
0.37520000 0.37215557 0.28864716
0.37600000 0.37228484 0.28874739
0.37680000 0.37412076 0.29017084
0.37760000 0.37502618 0.29087285
0.37840000 0.37465103 0.29058198
0.37920000 0.37565693 0.29136189
0.38000000 0.37730331 0.29263839
0.38080000 0.37804231 0.29321136
0.38160000 0.37800611 0.29318330
0.38240000 0.37875979 0.29376765
0.38320000 0.38065284 0.29523541
0.38400000 0.38125148 0.29569956
0.38480000 0.38196741 0.29625464
0.38560000 0.37675538 0.29221356
0.38640000 0.37836255 0.29345966
0.38720000 0.38389621 0.29775011
0.38800000 0.38446818 0.29819358
0.38880000 0.38005487 0.29477178
0.38960000 0.38075338 0.29531336
0.39040000 0.38302220 0.29707246
0.39120000 0.38816074 0.30105655
0.39200000 0.38840610 0.30124679
0.39280000 0.38929884 0.30193897
0.39360000 0.39097862 0.30324136
0.39440000 0.39064214 0.30298048
0.39520000 0.39106594 0.30330906
0.39600000 0.38802347 0.30095012
0.39680000 0.38830624 0.30116937
0.39760000 0.38883709 0.30158096
0.39840000 0.38979825 0.30232617
0.39920000 0.39083251 0.30312808
0.40000000 0.39666722 0.30765194
0.40080000 0.39716400 0.30803711
0.40160000 0.39854009 0.30910404
0.40240000 0.39918323 0.30960270
0.40320000 0.40006051 0.31028288
0.40400000 0.40011236 0.31032308
0.40480000 0.40121638 0.31117907
0.40560000 0.39615760 0.30725681
0.40640000 0.39753667 0.30832606
0.40720000 0.40389029 0.31325225
0.40800000 0.40415306 0.31345598
0.40880000 0.40504414 0.31414687
0.40960000 0.40116038 0.31113566
0.41040000 0.40066372 0.31075057
0.41120000 0.40197992 0.31177107
0.41200000 0.40311717 0.31265282
0.41280000 0.40344023 0.31290330
0.41360000 0.40388233 0.31324608
0.41440000 0.41082010 0.31862519
0.41520000 0.41151988 0.31916775
0.41600000 0.41201428 0.31955108
0.41680000 0.40710118 0.31574178
0.41760000 0.40433326 0.31359570
0.41840000 0.40809119 0.31650936
0.41920000 0.41623903 0.32282669
0.42000000 0.41561978 0.32234655
0.42080000 0.41160508 0.31923381
0.42160000 0.40632098 0.31513685
0.42200000 0.41157964 0.31921409
0.42120000 0.40840090 0.31674949
0.42040000 0.41009660 0.31806423
0.41960000 0.40949574 0.31759836
0.41880000 0.40833902 0.31670151
0.41800000 0.40479466 0.31395344
0.41720000 0.40712296 0.31575866
0.41640000 0.40582435 0.31475180
0.41560000 0.40531178 0.31435439
0.41480000 0.40253127 0.31219855
0.41400000 0.40347996 0.31293410
0.41320000 0.40299079 0.31255483
0.41240000 0.40004040 0.31026729
0.41160000 0.39914136 0.30957024
0.41080000 0.39703186 0.30793466
0.41000000 0.39953040 0.30987187
0.40920000 0.39682188 0.30777185
0.40840000 0.39621717 0.30730300
0.40760000 0.39719532 0.30806140
0.40680000 0.39636986 0.30742139
0.40600000 0.39356757 0.30524867
0.40520000 0.39263658 0.30452684
0.40440000 0.39396460 0.30555650
0.40360000 0.39321862 0.30497811
0.40280000 0.39039952 0.30279237
0.40200000 0.39189386 0.30395098
0.40120000 0.39066049 0.30299470
0.40040000 0.38993138 0.30242940
0.39960000 0.38903594 0.30173513
0.39880000 0.38816654 0.30106105
0.39800000 0.38753974 0.30057507
0.39720000 0.38678451 0.29998951
0.39640000 0.38598813 0.29937205
0.39560000 0.38318616 0.29719958
0.39480000 0.38189644 0.29619961
0.39400000 0.38336280 0.29733654
0.39320000 0.38280410 0.29690335
0.39240000 0.38190652 0.29620743
0.39160000 0.37928168 0.29417229
0.39080000 0.38021007 0.29489211
0.39000000 0.37942876 0.29428633
0.38920000 0.37716102 0.29252807
0.38840000 0.37565370 0.29135939
0.38760000 0.37739626 0.29271046
0.38680000 0.37664957 0.29213152
0.38600000 0.37570016 0.29139541
0.38520000 0.37482419 0.29071624
0.38440000 0.37381703 0.28993535
0.38360000 0.37328282 0.28952116
0.38280000 0.37226919 0.28873526
0.38200000 0.37187032 0.28842599
0.38120000 0.37095721 0.28771803
0.38040000 0.36980828 0.28682722
0.37960000 0.36907849 0.28626139
0.37880000 0.36847530 0.28579371
0.37800000 0.36784250 0.28530308
0.37720000 0.36669893 0.28441643
0.37640000 0.36610170 0.28395337
0.37560000 0.36520441 0.28325767
0.37480000 0.36444933 0.28267223
0.37400000 0.36370169 0.28209256
0.37320000 0.36303264 0.28157382
0.37240000 0.36200473 0.28077684
0.37160000 0.36130356 0.28023320
0.37080000 0.35846262 0.27803051
0.37000000 0.35977231 0.27904596
0.36920000 0.35889536 0.27836603
0.36840000 0.35766450 0.27741170
0.36760000 0.35715924 0.27701996
0.36680000 0.35660305 0.27658872
0.36600000 0.35562696 0.27583192
0.36520000 0.35487598 0.27524966
0.36440000 0.35385512 0.27445815
0.36360000 0.35339090 0.27409822
0.36280000 0.35241470 0.27334134
0.36200000 0.35152775 0.27265366
0.36120000 0.35094625 0.27220279
0.36040000 0.35099176 0.27223809
0.35960000 0.34982058 0.27133003
0.35880000 0.34928483 0.27091464
0.35800000 0.34851553 0.27031817
0.35720000 0.34766097 0.26965560
0.35640000 0.34648320 0.26874243
0.35560000 0.34629740 0.26859838
0.35480000 0.34507325 0.26764925
0.35400000 0.34463008 0.26730564
0.35320000 0.34358189 0.26649294
0.35240000 0.34268111 0.26579454
0.35160000 0.34212442 0.26536291
0.35080000 0.34123579 0.26467393
0.35000000 0.34031193 0.26395762
0.34920000 0.33965125 0.26344537
0.34840000 0.33878698 0.26277527
0.34760000 0.33815415 0.26228461
0.34680000 0.33747669 0.26175935
0.34600000 0.33632466 0.26086614
0.34520000 0.33580752 0.26046519
0.34440000 0.33501361 0.25984964
0.34360000 0.33403849 0.25909359
0.34280000 0.33325029 0.25848247
0.34200000 0.33286307 0.25818224
0.34120000 0.33147416 0.25710537
0.34040000 0.33103343 0.25676366
0.33960000 0.33023414 0.25614394
0.33880000 0.32940064 0.25549770
0.33800000 0.32858555 0.25486573
0.33720000 0.32776493 0.25422947
0.33640000 0.32696368 0.25360823
0.33560000 0.32641458 0.25318250
0.33480000 0.32488003 0.25199270
0.33400000 0.32460922 0.25178273
0.33320000 0.32367447 0.25105799
0.33240000 0.32287806 0.25044051
0.33160000 0.32211026 0.24984520
0.33080000 0.32138584 0.24928353
0.33000000 0.32052304 0.24861457
0.32920000 0.31960864 0.24790560
0.32840000 0.31898584 0.24742272
0.32760000 0.31802489 0.24667766
0.32680000 0.31722709 0.24605910
0.32600000 0.31622527 0.24528235
0.32520000 0.31397493 0.24353758
0.32440000 0.31477995 0.24416174
0.32360000 0.31405672 0.24360099
0.32280000 0.31343005 0.24311511
0.32200000 0.31218011 0.24214599
0.32120000 0.31204654 0.24204243
0.32040000 0.31097030 0.24120798
0.31960000 0.31004587 0.24049124
0.31880000 0.30939111 0.23998358
0.31800000 0.30856444 0.23934263
0.31720000 0.30783788 0.23877930
0.31640000 0.30692944 0.23807496
0.31560000 0.30613118 0.23745603
0.31480000 0.30553992 0.23699761
0.31400000 0.30458713 0.23625888
0.31320000 0.30717313 0.23826389
0.31240000 0.30286895 0.23492670
0.31160000 0.30223384 0.23443429
0.31080000 0.30149536 0.23386171
0.31000000 0.30073887 0.23327518
0.30920000 0.29961521 0.23240396
0.30840000 0.29895546 0.23189244
0.30760000 0.29828681 0.23137401
0.30680000 0.29744031 0.23071768
0.30600000 0.29626790 0.22980867
0.30520000 0.29573961 0.22939907
0.30440000 0.29529080 0.22905109
0.30360000 0.29390650 0.22797779
0.30280000 0.29326697 0.22748194
0.30200000 0.29236786 0.22678483
0.30120000 0.29192008 0.22643765
0.30040000 0.29126137 0.22592693
0.29960000 0.29000278 0.22495109
0.29880000 0.28913906 0.22428142
0.29800000 0.28891677 0.22410907
0.29720000 0.28761181 0.22309729
0.29640000 0.28700627 0.22262779
0.29560000 0.28652938 0.22225804
0.29480000 0.28577893 0.22167619
0.29400000 0.28426635 0.22050343
0.29320000 0.28393964 0.22025012
0.29240000 0.28327566 0.21973531
0.29160000 0.28203806 0.21877575
0.29080000 0.28133139 0.21822785
0.29000000 0.28069088 0.21773123
0.28920000 0.27984320 0.21707400
0.28840000 0.28267349 0.21926842
0.28760000 0.27821994 0.21581543
0.28680000 0.27747649 0.21523900
0.28600000 0.27693872 0.21482205
0.28520000 0.27571868 0.21387611
0.28440000 0.27495120 0.21328105
0.28360000 0.27467686 0.21306835
0.28280000 0.27346688 0.21213021
0.28200000 0.27252289 0.21139830
0.28120000 0.27197393 0.21097266
0.28040000 0.27114481 0.21032982
0.27960000 0.27010321 0.20952223
0.27880000 0.26944519 0.20901204
0.27800000 0.26877513 0.20849252
0.27720000 0.26771151 0.20766786
0.27640000 0.26680821 0.20696749
0.27560000 0.26641291 0.20666101
0.27480000 0.26570677 0.20611350
0.27400000 0.26494324 0.20552151
0.27320000 0.26396101 0.20475995
0.27240000 0.26315983 0.20413877
0.27160000 0.26242696 0.20357055
0.27080000 0.26151122 0.20286054
0.27000000 0.26059552 0.20215057
0.26920000 0.26023323 0.20186967
0.26840000 0.25928195 0.20113211
0.26760000 0.25809434 0.20021131
0.26680000 0.25758435 0.19981590
0.26600000 0.25692818 0.19930715
0.26520000 0.25990138 0.20161238
0.26440000 0.25850394 0.20052889
0.26360000 0.25393305 0.19698491
0.26280000 0.25339229 0.19656564
0.26200000 0.25262101 0.19596764
0.26120000 0.25200179 0.19548753
0.26040000 0.25504768 0.19784912
0.25960000 0.25423119 0.19721607
0.25880000 0.24979717 0.19377821
0.25800000 0.24857299 0.19282906
0.25720000 0.24790557 0.19231159
0.25640000 0.24731119 0.19185074
0.25560000 0.24635678 0.19111075
0.25480000 0.24534215 0.19032407
0.25400000 0.24501235 0.19006837
0.25320000 0.24403770 0.18931268
0.25240000 0.24330993 0.18874842
0.25160000 0.24268286 0.18826222
0.25080000 0.24181174 0.18758681
0.25000000 0.24069703 0.18672254
0.24920000 0.23929300 0.18563395
0.24840000 0.23930370 0.18564224
0.24760000 0.23868892 0.18516558
0.24680000 0.23743611 0.18419423
0.24600000 0.23672302 0.18364135
0.24520000 0.23632665 0.18333402
0.24440000 0.23486778 0.18220291
0.24360000 0.23402768 0.18155155
0.24280000 0.23351827 0.18115658
0.24200000 0.23273366 0.18054825
0.24120000 0.23175738 0.17979130
0.24040000 0.23098935 0.17919582
0.23960000 0.23405757 0.18157472
0.23880000 0.23358051 0.18120484
0.23800000 0.22849889 0.17726487
0.23720000 0.22783830 0.17675270
0.23640000 0.22709635 0.17617743
0.23560000 0.22659030 0.17578508
0.23480000 0.22539163 0.17485570
0.23400000 0.22420199 0.17393333
0.23320000 0.22411189 0.17386348
0.23240000 0.22349050 0.17338169
0.23160000 0.22235111 0.17249828
0.23080000 0.22166982 0.17197005
0.23000000 0.22097642 0.17143243
0.22920000 0.21993591 0.17062568
0.22840000 0.21884389 0.16977900
0.22760000 0.21849536 0.16950878
0.22680000 0.21771449 0.16890334
0.22600000 0.21669439 0.16811242
0.22520000 0.21548409 0.16717403
0.22440000 0.21518825 0.16694465
0.22360000 0.21812866 0.16922445
0.22280000 0.21342918 0.16558077
0.22200000 0.21298099 0.16523328
0.22120000 0.21572683 0.16736223
0.22040000 0.21502038 0.16681450
0.21960000 0.21046676 0.16328390
0.21880000 0.20981976 0.16278226
0.21800000 0.20902645 0.16216718
0.21720000 0.20809346 0.16144380
0.21640000 0.20731561 0.16084071
0.21560000 0.20633893 0.16008345
0.21480000 0.20575738 0.15963255
0.21400000 0.20491272 0.15897766
0.21320000 0.20397194 0.15824823
0.21240000 0.20330489 0.15773105
0.21160000 0.20254917 0.15714511
0.21080000 0.20552727 0.15945413
0.21000000 0.20068204 0.15569746
0.20920000 0.20037582 0.15546003
0.20840000 0.20295595 0.15746050
0.20760000 0.19851210 0.15401502
0.20680000 0.19781482 0.15347439
0.20600000 0.19689765 0.15276328
0.20520000 0.19608622 0.15213414
0.20440000 0.19505042 0.15133105
0.20360000 0.19420108 0.15067253
0.20280000 0.19365949 0.15025262
0.20200000 0.19315091 0.14985829
0.20120000 0.19216159 0.14909123
0.20040000 0.19144133 0.14853279
0.19960000 0.19076806 0.14801078
0.19880000 0.18962737 0.14712636
0.19800000 0.18907293 0.14669648
0.19720000 0.18822437 0.14603856
0.19640000 0.18733956 0.14535254
0.19560000 0.18659660 0.14477650
0.19480000 0.18587371 0.14421601
0.19400000 0.18490979 0.14346865
0.19320000 0.18776937 0.14568579
0.19240000 0.18749227 0.14547094
0.19160000 0.18284062 0.14186434
0.19080000 0.18178259 0.14104402
0.19000000 0.18460229 0.14323024
0.18920000 0.18019211 0.13981086
0.18840000 0.17937635 0.13917837
0.18760000 0.18237504 0.14150336
0.18680000 0.18141074 0.14075571
0.18600000 0.17717252 0.13746966
0.18520000 0.17618641 0.13670509
0.18440000 0.17549217 0.13616682
0.18360000 0.17830773 0.13834983
0.18280000 0.17382106 0.13487115
0.18200000 0.17316775 0.13436462
0.18120000 0.17203971 0.13349001
0.18040000 0.17101023 0.13269181
0.17960000 0.17035168 0.13218122
0.17880000 0.17004302 0.13194190
0.17800000 0.16894570 0.13109111
0.17720000 0.16809336 0.13043025
0.17640000 0.16764487 0.13008252
0.17560000 0.17008396 0.13197364
0.17480000 0.16930466 0.13136942
0.17400000 0.16476144 0.12784689
0.17320000 0.16399813 0.12725508
0.17240000 0.16339073 0.12678413
0.17160000 0.16243586 0.12604379
0.17080000 0.16193365 0.12565441
0.17000000 0.16107028 0.12498501
0.16920000 0.16050102 0.12454364
0.16840000 0.15951919 0.12378239
0.16760000 0.15855819 0.12303729
0.16680000 0.15805523 0.12264732
0.16600000 0.15704998 0.12186792
0.16520000 0.15992453 0.12409666
0.16440000 0.15885732 0.12326921
0.16360000 0.15805158 0.12264449
0.16280000 0.15749021 0.12220925
0.16200000 0.15687406 0.12173152
0.16120000 0.15570554 0.12082552
0.16040000 0.15133127 0.11743399
0.15960000 0.15089190 0.11709333
0.15880000 0.14963056 0.11611537
0.15800000 0.14904216 0.11565916
0.15720000 0.14836689 0.11513560
0.15640000 0.14724737 0.11426760
0.15560000 0.14644117 0.11364252
0.15480000 0.14601567 0.11331261
0.15400000 0.14500944 0.11253245
0.15320000 0.14429744 0.11198041
0.15240000 0.14336689 0.11125892
0.15160000 0.14249539 0.11058321
0.15080000 0.14180067 0.11004457
0.15000000 0.14074734 0.10922788
0.14920000 0.14016301 0.10877483
0.14840000 0.13945105 0.10822282
0.14760000 0.13851983 0.10750082
0.14680000 0.13783233 0.10696777
0.14600000 0.13699322 0.10631718
0.14520000 0.13605531 0.10558998
0.14440000 0.13889932 0.10779505
0.14360000 0.13784784 0.10697980
0.14280000 0.13409120 0.10406714
0.14200000 0.13304447 0.10325557
0.14120000 0.13234865 0.10271608
0.14040000 0.13115107 0.10178755
0.13960000 0.13054141 0.10131485
0.13880000 0.12982782 0.10076158
0.13800000 0.12911880 0.10021185
0.13720000 0.12836572 0.09962796
0.13640000 0.12752168 0.09897354
0.13560000 0.12663826 0.09828860
0.13480000 0.12557295 0.09746262
0.13400000 0.12848064 0.09971706
0.13320000 0.12439278 0.09654760
0.13240000 0.12334300 0.09573367
0.13160000 0.12302745 0.09548901
0.13080000 0.12190001 0.09461486
0.13000000 0.12123789 0.09410149
0.12920000 0.11993174 0.09308879
0.12840000 0.11899417 0.09236186
0.12760000 0.12251879 0.09509462
0.12680000 0.12116118 0.09404202
0.12600000 0.11710503 0.09089714
0.12520000 0.11628532 0.09026159
0.12440000 0.11545680 0.08961920
0.12360000 0.11476306 0.08908132
0.12280000 0.11377585 0.08831590
0.12200000 0.11312913 0.08781447
0.12120000 0.11218851 0.08708518
0.12040000 0.11147712 0.08653361
0.11960000 0.11436123 0.08876977
0.11880000 0.11337897 0.08800819
0.11800000 0.10899895 0.08461219
0.11720000 0.10824574 0.08402820
0.11640000 0.10744179 0.08340488
0.11560000 0.10685257 0.08294803
0.11480000 0.10571988 0.08206981
0.11400000 0.10837347 0.08412724
0.11320000 0.10719791 0.08321579
0.11240000 0.10662460 0.08277127
0.11160000 0.10619644 0.08243930
0.11080000 0.10193831 0.07913782
0.11000000 0.10096664 0.07838445
0.10920000 0.10007077 0.07768985
0.10840000 0.09936834 0.07714523
0.10760000 0.09893661 0.07681049
0.10680000 0.09778257 0.07591573
0.10600000 0.09824777 0.07627641
0.10520000 0.09624222 0.07472144
0.10440000 0.09555240 0.07418660
0.10360000 0.09468166 0.07351148
0.10280000 0.09387183 0.07288358
0.10200000 0.09314355 0.07231892
0.10120000 0.09196330 0.07140383
0.10040000 0.09113124 0.07075871
0.09960000 0.09035219 0.07015468
0.09880000 0.08985923 0.06977247
0.09800000 0.08890649 0.06903377
0.09720000 0.08800509 0.06833488
0.09640000 0.08699401 0.06755096
0.09560000 0.08689502 0.06747421
0.09480000 0.08582298 0.06664301
0.09400000 0.08503648 0.06603321
0.09320000 0.08430299 0.06546451
0.09240000 0.08374787 0.06503411
0.09160000 0.08271180 0.06423080
0.09080000 0.08199599 0.06367581
0.09000000 0.08117854 0.06304202
0.08920000 0.08360619 0.06492426
0.08840000 0.08265724 0.06418850
0.08760000 0.08188013 0.06358598
0.08680000 0.08091376 0.06283672
0.08600000 0.08034694 0.06239724
0.08520000 0.07945338 0.06170443
0.08440000 0.07866895 0.06109623
0.08360000 0.07841523 0.06089952
0.08280000 0.07731847 0.06004916
0.08200000 0.07611439 0.05911559
0.08120000 0.07227632 0.05613980
0.08040000 0.07074987 0.05495629
0.07960000 0.07140352 0.05546308
0.07880000 0.06978371 0.05420718
0.07800000 0.06897974 0.05358384
0.07720000 0.06885609 0.05348797
0.07640000 0.07152489 0.05555719
0.07560000 0.07024809 0.05456723
0.07480000 0.06615073 0.05139040
0.07400000 0.06448656 0.05010011
0.07320000 0.06432851 0.04997757
0.07240000 0.06317030 0.04907956
0.07160000 0.06256110 0.04860723
0.07080000 0.06203319 0.04819792
0.07000000 0.06094324 0.04735284
0.06920000 0.06063654 0.04711505
0.06840000 0.06257429 0.04861745
0.06760000 0.06203983 0.04820307
0.06680000 0.06141105 0.04771555
0.06600000 0.06114073 0.04750597
0.06520000 0.06002509 0.04664097
0.06440000 0.05863188 0.04556076
0.06360000 0.05493707 0.04269604
0.06280000 0.05398109 0.04195483
0.06200000 0.05311150 0.04128061
0.06120000 0.05526112 0.04294729
0.06040000 0.05565374 0.04325170
0.05960000 0.05138522 0.03994216
0.05880000 0.04982050 0.03872898
0.05800000 0.04919527 0.03824421
0.05720000 0.05212577 0.04051633
0.05640000 0.05127425 0.03985612
0.05560000 0.04993874 0.03882065
0.05480000 0.04977883 0.03869667
0.05400000 0.04913558 0.03819794
0.05320000 0.04747476 0.03691024
0.05240000 0.04659443 0.03622769
0.05160000 0.04311326 0.03352861
0.05080000 0.04284865 0.03332344
0.05000000 0.04095784 0.03185743
0.04920000 0.04367042 0.03396059
0.04840000 0.04253674 0.03308161
0.04760000 0.03887267 0.03024072
0.04680000 0.03783576 0.02943677
0.04600000 0.03693336 0.02873710
0.04520000 0.03686356 0.02868299
0.04440000 0.03857694 0.03001143
0.04360000 0.03776760 0.02938392
0.04280000 0.03682473 0.02865288
0.04200000 0.03641485 0.02833509
0.04120000 0.03622263 0.02818605
0.04040000 0.03517400 0.02737301
0.03960000 0.03460830 0.02693440
0.03880000 0.03387085 0.02636263
0.03800000 0.03304476 0.02572213
0.03720000 0.02824626 0.02200168
0.03640000 0.02800078 0.02181135
0.03560000 0.02706422 0.02108520
0.03480000 0.02653909 0.02067804
0.03400000 0.02906022 0.02263277
0.03320000 0.02712188 0.02112990
0.03240000 0.02653518 0.02067501
0.03160000 0.02282892 0.01780142
0.03080000 0.02193605 0.01710914
0.03000000 0.02221170 0.01732286
0.02920000 0.02071109 0.01615939
0.02840000 0.02325903 0.01813490
0.02760000 0.02276974 0.01775553
0.02680000 0.02147291 0.01675005
0.02600000 0.01744445 0.01362664
0.02520000 0.01739243 0.01358631
0.02440000 0.01672615 0.01306971
0.02360000 0.01592014 0.01244479
0.02280000 0.01674521 0.01308449
0.02200000 0.01593725 0.01245805
0.02120000 0.01268657 0.00993768
0.02040000 0.01163872 0.00912525
0.01960000 0.01253848 0.00982286
0.01880000 0.01293265 0.01012848
0.01800000 0.00924635 0.00727035
0.01720000 0.00927674 0.00729391
0.01640000 0.00798649 0.00629354
0.01560000 0.00672786 0.00531768
0.01480000 0.00702459 0.00554774
0.01400000 0.00775583 0.00611470
0.01320000 0.00801999 0.00631951
0.01240000 0.00773867 0.00610139
0.01160000 0.00595804 0.00472081
0.01080000 0.00186200 0.00154500
0.01000000 0.00154522 0.00129938
0.00920000 0.00064869 0.00060427
0.00840000 0.00278617 0.00226154
0.00760000 0.00176237 0.00146775
0.00680000 0.00108694 0.00094407
0.00600000 -0.00279979 -0.00206946
0.00520000 -0.00362514 -0.00270939
0.00440000 -0.00413522 -0.00310487
0.00360000 -0.00517797 -0.00391335
0.00280000 -0.00565271 -0.00428144
0.00200000 -0.00595190 -0.00451341
0.00120000 -0.00719661 -0.00547848
0.00040000 -0.00710987 -0.00541122
-0.00000000 -0.00786323 -0.00599533