File: plots/rawdata/Figure2-20K-2.txt
# strain(%), strain_el(%), stress(GPa)
0.00000000 -0.00013068 0.00000000
0.00080000 -0.00208651 -0.00151643
0.00160000 -0.00128903 -0.00089812
0.00240000 0.00041860 0.00042587
0.00320000 0.00074559 0.00067940
0.00400000 0.00443941 0.00354335
0.00480000 0.00474387 0.00377942
0.00560000 0.00533208 0.00423548
0.00640000 0.00678537 0.00536227
0.00720000 0.00700525 0.00553274
0.00800000 0.00531886 0.00422523
0.00880000 0.00611449 0.00484211
0.00960000 0.00982439 0.00771853
0.01040000 0.01139008 0.00893246
0.01120000 0.00828903 0.00652811
0.01200000 0.00894566 0.00703722
0.01280000 0.01308856 0.01024936
0.01360000 0.01110650 0.00871260
0.01440000 0.01142179 0.00895705
0.01520000 0.01510935 0.01181615
0.01600000 0.01587924 0.01241308
0.01680000 0.01384850 0.01083857
0.01760000 0.01755852 0.01371508
0.01840000 0.01962133 0.01531446
0.01920000 0.01605531 0.01254959
0.02000000 0.01830894 0.01429691
0.02080000 0.02163334 0.01687444
0.02160000 0.02254991 0.01758509
0.02240000 0.02064740 0.01611001
0.02320000 0.02099151 0.01637680
0.02400000 0.02369063 0.01846953
0.02480000 0.02521996 0.01965528
0.02560000 0.02240925 0.01747603
0.02640000 0.02333804 0.01819615
0.02720000 0.02435922 0.01898791
0.02800000 0.02482375 0.01934808
0.02880000 0.02703888 0.02106555
0.02960000 0.02695189 0.02099811
0.03040000 0.03032501 0.02361341
0.03120000 0.02833507 0.02207053
0.03200000 0.02875256 0.02239423
0.03280000 0.02968625 0.02311816
0.03360000 0.03021449 0.02352772
0.03440000 0.03261717 0.02539061
0.03520000 0.03211876 0.02500417
0.03600000 0.03669969 0.02855593
0.03680000 0.03439011 0.02676523
0.03760000 0.03454384 0.02688442
0.03840000 0.03864671 0.03006553
0.03920000 0.03599257 0.02800767
0.04000000 0.03879329 0.03017918
0.04080000 0.03785527 0.02945189
0.04160000 0.03859046 0.03002192
0.04240000 0.04225252 0.03286124
0.04320000 0.04313881 0.03354841
0.04400000 0.04504368 0.03502533
0.04480000 0.04480171 0.03483773
0.04560000 0.04237738 0.03295806
0.04640000 0.04672068 0.03632557
0.04720000 0.04813367 0.03742112
0.04800000 0.04863431 0.03780928
0.04880000 0.04862381 0.03780113
0.04960000 0.04939477 0.03839889
0.05040000 0.05035440 0.03914293
0.05120000 0.04887221 0.03799373
0.05200000 0.04872298 0.03787803
0.05280000 0.05258921 0.04087566
0.05360000 0.05045022 0.03921722
0.05440000 0.05137893 0.03993729
0.05520000 0.05606109 0.04356753
0.05600000 0.05383414 0.04184090
0.05680000 0.05474481 0.04254697
0.05760000 0.05394085 0.04192364
0.05840000 0.05813180 0.04517303
0.05920000 0.05894415 0.04580288
0.06000000 0.05654551 0.04394312
0.06080000 0.05749916 0.04468252
0.06160000 0.05971919 0.04640379
0.06240000 0.05922317 0.04601921
0.06320000 0.05960640 0.04631634
0.06400000 0.06421051 0.04988608
0.06480000 0.06520046 0.05065362
0.06560000 0.06578074 0.05110354
0.06640000 0.06305043 0.04898663
0.06720000 0.06397230 0.04970138
0.06800000 0.06827883 0.05304040
0.06880000 0.06880440 0.05344789
0.06960000 0.06603999 0.05130454
0.07040000 0.06688346 0.05195851
0.07120000 0.06919243 0.05374874
0.07200000 0.06871075 0.05337528
0.07280000 0.06906685 0.05365138
0.07360000 0.07399486 0.05747224
0.07440000 0.07109638 0.05522495
0.07520000 0.07194801 0.05588525
0.07600000 0.07668608 0.05955884
0.07680000 0.07661338 0.05950248
0.07760000 0.07424534 0.05766645
0.07840000 0.07468933 0.05801069
0.07920000 0.07607477 0.05908487
0.08000000 0.07666536 0.05954278
0.08080000 0.07749098 0.06018291
0.08160000 0.07843118 0.06091189
0.08240000 0.07913442 0.06145713
0.08320000 0.08312257 0.06454929
0.08400000 0.08379883 0.06507362
0.08480000 0.08150418 0.06329449
0.08560000 0.08349628 0.06483904
0.08640000 0.08416207 0.06535525
0.08720000 0.08383300 0.06510011
0.08800000 0.08450262 0.06561929
0.08880000 0.08570820 0.06655402
0.08960000 0.08630097 0.06701362
0.09040000 0.08718782 0.06770123
0.09120000 0.09193086 0.07137868
0.09200000 0.09181961 0.07129242
0.09280000 0.08956029 0.06954069
0.09360000 0.09021028 0.07004465
0.09440000 0.09112176 0.07075135
0.09520000 0.09196165 0.07140255
0.09600000 0.09240556 0.07174673
0.09680000 0.09680116 0.07515481
0.09760000 0.09750527 0.07570073
0.09840000 0.09510252 0.07383779
0.09920000 0.09567428 0.07428110
0.10000000 0.09662278 0.07501650
0.10080000 0.10063784 0.07812952
0.10160000 0.09811849 0.07617618
0.10240000 0.10222806 0.07936248
0.10320000 0.09974256 0.07743538
0.10400000 0.10084898 0.07829323
0.10480000 0.10134731 0.07867960
0.10560000 0.10213384 0.07928942
0.10640000 0.10649181 0.08266832
0.10720000 0.10762962 0.08355050
0.10800000 0.10475485 0.08132159
0.10880000 0.10556564 0.08195022
0.10960000 0.10944974 0.08496171
0.11040000 0.11026845 0.08559648
0.11120000 0.10780460 0.08368617
0.11200000 0.11188583 0.08685050
0.11280000 0.10938017 0.08490777
0.11360000 0.11010618 0.08547068
0.11440000 0.11099182 0.08615734
0.11520000 0.11158383 0.08661635
0.11600000 0.11322979 0.08789252
0.11680000 0.11701299 0.09082577
0.11760000 0.11753551 0.09123090
0.11840000 0.11499334 0.08925986
0.11920000 0.11573197 0.08983256
0.12000000 0.11640880 0.09035732
0.12080000 0.11720513 0.09097475
0.12160000 0.11844129 0.09193319
0.12240000 0.12271181 0.09524428
0.12320000 0.12310798 0.09555144
0.12400000 0.12051642 0.09354212
0.12480000 0.12132311 0.09416757
0.12560000 0.12590709 0.09772170
0.12640000 0.12650578 0.09818589
0.12720000 0.12351213 0.09586479
0.12800000 0.12457303 0.09668735
0.12880000 0.12511700 0.09710911
0.12960000 0.12603221 0.09781871
0.13040000 0.12686029 0.09846075
0.13120000 0.12770249 0.09911374
0.13200000 0.12854239 0.09976494
0.13280000 0.13277736 0.10304847
0.13360000 0.13351537 0.10362068
0.13440000 0.13113987 0.10177886
0.13520000 0.13178791 0.10228131
0.13600000 0.13588523 0.10545811
0.13680000 0.13686430 0.10621722
0.13760000 0.13414391 0.10410801
0.13840000 0.13830453 0.10733389
0.13920000 0.13918827 0.10801908
0.14000000 0.13646417 0.10590699
0.14080000 0.13720583 0.10648202
0.14160000 0.14742553 0.11440573
0.14240000 0.14863108 0.11534044
0.14320000 0.14588480 0.11321115
0.14400000 0.14036451 0.10893106
0.14480000 0.14113753 0.10953041
0.14560000 0.14202898 0.11022159
0.14640000 0.14293390 0.11092321
0.14720000 0.14693505 0.11402544
0.14800000 0.14438406 0.11204757
0.14880000 0.14528702 0.11274766
0.14960000 0.14579624 0.11314248
0.15040000 0.14683905 0.11395101
0.15120000 0.14752378 0.11448190
0.15200000 0.14822407 0.11502487
0.15280000 0.14909170 0.11569758
0.15360000 0.15013004 0.11650264
0.15440000 0.15404982 0.11954179
0.15520000 0.15501907 0.12029328
0.15600000 0.15194833 0.11791242
0.15680000 0.15319055 0.11887556
0.15760000 0.15366372 0.11924243
0.15840000 0.15470349 0.12004860
0.15920000 0.15536043 0.12055795
0.16000000 0.15652879 0.12146382
0.16080000 0.15703250 0.12185436
0.16160000 0.16132468 0.12518225
0.16240000 0.15854098 0.12302394
0.16320000 0.15937083 0.12366736
0.16400000 0.16016644 0.12428423
0.16480000 0.16162650 0.12541626
0.16560000 0.15303954 0.11875848
0.16640000 0.15754858 0.12225450
0.16720000 0.15486985 0.12017758
0.16800000 0.15548306 0.12065302
0.16880000 0.15613389 0.12115764
0.16960000 0.15727780 0.12204456
0.17040000 0.15808616 0.12267131
0.17120000 0.16215898 0.12582912
0.17200000 0.15950387 0.12377051
0.17280000 0.16018507 0.12429867
0.17360000 0.16112022 0.12502372
0.17440000 0.16211629 0.12579601
0.17520000 0.16271377 0.12625926
0.17600000 0.16335249 0.12675449
0.17680000 0.16418209 0.12739770
0.17760000 0.16495884 0.12799995
0.17840000 0.16594982 0.12876829
0.17920000 0.17548298 0.13615970
0.18000000 0.17602566 0.13658046
0.18080000 0.18068809 0.14019541
0.18160000 0.18141538 0.14075931
0.18240000 0.17846267 0.13846996
0.18320000 0.18317064 0.14212023
0.18400000 0.18018335 0.13980407
0.18480000 0.18095066 0.14039899
0.18560000 0.18176026 0.14102670
0.18640000 0.18238532 0.14151134
0.18720000 0.18337367 0.14227764
0.18800000 0.18387800 0.14266867
0.18880000 0.18852204 0.14626936
0.18960000 0.18934491 0.14690736
0.19040000 0.18640493 0.14462789
0.19120000 0.18711407 0.14517771
0.19200000 0.18799918 0.14586396
0.19280000 0.18893489 0.14658946
0.19360000 0.18930579 0.14687703
0.19440000 0.19031220 0.14765733
0.19520000 0.19153215 0.14860321
0.19600000 0.19219217 0.14911495
0.19680000 0.19657093 0.15250996
0.19760000 0.19370120 0.15028495
0.19840000 0.19437521 0.15080754
0.19920000 0.19515817 0.15141459
0.20000000 0.19621361 0.15223292
0.20080000 0.19678822 0.15267844
0.20160000 0.19787962 0.15352463
0.20240000 0.19825386 0.15381480
0.20320000 0.19940115 0.15470433
0.20400000 0.19996993 0.15514533
0.20480000 0.20078389 0.15577642
0.20560000 0.20091747 0.15587999
0.20640000 0.20214292 0.15683013
0.20720000 0.20310529 0.15757629
0.20800000 0.20786838 0.16126929
0.20880000 0.20822133 0.16154294
0.20960000 0.20561777 0.15952431
0.21040000 0.20627601 0.16003466
0.21120000 0.20720431 0.16075441
0.21200000 0.20768242 0.16112510
0.21280000 0.20835793 0.16164885
0.21360000 0.20933622 0.16240735
0.21440000 0.21065598 0.16343062
0.21520000 0.21094998 0.16365856
0.21600000 0.21162163 0.16417932
0.21680000 0.21616854 0.16770470
0.21760000 0.21361758 0.16572685
0.21840000 0.21404340 0.16605701
0.21920000 0.21505213 0.16683911
0.22000000 0.21916686 0.17002941
0.22080000 0.21631925 0.16782156
0.22160000 0.21751930 0.16875200
0.22240000 0.21812824 0.16922413
0.22320000 0.22286127 0.17289383
0.22400000 0.22346722 0.17336364
0.22480000 0.22061271 0.17115043
0.22560000 0.22145588 0.17180417
0.22640000 0.22618770 0.17547292
0.22720000 0.22293864 0.17295381
0.22800000 0.22354006 0.17342011
0.22880000 0.22842002 0.17720372
0.22960000 0.22895676 0.17761988
0.23040000 0.22594196 0.17528240
0.23120000 0.22697639 0.17608442
0.23200000 0.22739905 0.17641213
0.23280000 0.22850760 0.17727163
0.23360000 0.22937431 0.17794362
0.23440000 0.23004355 0.17846250
0.23520000 0.23068087 0.17895664
0.23600000 0.23156823 0.17964465
0.23680000 0.23241531 0.18030142
0.23760000 0.23700918 0.18386321
0.23840000 0.23754395 0.18427784
0.23920000 0.23886583 0.18530274
0.24000000 0.23562806 0.18279238
0.24080000 0.23632701 0.18333431
0.24160000 0.23702834 0.18387807
0.24240000 0.23794703 0.18459036
0.24320000 0.23851219 0.18502855
0.24400000 0.23941750 0.18573047
0.24480000 0.24035934 0.18646072
0.24560000 0.24094150 0.18691209
0.24640000 0.24183658 0.18760607
0.24720000 0.24261052 0.18820614
0.24800000 0.24764698 0.19211109
0.24880000 0.24438358 0.18958086
0.24960000 0.24508888 0.19012770
0.25040000 0.24582828 0.19070099
0.25120000 0.24678372 0.19144177
0.25200000 0.24756199 0.19204519
0.25280000 0.24833147 0.19264180
0.25360000 0.24928129 0.19337823
0.25440000 0.24998537 0.19392413
0.25520000 0.25052586 0.19434319
0.25600000 0.25152298 0.19511630
0.25680000 0.25228448 0.19570671
0.25760000 0.25285187 0.19614663
0.25840000 0.25382925 0.19690443
0.25920000 0.25424765 0.19722883
0.26000000 0.25572157 0.19837162
0.26080000 0.25640063 0.19889811
0.26160000 0.25700105 0.19936365
0.26240000 0.26179298 0.20307901
0.26320000 0.25814357 0.20024948
0.26400000 0.25929982 0.20114596
0.26480000 0.26402033 0.20480595
0.26560000 0.26105222 0.20250467
0.26640000 0.26151791 0.20286573
0.26720000 0.26304181 0.20404727
0.26800000 0.26362490 0.20449936
0.26880000 0.26407312 0.20484688
0.26960000 0.26484900 0.20544845
0.27040000 0.26545142 0.20591553
0.27120000 0.26653970 0.20675931
0.27200000 0.26713482 0.20722073
0.27280000 0.26777559 0.20771754
0.27360000 0.26888582 0.20857834
0.27440000 0.27391604 0.21247845
0.27520000 0.27055345 0.20987132
0.27600000 0.27107154 0.21027301
0.27680000 0.27190064 0.21091584
0.27760000 0.27314771 0.21188274
0.27840000 0.27375955 0.21235713
0.27920000 0.27439162 0.21284719
0.28000000 0.27911614 0.21651028
0.28080000 0.27630877 0.21433363
0.28160000 0.27675430 0.21467906
0.28240000 0.27733041 0.21512574
0.28320000 0.27832769 0.21589897
0.28400000 0.27909484 0.21649377
0.28480000 0.27975387 0.21700474
0.28560000 0.28057165 0.21763879
0.28640000 0.28110323 0.21805095
0.28720000 0.28251331 0.21914424
0.28800000 0.28341382 0.21984243
0.28880000 0.28377853 0.22012520
0.28960000 0.28469521 0.22083594
0.29040000 0.28894054 0.22412750
0.29120000 0.28634999 0.22211895
0.29200000 0.28667784 0.22237314
0.29280000 0.28806577 0.22344926
0.29360000 0.28844275 0.22374155
0.29440000 0.28950615 0.22456604
0.29520000 0.29040001 0.22525908
0.29600000 0.29149055 0.22610462
0.29680000 0.29504037 0.22885692
0.29760000 0.29608613 0.22966774
0.29840000 0.29382308 0.22791311
0.29920000 0.29430280 0.22828506
0.30000000 0.29521462 0.22899202
0.30080000 0.29564457 0.22932538
0.30160000 0.29683279 0.23024665
0.30240000 0.29731970 0.23062417
0.30320000 0.29808242 0.23121554
0.30400000 0.29887349 0.23182888
0.30480000 0.29980883 0.23255408
0.30560000 0.30031949 0.23295002
0.30640000 0.30101862 0.23349208
0.30720000 0.30212978 0.23435360
0.30800000 0.30322229 0.23520066
0.30880000 0.30357538 0.23547443
0.30960000 0.30522762 0.23675547
0.31040000 0.30537086 0.23686653
0.31120000 0.30630603 0.23759160
0.31200000 0.30705661 0.23817355
0.31280000 0.30773536 0.23869982
0.31360000 0.30885085 0.23956469
0.31440000 0.30927303 0.23989202
0.31520000 0.31019729 0.24060864
0.31600000 0.31085936 0.24112196
0.31680000 0.31153426 0.24164524
0.31760000 0.31307014 0.24283606
0.31840000 0.31323742 0.24296576
0.31920000 0.31385887 0.24344760
0.32000000 0.31468155 0.24408545
0.32080000 0.31496621 0.24430616
0.32160000 0.32008932 0.24827829
0.32240000 0.31725422 0.24608014
0.32320000 0.31804209 0.24669100
0.32400000 0.31908606 0.24750043
0.32480000 0.31932191 0.24768329
0.32560000 0.32042286 0.24853690
0.32640000 0.32102766 0.24900582
0.32720000 0.32175541 0.24957007
0.32800000 0.32286266 0.25042856
0.32880000 0.32340506 0.25084911
0.32960000 0.32833962 0.25467505
0.33040000 0.32459300 0.25177016
0.33120000 0.32617085 0.25299353
0.33200000 0.33072104 0.25652145
0.33280000 0.32725312 0.25383265
0.33360000 0.32826532 0.25461745
0.33440000 0.32917515 0.25532286
0.33520000 0.32984163 0.25583962
0.33600000 0.33024309 0.25615088
0.33680000 0.33133113 0.25699448
0.33760000 0.33226899 0.25772164
0.33840000 0.33285170 0.25817343
0.33920000 0.32217115 0.24989241
0.34000000 0.32692864 0.25358107
0.34080000 0.32782056 0.25427260
0.34160000 0.32860217 0.25487861
0.34240000 0.32944476 0.25553191
0.34320000 0.33004091 0.25599412
0.34400000 0.33083237 0.25660777
0.34480000 0.33181278 0.25736792
0.34560000 0.33251955 0.25791590
0.34640000 0.33345300 0.25863964
0.34720000 0.33432129 0.25931286
0.34800000 0.33472121 0.25962293
0.34880000 0.33585985 0.26050576
0.34960000 0.33651599 0.26101449
0.35040000 0.33734894 0.26166031
0.35120000 0.33776680 0.26198429
0.35200000 0.33854343 0.26258644
0.35280000 0.33987127 0.26361596
0.35360000 0.34059569 0.26417763
0.35440000 0.34098841 0.26448212
0.35520000 0.34236605 0.26555026
0.35600000 0.34303897 0.26607200
0.35680000 0.34366894 0.26656043
0.35760000 0.34449447 0.26720050
0.35840000 0.34533112 0.26784918
0.35920000 0.34591070 0.26829855
0.36000000 0.34682266 0.26900562
0.36080000 0.34759723 0.26960618
0.36160000 0.34868245 0.27044759
0.36240000 0.34645650 0.26872173
0.36320000 0.34989032 0.27138410
0.36400000 0.35108270 0.27230859
0.36480000 0.34792805 0.26986268
0.36560000 0.35272720 0.27358363
0.36640000 0.35316230 0.27392099
0.36720000 0.35433493 0.27483016
0.36800000 0.35497885 0.27532942
0.36880000 0.35375149 0.27437780
0.36960000 0.35631072 0.27636207
0.37040000 0.35695623 0.27686255
0.37120000 0.35653142 0.27653319
0.37200000 0.35861698 0.27815020
0.37280000 0.35949496 0.27883093
0.37360000 0.36090632 0.27992521
0.37440000 0.35889191 0.27836336
0.37520000 0.36046347 0.27958184
0.37600000 0.36296585 0.28152203
0.37680000 0.36357078 0.28199106
0.37760000 0.36484749 0.28298094
0.37840000 0.36476394 0.28291616
0.37920000 0.36625510 0.28407231
0.38000000 0.36691151 0.28458125
0.38080000 0.36773845 0.28522240
0.38160000 0.36458502 0.28277744
0.38240000 0.36543116 0.28343348
0.38320000 0.36624923 0.28406776
0.38400000 0.37068404 0.28750623
0.38480000 0.37163842 0.28824619
0.38560000 0.37253087 0.28893815
0.38640000 0.37302206 0.28931898
0.38720000 0.37390851 0.29000628
0.38800000 0.37472340 0.29063810
0.38880000 0.37573321 0.29142104
0.38960000 0.37213762 0.28863325
0.39040000 0.37699918 0.29240259
0.39120000 0.37797196 0.29315682
0.39200000 0.37877949 0.29378293
0.39280000 0.37953082 0.29436546
0.39360000 0.38034608 0.29499756
0.39440000 0.38126249 0.29570809
0.39520000 0.38204942 0.29631822
0.39600000 0.38273094 0.29684663
0.39680000 0.37915926 0.29407738
0.39760000 0.38018105 0.29486961
0.39840000 0.38347383 0.29742262
0.39920000 0.38389198 0.29774683
0.40000000 0.38070823 0.29527835
0.40080000 0.38315231 0.29717334
0.40160000 0.38839928 0.30124150
0.40240000 0.38745536 0.30050965
0.40320000 0.38601688 0.29939435
0.40400000 0.38633186 0.29963856
0.40480000 0.39166471 0.30377331
0.40560000 0.39244357 0.30437719
0.40640000 0.38807465 0.30098980
0.40720000 0.38938348 0.30200459
0.40800000 0.39481029 0.30621219
0.40880000 0.39587683 0.30703913
0.40960000 0.39268373 0.30456339
0.41040000 0.39253449 0.30444768
0.41120000 0.39771370 0.30846331
0.41200000 0.39804255 0.30871828
0.41280000 0.39354594 0.30523190
0.41360000 0.39378505 0.30541729
0.41440000 0.39870250 0.30922997
0.41520000 0.40027639 0.31045026
0.41600000 0.39813041 0.30878641
0.41680000 0.39860182 0.30915191
0.41760000 0.40051559 0.31063572
0.41840000 0.40526119 0.31431516
0.41920000 0.40092548 0.31095353
0.42000000 0.40229965 0.31201897
0.42080000 0.40765607 0.31617200
0.42160000 0.40615444 0.31500773
0.42240000 0.40914967 0.31733004
0.42320000 0.40494797 0.31407231
0.42400000 0.40828176 0.31665712
0.42480000 0.40922337 0.31738719
0.42560000 0.41260202 0.32000677
0.42640000 0.40823292 0.31661925
0.42720000 0.40814757 0.31655308
0.42800000 0.41003967 0.31802009
0.42880000 0.41568390 0.32239627
0.42960000 0.41113999 0.31887321
0.43040000 0.41154142 0.31918445
0.43120000 0.41136005 0.31904383
0.43200000 0.41663819 0.32313617
0.43280000 0.41925948 0.32516855
0.43360000 0.42056549 0.32618114
0.43440000 0.41573256 0.32243400
0.43520000 0.41747406 0.32378425
0.43600000 0.41778424 0.32402474
0.43680000 0.41729567 0.32364593
0.43760000 0.41739177 0.32372045
0.43840000 0.42326266 0.32827236
0.43920000 0.42575212 0.33020253
0.44000000 0.42660581 0.33086443
0.44080000 0.42756356 0.33160700
0.44160000 0.42754399 0.33159183
0.44240000 0.42873083 0.33251203
0.44320000 0.42479148 0.32945771
0.44400000 0.42183832 0.32716802
0.44480000 0.42556054 0.33005399
0.44560000 0.43246026 0.33540359
0.44640000 0.42815477 0.33206539
0.44720000 0.42701779 0.33118385
0.44800000 0.42862614 0.33243086
0.44880000 0.43570799 0.33792168
0.44960000 0.43097631 0.33425304
0.45040000 0.43172643 0.33483463
0.45120000 0.43279493 0.33566307
0.45200000 0.43852745 0.34010771
0.45280000 0.43944006 0.34081529
0.45360000 0.44027710 0.34146428
0.45440000 0.43576883 0.33796885
0.45520000 0.43670606 0.33869552
0.45600000 0.44273850 0.34337269
0.45680000 0.43594231 0.33810336
0.45760000 0.43667358 0.33867034
0.45840000 0.44500180 0.34512751
0.45920000 0.44610310 0.34598139
0.46000000 0.44119439 0.34217548
0.46080000 0.44177940 0.34262906
0.46160000 0.44309001 0.34364523
0.46240000 0.44916554 0.34835581
0.46320000 0.44024453 0.34143902
0.46400000 0.44089167 0.34194078
0.46480000 0.44613294 0.34600453
0.46560000 0.44459032 0.34480848
0.46640000 0.45015879 0.34912592
0.46720000 0.45194986 0.35051460
0.46800000 0.44911955 0.34832015
0.46880000 0.44518884 0.34527253
0.46960000 0.45152831 0.35018775
0.47040000 0.45700156 0.35443137
0.47120000 0.45223266 0.35073386
0.47200000 0.44666944 0.34642049
0.47280000 0.45385820 0.35199420
0.47360000 0.46008891 0.35682510
0.47440000 0.45852113 0.35560954
0.47520000 0.45372313 0.35188948
0.47600000 0.45564921 0.35338284
0.47680000 0.45760511 0.35489932
0.47760000 0.46218054 0.35844681
0.47840000 0.45705555 0.35447322
0.47920000 0.45942130 0.35630748
0.48000000 0.46570672 0.36118080
0.48080000 0.45969034 0.35651607
0.48160000 0.46061559 0.35723345
0.48240000 0.45892494 0.35592263
0.48320000 0.46446775 0.36022018
0.48400000 0.46983877 0.36438452
0.48480000 0.47117332 0.36541925
0.48560000 0.46670307 0.36195330
0.48640000 0.46670519 0.36195495
0.48720000 0.46706829 0.36223647
0.48800000 0.46403776 0.35988679
0.48880000 0.46826063 0.36316094
0.48960000 0.46787579 0.36286255
0.49040000 0.47022226 0.36468186
0.49120000 0.46740389 0.36249667
0.49200000 0.47284936 0.36671874
0.49280000 0.47654292 0.36958249
0.49360000 0.46709997 0.36226103
0.49440000 0.46852834 0.36336850
0.49520000 0.47401054 0.36761905
0.49600000 0.47402543 0.36763059
0.49680000 0.47198361 0.36604749
0.49760000 0.47366334 0.36734985
0.49840000 0.47793100 0.37065872
0.49920000 0.48305263 0.37462971
0.50000000 0.48455353 0.37579342
0.50080000 0.48631553 0.37715956
0.50160000 0.48127631 0.37325246
0.50240000 0.48628609 0.37713673
0.50320000 0.48657660 0.37736197
0.50400000 0.48968908 0.37977520
0.50480000 0.47996859 0.37223854
0.50560000 0.48089712 0.37295847
0.50640000 0.49207817 0.38162755
0.50720000 0.48721619 0.37785787
0.50800000 0.48312834 0.37468841
0.50880000 0.48826402 0.37867029
0.50960000 0.48784137 0.37834260
0.51040000 0.48945447 0.37959329
0.51120000 0.48657397 0.37735993
0.51200000 0.49160044 0.38125714
0.51280000 0.49305563 0.38238540
0.51360000 0.49505979 0.38393930
0.51440000 0.49503590 0.38392078
0.51520000 0.49006146 0.38006392
0.51600000 0.49547184 0.38425878
0.51680000 0.49649474 0.38505188
0.51760000 0.49815904 0.38634227
0.51840000 0.49206704 0.38161892
0.51920000 0.49915804 0.38711683
0.52000000 0.50045687 0.38812386
0.52080000 0.50203096 0.38934430
0.52160000 0.49664646 0.38516951
0.52240000 0.50153812 0.38896219
0.52320000 0.50097678 0.38852696
0.52400000 0.50209583 0.38939460
0.52480000 0.51103580 0.39632609
0.52560000 0.51027056 0.39573277
0.52640000 0.50336981 0.39038237
0.52720000 0.50503205 0.39167117
0.52800000 0.50918022 0.39488739
0.52880000 0.50328473 0.39031640
0.52960000 0.50191173 0.38925186
0.53040000 0.50803389 0.39399860
0.53120000 0.51511592 0.39948955
0.53200000 0.51044039 0.39586445
0.53280000 0.51154719 0.39672259
0.53360000 0.51294101 0.39780327
0.53440000 0.52025033 0.40347046
0.53520000 0.51309732 0.39792446
0.53600000 0.51367238 0.39837033
0.53680000 0.51489327 0.39931693
0.53760000 0.51604112 0.40020690
0.53840000 0.51827502 0.40193892
0.53920000 0.51304941 0.39788732
0.54000000 0.51425275 0.39882031
0.54080000 0.51591160 0.40010647
0.54160000 0.52169033 0.40458693
0.54240000 0.51990646 0.40320384
0.54320000 0.52658546 0.40838231
0.54400000 0.52288843 0.40551586
0.54480000 0.52272450 0.40538877
0.54560000 0.52364892 0.40610550
0.54640000 0.53155127 0.41223248
0.54720000 0.52636206 0.40820910
0.54800000 0.52743502 0.40904100
0.54880000 0.53257006 0.41302239
0.54960000 0.53282183 0.41321760
0.55040000 0.52759127 0.40916215
0.55120000 0.52910288 0.41033416
0.55200000 0.52953946 0.41067265
0.55280000 0.53093634 0.41175571
0.55360000 0.52842621 0.40980951
0.55440000 0.52811777 0.40957037
0.55520000 0.53241145 0.41289942
0.55600000 0.53380798 0.41398219
0.55680000 0.53382407 0.41399467
0.55760000 0.53426465 0.41433627
0.55840000 0.54183531 0.42020608
0.55920000 0.53850864 0.41762679
0.56000000 0.53734225 0.41672244
0.56080000 0.53806403 0.41728207
0.56160000 0.53672897 0.41624695
0.56240000 0.53732890 0.41671209
0.56320000 0.54208760 0.42040169
0.56400000 0.54245708 0.42068816
0.56480000 0.54457775 0.42233239
0.56560000 0.53743349 0.41679319
0.56640000 0.53825026 0.41742646
0.56720000 0.53869475 0.41777109
0.40000000 0.38070823 0.29527835
0.39920000 0.38362236 0.29753779
0.39840000 0.38464779 0.29833283
0.39760000 0.37948304 0.29432842
0.39680000 0.37823602 0.29336156
0.39600000 0.37793214 0.29312594
0.39520000 0.38117004 0.29563641
0.39440000 0.38035186 0.29500205
0.39360000 0.37485181 0.29073766
0.39280000 0.37687744 0.29230820
0.39200000 0.37817266 0.29331243
0.39120000 0.37709922 0.29248015
0.39040000 0.37660875 0.29209987
0.38960000 0.37353738 0.28971853
0.38880000 0.37529969 0.29108492
0.38800000 0.37004630 0.28701177
0.38720000 0.37341577 0.28962424
0.38640000 0.37317736 0.28943939
0.38560000 0.37154885 0.28817675
0.38480000 0.36700780 0.28465591
0.38400000 0.37033853 0.28723834
0.38320000 0.36703176 0.28467448
0.38240000 0.36686653 0.28454638
0.38160000 0.36517427 0.28323430
0.38080000 0.36715221 0.28476787
0.38000000 0.36617409 0.28400950
0.37920000 0.36139846 0.28030678
0.37840000 0.36465485 0.28283158
0.37760000 0.36355237 0.28197678
0.37680000 0.36311492 0.28163762
0.37600000 0.36213012 0.28087406
0.37520000 0.36149579 0.28038224
0.37440000 0.36082735 0.27986398
0.37360000 0.35976547 0.27904066
0.37280000 0.35891551 0.27838166
0.37200000 0.35824429 0.27786123
0.37120000 0.35731398 0.27713994
0.37040000 0.35683336 0.27676729
0.36960000 0.35557141 0.27578886
0.36880000 0.35481911 0.27520557
0.36800000 0.35119033 0.27239204
0.36720000 0.34976175 0.27128441
0.36640000 0.35236192 0.27330042
0.36560000 0.35162626 0.27273003
0.36480000 0.34780265 0.26976545
0.36400000 0.34638155 0.26866362
0.36320000 0.34950379 0.27108441
0.36240000 0.34873978 0.27049204
0.36160000 0.34423463 0.26699903
0.36080000 0.34705666 0.26918706
0.36000000 0.34602774 0.26838930
0.35920000 0.34559157 0.26805112
0.35840000 0.34104056 0.26452255
0.35760000 0.34363027 0.26653045
0.35680000 0.34325040 0.26623592
0.35600000 0.34225718 0.26546585
0.35520000 0.34135652 0.26476753
0.35440000 0.34046444 0.26407587
0.35360000 0.33981792 0.26357459
0.35280000 0.33924199 0.26312806
0.35200000 0.33824067 0.26235169
0.35120000 0.33725790 0.26158972
0.35040000 0.33689157 0.26130569
0.34960000 0.33598837 0.26060541
0.34880000 0.33508629 0.25990599
0.34800000 0.33444618 0.25940969
0.34720000 0.33378524 0.25889724
0.34640000 0.33271170 0.25806488
0.34560000 0.33180123 0.25735897
0.34480000 0.33096815 0.25671305
0.34400000 0.33027599 0.25617639
0.34320000 0.32957836 0.25563549
0.34240000 0.32855710 0.25484367
0.34160000 0.32791914 0.25434904
0.34080000 0.32722797 0.25381315
0.34000000 0.32622217 0.25303331
0.33920000 0.32538081 0.25238097
0.33840000 0.32470650 0.25185816
0.33760000 0.32436126 0.25159048
0.33680000 0.32352423 0.25094150
0.33600000 0.32199545 0.24975619
0.33520000 0.32161580 0.24946183
0.33440000 0.32090393 0.24890989
0.33360000 0.31979120 0.24804715
0.33280000 0.31908244 0.24749762
0.33200000 0.31824811 0.24685073
0.33120000 0.31759455 0.24634400
0.33040000 0.31663095 0.24559689
0.32960000 0.31579858 0.24495152
0.32880000 0.31547340 0.24469940
0.32800000 0.31426925 0.24376578
0.32720000 0.31350379 0.24317229
0.32640000 0.31253976 0.24242484
0.32560000 0.31220685 0.24216673
0.32480000 0.31108525 0.24129710
0.32400000 0.31060760 0.24092677
0.32320000 0.30963518 0.24017281
0.32240000 0.30887725 0.23958516
0.32160000 0.30818363 0.23904737
0.32080000 0.30739693 0.23843742
0.32000000 0.30637368 0.23764405
0.31920000 0.30544958 0.23692757
0.31840000 0.30497877 0.23656253
0.31760000 0.30385450 0.23569084
0.31680000 0.30314081 0.23513749
0.31600000 0.30237907 0.23454688
0.31520000 0.30166226 0.23399111
0.31440000 0.30057218 0.23314593
0.31360000 0.29977297 0.23252628
0.31280000 0.29872915 0.23171697
0.31200000 0.29806060 0.23119862
0.31120000 0.29778643 0.23098604
0.31040000 0.29718403 0.23051898
0.30960000 0.29610337 0.22968110
0.30880000 0.29512194 0.22892017
0.30800000 0.29476418 0.22864278
0.30720000 0.29383187 0.22791993
0.30640000 0.29250909 0.22689433
0.30560000 0.29171778 0.22628080
0.30480000 0.29122479 0.22589856
0.30400000 0.29050074 0.22533718
0.30320000 0.28946456 0.22453379
0.30240000 0.29227016 0.22670907
0.30160000 0.28806500 0.22344866
0.30080000 0.28723122 0.22280220
0.30000000 0.28629425 0.22207573
0.29920000 0.28598254 0.22183405
0.29840000 0.28495138 0.22103456
0.29760000 0.28396735 0.22027160
0.29680000 0.28294367 0.21947791
0.29600000 0.28262237 0.21922879
0.29520000 0.28200989 0.21875391
0.29440000 0.28081479 0.21782731
0.29360000 0.27988635 0.21710745
0.29280000 0.27934455 0.21668738
0.29200000 0.27846032 0.21600180
0.29120000 0.28108436 0.21803631
0.29040000 0.28076765 0.21779076
0.28960000 0.27604554 0.21412953
0.28880000 0.27528787 0.21354208
0.28800000 0.27468414 0.21307399
0.28720000 0.27403144 0.21256793
0.28640000 0.27250530 0.21138466
0.28560000 0.27180723 0.21084341
0.28480000 0.27153994 0.21063618
0.28400000 0.27069680 0.20998246
0.28320000 0.26995049 0.20940382
0.28240000 0.26931476 0.20891091
0.28160000 0.26833495 0.20815123
0.28080000 0.26707636 0.20717540
0.28000000 0.26649987 0.20672843
0.27920000 0.26548899 0.20594466
0.27840000 0.26522033 0.20573635
0.27760000 0.26436218 0.20507100
0.27680000 0.26331129 0.20425621
0.27600000 0.26271341 0.20379265
0.27520000 0.26142646 0.20279483
0.27440000 0.26088761 0.20237704
0.27360000 0.26015938 0.20181242
0.27280000 0.25921554 0.20108062
0.27200000 0.25849307 0.20052046
0.27120000 0.25778072 0.19996815
0.27040000 0.25735756 0.19964006
0.26960000 0.25591553 0.19852200
0.26880000 0.25541358 0.19813282
0.26800000 0.25459216 0.19749595
0.26720000 0.25762923 0.19985069
0.26640000 0.25271587 0.19604119
0.26560000 0.25197091 0.19546359
0.26480000 0.25137326 0.19500021
0.26400000 0.25443596 0.19737483
0.26320000 0.25351338 0.19665953
0.26240000 0.24896544 0.19313334
0.26160000 0.24861350 0.19286047
0.26080000 0.24752827 0.19201905
0.26000000 0.24647198 0.19120007
0.25920000 0.24580837 0.19068555
0.25840000 0.24516300 0.19018517
0.25760000 0.24406478 0.18933368
0.25680000 0.24330838 0.18874722
0.25600000 0.24277573 0.18833423
0.25520000 0.24161365 0.18743323
0.25440000 0.24071116 0.18673349
0.25360000 0.24026826 0.18639010
0.25280000 0.23943520 0.18574420
0.25200000 0.23846942 0.18499539
0.25120000 0.23771598 0.18441122
0.25040000 0.23718742 0.18400141
0.24960000 0.23619929 0.18323528
0.24880000 0.23550462 0.18269668
0.24800000 0.23463014 0.18201866
0.24720000 0.23766113 0.18436870
0.24640000 0.23303122 0.18077896
0.24560000 0.23240063 0.18029004
0.24480000 0.23142740 0.17953546
0.24400000 0.23062591 0.17891403
0.24320000 0.22963618 0.17814666
0.24240000 0.22919926 0.17780790
0.24160000 0.22827604 0.17709210
0.24080000 0.22731008 0.17634315
0.24000000 0.22671133 0.17587892
0.23920000 0.22597401 0.17530725
0.23840000 0.22502407 0.17457072
0.23760000 0.22422899 0.17395427
0.23680000 0.22357325 0.17344584
0.23600000 0.22295678 0.17296787
0.23520000 0.22171657 0.17200629
0.23440000 0.22511117 0.17463825
0.23360000 0.22417418 0.17391177
0.23280000 0.21976388 0.17049230
0.23200000 0.21841973 0.16945014
0.23120000 0.22182331 0.17208906
0.23040000 0.21721956 0.16851960
0.22960000 0.21657918 0.16802309
0.22880000 0.21928470 0.17012078
0.22800000 0.21474560 0.16660144
0.22720000 0.21397098 0.16600086
0.22640000 0.21319422 0.16539860
0.22560000 0.21602619 0.16759434
0.22480000 0.21160103 0.16416335
0.22400000 0.21064100 0.16341900
0.22320000 0.20977130 0.16274469
0.22240000 0.20927082 0.16235665
0.22160000 0.20832144 0.16162056
0.22080000 0.20711995 0.16068900
0.22000000 0.20656839 0.16026135
0.21920000 0.20605668 0.15986461
0.21840000 0.20522911 0.15922296
0.21760000 0.21276003 0.16506196
0.21680000 0.21209525 0.16454653
0.21600000 0.21147812 0.16406805
0.21520000 0.21070605 0.16346943
0.21440000 0.20984178 0.16279934
0.21360000 0.20904932 0.16218491
0.21280000 0.20812843 0.16147091
0.21200000 0.20741350 0.16091660
0.21120000 0.20646680 0.16018259
0.21040000 0.20576397 0.15963766
0.20960000 0.20508018 0.15910749
0.20880000 0.20403590 0.15829782
0.20800000 0.20315413 0.15761416
0.20720000 0.20242068 0.15704549
0.20640000 0.20180098 0.15656501
0.20560000 0.20089081 0.15585932
0.20480000 0.20028673 0.15539096
0.20400000 0.19981341 0.15502397
0.20320000 0.19861392 0.15409396
0.20240000 0.19769354 0.15338036
0.20160000 0.19716198 0.15296822
0.20080000 0.19971404 0.15494693
0.20000000 0.19502455 0.15131099
0.19920000 0.19437710 0.15080900
0.19840000 0.19376872 0.15033730
0.19760000 0.19290541 0.14966794
0.19680000 0.19218570 0.14910993
0.19600000 0.19517306 0.15142614
0.19520000 0.19404275 0.15054977
0.19440000 0.18986930 0.14731394
0.19360000 0.18903897 0.14667015
0.19280000 0.19187816 0.14887148
0.19200000 0.18700041 0.14508959
0.19120000 0.18658387 0.14476663
0.19040000 0.18598289 0.14430066
0.18960000 0.18493588 0.14348888
0.18880000 0.18799859 0.14586351
0.18800000 0.18364696 0.14248953
0.18720000 0.18250464 0.14160385
0.18640000 0.18210067 0.14129064
0.18560000 0.18111998 0.14053027
0.18480000 0.18034916 0.13993263
0.18400000 0.18276869 0.14180858
0.18320000 0.17888678 0.13879879
0.18240000 0.17805185 0.13815144
0.18160000 0.17695200 0.13729868
0.18080000 0.17613112 0.13666223
0.18000000 0.17558365 0.13623776
0.17920000 0.17475372 0.13559427
0.17840000 0.17736480 0.13761875
0.17760000 0.17292035 0.13417280
0.17680000 0.17234610 0.13372756
0.17600000 0.17528125 0.13600329
0.17520000 0.17093085 0.13263027
0.17440000 0.17344767 0.13458165
0.17360000 0.16392786 0.12720059
0.17280000 0.15936860 0.12366563
0.17200000 0.15895215 0.12334274
0.17120000 0.17035720 0.13218549
0.17040000 0.16954581 0.13155639
0.16960000 0.16522727 0.12820807
0.16880000 0.16428945 0.12748095
0.16800000 0.16720593 0.12974220
0.16720000 0.16653064 0.12921862
0.16640000 0.16598186 0.12879313
0.16560000 0.16120648 0.12509061
0.16480000 0.16015997 0.12427921
0.16400000 0.15959181 0.12383869
0.16320000 0.15851935 0.12300717
0.16240000 0.16154946 0.12535653
0.16160000 0.16068661 0.12468753
0.16080000 0.15588962 0.12096825
0.16000000 0.15543658 0.12061699
0.15920000 0.15527129 0.12048884
0.15840000 0.15406873 0.11955644
0.15760000 0.15330184 0.11896185
0.15680000 0.15252316 0.11835811
0.15600000 0.15551951 0.12068129
0.15520000 0.15087682 0.11708164
0.15440000 0.14980005 0.11624678
0.15360000 0.14911411 0.11571495
0.15280000 0.14858052 0.11530124
0.15200000 0.14744986 0.11442460
0.15120000 0.15038033 0.11669670
0.15040000 0.14610388 0.11338101
0.14960000 0.14519105 0.11267325
0.14880000 0.14461861 0.11222942
0.14800000 0.14383293 0.11162025
0.14720000 0.14646426 0.11366043
0.14640000 0.14190300 0.11012391
0.14560000 0.14147957 0.10979561
0.14480000 0.14068310 0.10917808
0.14400000 0.13996204 0.10861901
0.14320000 0.13920400 0.10803128
0.14240000 0.13807756 0.10715790
0.14160000 0.14111984 0.10951670
0.14080000 0.13646450 0.10590724
0.14000000 0.13578767 0.10538247
0.13920000 0.13507534 0.10483018
0.13840000 0.13418052 0.10413639
0.13760000 0.13335849 0.10349904
0.13680000 0.13248980 0.10282551
0.13600000 0.13181361 0.10230124
0.13520000 0.13091436 0.10160401
0.13440000 0.13041631 0.10121786
0.13360000 0.12928950 0.10034420
0.13280000 0.12859480 0.09980558
0.13200000 0.13131051 0.10191117
0.13120000 0.13054248 0.10131568
0.13040000 0.12993550 0.10084507
0.12960000 0.12553307 0.09743171
0.12880000 0.12474807 0.09682306
0.12800000 0.12691540 0.09850347
0.12720000 0.12658506 0.09824735
0.12640000 0.12618585 0.09793783
0.12560000 0.12141851 0.09424153
0.12480000 0.12076495 0.09373480
0.12400000 0.12347057 0.09583258
0.12320000 0.12320197 0.09562432
0.12240000 0.12266978 0.09521169
0.12160000 0.12091770 0.09385324
0.12080000 0.11656057 0.09047500
0.12000000 0.11595457 0.09000514
0.11920000 0.11507468 0.08932293
0.11840000 0.11430371 0.08872517
0.11760000 0.11356371 0.08815142
0.11680000 0.11263368 0.08743034
0.11600000 0.11192490 0.08688079
0.11520000 0.11113927 0.08627167
0.11440000 0.11039521 0.08569477
0.11360000 0.10939911 0.08492245
0.11280000 0.10908281 0.08467721
0.11200000 0.10791793 0.08377404
0.11120000 0.11049327 0.08577080
0.11040000 0.11007294 0.08544490
0.10960000 0.10884665 0.08449411
0.10880000 0.10811317 0.08392541
0.10800000 0.10752112 0.08346638
0.10720000 0.10691750 0.08299837
0.10640000 0.10611175 0.08237365
0.10560000 0.10474898 0.08131704
0.10480000 0.10385002 0.08062004
0.10400000 0.10379584 0.08057804
0.10320000 0.10265981 0.07969723
0.10240000 0.09833972 0.07634770
0.10160000 0.09776793 0.07590438
0.10080000 0.09661783 0.07501266
0.10000000 0.09594526 0.07449119
0.09920000 0.09517283 0.07389230
0.09840000 0.09437737 0.07327555
0.09760000 0.09702110 0.07532533
0.09680000 0.09268703 0.07196497
0.09600000 0.09201713 0.07144557
0.09520000 0.09121328 0.07082232
0.09440000 0.09361809 0.07268685
0.09360000 0.09350920 0.07260243
0.09280000 0.09202955 0.07145520
0.09200000 0.09131176 0.07089867
0.09120000 0.09041468 0.07020313
0.09040000 0.08663295 0.06727102
0.08960000 0.08607677 0.06683979
0.08880000 0.08844253 0.06867405
0.08800000 0.08385648 0.06511832
0.08720000 0.08328438 0.06467474
0.08640000 0.08252690 0.06408745
0.08560000 0.08456426 0.06566709
0.08480000 0.08411239 0.06531673
0.08400000 0.07999036 0.06212077
0.08320000 0.07942972 0.06168609
0.08240000 0.08183209 0.06354873
0.08160000 0.07778029 0.06040723
0.08080000 0.07658420 0.05947985
0.08000000 0.07920389 0.06151100
0.07920000 0.07537972 0.05854598
0.07840000 0.07460860 0.05794810
0.07760000 0.07671796 0.05958356
0.07680000 0.07300173 0.05670223
0.07600000 0.07188958 0.05583994
0.07520000 0.07142230 0.05547764
0.07440000 0.07361332 0.05717642
0.07360000 0.07283368 0.05657194
0.07280000 0.06889835 0.05352073
0.07200000 0.06818029 0.05296399
0.07120000 0.06737637 0.05234069
0.07040000 0.06658035 0.05172350
0.06960000 0.06550690 0.05089121
0.06880000 0.06488257 0.05040715
0.06800000 0.06522785 0.05067486
0.06720000 0.06303058 0.04897124
0.06640000 0.06253748 0.04858892
0.06560000 0.06478445 0.05033107
0.06480000 0.06492416 0.05043940
0.06400000 0.06043131 0.04695593
0.06320000 0.05928310 0.04606568
0.06240000 0.06151166 0.04779356
0.06160000 0.06091292 0.04732933
0.06080000 0.05693909 0.04424828
0.06000000 0.05615634 0.04364138
0.05920000 0.05664663 0.04402153
0.05840000 0.05765644 0.04480447
0.05760000 0.05736576 0.04457910
0.05680000 0.05723612 0.04447857
0.05600000 0.05571647 0.04330034
0.05520000 0.05444654 0.04231571
0.05440000 0.05385702 0.04185864
0.05360000 0.05434562 0.04223747
0.05280000 0.04895228 0.03805582
0.05200000 0.04937960 0.03838713
0.05120000 0.04867810 0.03784323
0.05040000 0.04644725 0.03611357
0.04960000 0.04589720 0.03568710
0.04880000 0.04506847 0.03504455
0.04800000 0.04423359 0.03439724
0.04720000 0.04339118 0.03374409
0.04640000 0.04587357 0.03566878
0.04560000 0.04489062 0.03490666
0.04480000 0.04104058 0.03192158
0.04400000 0.04011853 0.03120669
0.04320000 0.03943437 0.03067623
0.04240000 0.03870370 0.03010971
0.04160000 0.03941011 0.03065742
0.04080000 0.03847555 0.02993282
0.04000000 0.03637623 0.02830514
0.03920000 0.03596556 0.02798673
0.03840000 0.03472177 0.02702238
0.03760000 0.03507522 0.02729642
0.03680000 0.03309719 0.02576278
0.03600000 0.03218461 0.02505523
0.03520000 0.03281125 0.02554108
0.03440000 0.03070645 0.02390915
0.03360000 0.02980391 0.02320938
0.03280000 0.02999469 0.02335730
0.03200000 0.02934979 0.02285729
0.03120000 0.02750498 0.02142693
0.03040000 0.02642673 0.02059093
0.02960000 0.02880371 0.02243389
0.02880000 0.02813960 0.02191898
0.02800000 0.02431271 0.01895186
0.02720000 0.02474247 0.01928506
0.02640000 0.02586042 0.02015185
0.02560000 0.02555926 0.01991835
0.02480000 0.02104419 0.01641765
0.02400000 0.02018248 0.01574953
0.02320000 0.02245593 0.01751222
0.02240000 0.02139900 0.01669275
0.02160000 0.01888217 0.01474136
0.02080000 0.01820991 0.01422013
0.02000000 0.01627901 0.01272303
0.01920000 0.01850954 0.01445244
0.01840000 0.01817555 0.01419348
0.01760000 0.01400015 0.01095614
0.01680000 0.01306371 0.01023009
0.01600000 0.01330530 0.01041740
0.01520000 0.01120754 0.00879093
0.01440000 0.01087445 0.00853268
0.01360000 0.01323975 0.01036658
0.01280000 0.01225780 0.00960524
0.01200000 0.00834114 0.00656851
0.01120000 0.00846384 0.00666364
0.01040000 0.00676387 0.00534560
0.00960000 0.00887961 0.00698600
0.00880000 0.00513322 0.00408129
0.00800000 0.00450319 0.00359281
0.00720000 0.00355562 0.00285812
0.00640000 0.00579614 0.00459528
0.00560000 0.00507015 0.00403239
0.00480000 0.00208796 0.00172019
0.00400000 0.00370548 0.00297431
0.00320000 -0.00021033 -0.00006176
0.00240000 -0.00103333 -0.00069986
0.00160000 0.00040344 0.00041412
0.00080000 -0.00225577 -0.00164766
-0.00000000 -0.00103282 -0.00069946