File: plots/rawdata/Figure2-5K-1.txt
# strain(%), strain_el(%), stress(GPa)
0.00000000 -0.00013068 0.00000000
0.00080000 0.00014433 0.00021322
0.00160000 0.00152414 0.00128304
0.00240000 0.00220467 0.00181068
0.00320000 0.00272637 0.00221517
0.00400000 0.00389262 0.00311941
0.00480000 0.00478356 0.00381019
0.00560000 0.00492943 0.00392328
0.00640000 0.00660682 0.00522382
0.00720000 0.00713398 0.00563256
0.00800000 0.00792894 0.00624892
0.00880000 0.00938043 0.00737431
0.00960000 0.01030241 0.00808915
0.01040000 0.01088548 0.00854123
0.01120000 0.01095956 0.00859867
0.01200000 0.01188697 0.00931772
0.01280000 0.01261667 0.00988348
0.01360000 0.01348266 0.01055492
0.01440000 0.01458733 0.01141141
0.01520000 0.01551413 0.01212999
0.01600000 0.01637586 0.01279812
0.01680000 0.01670081 0.01305007
0.01760000 0.01736084 0.01356181
0.01840000 0.01821231 0.01422199
0.01920000 0.01904279 0.01486589
0.02000000 0.02007942 0.01566963
0.02080000 0.02131570 0.01662816
0.02160000 0.02208301 0.01722308
0.02240000 0.02280468 0.01778262
0.02320000 0.02341261 0.01825397
0.02400000 0.02434442 0.01897644
0.02480000 0.02486554 0.01938048
0.02560000 0.02551473 0.01988382
0.02640000 0.02635303 0.02053379
0.02720000 0.02718832 0.02118142
0.02800000 0.02771059 0.02158635
0.02880000 0.02874361 0.02238729
0.02960000 0.02968177 0.02311468
0.03040000 0.03124696 0.02432823
0.03120000 0.03229017 0.02513707
0.03200000 0.03244009 0.02525330
0.03280000 0.03280715 0.02553790
0.03360000 0.03343172 0.02602216
0.03440000 0.03423229 0.02664287
0.03520000 0.03498485 0.02722635
0.03600000 0.03603310 0.02803910
0.03680000 0.03692816 0.02873307
0.03760000 0.03841594 0.02988660
0.03840000 0.03928521 0.03056058
0.03920000 0.03928798 0.03056272
0.04000000 0.03977730 0.03094212
0.04080000 0.04060858 0.03158664
0.04160000 0.04156531 0.03232842
0.04240000 0.04277169 0.03326377
0.04320000 0.04399629 0.03421326
0.04400000 0.04500748 0.03499726
0.04480000 0.04475445 0.03480108
0.04560000 0.04537074 0.03527892
0.04640000 0.04345979 0.03379729
0.04720000 0.04393412 0.03416505
0.04800000 0.04596503 0.03573969
0.04880000 0.04572932 0.03555693
0.04960000 0.04680860 0.03639374
0.05040000 0.04745248 0.03689297
0.05120000 0.04820418 0.03747579
0.05200000 0.04892092 0.03803150
0.05280000 0.04963489 0.03858507
0.05360000 0.05040895 0.03918523
0.05440000 0.05169138 0.04017954
0.05520000 0.05186393 0.04031332
0.05600000 0.05599709 0.04351791
0.05680000 0.05721559 0.04446266
0.05760000 0.05848998 0.04545074
0.05840000 0.05921110 0.04600985
0.05920000 0.05945737 0.04620079
0.06000000 0.05996744 0.04659627
0.06080000 0.06058401 0.04707432
0.06160000 0.06147467 0.04776488
0.06240000 0.06235909 0.04845061
0.06320000 0.06386839 0.04962082
0.06400000 0.06492212 0.05043781
0.06480000 0.06457663 0.05016995
0.06560000 0.06546220 0.05085656
0.06640000 0.06642840 0.05160569
0.06720000 0.06825477 0.05302174
0.06800000 0.06831082 0.05306520
0.06880000 0.06880467 0.05344810
0.06960000 0.06924822 0.05379200
0.07040000 0.07037296 0.05466405
0.07120000 0.07186384 0.05581998
0.07200000 0.07282285 0.05656354
0.07280000 0.07309194 0.05677217
0.07360000 0.07368776 0.05723414
0.07440000 0.07406472 0.05752641
0.07520000 0.07502612 0.05827181
0.07600000 0.07600712 0.05903243
0.07680000 0.07667745 0.05955215
0.07760000 0.07732483 0.06005409
0.07840000 0.07842935 0.06091047
0.07920000 0.07908680 0.06142021
0.08000000 0.07970070 0.06189619
0.08080000 0.08071070 0.06267928
0.08160000 0.08145559 0.06325682
0.08240000 0.08215634 0.06380014
0.08320000 0.08324927 0.06464753
0.08400000 0.08400679 0.06523486
0.08480000 0.08461686 0.06570787
0.08560000 0.08555305 0.06643373
0.08640000 0.08620719 0.06694091
0.08720000 0.08696480 0.06752831
0.08800000 0.08806893 0.06838438
0.08880000 0.08525910 0.06620582
0.08960000 0.08649782 0.06716625
0.09040000 0.08705472 0.06759803
0.09120000 0.08807656 0.06839030
0.09200000 0.08879627 0.06894832
0.09280000 0.08942083 0.06943256
0.09360000 0.08999277 0.06987601
0.09440000 0.09105043 0.07069605
0.09520000 0.09167831 0.07118287
0.09600000 0.09262722 0.07191859
0.09680000 0.09346846 0.07257084
0.09760000 0.09427852 0.07319890
0.09840000 0.09498421 0.07374605
0.09920000 0.09565097 0.07426301
0.10000000 0.09665001 0.07503761
0.10080000 0.09775114 0.07589136
0.10160000 0.09822223 0.07625661
0.10240000 0.09926744 0.07706700
0.10320000 0.09986562 0.07753079
0.10400000 0.10075854 0.07822311
0.10480000 0.10133584 0.07867070
0.10560000 0.10230992 0.07942594
0.10640000 0.10307823 0.08002164
0.10720000 0.10387805 0.08064178
0.10800000 0.10444023 0.08107766
0.10880000 0.10555790 0.08194422
0.10960000 0.10602216 0.08230418
0.11040000 0.10689277 0.08297920
0.11120000 0.10778395 0.08367016
0.11200000 0.10852477 0.08424454
0.11280000 0.10959600 0.08507511
0.11360000 0.11006333 0.08543745
0.11440000 0.11108342 0.08622836
0.11520000 0.11173361 0.08673247
0.11600000 0.11266417 0.08745398
0.11680000 0.11356956 0.08815596
0.11760000 0.11414310 0.08860064
0.11840000 0.11497861 0.08924845
0.11920000 0.11568259 0.08979427
0.12000000 0.11659107 0.09049865
0.12080000 0.11749884 0.09120247
0.12160000 0.11805563 0.09163417
0.12240000 0.11887625 0.09227043
0.12320000 0.11979466 0.09298251
0.12400000 0.12045170 0.09349193
0.12480000 0.12140498 0.09423104
0.12560000 0.12223051 0.09487111
0.12640000 0.12304767 0.09550469
0.12720000 0.12366984 0.09598707
0.12800000 0.12437515 0.09653393
0.12880000 0.12532018 0.09726664
0.12960000 0.12608968 0.09786326
0.13040000 0.12716997 0.09870086
0.13120000 0.12768890 0.09910320
0.13200000 0.12855401 0.09977395
0.13280000 0.12929378 0.10034752
0.13360000 0.13020021 0.10105031
0.13440000 0.13064965 0.10139878
0.13520000 0.13199223 0.10243973
0.13600000 0.13242320 0.10277388
0.13680000 0.13319952 0.10337578
0.13760000 0.13426252 0.10419996
0.13840000 0.13486337 0.10466583
0.13920000 0.13564284 0.10527018
0.14000000 0.13638298 0.10584403
0.14080000 0.13745755 0.10667719
0.14160000 0.13816244 0.10722372
0.14240000 0.13849021 0.10747785
0.14320000 0.13977854 0.10847674
0.14400000 0.14041763 0.10897225
0.14480000 0.14502648 0.11254566
0.14560000 0.14561527 0.11300217
0.14640000 0.14621018 0.11346342
0.14720000 0.14710715 0.11415888
0.14800000 0.14777198 0.11467435
0.14880000 0.14885117 0.11551108
0.14960000 0.14908264 0.11569055
0.15040000 0.15042075 0.11672804
0.15120000 0.15101439 0.11718830
0.15200000 0.15152948 0.11758767
0.15280000 0.15277357 0.11855226
0.15360000 0.15345454 0.11908024
0.15440000 0.15428175 0.11972161
0.15520000 0.15492691 0.12022183
0.15600000 0.15597362 0.12103338
0.15680000 0.15657911 0.12150283
0.15760000 0.15391749 0.11943919
0.15840000 0.15483533 0.12015082
0.15920000 0.15572941 0.12084403
0.16000000 0.15608289 0.12111810
0.16080000 0.15701998 0.12184466
0.16160000 0.15804587 0.12264007
0.16240000 0.15882856 0.12324692
0.16320000 0.15956822 0.12382041
0.16400000 0.16029574 0.12438448
0.16480000 0.16095852 0.12489836
0.16560000 0.16206838 0.12575887
0.16640000 0.16277178 0.12630424
0.16720000 0.16345636 0.12683502
0.16800000 0.16448048 0.12762906
0.16880000 0.16523349 0.12821289
0.16960000 0.16569462 0.12857043
0.17040000 0.16652444 0.12921382
0.17120000 0.16753457 0.12999701
0.17200000 0.16843458 0.13069482
0.17280000 0.16895863 0.13110113
0.17360000 0.16990027 0.13183122
0.17440000 0.17065300 0.13241484
0.17520000 0.17152090 0.13308776
0.17600000 0.17211530 0.13354861
0.17680000 0.17321044 0.13439771
0.17760000 0.17402306 0.13502777
0.17840000 0.17429735 0.13524043
0.17920000 0.17513351 0.13588875
0.18000000 0.17642639 0.13689116
0.18080000 0.17695115 0.13729803
0.18160000 0.17762411 0.13781980
0.18240000 0.17863129 0.13860070
0.18320000 0.17965021 0.13939070
0.18400000 0.18010445 0.13974290
0.18480000 0.18065028 0.14016610
0.18560000 0.18187065 0.14111229
0.18640000 0.18283936 0.14186337
0.18720000 0.18336075 0.14226762
0.18800000 0.18386115 0.14265560
0.18880000 0.18472734 0.14332719
0.18960000 0.18607401 0.14437132
0.19040000 0.18651486 0.14471312
0.19120000 0.18726590 0.14529543
0.19200000 0.18806642 0.14591610
0.19280000 0.18926885 0.14684839
0.19360000 0.18965171 0.14714523
0.19440000 0.19046898 0.14777889
0.19520000 0.19148944 0.14857009
0.19600000 0.19223868 0.14915101
0.19680000 0.19273494 0.14953578
0.19760000 0.19371488 0.15029556
0.19840000 0.19465607 0.15102529
0.19920000 0.19518380 0.15143447
0.20000000 0.19577843 0.15189550
0.20080000 0.19688063 0.15275008
0.20160000 0.19775016 0.15342426
0.20240000 0.19845488 0.15397065
0.20320000 0.19895407 0.15435770
0.20400000 0.20002930 0.15519136
0.20480000 0.20099056 0.15593666
0.20560000 0.20126872 0.15615233
0.20640000 0.20228577 0.15694088
0.20720000 0.20326965 0.15770372
0.20800000 0.20405473 0.15831243
0.20880000 0.20456850 0.15871077
0.20960000 0.20546985 0.15940962
0.21040000 0.20662434 0.16030474
0.21120000 0.20695171 0.16055856
0.21200000 0.20792367 0.16131215
0.21280000 0.20875803 0.16195907
0.21360000 0.20982110 0.16278330
0.21440000 0.21012829 0.16302148
0.21520000 0.21088149 0.16360546
0.21600000 0.21194297 0.16442846
0.21680000 0.21277645 0.16507469
0.21760000 0.21371457 0.16580205
0.21840000 0.21409198 0.16609467
0.21920000 0.21505117 0.16683836
0.22000000 0.21600004 0.16757406
0.22080000 0.21665482 0.16808174
0.22160000 0.21741369 0.16867011
0.22240000 0.21810788 0.16920835
0.22320000 0.21916492 0.17002791
0.22400000 0.21980228 0.17052207
0.22480000 0.22079503 0.17129179
0.22560000 0.22135042 0.17172240
0.22640000 0.22207411 0.17228351
0.22720000 0.22292067 0.17293988
0.22800000 0.22388718 0.17368924
0.22880000 0.22466058 0.17428890
0.22960000 0.22512862 0.17465178
0.23040000 0.22600401 0.17533050
0.23120000 0.22690187 0.17602665
0.23200000 0.22788772 0.17679102
0.23280000 0.22848572 0.17725466
0.23360000 0.22927106 0.17786356
0.23440000 0.23029726 0.17865922
0.23520000 0.23109930 0.17928107
0.23600000 0.23175947 0.17979292
0.23680000 0.23233170 0.18023659
0.23760000 0.23343328 0.18109069
0.23840000 0.23433054 0.18178637
0.23920000 0.23461716 0.18200860
0.24000000 0.23564423 0.18280492
0.24080000 0.23653482 0.18349543
0.24160000 0.23749171 0.18423734
0.24240000 0.23807796 0.18469188
0.24320000 0.23865592 0.18513999
0.24400000 0.23976189 0.18599749
0.24480000 0.24034072 0.18644628
0.24560000 0.24127351 0.18716951
0.24640000 0.24178678 0.18756746
0.24720000 0.24288311 0.18841749
0.24800000 0.24355686 0.18893987
0.24880000 0.24434261 0.18954909
0.24960000 0.24516160 0.19018408
0.25040000 0.24589777 0.19075487
0.25120000 0.24663781 0.19132865
0.25200000 0.24745250 0.19196030
0.25280000 0.24859121 0.19284319
0.25360000 0.24930254 0.19339471
0.25440000 0.24979449 0.19377613
0.25520000 0.25044022 0.19427679
0.25600000 0.25148764 0.19508890
0.25680000 0.25242384 0.19581477
0.25760000 0.25312625 0.19635937
0.25840000 0.25393767 0.19698849
0.25920000 0.25480840 0.19766360
0.26000000 0.25545429 0.19816438
0.26080000 0.25643627 0.19892575
0.26160000 0.25701658 0.19937569
0.26240000 0.25788348 0.20004782
0.26320000 0.25866090 0.20065058
0.26400000 0.25960361 0.20138150
0.26480000 0.26015809 0.20181141
0.26560000 0.26108994 0.20253391
0.26640000 0.26191707 0.20317522
0.26720000 0.26259066 0.20369747
0.26800000 0.26353281 0.20442796
0.26880000 0.26430594 0.20502739
0.26960000 0.26460227 0.20525715
0.27040000 0.26572426 0.20612707
0.27120000 0.26692877 0.20706097
0.27200000 0.26777789 0.20771932
0.27280000 0.26801753 0.20790513
0.27360000 0.26889631 0.20858647
0.27440000 0.27021342 0.20960768
0.27520000 0.27058242 0.20989378
0.27600000 0.27127229 0.21042866
0.27680000 0.27207927 0.21105434
0.27760000 0.27331979 0.21201616
0.27840000 0.27377721 0.21237082
0.27920000 0.27439959 0.21285337
0.28000000 0.27563900 0.21381433
0.28080000 0.27627195 0.21430508
0.28160000 0.27700538 0.21487373
0.28240000 0.27762580 0.21535476
0.28320000 0.27865366 0.21615171
0.28400000 0.27926674 0.21662705
0.28480000 0.27998514 0.21718405
0.28560000 0.28092132 0.21790991
0.28640000 0.28190387 0.21867171
0.28720000 0.28245556 0.21909946
0.28800000 0.28322321 0.21969465
0.28880000 0.28443846 0.22063688
0.28960000 0.28498412 0.22105994
0.29040000 0.28546088 0.22142959
0.29120000 0.28642596 0.22217785
0.29200000 0.28747593 0.22299194
0.29280000 0.28799113 0.22339139
0.29360000 0.28864729 0.22390013
0.29440000 0.28964530 0.22467393
0.29520000 0.29060053 0.22541455
0.29600000 0.29126887 0.22593274
0.29680000 0.29186871 0.22639782
0.29760000 0.29277016 0.22709674
0.29840000 0.29378744 0.22788548
0.29920000 0.29448991 0.22843013
0.30000000 0.29492842 0.22877013
0.30080000 0.29576101 0.22941566
0.30160000 0.29700015 0.23037641
0.30240000 0.29765415 0.23088348
0.30320000 0.29800678 0.23115689
0.30400000 0.29894321 0.23188294
0.30480000 0.30004047 0.23273369
0.30560000 0.30095839 0.23344538
0.30640000 0.30131229 0.23371977
0.30720000 0.30183724 0.23412679
0.30800000 0.30332587 0.23528097
0.30880000 0.30400476 0.23580734
0.30960000 0.30452824 0.23621322
0.31040000 0.30519734 0.23673200
0.31120000 0.30677775 0.23795734
0.31200000 0.30727417 0.23834224
0.31280000 0.30788352 0.23881468
0.31360000 0.30859730 0.23936811
0.31440000 0.30909786 0.23975621
0.31520000 0.31030585 0.24069280
0.31600000 0.31119540 0.24138251
0.31680000 0.31172549 0.24179351
0.31760000 0.31231980 0.24225430
0.31840000 0.31344102 0.24312362
0.31920000 0.31432525 0.24380920
0.32000000 0.31499762 0.24433051
0.32080000 0.31553934 0.24475053
0.32160000 0.31652483 0.24551461
0.32240000 0.31747474 0.24625111
0.32320000 0.31849360 0.24704107
0.32400000 0.31884669 0.24731484
0.32480000 0.31964199 0.24793146
0.32560000 0.32058362 0.24866154
0.32640000 0.32126000 0.24918596
0.32720000 0.32218705 0.24990474
0.32800000 0.32309441 0.25060825
0.32880000 0.32396458 0.25128292
0.32960000 0.32440501 0.25162440
0.33040000 0.32550970 0.25248091
0.33120000 0.32614866 0.25297632
0.33200000 0.32644634 0.25320712
0.33280000 0.32753444 0.25405077
0.33360000 0.32860112 0.25487780
0.33440000 0.32939697 0.25549486
0.33520000 0.32965742 0.25569679
0.33600000 0.33037509 0.25625323
0.33680000 0.33164716 0.25723951
0.33760000 0.33246280 0.25787191
0.33840000 0.33326042 0.25849033
0.33920000 0.33414638 0.25917724
0.34000000 0.33421750 0.25923239
0.34080000 0.33522899 0.26001663
0.34160000 0.33655513 0.26104483
0.34240000 0.33706789 0.26144239
0.34320000 0.33766374 0.26190439
0.34400000 0.33821390 0.26233094
0.34480000 0.33967492 0.26346372
0.34560000 0.34047207 0.26408178
0.34640000 0.34103572 0.26451880
0.34720000 0.34121929 0.26466113
0.34800000 0.34262235 0.26574897
0.34880000 0.34361046 0.26651509
0.34960000 0.34459965 0.26728205
0.35040000 0.34509287 0.26766446
0.35120000 0.34524638 0.26778348
0.35200000 0.34640524 0.26868199
0.35280000 0.34711825 0.26923481
0.35360000 0.34768985 0.26967799
0.35440000 0.34928803 0.27091712
0.35520000 0.35001821 0.27148326
0.35600000 0.35077787 0.27207225
0.35680000 0.35096061 0.27221393
0.35760000 0.35173900 0.27281745
0.35840000 0.35252034 0.27342325
0.35920000 0.35390246 0.27449485
0.36000000 0.35483032 0.27521426
0.36080000 0.35533233 0.27560349
0.36160000 0.35565033 0.27585004
0.36240000 0.35663058 0.27661007
0.36320000 0.35810067 0.27774988
0.36400000 0.35876993 0.27826878
0.36480000 0.35902298 0.27846498
0.36560000 0.35940766 0.27876324
0.36640000 0.36031896 0.27946981
0.36720000 0.36137968 0.28029222
0.36800000 0.36304173 0.28158087
0.36880000 0.36355359 0.28197773
0.36960000 0.36340301 0.28186098
0.37040000 0.36433501 0.28258360
0.37120000 0.36584096 0.28375121
0.37200000 0.36672777 0.28443879
0.37280000 0.36687477 0.28455276
0.37360000 0.36745663 0.28500390
0.37440000 0.36829012 0.28565013
0.37520000 0.36942723 0.28653178
0.37600000 0.37059311 0.28743573
0.37680000 0.37128994 0.28797601
0.37760000 0.37145840 0.28810662
0.37840000 0.37230037 0.28875943
0.37920000 0.37343975 0.28964283
0.38000000 0.37454286 0.29049811
0.38080000 0.37522458 0.29102668
0.38160000 0.37550483 0.29124397
0.38240000 0.37639001 0.29193028
0.38320000 0.37410837 0.29016124
0.38400000 0.37460842 0.29054895
0.38480000 0.37523785 0.29103697
0.38560000 0.37585544 0.29151580
0.38640000 0.38014661 0.29484290
0.38720000 0.38068745 0.29526224
0.38800000 0.37818932 0.29332535
0.38880000 0.37787733 0.29308345
0.38960000 0.38390544 0.29775727
0.39040000 0.38396705 0.29780504
0.39120000 0.38528475 0.29882669
0.39200000 0.38131276 0.29574706
0.39280000 0.38711114 0.30024276
0.39360000 0.38735926 0.30043514
0.39440000 0.38812119 0.30102589
0.39520000 0.38917268 0.30184115
0.39600000 0.39002883 0.30250496
0.39680000 0.39063861 0.30297774
0.39760000 0.39125549 0.30345603
0.39840000 0.39207747 0.30409334
0.39920000 0.39314812 0.30492345
0.40000000 0.39413495 0.30568858
0.40080000 0.39504942 0.30639760
0.40160000 0.39554231 0.30677976
0.40240000 0.39617063 0.30726692
0.40320000 0.39672747 0.30769866
0.40400000 0.39779419 0.30852572
0.40480000 0.39922375 0.30963411
0.40560000 0.39977537 0.31006181
0.40640000 0.39487996 0.30626621
0.40720000 0.39534233 0.30662471
0.40800000 0.39636461 0.30741732
0.40880000 0.39727667 0.30812447
0.40960000 0.39815097 0.30880235
0.41040000 0.39914936 0.30957644
0.41120000 0.40462293 0.31382030
0.41200000 0.40589074 0.31480327
0.41280000 0.40692154 0.31560249
0.41360000 0.40728802 0.31588664
0.41440000 0.40804245 0.31647157
0.41520000 0.40866910 0.31695744
0.41600000 0.41039853 0.31829833
0.41680000 0.41101586 0.31877697
0.41760000 0.41087692 0.31866924
0.41840000 0.41187447 0.31944268
0.41920000 0.41345019 0.32066439
0.42000000 0.41444411 0.32143502
0.42080000 0.41416165 0.32121601
0.42160000 0.41504731 0.32190270
0.42240000 0.41673153 0.32320854
0.42320000 0.41741822 0.32374095
0.42400000 0.41740513 0.32373080
0.42480000 0.41797645 0.32417377
0.42560000 0.41955610 0.32539853
0.42640000 0.42055667 0.32617431
0.42720000 0.42119850 0.32667194
0.42800000 0.42115116 0.32663524
0.42880000 0.42199999 0.32729337
0.42960000 0.42355789 0.32850126
0.43040000 0.42423661 0.32902750
0.43120000 0.42480988 0.32947198
0.43200000 0.42514653 0.32973299
0.43280000 0.42644312 0.33073829
0.43360000 0.42772979 0.33173589
0.43440000 0.42837857 0.33223891
0.43520000 0.42846531 0.33230617
0.43600000 0.42889400 0.33263854
0.43680000 0.43115627 0.33439257
0.43760000 0.43176091 0.33486137
0.43840000 0.43213558 0.33515186
0.43920000 0.43233721 0.33530819
0.44000000 0.43318243 0.33596352
0.44080000 0.43462910 0.33708518
0.44160000 0.43538312 0.33766980
0.44240000 0.43575889 0.33796115
0.44320000 0.43603599 0.33817599
0.44400000 0.43705493 0.33896601
0.44480000 0.43851224 0.34009592
0.44560000 0.43923773 0.34065841
0.44640000 0.43966837 0.34099231
0.44720000 0.44017599 0.34138588
0.44800000 0.44185335 0.34268640
0.44880000 0.44224025 0.34298638
0.44960000 0.44355719 0.34400746
0.45040000 0.44340122 0.34388653
0.45120000 0.43873997 0.34027248
0.45200000 0.43946741 0.34083649
0.45280000 0.43986828 0.34114731
0.45360000 0.44072374 0.34181057
0.45440000 0.43702728 0.33894457
0.45520000 0.43712558 0.33902079
0.45600000 0.44284262 0.34345342
0.45680000 0.44977399 0.34882757
0.45760000 0.45051530 0.34940233
0.45840000 0.45132165 0.35002752
0.45920000 0.45215661 0.35067490
0.46000000 0.44681555 0.34653378
0.46080000 0.44771318 0.34722974
0.46160000 0.44897785 0.34821029
0.46240000 0.44878570 0.34806131
0.46320000 0.45080148 0.34962422
0.46400000 0.45108786 0.34984626
0.46480000 0.45163210 0.35026822
0.46560000 0.45192495 0.35049528
0.46640000 0.45285520 0.35121654
0.46720000 0.45368818 0.35186238
0.46800000 0.45496420 0.35285173
0.46880000 0.45517910 0.35301835
0.46960000 0.45613202 0.35375718
0.47040000 0.45686302 0.35432395
0.47120000 0.45774332 0.35500648
0.47200000 0.45824538 0.35539574
0.47280000 0.45927115 0.35619106
0.47360000 0.46035211 0.35702917
0.47440000 0.46132688 0.35778494
0.47520000 0.46151273 0.35792904
0.47600000 0.46236777 0.35859198
0.47680000 0.46285890 0.35897277
0.47760000 0.46380399 0.35970554
0.47840000 0.46456196 0.36029322
0.47920000 0.46558980 0.36109014
0.48000000 0.46589185 0.36132433
0.48080000 0.46695804 0.36215098
0.48160000 0.46790990 0.36288900
0.48240000 0.46836024 0.36323816
0.48320000 0.46949225 0.36411585
0.48400000 0.46987088 0.36440942
0.48480000 0.47136111 0.36556485
0.48560000 0.47137386 0.36557474
0.48640000 0.47223321 0.36624102
0.48720000 0.47380592 0.36746040
0.48800000 0.47389240 0.36752745
0.48880000 0.47436456 0.36789353
0.48960000 0.47535486 0.36866135
0.49040000 0.47622148 0.36933327
0.49120000 0.47714205 0.37004702
0.49200000 0.47819395 0.37086260
0.49280000 0.47877206 0.37131083
0.49360000 0.47926785 0.37169523
0.49440000 0.48057894 0.37271177
0.49520000 0.48107848 0.37309908
0.49600000 0.48197508 0.37379425
0.49680000 0.48276288 0.37440506
0.49760000 0.48316683 0.37471826
0.49840000 0.48406281 0.37541294
0.49920000 0.48495600 0.37610546
0.50000000 0.48533119 0.37639636
0.50080000 0.48615114 0.37703210
0.50160000 0.48677753 0.37751776
0.50240000 0.48820447 0.37862412
0.50320000 0.48856226 0.37890153
0.50400000 0.48956075 0.37967570
0.50480000 0.49035569 0.38029205
0.50560000 0.49104932 0.38082984
0.50640000 0.49165147 0.38129671
0.50720000 0.49314868 0.38245755
0.50800000 0.49345915 0.38269827
0.50880000 0.49391331 0.38305040
0.50960000 0.49514887 0.38400837
0.51040000 0.49568473 0.38442385
0.51120000 0.49654136 0.38508802
0.51200000 0.49719506 0.38559486
0.51280000 0.49837863 0.38651252
0.51360000 0.49905084 0.38703371
0.51440000 0.49956154 0.38742967
0.51520000 0.50048643 0.38814678
0.51600000 0.50144880 0.38889294
0.51680000 0.50202904 0.38934282
0.51760000 0.50257995 0.38976996
0.51840000 0.50352941 0.39050611
0.51920000 0.50441370 0.39119173
0.52000000 0.50529686 0.39187648
0.52080000 0.50578615 0.39225584
0.52160000 0.50685986 0.39308833
0.52240000 0.50741458 0.39351843
0.52320000 0.50834293 0.39423821
0.52400000 0.50929836 0.39497899
0.52480000 0.50994021 0.39547664
0.52560000 0.51093992 0.39625175
0.52640000 0.51166777 0.39681607
0.52720000 0.51236169 0.39735410
0.52800000 0.51267110 0.39759400
0.52880000 0.51381510 0.39848098
0.52960000 0.51491504 0.39933381
0.53040000 0.51514648 0.39951325
0.53120000 0.51599168 0.40016857
0.53200000 0.51658448 0.40062818
0.53280000 0.51798178 0.40171156
0.53360000 0.51848499 0.40210172
0.53440000 0.51904661 0.40253716
0.53520000 0.51978564 0.40311016
0.53600000 0.52060422 0.40374483
0.53680000 0.52145805 0.40440684
0.53760000 0.52254106 0.40524654
0.53840000 0.52335719 0.40587931
0.53920000 0.52372314 0.40616305
0.54000000 0.52482578 0.40701797
0.54080000 0.52552956 0.40756363
0.54160000 0.52617368 0.40806304
0.54240000 0.52691573 0.40863838
0.54320000 0.52794322 0.40943503
0.54400000 0.52864006 0.40997531
0.54480000 0.52913726 0.41036082
0.54560000 0.53039482 0.41133585
0.54640000 0.53089461 0.41172335
0.54720000 0.53162398 0.41228886
0.54800000 0.53261748 0.41305916
0.54880000 0.53332980 0.41361144
0.54960000 0.53406202 0.41417916
0.55040000 0.53489974 0.41482868
0.55120000 0.53576645 0.41550067
0.55200000 0.53660575 0.41615141
0.55280000 0.53711100 0.41654315
0.55360000 0.53777346 0.41705678
0.55440000 0.53353317 0.41376913
0.55520000 0.53464216 0.41462896
0.55600000 0.53523926 0.41509192
0.55680000 0.54118576 0.41970246
0.55760000 0.54204388 0.42036779
0.55840000 0.54241193 0.42065315
0.55920000 0.54371372 0.42166247
0.56000000 0.54160913 0.42003071
0.56080000 0.53960601 0.41847762
0.56160000 0.54063000 0.41927155
0.56200000 0.54102494 0.41957777
0.56120000 0.54028342 0.41900284
0.56040000 0.53962928 0.41849566
0.55960000 0.53881753 0.41786628
0.55880000 0.53819177 0.41738111
0.55800000 0.53212368 0.41267629
0.55720000 0.53226414 0.41278520
0.55640000 0.53172007 0.41236336
0.55560000 0.53007781 0.41109005
0.55480000 0.53456044 0.41456561
0.55400000 0.53377183 0.41395417
0.55320000 0.53305611 0.41339924
0.55240000 0.52556538 0.40759141
0.55160000 0.52444512 0.40672283
0.55080000 0.52382364 0.40624097
0.55000000 0.52305570 0.40564556
0.54920000 0.52215012 0.40494343
0.54840000 0.52142755 0.40438319
0.54760000 0.52088991 0.40396634
0.54680000 0.51929860 0.40273254
0.54600000 0.51873085 0.40229234
0.54520000 0.51831854 0.40197267
0.54440000 0.52296656 0.40557645
0.54360000 0.52223035 0.40500564
0.54280000 0.52081142 0.40390548
0.54200000 0.51975047 0.40308289
0.54120000 0.51912914 0.40260115
0.54040000 0.51921645 0.40266885
0.53960000 0.51822663 0.40190140
0.53880000 0.51664698 0.40067664
0.53800000 0.51580882 0.40002679
0.53720000 0.51541401 0.39972068
0.53640000 0.51484120 0.39927655
0.53560000 0.51328574 0.39807055
0.53480000 0.51287751 0.39775403
0.53400000 0.51250140 0.39746242
0.53320000 0.51135774 0.39657570
0.53240000 0.51140191 0.39660994
0.53160000 0.51090906 0.39622782
0.53080000 0.50921847 0.39491705
0.53000000 0.50837238 0.39426104
0.52920000 0.50808303 0.39403670
0.52840000 0.50701299 0.39320706
0.52760000 0.50584398 0.39230068
0.52680000 0.50530491 0.39188272
0.52600000 0.50509189 0.39171756
0.52520000 0.50374269 0.39067148
0.52440000 0.50251418 0.38971897
0.52360000 0.50195183 0.38928295
0.52280000 0.50191079 0.38925114
0.52200000 0.50065796 0.38827977
0.52120000 0.49899581 0.38699104
0.52040000 0.49857015 0.38666101
0.51960000 0.49854535 0.38664178
0.51880000 0.49818256 0.38636050
0.51800000 0.49663333 0.38515932
0.51720000 0.49567668 0.38441760
0.51640000 0.49491576 0.38382763
0.51560000 0.49418278 0.38325932
0.51480000 0.49519365 0.38404309
0.51400000 0.49477001 0.38371463
0.51320000 0.49393424 0.38306663
0.51240000 0.49302989 0.38236545
0.51160000 0.49208216 0.38163064
0.51080000 0.49112994 0.38089235
0.51000000 0.48938688 0.37954089
0.50920000 0.48836391 0.37874774
0.50840000 0.48768396 0.37822055
0.50760000 0.48781746 0.37832406
0.50680000 0.48693045 0.37763633
0.50600000 0.48715925 0.37781373
0.50520000 0.48667757 0.37744026
0.50440000 0.48543471 0.37647663
0.50360000 0.48383600 0.37523709
0.50280000 0.48318443 0.37473190
0.50200000 0.48340248 0.37490096
0.50120000 0.48248373 0.37418862
0.50040000 0.48118352 0.37318052
0.49960000 0.48022059 0.37243393
0.49880000 0.47924813 0.37167994
0.49800000 0.47763764 0.37043127
0.49720000 0.47614940 0.36927738
0.49640000 0.47512205 0.36848084
0.49560000 0.47462957 0.36809901
0.49480000 0.47426610 0.36781720
0.49400000 0.47378583 0.36744482
0.49320000 0.47397109 0.36758846
0.49240000 0.47308382 0.36690053
0.49160000 0.47259330 0.36652021
0.49080000 0.47232190 0.36630978
0.49000000 0.47145027 0.36563398
0.48920000 0.46959667 0.36419681
0.48840000 0.46744872 0.36253143
0.48760000 0.46672493 0.36197025
0.48680000 0.46625724 0.36160763
0.48600000 0.46711281 0.36227099
0.48520000 0.46638544 0.36170703
0.48440000 0.46528724 0.36085555
0.48360000 0.46250958 0.35870194
0.48280000 0.46257341 0.35875143
0.48200000 0.46238527 0.35860555
0.48120000 0.46244544 0.35865220
0.48040000 0.46155030 0.35795817
0.47960000 0.46123454 0.35771335
0.47880000 0.45838994 0.35550782
0.47800000 0.45714527 0.35454279
0.47720000 0.45658143 0.35410562
0.47640000 0.45805584 0.35524879
0.47560000 0.46256522 0.35874507
0.47480000 0.46184591 0.35818737
0.47400000 0.46020503 0.35691513
0.47320000 0.45476821 0.35269976
0.47240000 0.45390289 0.35202885
0.47160000 0.45300525 0.35133288
0.47080000 0.45778684 0.35504022
0.47000000 0.45676513 0.35424805
0.46920000 0.45596318 0.35362627
0.46840000 0.45558412 0.35333237
0.46760000 0.44949131 0.34860839
0.46680000 0.44806236 0.34750047
0.46600000 0.44746592 0.34703803
0.46520000 0.44720256 0.34683384
0.46440000 0.45124051 0.34996461
0.46360000 0.45033241 0.34926053
0.46280000 0.44992724 0.34894638
0.46200000 0.44919357 0.34837754
0.46120000 0.44791492 0.34738616
0.46040000 0.44685595 0.34656510
0.45960000 0.44654416 0.34632336
0.45880000 0.44610248 0.34598091
0.45800000 0.44508670 0.34519334
0.45720000 0.44371184 0.34412736
0.45640000 0.44304054 0.34360687
0.45560000 0.44293212 0.34352281
0.45480000 0.44202716 0.34282117
0.45400000 0.44102568 0.34204468
0.45320000 0.43744890 0.33927147
0.45240000 0.43681769 0.33878207
0.45160000 0.43678806 0.33875910
0.45080000 0.43793962 0.33965194
0.45000000 0.43680929 0.33877556
0.44920000 0.43578765 0.33798344
0.44840000 0.43352271 0.33622736
0.44760000 0.43272402 0.33560810
0.44680000 0.43173702 0.33484284
0.44600000 0.43263025 0.33553540
0.44520000 0.43194570 0.33500464
0.44440000 0.42760361 0.33163805
0.44360000 0.42561967 0.33009984
0.44280000 0.42469788 0.32938513
0.44200000 0.42394635 0.32880245
0.44120000 0.42819131 0.33209372
0.44040000 0.42784631 0.33182623
0.43960000 0.42673981 0.33096832
0.43880000 0.42564514 0.33011958
0.43800000 0.42445068 0.32919347
0.43720000 0.42414713 0.32895812
0.43640000 0.42333378 0.32832750
0.43560000 0.42306007 0.32811528
0.43480000 0.42202846 0.32731544
0.43400000 0.42073137 0.32630976
0.43320000 0.42001348 0.32575315
0.43240000 0.41966769 0.32548505
0.43160000 0.41879083 0.32480518
0.43080000 0.41784751 0.32407380
0.43000000 0.41712338 0.32351235
0.42920000 0.41618859 0.32278758
0.42840000 0.41553931 0.32228416
0.42760000 0.41487419 0.32176847
0.42680000 0.41393929 0.32104361
0.42600000 0.41289192 0.32023154
0.42520000 0.41241815 0.31986421
0.42440000 0.41170271 0.31930950
0.42360000 0.40914003 0.31732257
0.42280000 0.40753834 0.31608072
0.42200000 0.40649610 0.31527263
0.42120000 0.40638155 0.31518382
0.42040000 0.40757382 0.31610823
0.41960000 0.40681593 0.31552061
0.41880000 0.40575742 0.31469990
0.41800000 0.40480923 0.31396474
0.41720000 0.40440725 0.31365307
0.41640000 0.40379409 0.31317766
0.41560000 0.40273661 0.31235776
0.41480000 0.40148531 0.31138758
0.41400000 0.40113679 0.31111736
0.41320000 0.40071221 0.31078817
0.41240000 0.39951749 0.30986186
0.41160000 0.39872780 0.30924958
0.41080000 0.39797226 0.30866378
0.41000000 0.39734446 0.30817703
0.40920000 0.39643770 0.30747399
0.40840000 0.39560289 0.30682673
0.40760000 0.39474720 0.30616328
0.40680000 0.39397239 0.30556254
0.40600000 0.39328749 0.30503151
0.40520000 0.39251034 0.30442896
0.40440000 0.39143886 0.30359820
0.40360000 0.39021973 0.30265297
0.40280000 0.39007788 0.30254298
0.40200000 0.38937891 0.30200105
0.40120000 0.38812145 0.30102609
0.40040000 0.38758325 0.30060881
0.39960000 0.38694669 0.30011525
0.39880000 0.38627682 0.29959588
0.39800000 0.38515877 0.29872902
0.39720000 0.38435620 0.29810676
0.39640000 0.38371645 0.29761074
0.39560000 0.38310234 0.29713460
0.39480000 0.38179572 0.29612152
0.39400000 0.38104608 0.29554030
0.39320000 0.38070745 0.29527775
0.39240000 0.37954884 0.29437944
0.39160000 0.37880895 0.29380577
0.39080000 0.37778848 0.29301456
0.39000000 0.37736830 0.29268878
0.38920000 0.37646108 0.29198538
0.38840000 0.37545978 0.29120904
0.38760000 0.37471917 0.29063481
0.38680000 0.37403622 0.29010530
0.38600000 0.37330203 0.28953605
0.38520000 0.37249528 0.28891055
0.38440000 0.36742633 0.28498041
0.38360000 0.36750368 0.28504038
0.38280000 0.37018707 0.28712091
0.38200000 0.36935559 0.28647623
0.38120000 0.36829034 0.28565031
0.38040000 0.36753705 0.28506625
0.37960000 0.36697534 0.28463074
0.37880000 0.36610437 0.28395544
0.37800000 0.36525379 0.28329596
0.37720000 0.36434197 0.28258899
0.37640000 0.36367297 0.28207029
0.37560000 0.36293129 0.28149524
0.37480000 0.36214649 0.28088675
0.37400000 0.36139748 0.28030602
0.37320000 0.36019468 0.27937344
0.37240000 0.35986475 0.27911764
0.37160000 0.35884144 0.27832423
0.37080000 0.35820168 0.27782820
0.37000000 0.35716265 0.27702260
0.36920000 0.35644691 0.27646766
0.36840000 0.35563036 0.27583456
0.36760000 0.35457690 0.27501777
0.36680000 0.35410186 0.27464946
0.36600000 0.35302307 0.27381303
0.36520000 0.35238759 0.27332032
0.36440000 0.35173814 0.27281678
0.36360000 0.35102273 0.27226210
0.36280000 0.35009172 0.27154025
0.36200000 0.34910585 0.27077587
0.36120000 0.34872934 0.27048395
0.36040000 0.34752516 0.26955030
0.35960000 0.34691504 0.26907726
0.35880000 0.34625518 0.26856564
0.35800000 0.34557935 0.26804165
0.35720000 0.34427111 0.26702732
0.35640000 0.34382634 0.26668247
0.35560000 0.34279425 0.26588226
0.35480000 0.34221651 0.26543431
0.35400000 0.34109029 0.26456111
0.35320000 0.34056520 0.26415399
0.35240000 0.33953552 0.26335564
0.35160000 0.33884470 0.26282002
0.35080000 0.33818553 0.26230895
0.35000000 0.33721721 0.26155817
0.34920000 0.33647075 0.26097941
0.34840000 0.33571560 0.26039392
0.34760000 0.33494922 0.25979972
0.34680000 0.33404639 0.25909972
0.34600000 0.33328157 0.25850672
0.34520000 0.33256276 0.25794941
0.34440000 0.33159422 0.25719846
0.34360000 0.33089456 0.25665599
0.34280000 0.33057060 0.25640481
0.34200000 0.32917232 0.25532068
0.34120000 0.32851762 0.25481306
0.34040000 0.32751707 0.25403730
0.33960000 0.32685940 0.25352738
0.33880000 0.32598555 0.25284985
0.33800000 0.32543636 0.25242405
0.33720000 0.32459545 0.25177206
0.33640000 0.32354161 0.25095498
0.33560000 0.32281125 0.25038870
0.33480000 0.32248590 0.25013645
0.33400000 0.32136948 0.24927085
0.33320000 0.32047116 0.24857435
0.33240000 0.32001458 0.24822034
0.33160000 0.31947980 0.24780571
0.33080000 0.31800839 0.24666487
0.33000000 0.31731048 0.24612375
0.32920000 0.31665957 0.24561908
0.32840000 0.31572476 0.24489429
0.32760000 0.31471006 0.24410755
0.32680000 0.31453367 0.24397079
0.32600000 0.31360899 0.24325385
0.32520000 0.31235455 0.24228124
0.32440000 0.31172654 0.24179432
0.32360000 0.31137531 0.24152200
0.32280000 0.31013041 0.24055678
0.32200000 0.30920701 0.23984084
0.32120000 0.30846833 0.23926811
0.32040000 0.30789589 0.23882428
0.31960000 0.30693528 0.23807948
0.31880000 0.30632787 0.23760853
0.31800000 0.30529873 0.23681060
0.31720000 0.30458031 0.23625358
0.31640000 0.30372280 0.23558873
0.31560000 0.30313813 0.23513541
0.31480000 0.30199484 0.23424897
0.31400000 0.30119255 0.23362693
0.31320000 0.30047570 0.23307113
0.31240000 0.29973681 0.23249825
0.31160000 0.29895213 0.23188985
0.31080000 0.29792069 0.23109014
0.31000000 0.29732793 0.23063055
0.30920000 0.29634860 0.22987124
0.30840000 0.29556265 0.22926186
0.30760000 0.29544857 0.22917341
0.30680000 0.29418738 0.22819557
0.30600000 0.29312969 0.22737550
0.30520000 0.29263436 0.22699145
0.30440000 0.29203701 0.22652830
0.30360000 0.29107089 0.22577924
0.30280000 0.29002493 0.22496827
0.30200000 0.28924465 0.22436329
0.30120000 0.28859896 0.22386266
0.30040000 0.28767723 0.22314801
0.29960000 0.28690127 0.22254638
0.29880000 0.28620224 0.22200440
0.29800000 0.28524538 0.22126251
0.29720000 0.28452711 0.22070561
0.29640000 0.28368456 0.22005235
0.29560000 0.28274950 0.21932736
0.29480000 0.28218875 0.21889259
0.29400000 0.28120035 0.21812625
0.29320000 0.28060003 0.21766080
0.29240000 0.27951319 0.21681813
0.29160000 0.27896493 0.21639304
0.29080000 0.27808445 0.21571037
0.29000000 0.27744009 0.21521078
0.28920000 0.27640652 0.21440942
0.28840000 0.27620485 0.21425305
0.28760000 0.27514373 0.21343033
0.28680000 0.27402822 0.21256543
0.28600000 0.27345451 0.21212061
0.28520000 0.27299644 0.21176546
0.28440000 0.27180133 0.21083884
0.28360000 0.27082384 0.21008096
0.28280000 0.27065199 0.20994772
0.28200000 0.26969999 0.20920960
0.28120000 0.26865458 0.20839905
0.28040000 0.26748604 0.20749304
0.27960000 0.26692632 0.20705907
0.27880000 0.26599793 0.20633925
0.27800000 0.26548348 0.20594038
0.27720000 0.26473935 0.20536343
0.27640000 0.26390525 0.20471673
0.27560000 0.26269934 0.20378174
0.27480000 0.26207376 0.20329670
0.27400000 0.26180469 0.20308808
0.27320000 0.26074525 0.20226666
0.27240000 0.25978739 0.20152399
0.27160000 0.25917091 0.20104602
0.27080000 0.25837542 0.20042925
0.27000000 0.25767698 0.19988772
0.26920000 0.25695860 0.19933073
0.26840000 0.25589472 0.19850587
0.26760000 0.25497950 0.19779626
0.26680000 0.25426782 0.19724447
0.26600000 0.25388231 0.19694557
0.26520000 0.25275299 0.19606997
0.26440000 0.25200498 0.19549001
0.26360000 0.25084299 0.19458907
0.26280000 0.25031181 0.19417723
0.26200000 0.24987195 0.19383619
0.26120000 0.24855482 0.19281497
0.26040000 0.24788890 0.19229866
0.25960000 0.24718809 0.19175530
0.25880000 0.24652718 0.19124287
0.25800000 0.24529452 0.19028714
0.25720000 0.24455335 0.18971249
0.25640000 0.24408204 0.18934706
0.25560000 0.24311027 0.18859362
0.25480000 0.24222436 0.18790673
0.25400000 0.24137607 0.18724902
0.25320000 0.24084803 0.18683962
0.25240000 0.23959449 0.18586770
0.25160000 0.23904854 0.18544440
0.25080000 0.23810687 0.18471430
0.25000000 0.23785986 0.18452278
0.24920000 0.23654819 0.18350579
0.24840000 0.23608867 0.18314951
0.24760000 0.23500576 0.18230989
0.24680000 0.23435817 0.18180779
0.24600000 0.23385789 0.18141991
0.24520000 0.23292094 0.18069346
0.24440000 0.23180895 0.17983128
0.24360000 0.23114562 0.17931698
0.24280000 0.23036967 0.17871536
0.24200000 0.22966738 0.17817085
0.24120000 0.22903042 0.17767699
0.24040000 0.22797618 0.17685960
0.23960000 0.22689615 0.17602221
0.23880000 0.22650797 0.17572124
0.23800000 0.22585890 0.17521800
0.23720000 0.22474333 0.17435305
0.23640000 0.22383690 0.17365026
0.23560000 0.22321365 0.17316703
0.23480000 0.22291056 0.17293204
0.23400000 0.22129551 0.17167983
0.23320000 0.22067542 0.17119905
0.23240000 0.21998667 0.17066504
0.23160000 0.21952188 0.17030467
0.23080000 0.21826120 0.16932722
0.23000000 0.21739148 0.16865290
0.22920000 0.21698758 0.16833974
0.22840000 0.21627393 0.16778642
0.22760000 0.21499808 0.16679720
0.22680000 0.21434614 0.16629173
0.22600000 0.21381391 0.16587907
0.22520000 0.21323538 0.16543052
0.22440000 0.21171198 0.16424937
0.22360000 0.21122072 0.16386848
0.22280000 0.21068789 0.16345536
0.22200000 0.20968043 0.16267424
0.22120000 0.20880745 0.16199738
0.22040000 0.20819241 0.16152052
0.21960000 0.20721792 0.16076496
0.21880000 0.20631782 0.16006708
0.21800000 0.20587321 0.15972235
0.21720000 0.20503209 0.15907021
0.21640000 0.20390428 0.15819577
0.21560000 0.20332136 0.15774382
0.21480000 0.20276494 0.15731240
0.21400000 0.20184502 0.15659915
0.21320000 0.20089224 0.15586043
0.21240000 0.20021252 0.15533342
0.21160000 0.19962544 0.15487823
0.21080000 0.19850055 0.15400606
0.21000000 0.19805701 0.15366217
0.20920000 0.19691379 0.15277579
0.20840000 0.19655624 0.15249857
0.20760000 0.19489123 0.15120763
0.20680000 0.19447062 0.15088151
0.20600000 0.19394821 0.15047647
0.20520000 0.19277870 0.14956971
0.20440000 0.19185071 0.14885020
0.20360000 0.19129808 0.14842172
0.20280000 0.19036164 0.14769567
0.20200000 0.18971964 0.14719791
0.20120000 0.18870362 0.14641015
0.20040000 0.18804088 0.14589630
0.19960000 0.18727596 0.14530323
0.19880000 0.18653718 0.14473042
0.19800000 0.18578059 0.14414382
0.19720000 0.18500226 0.14354035
0.19640000 0.18423572 0.14294602
0.19560000 0.18335112 0.14226016
0.19480000 0.18272461 0.14177440
0.19400000 0.18165132 0.14094224
0.19320000 0.18085469 0.14032458
0.19240000 0.18020553 0.13982126
0.19160000 0.17950669 0.13927943
0.19080000 0.17876705 0.13870596
0.19000000 0.17777927 0.13794010
0.18920000 0.17702129 0.13735241
0.18840000 0.17628105 0.13677848
0.18760000 0.17539816 0.13609394
0.18680000 0.17452339 0.13541570
0.18600000 0.17375553 0.13482034
0.18520000 0.17295994 0.13420350
0.18440000 0.17217981 0.13359863
0.18360000 0.17104151 0.13271607
0.18280000 0.17026527 0.13211422
0.18200000 0.16984184 0.13178592
0.18120000 0.16872707 0.13092159
0.18040000 0.16817613 0.13049443
0.17960000 0.16732318 0.12983311
0.17880000 0.16667658 0.12933177
0.17800000 0.16590101 0.12873045
0.17720000 0.16516058 0.12815637
0.17640000 0.16433684 0.12751769
0.17560000 0.16337004 0.12676809
0.17480000 0.16281674 0.12633910
0.17400000 0.16188965 0.12562029
0.17320000 0.16098317 0.12491746
0.17240000 0.16024540 0.12434545
0.17160000 0.15950822 0.12377389
0.17080000 0.15855424 0.12303423
0.17000000 0.15777519 0.12243020
0.16920000 0.15696193 0.12179965
0.16840000 0.15636576 0.12133742
0.16760000 0.15518175 0.12041941
0.16680000 0.15458745 0.11995863
0.16600000 0.15406364 0.11955250
0.16520000 0.15301821 0.11874194
0.16440000 0.15213208 0.11805489
0.16360000 0.15155423 0.11760686
0.16280000 0.15082470 0.11704123
0.16200000 0.14985451 0.11628901
0.16120000 0.14892972 0.11557199
0.16040000 0.14850816 0.11524514
0.15960000 0.14718825 0.11422176
0.15880000 0.14677686 0.11390280
0.15800000 0.14571577 0.11308009
0.15720000 0.14507463 0.11258299
0.15640000 0.14421465 0.11191622
0.15560000 0.14341665 0.11129750
0.15480000 0.14295190 0.11093716
0.15400000 0.14182937 0.11006682
0.15320000 0.14093895 0.10937645
0.15240000 0.14017944 0.10878757
0.15160000 0.13947424 0.10824080
0.15080000 0.13848363 0.10747274
0.15000000 0.13778912 0.10693427
0.14920000 0.13683427 0.10619394
0.14840000 0.13614962 0.10566310
0.14760000 0.13543643 0.10511015
0.14680000 0.13444311 0.10433999
0.14600000 0.13373100 0.10378786
0.14520000 0.13301197 0.10323037
0.14440000 0.13227689 0.10266043
0.14360000 0.13153110 0.10208220
0.14280000 0.13061501 0.10137192
0.14200000 0.12975864 0.10070795
0.14120000 0.12927431 0.10033243
0.14040000 0.12810033 0.09942220
0.13960000 0.12724427 0.09875846
0.13880000 0.12673679 0.09836499
0.13800000 0.12605629 0.09783738
0.13720000 0.12496378 0.09699031
0.13640000 0.12397422 0.09622307
0.13560000 0.12356673 0.09590713
0.13480000 0.12277445 0.09529284
0.13400000 0.12155165 0.09434476
0.13320000 0.12084258 0.09379500
0.13240000 0.12060181 0.09360832
0.13160000 0.11952917 0.09277666
0.13080000 0.11885555 0.09225438
0.13000000 0.11793585 0.09154130
0.12920000 0.11716640 0.09094472
0.12840000 0.11617015 0.09017229
0.12760000 0.11548364 0.08964002
0.12680000 0.11434220 0.08875501
0.12600000 0.11395139 0.08845200
0.12520000 0.11301738 0.08772783
0.12440000 0.11224864 0.08713180
0.12360000 0.11141954 0.08648897
0.12280000 0.11072478 0.08595030
0.12200000 0.11005598 0.08543175
0.12120000 0.10886699 0.08450988
0.12040000 0.10808369 0.08390256
0.11960000 0.10775526 0.08364792
0.11880000 0.10671008 0.08283755
0.11800000 0.10564620 0.08201269
0.11720000 0.10496173 0.08148199
0.11640000 0.10440139 0.08104754
0.11560000 0.10690926 0.08299199
0.11480000 0.10582160 0.08214868
0.11400000 0.10514190 0.08162168
0.11320000 0.10469924 0.08127847
0.11240000 0.10336158 0.08024134
0.11160000 0.10266552 0.07970165
0.11080000 0.10185012 0.07906944
0.11000000 0.10117977 0.07854970
0.10920000 0.10032815 0.07788941
0.10840000 0.09948319 0.07723428
0.10760000 0.09913648 0.07696546
0.10680000 0.09850020 0.07647213
0.10600000 0.09793113 0.07603091
0.10520000 0.09633702 0.07479494
0.10440000 0.09529629 0.07398802
0.10360000 0.09456473 0.07342082
0.10280000 0.09462338 0.07346629
0.10200000 0.09364481 0.07270757
0.10120000 0.09242667 0.07176310
0.10040000 0.09177085 0.07125462
0.09960000 0.09059483 0.07034281
0.09880000 0.08997790 0.06986448
0.09800000 0.08991632 0.06981673
0.09720000 0.08889418 0.06902423
0.09640000 0.08770433 0.06810170
0.09560000 0.08658508 0.06723390
0.09480000 0.08614562 0.06689317
0.09400000 0.08505195 0.06604521
0.09320000 0.08486798 0.06590257
0.09240000 0.08414229 0.06533991
0.09160000 0.08278208 0.06428529
0.09080000 0.07862681 0.06106356
0.09000000 0.07793426 0.06052660
0.08920000 0.07695716 0.05976902
0.08840000 0.07638416 0.05932475
0.08760000 0.07553448 0.05866597
0.08680000 0.07453788 0.05789326
0.08600000 0.07387264 0.05737748
0.08520000 0.07274838 0.05650580
0.08440000 0.07262825 0.05641266
0.08360000 0.07127168 0.05536086
0.08280000 0.07067324 0.05489687
0.08200000 0.07008083 0.05443755
0.08120000 0.06902699 0.05362047
0.08040000 0.06895707 0.05356626
0.07960000 0.06739090 0.05235195
0.07880000 0.06651968 0.05167646
0.07800000 0.06722745 0.05222522
0.07720000 0.06543645 0.05083659
0.07640000 0.06414625 0.04983625
0.07560000 0.06333043 0.04920372
0.07480000 0.06249014 0.04855221
0.07400000 0.06173465 0.04796645
0.07320000 0.06073384 0.04719049
0.07240000 0.06515341 0.05061714
0.07160000 0.06247329 0.04853914
0.07080000 0.06167588 0.04792089
0.07000000 0.06135856 0.04767485
0.06920000 0.06083947 0.04727239
0.06840000 0.06024230 0.04680938
0.06760000 0.05924027 0.04603247
0.06680000 0.05805600 0.04511426
0.06600000 0.05669939 0.04406244
0.06520000 0.05688659 0.04420758
0.06440000 0.05709771 0.04437126
0.06360000 0.05520642 0.04290488
0.06280000 0.05350916 0.04158893
0.06200000 0.05280444 0.04104253
0.06120000 0.05295891 0.04116230
0.06040000 0.05277858 0.04102249
0.05960000 0.05156328 0.04008022
0.05880000 0.04980912 0.03872015
0.05800000 0.04907780 0.03815313
0.05720000 0.04803743 0.03734650
0.05640000 0.04723854 0.03672709
0.05560000 0.04718749 0.03668751
0.05480000 0.04697473 0.03652255
0.05400000 0.04557134 0.03543445
0.05320000 0.04397647 0.03419789
0.05240000 0.04336159 0.03372115
0.05160000 0.04278534 0.03327436
0.05080000 0.04198189 0.03265142
0.05000000 0.04179978 0.03251022
0.04920000 0.04116715 0.03201972
0.04840000 0.03980905 0.03096673
0.04760000 0.03845531 0.02991713
0.04680000 0.03762525 0.02927355
0.04600000 0.03689302 0.02870582
0.04520000 0.03645157 0.02836356
0.04440000 0.03610211 0.02809261
0.04360000 0.03556879 0.02767910
0.04280000 0.03462349 0.02694617
0.04200000 0.03322086 0.02585866
0.04120000 0.03196462 0.02488466
0.04040000 0.03100596 0.02414137
0.03960000 0.03023320 0.02354222
0.03880000 0.02964474 0.02308597
0.03800000 0.02908552 0.02265239
0.03720000 0.02807875 0.02187180
0.03640000 0.02706082 0.02108256
0.03560000 0.02641692 0.02058332
0.03480000 0.02639750 0.02056827
0.03400000 0.02560042 0.01995026
0.03320000 0.02466581 0.01922563
0.03240000 0.02399715 0.01870719
0.03160000 0.02275142 0.01774133
0.03080000 0.02167393 0.01690591
0.03000000 0.02142819 0.01671538
0.02920000 0.02033914 0.01587100
0.02840000 0.01911502 0.01492190
0.02760000 0.01839962 0.01436721
0.02680000 0.01798679 0.01404713
0.02600000 0.01660068 0.01297243
0.02520000 0.01586714 0.01240369
0.02440000 0.01537501 0.01202213
0.02360000 0.01441595 0.01127853
0.02280000 0.01342297 0.01050864
0.02200000 0.01293188 0.01012788
0.02120000 0.01233604 0.00966590
0.02040000 0.01120547 0.00878933
0.01960000 0.01045305 0.00820595
0.01880000 0.00958234 0.00753086
0.01800000 0.00602744 0.00477461
0.01720000 0.00543346 0.00431408
0.01640000 0.00430930 0.00344248
0.01560000 0.00766046 0.00604075
0.01480000 0.00564238 0.00447606
0.01400000 0.00221735 0.00182051
0.01320000 0.00120953 0.00103911
0.01240000 0.00038643 0.00040093
0.01160000 -0.00036888 -0.00018469
0.01080000 -0.00113351 -0.00077754
0.01000000 -0.00215588 -0.00157022
0.00920000 -0.00279109 -0.00206272
0.00840000 -0.00301240 -0.00223431
0.00760000 -0.00322402 -0.00239839
0.00680000 -0.00508628 -0.00384226
0.00600000 -0.00551751 -0.00417661
0.00520000 -0.00664690 -0.00505227
0.00440000 -0.00704195 -0.00535856
0.00360000 -0.00771037 -0.00587682
0.00280000 -0.00862198 -0.00658362
0.00200000 -0.00987851 -0.00755785
0.00160000 -0.01066294 -0.00816605