File: plots/rawdata/Figure2-0K.txt
# strain(%), strain_el(%), stress(GPa)
0.00000000 -0.00013068 0.00000000
0.00080000 0.00068580 0.00063304
0.00160000 0.00170870 0.00142613
0.00240000 0.00243566 0.00198978
0.00320000 0.00336339 0.00270908
0.00400000 0.00396412 0.00317484
0.00480000 0.00473277 0.00377081
0.00560000 0.00583534 0.00462567
0.00640000 0.00633302 0.00501154
0.00720000 0.00720430 0.00568707
0.00800000 0.00788728 0.00621661
0.00880000 0.00896298 0.00705064
0.00960000 0.00968712 0.00761210
0.01040000 0.01027653 0.00806909
0.01120000 0.01119182 0.00877875
0.01200000 0.01198649 0.00939488
0.01280000 0.01276754 0.01000046
0.01360000 0.01358527 0.01063447
0.01440000 0.01428816 0.01117945
0.01520000 0.01525898 0.01193216
0.01600000 0.01603706 0.01253543
0.01680000 0.01673082 0.01307333
0.01760000 0.01766274 0.01379589
0.01840000 0.01839453 0.01436327
0.01920000 0.01911217 0.01491969
0.02000000 0.01986291 0.01550176
0.02080000 0.02077540 0.01620924
0.02160000 0.02145717 0.01673785
0.02240000 0.02253962 0.01757711
0.02320000 0.02327761 0.01814930
0.02400000 0.02397337 0.01868875
0.02480000 0.02484822 0.01936705
0.02560000 0.02574214 0.02006014
0.02640000 0.02642015 0.02058583
0.02720000 0.02725747 0.02123504
0.02800000 0.02791789 0.02174708
0.02880000 0.02866894 0.02232939
0.02960000 0.02961918 0.02306616
0.03040000 0.03029993 0.02359397
0.03120000 0.03111593 0.02422664
0.03200000 0.03212544 0.02500935
0.03280000 0.03287946 0.02559397
0.03360000 0.03347601 0.02605649
0.03440000 0.03438043 0.02675773
0.03520000 0.03537200 0.02752653
0.03600000 0.03587979 0.02792023
0.03680000 0.03667143 0.02853402
0.03760000 0.03766629 0.02930538
0.03840000 0.03837148 0.02985213
0.03920000 0.03921447 0.03050573
0.04000000 0.04000493 0.03111861
0.04080000 0.04092684 0.03183339
0.04160000 0.04148608 0.03226700
0.04240000 0.04239894 0.03297477
0.04320000 0.04330904 0.03368040
0.04400000 0.04395421 0.03418063
0.04480000 0.04495258 0.03495470
0.04560000 0.04575484 0.03557672
0.04640000 0.04637287 0.03605590
0.04720000 0.04705892 0.03658782
0.04800000 0.04793397 0.03726628
0.04880000 0.04893770 0.03804451
0.04960000 0.04964848 0.03859560
0.05040000 0.05027058 0.03907794
0.05120000 0.05122141 0.03981515
0.05200000 0.05195612 0.04038480
0.05280000 0.05288921 0.04110826
0.05360000 0.05348594 0.04157092
0.05440000 0.05426823 0.04217746
0.05520000 0.05505272 0.04278571
0.05600000 0.05588673 0.04343235
0.05680000 0.05685059 0.04417967
0.05760000 0.05771679 0.04485126
0.05840000 0.05826008 0.04527249
0.05920000 0.05920610 0.04600598
0.06000000 0.05984114 0.04649835
0.06080000 0.06081771 0.04725552
0.06160000 0.06145102 0.04774654
0.06240000 0.06236231 0.04845310
0.06320000 0.06317525 0.04908341
0.06400000 0.06420874 0.04988470
0.06480000 0.06481468 0.05035451
0.06560000 0.06566025 0.05101011
0.06640000 0.06627140 0.05148396
0.06720000 0.06719721 0.05220177
0.06800000 0.06794522 0.05278173
0.06880000 0.06893384 0.05354825
0.06960000 0.06956464 0.05403733
0.07040000 0.07024398 0.05456404
0.07120000 0.07112179 0.05524464
0.07200000 0.07205365 0.05596715
0.07280000 0.07272583 0.05648832
0.07360000 0.07366498 0.05721647
0.07440000 0.07440903 0.05779337
0.07520000 0.07524139 0.05843872
0.07600000 0.07584540 0.05890704
0.07680000 0.07697053 0.05977939
0.07760000 0.07766273 0.06031608
0.07840000 0.07841381 0.06089842
0.07920000 0.07921588 0.06152029
0.08000000 0.08009594 0.06220263
0.08080000 0.08067067 0.06264824
0.08160000 0.08163924 0.06339921
0.08240000 0.08226390 0.06388353
0.08320000 0.08311844 0.06454609
0.08400000 0.08401427 0.06524066
0.08480000 0.08486949 0.06590374
0.08560000 0.08553354 0.06641860
0.08640000 0.08628536 0.06700152
0.08720000 0.08709103 0.06762618
0.08800000 0.08812131 0.06842499
0.08880000 0.08867856 0.06885705
0.08960000 0.08956286 0.06954268
0.09040000 0.09027139 0.07009204
0.09120000 0.09111992 0.07074993
0.09200000 0.09212505 0.07152924
0.09280000 0.09283172 0.07207715
0.09360000 0.09387383 0.07288514
0.09440000 0.09439636 0.07329027
0.09520000 0.09513648 0.07386411
0.09600000 0.09593883 0.07448621
0.09680000 0.09685234 0.07519448
0.09760000 0.09748501 0.07568502
0.09840000 0.09829992 0.07631685
0.09920000 0.09910790 0.07694330
0.10000000 0.10000016 0.07763511
0.10080000 0.10071745 0.07819125
0.10160000 0.10157382 0.07885522
0.10240000 0.10226023 0.07938742
0.10320000 0.10324334 0.08014966
0.10400000 0.10395628 0.08070243
0.10480000 0.10474708 0.08131556
0.10560000 0.10558824 0.08196775
0.10640000 0.10637045 0.08257422
0.10720000 0.10708333 0.08312694
0.10800000 0.10791701 0.08377333
0.10880000 0.10880051 0.08445834
0.10960000 0.10958230 0.08506449
0.11040000 0.11043362 0.08572455
0.11120000 0.11126398 0.08636836
0.11200000 0.11193039 0.08688505
0.11280000 0.11280440 0.08756270
0.11360000 0.11345943 0.08807057
0.11440000 0.11446747 0.08885214
0.11520000 0.11516137 0.08939015
0.11600000 0.11604167 0.09007268
0.11680000 0.11676992 0.09063731
0.11760000 0.11778151 0.09142164
0.11840000 0.11848340 0.09196584
0.11920000 0.11923697 0.09255010
0.12000000 0.11986177 0.09303454
0.12080000 0.12083763 0.09379116
0.12160000 0.12179284 0.09453177
0.12240000 0.12240422 0.09500579
0.12320000 0.12309658 0.09554261
0.12400000 0.12416795 0.09637328
0.12480000 0.12486754 0.09691570
0.12560000 0.12560996 0.09749132
0.12640000 0.12650053 0.09818181
0.12720000 0.12726816 0.09877698
0.12800000 0.12817009 0.09947629
0.12880000 0.12879937 0.09996419
0.12960000 0.12962257 0.10060244
0.13040000 0.13042530 0.10122483
0.13120000 0.13144147 0.10201270
0.13200000 0.13210719 0.10252886
0.13280000 0.13266161 0.10295872
0.13360000 0.13363340 0.10371218
0.13440000 0.13443160 0.10433106
0.13520000 0.13518654 0.10491639
0.13600000 0.13593302 0.10549517
0.13680000 0.13670976 0.10609740
0.13760000 0.13760297 0.10678994
0.13840000 0.13840954 0.10741530
0.13920000 0.13934497 0.10814058
0.14000000 0.14010062 0.10872646
0.14080000 0.14069862 0.10919011
0.14160000 0.14150470 0.10981510
0.14240000 0.14241503 0.11052091
0.14320000 0.14342796 0.11130627
0.14400000 0.14392828 0.11169419
0.14480000 0.14472459 0.11231159
0.14560000 0.14564265 0.11302340
0.14640000 0.14639363 0.11360566
0.14720000 0.14723023 0.11425431
0.14800000 0.14805998 0.11489764
0.14880000 0.14891850 0.11556328
0.14960000 0.14979588 0.11624355
0.15040000 0.15030420 0.11663767
0.15120000 0.15137449 0.11746751
0.15200000 0.15209342 0.11802492
0.15280000 0.15286465 0.11862288
0.15360000 0.15369612 0.11926755
0.15440000 0.15449271 0.11988518
0.15520000 0.15509702 0.12035372
0.15600000 0.15599897 0.12105303
0.15680000 0.15692474 0.12177081
0.15760000 0.15756961 0.12227081
0.15840000 0.15845995 0.12296112
0.15920000 0.15936714 0.12366450
0.16000000 0.15997685 0.12413723
0.16080000 0.16084422 0.12480973
0.16160000 0.16182292 0.12556856
0.16240000 0.16254986 0.12613218
0.16320000 0.16321079 0.12664462
0.16400000 0.16394650 0.12721504
0.16480000 0.16496600 0.12800550
0.16560000 0.16548607 0.12840873
0.16640000 0.16636930 0.12909353
0.16720000 0.16737976 0.12987697
0.16800000 0.16796548 0.13033111
0.16880000 0.16898111 0.13111856
0.16960000 0.16962069 0.13161445
0.17040000 0.17068345 0.13243845
0.17120000 0.17120044 0.13283929
0.17200000 0.17189340 0.13337657
0.17280000 0.17286676 0.13413125
0.17360000 0.17350198 0.13462375
0.17440000 0.17457332 0.13545441
0.17520000 0.17539528 0.13609170
0.17600000 0.17600082 0.13656120
0.17680000 0.17690829 0.13726479
0.17760000 0.17754296 0.13775688
0.17840000 0.17836646 0.13839537
0.17920000 0.17933034 0.13914270
0.18000000 0.18001045 0.13967001
0.18080000 0.18068293 0.14019141
0.18160000 0.18165919 0.14094834
0.18240000 0.18232819 0.14146704
0.18320000 0.18316742 0.14211773
0.18400000 0.18392113 0.14270211
0.18480000 0.18474374 0.14333990
0.18560000 0.18560239 0.14400565
0.18640000 0.18647390 0.14468136
0.18720000 0.18714625 0.14520266
0.18800000 0.18806628 0.14591599
0.18880000 0.18891278 0.14657232
0.18960000 0.18960448 0.14710861
0.19040000 0.19035074 0.14768722
0.19120000 0.19144881 0.14853859
0.19200000 0.19199965 0.14896568
0.19280000 0.19281608 0.14959869
0.19360000 0.19350798 0.15013514
0.19440000 0.19426651 0.15072326
0.19520000 0.19533101 0.15154861
0.19600000 0.19606434 0.15211718
0.19680000 0.19694473 0.15279978
0.19760000 0.19765350 0.15334931
0.19840000 0.19831015 0.15385844
0.19920000 0.19905921 0.15443921
0.20000000 0.20014830 0.15528363
0.20080000 0.20077260 0.15576767
0.20160000 0.20145934 0.15630012
0.20240000 0.20225791 0.15691929
0.20320000 0.20324372 0.15768362
0.20400000 0.20400690 0.15827534
0.20480000 0.20497804 0.15902830
0.20560000 0.20559072 0.15950333
0.20640000 0.20629705 0.16005098
0.20720000 0.20711539 0.16068547
0.20800000 0.20786117 0.16126370
0.20880000 0.20872174 0.16193093
0.20960000 0.20949371 0.16252946
0.21040000 0.21057559 0.16336828
0.21120000 0.21110991 0.16378256
0.21200000 0.21185298 0.16435869
0.21280000 0.21280834 0.16509942
0.21360000 0.21366765 0.16576567
0.21440000 0.21431564 0.16626808
0.21520000 0.21514551 0.16691151
0.21600000 0.21627903 0.16779037
0.21680000 0.21670256 0.16811875
0.21760000 0.21742557 0.16867932
0.21840000 0.21844186 0.16946729
0.21920000 0.21921920 0.17006999
0.22000000 0.21984531 0.17055544
0.22080000 0.22069142 0.17121146
0.22160000 0.22150616 0.17184316
0.22240000 0.22221734 0.17239456
0.22320000 0.22305851 0.17304675
0.22400000 0.22398731 0.17376688
0.22480000 0.22462039 0.17425773
0.22560000 0.22559456 0.17501304
0.22640000 0.22622234 0.17549978
0.22720000 0.22703228 0.17612776
0.22800000 0.22796732 0.17685273
0.22880000 0.22858362 0.17733057
0.22960000 0.22954241 0.17807395
0.23040000 0.23032650 0.17868189
0.23120000 0.23098063 0.17918906
0.23200000 0.23183100 0.17984838
0.23280000 0.23269523 0.18051845
0.23360000 0.23338731 0.18105505
0.23440000 0.23421055 0.18169333
0.23520000 0.23504270 0.18233853
0.23600000 0.23607277 0.18313718
0.23680000 0.23682360 0.18371933
0.23760000 0.23738388 0.18415373
0.23840000 0.23835246 0.18490471
0.23920000 0.23913197 0.18550909
0.24000000 0.23998472 0.18617026
0.24080000 0.24057993 0.18663175
0.24160000 0.24161191 0.18743188
0.24240000 0.24225901 0.18793360
0.24320000 0.24310860 0.18859232
0.24400000 0.24380128 0.18912938
0.24480000 0.24471838 0.18984044
0.24560000 0.24555218 0.19048692
0.24640000 0.24628506 0.19105514
0.24720000 0.24727134 0.19181985
0.24800000 0.24785652 0.19227356
0.24880000 0.24874138 0.19295962
0.24960000 0.24936955 0.19344666
0.25040000 0.25022106 0.19410687
0.25120000 0.25106793 0.19476348
0.25200000 0.25169144 0.19524691
0.25280000 0.25253446 0.19590053
0.25360000 0.25333926 0.19652452
0.25440000 0.25422720 0.19721298
0.25520000 0.25498954 0.19780404
0.25600000 0.25568554 0.19834368
0.25680000 0.25676163 0.19917801
0.25760000 0.25762911 0.19985061
0.25840000 0.25807998 0.20020018
0.25920000 0.25893492 0.20086304
0.26000000 0.25968719 0.20144631
0.26080000 0.26066545 0.20220479
0.26160000 0.26124735 0.20265596
0.26240000 0.26205263 0.20328032
0.26320000 0.26289893 0.20393649
0.26400000 0.26382732 0.20465630
0.26480000 0.26495606 0.20553145
0.26560000 0.26536137 0.20584571
0.26640000 0.26609441 0.20641406
0.26720000 0.26679031 0.20695361
0.26800000 0.26760388 0.20758441
0.26880000 0.26864061 0.20838822
0.26960000 0.26948957 0.20904645
0.27040000 0.27000080 0.20944283
0.27120000 0.27082991 0.21008566
0.27200000 0.27179332 0.21083264
0.27280000 0.27255433 0.21142267
0.27360000 0.27348589 0.21214495
0.27440000 0.27401698 0.21255672
0.27520000 0.27514581 0.21343194
0.27600000 0.27561328 0.21379439
0.27680000 0.27640848 0.21441093
0.27760000 0.27739567 0.21517634
0.27840000 0.27810246 0.21572434
0.27920000 0.27891460 0.21635402
0.28000000 0.27983351 0.21706648
0.28080000 0.28034386 0.21746218
0.28160000 0.28115166 0.21808850
0.28240000 0.28200737 0.21875196
0.28320000 0.28284062 0.21939801
0.28400000 0.28355286 0.21995023
0.28480000 0.28423952 0.22048263
0.28560000 0.28508804 0.22114051
0.28640000 0.28602436 0.22186648
0.28720000 0.28670169 0.22239164
0.28800000 0.28758863 0.22307931
0.28880000 0.28831756 0.22364448
0.28960000 0.28917757 0.22431128
0.29040000 0.28980505 0.22479779
0.29120000 0.29061008 0.22542196
0.29200000 0.29153562 0.22613956
0.29280000 0.29210030 0.22657738
0.29360000 0.29294217 0.22723011
0.29440000 0.29388042 0.22795757
0.29520000 0.29454209 0.22847059
0.29600000 0.29546127 0.22918326
0.29680000 0.29612465 0.22969760
0.29760000 0.29698956 0.23036820
0.29840000 0.29755582 0.23080725
0.29920000 0.29862247 0.23163425
0.30000000 0.29929856 0.23215845
0.30080000 0.30026442 0.23290732
0.30160000 0.30077549 0.23330357
0.30240000 0.30157218 0.23392127
0.30320000 0.30238766 0.23455354
0.30400000 0.30325662 0.23522728
0.30480000 0.30395757 0.23577075
0.30560000 0.30467397 0.23632621
0.30640000 0.30548398 0.23695423
0.30720000 0.30649387 0.23773724
0.30800000 0.30699108 0.23812274
0.30880000 0.30804826 0.23894242
0.30960000 0.30876672 0.23949947
0.31040000 0.30949059 0.24006071
0.31120000 0.31041335 0.24077615
0.31200000 0.31095076 0.24119283
0.31280000 0.31196973 0.24198287
0.31360000 0.31276908 0.24260264
0.31440000 0.31334077 0.24304589
0.31520000 0.31435259 0.24383039
0.31600000 0.31505856 0.24437775
0.31680000 0.31573673 0.24490357
0.31760000 0.31650190 0.24549683
0.31840000 0.31731861 0.24613006
0.31920000 0.31806547 0.24670913
0.32000000 0.31881241 0.24728826
0.32080000 0.31993343 0.24815742
0.32160000 0.32039777 0.24851745
0.32240000 0.32131268 0.24922681
0.32320000 0.32198895 0.24975114
0.32400000 0.32301869 0.25054954
0.32480000 0.32387213 0.25121124
0.32560000 0.32449240 0.25169216
0.32640000 0.32530454 0.25232184
0.32720000 0.32626892 0.25306956
0.32800000 0.32670059 0.25340425
0.32880000 0.32769728 0.25417702
0.32960000 0.32843663 0.25475027
0.33040000 0.32924165 0.25537443
0.33120000 0.33010764 0.25604586
0.33200000 0.33066384 0.25647710
0.33280000 0.33152480 0.25714464
0.33360000 0.33219943 0.25766770
0.33440000 0.33303669 0.25831686
0.33520000 0.33401764 0.25907743
0.33600000 0.33478104 0.25966932
0.33680000 0.33572698 0.26040274
0.33760000 0.33618466 0.26075760
0.33840000 0.33714682 0.26150360
0.33920000 0.33773716 0.26196131
0.34000000 0.33874599 0.26274349
0.34080000 0.33934637 0.26320899
0.34160000 0.34016090 0.26384052
0.34240000 0.34101741 0.26450460
0.34320000 0.34172164 0.26505062
0.34400000 0.34245332 0.26561792
0.34480000 0.34345126 0.26639166
0.34560000 0.34418444 0.26696012
0.34640000 0.34504520 0.26762750
0.34720000 0.34562135 0.26807421
0.34800000 0.34649196 0.26874923
0.34880000 0.34748336 0.26951790
0.34960000 0.34809917 0.26999535
0.35040000 0.34880731 0.27054440
0.35120000 0.34986105 0.27136140
0.35200000 0.35045954 0.27182543
0.35280000 0.35112896 0.27234446
0.35360000 0.35199864 0.27301875
0.35440000 0.35271118 0.27357121
0.35520000 0.35372608 0.27435810
0.35600000 0.35446116 0.27492804
0.35680000 0.35522421 0.27551965
0.35760000 0.35591930 0.27605859
0.35840000 0.35668523 0.27665244
0.35920000 0.35744822 0.27724402
0.36000000 0.35796433 0.27764417
0.36080000 0.35895070 0.27840894
0.36160000 0.35984657 0.27910354
0.36240000 0.36054672 0.27964640
0.36320000 0.35727380 0.27710878
0.36280000 0.35737818 0.27718971
0.36200000 0.35696641 0.27687045
0.36120000 0.35602979 0.27614425
0.36040000 0.35455254 0.27499888
0.35960000 0.35358284 0.27424704
0.35880000 0.35360258 0.27426235
0.35800000 0.35292581 0.27373762
0.35720000 0.35190821 0.27294864
0.35640000 0.35039967 0.27177902
0.35560000 0.34994868 0.27142934
0.35480000 0.34934480 0.27096113
0.35400000 0.34886955 0.27059266
0.35320000 0.34793067 0.26986471
0.35240000 0.34692484 0.26908485
0.35160000 0.34583157 0.26823720
0.35080000 0.34543907 0.26793288
0.35000000 0.34484525 0.26747247
0.34920000 0.34425333 0.26701353
0.34840000 0.34302908 0.26606433
0.34760000 0.34193851 0.26521876
0.34680000 0.34133039 0.26474727
0.34600000 0.34090511 0.26441754
0.34520000 0.34001181 0.26372493
0.34440000 0.33917059 0.26307270
0.34360000 0.33817590 0.26230148
0.34280000 0.33741408 0.26171081
0.34200000 0.33678315 0.26122162
0.34120000 0.33619082 0.26076238
0.34040000 0.33513942 0.25994718
0.33960000 0.33393091 0.25901018
0.33880000 0.33333469 0.25854791
0.33800000 0.33297266 0.25826722
0.33720000 0.33211006 0.25759841
0.33640000 0.33120921 0.25689995
0.33560000 0.33029207 0.25618886
0.33480000 0.32963464 0.25567913
0.33400000 0.32883201 0.25505682
0.33320000 0.32824254 0.25459978
0.33240000 0.32724878 0.25382928
0.33160000 0.32646275 0.25321984
0.33080000 0.32567353 0.25260793
0.33000000 0.32486778 0.25198321
0.32920000 0.32422660 0.25148607
0.32840000 0.32321296 0.25070017
0.32760000 0.32249391 0.25014265
0.32680000 0.32175368 0.24956873
0.32600000 0.32100193 0.24898587
0.32520000 0.32026777 0.24841665
0.32440000 0.31925016 0.24762766
0.32360000 0.31857831 0.24710675
0.32280000 0.31776509 0.24647623
0.32200000 0.31718383 0.24602556
0.32120000 0.31585050 0.24499178
0.32040000 0.31544271 0.24467560
0.31960000 0.31460430 0.24402555
0.31880000 0.31371264 0.24333422
0.31800000 0.31313467 0.24288610
0.31720000 0.31217467 0.24214177
0.31640000 0.31134394 0.24149768
0.31560000 0.31074218 0.24103111
0.31480000 0.31009126 0.24052643
0.31400000 0.30873991 0.23947868
0.31320000 0.30805323 0.23894627
0.31240000 0.30773697 0.23870106
0.31160000 0.30674280 0.23793025
0.31080000 0.30571935 0.23713673
0.31000000 0.30498942 0.23657078
0.30920000 0.30422847 0.23598079
0.30840000 0.30365023 0.23553246
0.30760000 0.30277298 0.23485230
0.30680000 0.30187574 0.23415664
0.30600000 0.30096296 0.23344892
0.30520000 0.30032016 0.23295054
0.30440000 0.29955432 0.23235675
0.30360000 0.29890422 0.23185271
0.30280000 0.29787673 0.23105606
0.30200000 0.29692139 0.23031535
0.30120000 0.29643025 0.22993455
0.30040000 0.29585421 0.22948793
0.29960000 0.29464341 0.22854915
0.29880000 0.29351953 0.22767776
0.29800000 0.29298934 0.22726669
0.29720000 0.29258766 0.22695525
0.29640000 0.29163425 0.22621603
0.29560000 0.29052544 0.22535633
0.29480000 0.28980371 0.22479675
0.29400000 0.28949388 0.22455653
0.29320000 0.28863227 0.22388849
0.29240000 0.28748943 0.22300240
0.29160000 0.28670630 0.22239522
0.29080000 0.28593930 0.22180053
0.29000000 0.28543016 0.22140578
0.28920000 0.28433858 0.22055943
0.28840000 0.28354488 0.21994405
0.28760000 0.28281468 0.21937790
0.28680000 0.28202034 0.21876202
0.28600000 0.28148498 0.21834693
0.28520000 0.28046983 0.21755985
0.28440000 0.27978892 0.21703191
0.28360000 0.27868279 0.21617429
0.28280000 0.27811552 0.21573447
0.28200000 0.27763092 0.21535873
0.28120000 0.27680911 0.21472156
0.28040000 0.27544865 0.21366675
0.27960000 0.27464340 0.21304240
0.27880000 0.27431117 0.21278481
0.27800000 0.27353596 0.21218377
0.27720000 0.27246842 0.21135606
0.27640000 0.27126629 0.21042401
0.27560000 0.27094847 0.21017759
0.27480000 0.27042745 0.20977362
0.27400000 0.26924760 0.20885885
0.27320000 0.26832653 0.20814471
0.27240000 0.26751211 0.20751325
0.27160000 0.26724188 0.20730373
0.27080000 0.26638962 0.20664294
0.27000000 0.26526024 0.20576729
0.26920000 0.26419733 0.20494318
0.26840000 0.26394060 0.20474413
0.26760000 0.26319415 0.20416538
0.26680000 0.26217038 0.20337161
0.26600000 0.26134754 0.20273364
0.26520000 0.26058219 0.20214023
0.26440000 0.25983818 0.20156337
0.26360000 0.25916149 0.20103871
0.26280000 0.25856822 0.20057873
0.26200000 0.25750723 0.19975611
0.26120000 0.25654490 0.19900997
0.26040000 0.25585245 0.19847309
0.25960000 0.25514605 0.19792539
0.25880000 0.25437300 0.19732602
0.25800000 0.25341967 0.19658687
0.25720000 0.25269455 0.19602466
0.25640000 0.25191858 0.19542302
0.25560000 0.25135474 0.19498585
0.25480000 0.25033757 0.19419721
0.25400000 0.24952213 0.19356496
0.25320000 0.24869613 0.19292453
0.25240000 0.24784589 0.19226532
0.25160000 0.24724212 0.19179719
0.25080000 0.24640719 0.19114983
0.25000000 0.24579356 0.19067407
0.24920000 0.24475206 0.18986655
0.24840000 0.24390686 0.18921124
0.24760000 0.24313339 0.18861154
0.24680000 0.24266833 0.18825096
0.24600000 0.24164444 0.18745710
0.24520000 0.24064445 0.18668177
0.24440000 0.24009707 0.18625737
0.24360000 0.23939403 0.18571228
0.24280000 0.23850155 0.18502030
0.24200000 0.23729644 0.18408594
0.24120000 0.23673780 0.18365280
0.24040000 0.23631459 0.18332467
0.23960000 0.23568855 0.18283928
0.23880000 0.23420452 0.18168866
0.23800000 0.23345462 0.18110723
0.23720000 0.23333020 0.18101077
0.23640000 0.23257207 0.18042296
0.23560000 0.23119426 0.17935470
0.23480000 0.23017781 0.17856661
0.23400000 0.22998368 0.17841609
0.23320000 0.22933976 0.17791683
0.23240000 0.22798265 0.17686462
0.23160000 0.22734241 0.17636821
0.23080000 0.22689573 0.17602189
0.23000000 0.22633248 0.17558518
0.22920000 0.22493174 0.17449913
0.22840000 0.22369448 0.17353984
0.22760000 0.22331364 0.17324456
0.22680000 0.22285366 0.17288793
0.22600000 0.22201502 0.17223769
0.22520000 0.22091024 0.17138111
0.22440000 0.21984998 0.17055906
0.22360000 0.21968885 0.17043413
0.22280000 0.21884768 0.16978194
0.22200000 0.21779787 0.16896798
0.22120000 0.21679323 0.16818905
0.22040000 0.21644492 0.16791899
0.21960000 0.21570429 0.16734476
0.21880000 0.21472956 0.16658901
0.21800000 0.21354585 0.16567124
0.21720000 0.21301089 0.16525646
0.21640000 0.21251158 0.16486933
0.21560000 0.21153087 0.16410895
0.21480000 0.21062506 0.16340664
0.21400000 0.20987624 0.16282605
0.21320000 0.20948758 0.16252471
0.21240000 0.20835858 0.16164936
0.21160000 0.20754357 0.16101745
0.21080000 0.20676709 0.16041542
0.21000000 0.20609587 0.15989500
0.20920000 0.20492292 0.15898556
0.20840000 0.20446929 0.15863385
0.20760000 0.20367028 0.15801434
0.20680000 0.20284495 0.15737444
0.20600000 0.20179261 0.15655852
0.20520000 0.20114342 0.15605518
0.20440000 0.20054766 0.15559327
0.20360000 0.19973833 0.15496576
0.20280000 0.19877736 0.15422068
0.20200000 0.19777636 0.15344457
0.20120000 0.19743788 0.15318214
0.20040000 0.19671221 0.15261950
0.19960000 0.19545727 0.15164649
0.19880000 0.19472844 0.15108141
0.19800000 0.19422812 0.15069350
0.19720000 0.19344245 0.15008433
0.19640000 0.19255481 0.14939611
0.19560000 0.19148634 0.14856769
0.19480000 0.19082243 0.14805294
0.19400000 0.19034843 0.14768543
0.19320000 0.18948235 0.14701392
0.19240000 0.18829398 0.14609254
0.19160000 0.18763537 0.14558189
0.19080000 0.18722671 0.14526504
0.19000000 0.18608347 0.14437865
0.18920000 0.18517709 0.14367590
0.18840000 0.18452333 0.14316901
0.18760000 0.18383263 0.14263349
0.18680000 0.18302497 0.14200728
0.18600000 0.18217027 0.14134460
0.18520000 0.18123929 0.14062278
0.18440000 0.18044498 0.14000692
0.18360000 0.17992635 0.13960481
0.18280000 0.17917066 0.13901889
0.18200000 0.17800446 0.13811469
0.18120000 0.17726165 0.13753877
0.18040000 0.17659932 0.13702524
0.17960000 0.17588915 0.13647462
0.17880000 0.17504929 0.13582344
0.17800000 0.17417172 0.13514303
0.17720000 0.17329011 0.13445949
0.17640000 0.17280245 0.13408139
0.17560000 0.17217826 0.13359743
0.17480000 0.17086232 0.13257713
0.17400000 0.16996514 0.13188151
0.17320000 0.16956064 0.13156789
0.17240000 0.16878278 0.13096479
0.17160000 0.16780715 0.13020835
0.17080000 0.16688672 0.12949470
0.17000000 0.16621289 0.12897226
0.16920000 0.16560803 0.12850329
0.16840000 0.16473701 0.12782796
0.16760000 0.16366452 0.12699641
0.16680000 0.16285934 0.12637213
0.16600000 0.16244585 0.12605153
0.16520000 0.16165176 0.12543585
0.16440000 0.16041952 0.12448045
0.16360000 0.15983825 0.12402976
0.16280000 0.15920635 0.12353983
0.16200000 0.15842184 0.12293157
0.16120000 0.15737273 0.12211816
0.16040000 0.15659215 0.12151294
0.15960000 0.15597734 0.12103626
0.15880000 0.15514862 0.12039373
0.15800000 0.15423461 0.11968506
0.15720000 0.15360740 0.11919876
0.15640000 0.15277408 0.11855265
0.15560000 0.15199203 0.11794631
0.15480000 0.15091564 0.11711174
0.15400000 0.15018352 0.11654410
0.15320000 0.14970140 0.11617030
0.15240000 0.14874656 0.11542997
0.15160000 0.14779915 0.11469541
0.15080000 0.14705770 0.11412054
0.15000000 0.14637863 0.11359403
0.14920000 0.14533246 0.11278290
0.14840000 0.14467018 0.11226941
0.14760000 0.14395739 0.11171675
0.14680000 0.14321212 0.11113892
0.14600000 0.14250232 0.11058859
0.14520000 0.14156977 0.10986555
0.14440000 0.14065608 0.10915713
0.14360000 0.14012821 0.10874785
0.14280000 0.13915687 0.10799474
0.14200000 0.13837372 0.10738753
0.14120000 0.13742124 0.10664903
0.14040000 0.13699959 0.10632211
0.13960000 0.13594742 0.10550633
0.13880000 0.13513446 0.10487601
0.13800000 0.13457486 0.10444213
0.13720000 0.13382280 0.10385904
0.13640000 0.13272673 0.10300921
0.13560000 0.13181921 0.10230558
0.13480000 0.13130950 0.10191038
0.13400000 0.13050820 0.10128911
0.13320000 0.12949324 0.10050217
0.13240000 0.12882529 0.09998428
0.13160000 0.12809709 0.09941968
0.13080000 0.12733384 0.09882791
0.13000000 0.12638842 0.09809489
0.12920000 0.12552851 0.09742817
0.12840000 0.12494526 0.09697595
0.12760000 0.12420700 0.09640356
0.12680000 0.12317708 0.09560502
0.12600000 0.12230283 0.09492718
0.12520000 0.12177819 0.09452041
0.12440000 0.12077297 0.09374103
0.12360000 0.11996319 0.09311318
0.12280000 0.11928956 0.09259088
0.12200000 0.11858288 0.09204296
0.12120000 0.11760799 0.09128710
0.12040000 0.11686004 0.09070719
0.11960000 0.11608139 0.09010347
0.11880000 0.11530633 0.08950254
0.11800000 0.11438882 0.08879116
0.11720000 0.11372152 0.08827378
0.11640000 0.11283105 0.08758336
0.11560000 0.11228862 0.08716280
0.11480000 0.11122862 0.08634094
0.11400000 0.11055017 0.08581491
0.11320000 0.10995502 0.08535347
0.11240000 0.10902034 0.08462878
0.11160000 0.10811276 0.08392510
0.11080000 0.10741863 0.08338691
0.11000000 0.10652158 0.08269140
0.10920000 0.10554144 0.08193146
0.10840000 0.10505511 0.08155439
0.10760000 0.10426880 0.08094473
0.10680000 0.10334965 0.08023208
0.10600000 0.10260082 0.07965149
0.10520000 0.10188155 0.07909382
0.10440000 0.10107304 0.07846695
0.10360000 0.10010013 0.07771261
0.10280000 0.09937104 0.07714733
0.10200000 0.09865119 0.07658920
0.10120000 0.09780781 0.07593529
0.10040000 0.09707896 0.07537019
0.09960000 0.09619238 0.07468280
0.09880000 0.09550106 0.07414678
0.09800000 0.09466988 0.07350234
0.09720000 0.09391446 0.07291664
0.09640000 0.09313475 0.07231210
0.09560000 0.09236706 0.07171688
0.09480000 0.09135166 0.07092960
0.09400000 0.09059518 0.07034308
0.09320000 0.08984712 0.06976308
0.09240000 0.08903772 0.06913553
0.09160000 0.08815250 0.06844918
0.09080000 0.08735065 0.06782747
0.09000000 0.08712237 0.06765049
0.08920000 0.08607217 0.06683622
0.08840000 0.08520733 0.06616568
0.08760000 0.08438376 0.06552714
0.08680000 0.08362134 0.06493601
0.08600000 0.08264124 0.06417610
0.08520000 0.08206826 0.06373185
0.08440000 0.08091993 0.06284150
0.08360000 0.08036286 0.06240958
0.08280000 0.07964765 0.06185506
0.08200000 0.07865351 0.06108427
0.08120000 0.07797024 0.06055450
0.08040000 0.07723200 0.05998212
0.07960000 0.07636276 0.05930816
0.07880000 0.07557903 0.05870051
0.07800000 0.07473392 0.05804526
0.07720000 0.07403977 0.05750707
0.07640000 0.07316044 0.05682529
0.07560000 0.07235840 0.05620344
0.07480000 0.07143584 0.05548814
0.07400000 0.07064833 0.05487756
0.07320000 0.06988708 0.05428733
0.07240000 0.06927702 0.05381433
0.07160000 0.06832322 0.05307482
0.07080000 0.06756844 0.05248960
0.07000000 0.06680723 0.05189941
0.06920000 0.06585013 0.05115733
0.06840000 0.06497804 0.05048117
0.06760000 0.06455171 0.05015063
0.06680000 0.06352173 0.04935204
0.06600000 0.06261607 0.04864985
0.06520000 0.06215338 0.04829111
0.06440000 0.06109723 0.04747224
0.06360000 0.06026126 0.04682408
0.06280000 0.05987101 0.04652150
0.06200000 0.05879623 0.04568819
0.06120000 0.05801419 0.04508185
0.06040000 0.05735438 0.04457027
0.05960000 0.05647144 0.04388570
0.05880000 0.05571085 0.04329598
0.05800000 0.05466952 0.04248860
0.05720000 0.05423024 0.04214801
0.05640000 0.05318221 0.04133543
0.05560000 0.05276370 0.04101095
0.05480000 0.05163954 0.04013934
0.05400000 0.05098371 0.03963085
0.05320000 0.04992317 0.03880858
0.05240000 0.04926093 0.03829512
0.05160000 0.04847969 0.03768939
0.05080000 0.04773201 0.03710969
0.05000000 0.04667556 0.03629059
0.04920000 0.04605824 0.03581196
0.04840000 0.04511469 0.03508039
0.04760000 0.04444993 0.03456498
0.04680000 0.04360274 0.03390812
0.04600000 0.04291538 0.03337518
0.04520000 0.04200927 0.03267264
0.04440000 0.04129223 0.03211670
0.04360000 0.04059894 0.03157916
0.04280000 0.03976199 0.03093025
0.04200000 0.03876649 0.03015840
0.04120000 0.03817134 0.02969695
0.04040000 0.03735669 0.02906533
0.03960000 0.03652536 0.02842077
0.03880000 0.03556222 0.02767401
0.03800000 0.03500543 0.02724231
0.03720000 0.03431943 0.02671043
0.03640000 0.03329807 0.02591853
0.03560000 0.03267913 0.02543864
0.03480000 0.03195795 0.02487949
0.03400000 0.03096820 0.02411209
0.03320000 0.03016463 0.02348906
0.03240000 0.02922841 0.02276318
0.03160000 0.02888864 0.02249974
0.03080000 0.02766092 0.02154784
0.03000000 0.02681573 0.02089254
0.02920000 0.02621634 0.02042780
0.02840000 0.02531881 0.01973192
0.02760000 0.02454071 0.01912863
0.02680000 0.02375182 0.01851697
0.02600000 0.02304152 0.01796625
0.02520000 0.02220622 0.01731862
0.02440000 0.02136166 0.01666380
0.02360000 0.02070465 0.01615439
0.02280000 0.01973175 0.01540007
0.02200000 0.01893219 0.01478014
0.02120000 0.01826544 0.01426319
0.02040000 0.01769668 0.01382220
0.01960000 0.01673914 0.01307978
0.01880000 0.01573545 0.01230158
0.01800000 0.01520233 0.01188824
0.01720000 0.01426177 0.01115899
0.01640000 0.01338868 0.01048205
0.01560000 0.01283151 0.01005006
0.01480000 0.01187949 0.00931192
0.01400000 0.01087600 0.00853388
0.01320000 0.01018388 0.00799725
0.01240000 0.00973555 0.00764965
0.01160000 0.00852384 0.00671016
0.01080000 0.00771757 0.00608504
0.01000000 0.00718763 0.00567415
0.00920000 0.00644199 0.00509603
0.00840000 0.00542468 0.00430727
0.00760000 0.00477522 0.00380372
0.00680000 0.00402482 0.00322190
0.00600000 0.00313430 0.00253146
0.00520000 0.00214379 0.00176348
0.00440000 0.00154878 0.00130214
0.00400000 0.00137045 0.00116388