File: plots/rawdata/Figure2-30K.txt
# strain(%), strain_el(%), stress(GPa)
0.00000000 -0.00013068 0.00000000
0.00440000 0.00464700 0.00370431
0.00880000 0.00811887 0.00639618
0.01320000 0.01500524 0.01173543
0.01760000 0.01746978 0.01364628
0.02200000 0.01998607 0.01559725
0.02640000 0.02438113 0.01900490
0.03080000 0.02879388 0.02242626
0.03520000 0.03585092 0.02789785
0.03960000 0.04125801 0.03209016
0.04400000 0.05301884 0.04120877
0.04840000 0.06462571 0.05020800
0.05280000 0.06898493 0.05358786
0.05720000 0.06970745 0.05414806
0.06160000 0.08129405 0.06313158
0.06600000 0.08684072 0.06743211
0.07040000 0.08266041 0.06419096
0.07480000 0.09074465 0.07045897
0.07920000 0.07795389 0.06054182
0.08360000 0.08229927 0.06391096
0.08800000 0.08754072 0.06797484
0.09240000 0.09424998 0.07317678
0.09680000 0.09533430 0.07401749
0.10120000 0.09974039 0.07743369
0.10560000 0.10802736 0.08385888
0.11000000 0.10861712 0.08431615
0.11440000 0.11293368 0.08766293
0.11880000 0.11753034 0.09122690
0.12320000 0.11279837 0.08755803
0.12760000 0.11709037 0.09088577
0.13200000 0.12129772 0.09414789
0.13640000 0.12321791 0.09563668
0.14080000 0.13677755 0.10614996
0.14520000 0.14119263 0.10957314
0.14960000 0.14525368 0.11272181
0.15400000 0.14951504 0.11602580
0.15840000 0.16112871 0.12503031
0.16280000 0.15824221 0.12279230
0.16720000 0.16270719 0.12625416
0.17160000 0.17058332 0.13236081
0.17600000 0.17428626 0.13523184
0.18040000 0.17340976 0.13455226
0.18480000 0.17159725 0.13314695
0.18920000 0.17827532 0.13832470
0.19360000 0.18315934 0.14211146
0.19800000 0.18750757 0.14548281
0.20240000 0.20038767 0.15546922
0.20680000 0.20481822 0.15890438
0.21120000 0.20919322 0.16229648
0.21560000 0.21363531 0.16574060
0.22000000 0.23089325 0.17912131
0.22440000 0.23850893 0.18502603
0.22880000 0.24238509 0.18803136
0.23320000 0.24353105 0.18891986
0.23760000 0.24799072 0.19237761
0.24200000 0.25209368 0.19555878
0.24640000 0.24854719 0.19280906
0.25080000 0.26061853 0.20216841
0.25520000 0.25260910 0.19595840
0.25960000 0.26089272 0.20238100
0.26400000 0.25304552 0.19629678
0.26840000 0.25745095 0.19971247
0.27280000 0.26194958 0.20320042
0.27720000 0.26622694 0.20651681
0.28160000 0.27088363 0.21012731
0.28600000 0.27474335 0.21311990
0.29040000 0.27961362 0.21689600
0.29480000 0.28386647 0.22019339
0.29920000 0.28841009 0.22371623
0.30360000 0.30052399 0.23310858
0.30800000 0.30457233 0.23624740
0.31240000 0.30919856 0.23983429
0.31680000 0.31347566 0.24315048
0.32120000 0.31019859 0.24060965
0.32560000 0.31475030 0.24413875
0.33000000 0.31925162 0.24762879
0.33440000 0.32344307 0.25087857
0.33880000 0.32734573 0.25390445
0.34320000 0.33982015 0.26357633
0.34760000 0.33622074 0.26078557
0.35200000 0.34073725 0.26428739
0.35640000 0.34544814 0.26793991
0.36080000 0.34983042 0.27133765
0.36520000 0.35359694 0.27425797
0.36960000 0.35547663 0.27571537
0.37400000 0.35606087 0.27616835
0.37840000 0.36397995 0.28230831
0.38280000 0.36857260 0.28586915
0.38720000 0.36037457 0.27951292
0.39160000 0.36836450 0.28570780
0.39600000 0.37702792 0.29242487
0.40040000 0.38532660 0.29885914
0.40480000 0.38442109 0.29815706
0.40920000 0.38508622 0.29867276
0.41360000 0.38946777 0.30206994
0.41800000 0.40234884 0.31205711
0.42240000 0.39908917 0.30952977
0.42680000 0.41186212 0.31943311
0.43120000 0.41622788 0.32281804
0.43560000 0.41156390 0.31920188
0.44000000 0.41068221 0.31851827
0.44440000 0.42699217 0.33116399
0.44880000 0.42477119 0.32944198
0.45320000 0.43110196 0.33435046
0.45760000 0.44279842 0.34341915
0.46200000 0.44447899 0.34472216
0.46640000 0.44216569 0.34292857
0.47080000 0.44074410 0.34182636
0.47520000 0.44530653 0.34536378
0.47960000 0.44976076 0.34881731
0.48400000 0.45968860 0.35651472
0.48840000 0.45680763 0.35428101
0.49280000 0.46787228 0.36285983
0.49720000 0.48174545 0.37361621
0.50160000 0.46927012 0.36394363
0.50600000 0.48199264 0.37380786
0.51040000 0.48459374 0.37582459
0.51480000 0.48988534 0.37992736
0.51920000 0.49233835 0.38182927
0.52360000 0.49156033 0.38122604
0.52800000 0.50221829 0.38948955
0.53240000 0.51325379 0.39804578
0.53680000 0.51036619 0.39580691
0.54120000 0.51178051 0.39690349
0.54560000 0.51776225 0.40154135
0.55000000 0.52444727 0.40672449
0.55440000 0.52510575 0.40723504
0.55880000 0.53323031 0.41353430
0.56320000 0.53518405 0.41504912
0.56760000 0.54175138 0.42014100
0.57200000 0.53982603 0.41864821
0.57640000 0.54397191 0.42186266
0.58080000 0.54688893 0.42412434
0.58520000 0.55119060 0.42745957
0.58960000 0.55549619 0.43079786
0.59400000 0.56113876 0.43517275
0.59840000 0.57022045 0.44221412
0.60280000 0.56817949 0.44063168
0.60720000 0.57252575 0.44400150
0.61160000 0.57833240 0.44850361
0.61600000 0.58121050 0.45073510
0.62040000 0.58698976 0.45521598
0.62480000 0.58765029 0.45572811
0.62920000 0.59443408 0.46098783
0.63360000 0.59997086 0.46528070
0.63800000 0.60908379 0.47234628
0.64240000 0.61310183 0.47546162
0.64680000 0.61262667 0.47509321
0.65120000 0.61544045 0.47727484
0.65560000 0.62161382 0.48206127
0.66000000 0.62796415 0.48698492
0.66440000 0.62878776 0.48762350
0.66880000 0.63326906 0.49109801
0.67320000 0.63845257 0.49511698
0.67760000 0.64136613 0.49737596
0.68200000 0.64567688 0.50071825
0.68640000 0.65073891 0.50464303
0.69080000 0.65618785 0.50886779
0.69520000 0.65772333 0.51005830
0.69960000 0.67071391 0.52013037
0.70400000 0.67467771 0.52320365
0.70840000 0.67337565 0.52219412
0.71280000 0.67742558 0.52533418
0.71720000 0.67937013 0.52684186
0.72160000 0.69208577 0.53670076
0.72600000 0.69655293 0.54016431
0.73040000 0.69496983 0.53893688
0.73480000 0.69947931 0.54243324
0.73920000 0.70312304 0.54525836
0.74360000 0.70759210 0.54872339
0.74800000 0.71216425 0.55226834
0.75240000 0.72307939 0.56073125
0.75680000 0.71948923 0.55794767
0.76120000 0.72394840 0.56140503
0.76560000 0.72811881 0.56463850
0.77000000 0.73002099 0.56611333
0.77440000 0.73665219 0.57125474
0.77880000 0.74261012 0.57587414
0.78320000 0.74586485 0.57839765
0.78760000 0.75086985 0.58227821
0.79200000 0.75290533 0.58385640
0.79640000 0.75691940 0.58696865
0.80080000 0.76375490 0.59226847
0.80520000 0.76798065 0.59554484
0.80960000 0.77222450 0.59883525
0.81400000 0.77492913 0.60093225
0.81840000 0.77921193 0.60425286
0.82280000 0.78355069 0.60761686
0.82720000 0.78768538 0.61082264
0.83160000 0.78971129 0.61239340
0.83600000 0.79655091 0.61769641
0.84040000 0.79842037 0.61914587
0.84480000 0.80264178 0.62241888
0.84920000 0.80944856 0.62769643
0.85360000 0.81127409 0.62911183
0.85800000 0.81783330 0.63419742
0.86240000 0.82205670 0.63747198
0.86680000 0.82435554 0.63925436
0.87120000 0.83083643 0.64427923
0.87560000 0.83691254 0.64899026
0.88000000 0.84149547 0.65254358
0.88440000 0.84469689 0.65502575
0.88880000 0.84747492 0.65717966
0.89320000 0.85600535 0.66379362
0.89760000 0.85838239 0.66563662
0.90200000 0.86082745 0.66753236
0.90640000 0.86275794 0.66902915
0.91080000 0.86948857 0.67424765
0.91520000 0.87305223 0.67701068
0.91960000 0.87990731 0.68232568
0.92400000 0.88200347 0.68395091
0.92840000 0.88417307 0.68563308
0.93280000 0.89119166 0.69107485
0.93720000 0.89515401 0.69414701
0.94160000 0.89965769 0.69763887
0.94600000 0.90392295 0.70094589
0.95040000 0.90603151 0.70258073
0.95480000 0.91409698 0.70883419
0.95920000 0.91685449 0.71097218
0.96360000 0.92120737 0.71434713
0.96800000 0.92682887 0.71870568
0.97240000 0.92835661 0.71989019
0.97680000 0.93528515 0.72526215
0.98120000 0.93579926 0.72566075
0.98560000 0.94007353 0.72897476
0.99000000 0.94452264 0.73242431
0.99440000 0.94861692 0.73559876
0.99880000 0.95288416 0.73890730
1.00320000 0.95751623 0.74249872
1.00760000 0.96412627 0.74762372
1.01200000 0.96687361 0.74975383
1.01640000 0.97159063 0.75341111
1.02080000 0.97842505 0.75871009
1.02520000 0.98069039 0.76046649
1.02960000 0.98304722 0.76229383
1.03400000 0.98614012 0.76469187
1.03840000 0.99155306 0.76888872
1.04280000 0.99864094 0.77438421
1.04720000 1.00272283 0.77754905
1.05160000 1.00855021 0.78206723
1.05600000 1.01284002 0.78539328
1.06040000 1.01395198 0.78625542
1.06480000 1.01735491 0.78889383
1.06920000 1.02156103 0.79215500
1.07360000 1.02591893 0.79553384
1.07800000 1.03047510 0.79906640
1.08240000 1.03453022 0.80221048
1.08680000 1.03865415 0.80540792
1.09120000 1.04361354 0.80925311
1.09560000 1.04715828 0.81200148
1.10000000 1.05132199 0.81522976
1.10440000 1.05992922 0.82190326
1.10880000 1.05903698 0.82121148
1.11320000 1.06449680 0.82544467
1.11760000 1.06869703 0.82870126
1.12200000 1.07272784 0.83182650
1.12640000 1.07715879 0.83526198
1.13080000 1.08136071 0.83851988
1.13520000 1.08799589 0.84366438
1.13960000 1.09018138 0.84535886
1.14400000 1.09066410 0.84573314
1.14840000 1.09856749 0.85186093
1.15280000 1.10278860 0.85513370
1.15720000 1.10701177 0.85840809
1.16160000 1.11144063 0.86184194
1.16600000 1.11530447 0.86483772
1.17040000 1.12005498 0.86852097
1.17480000 1.12398099 0.87156495
1.17920000 1.12864579 0.87518174
1.18360000 1.13278705 0.87839260
1.18800000 1.13705023 0.88169800
1.19240000 1.14122457 0.88493453
1.19680000 1.14565129 0.88836672
1.20120000 1.15402804 0.89486152
1.20560000 1.15447219 0.89520588
1.21000000 1.15835698 0.89821791
1.21440000 1.16271621 0.90159778
1.21880000 1.16699314 0.90491384
1.22320000 1.17225542 0.90899387
1.22760000 1.17645158 0.91224731
1.23200000 1.18069610 0.91553825
1.23640000 1.18428946 0.91832431
1.24080000 1.18873741 0.92177297
1.24520000 1.18894898 0.92193701
1.24960000 1.19308578 0.92514441
1.25400000 1.19743307 0.92851503
1.25840000 1.21003217 0.93828357
1.26280000 1.20998555 0.93824743
1.26720000 1.21069037 0.93879390
1.27160000 1.21462607 0.94184539
1.27600000 1.22162832 0.94727450
1.28040000 1.22780287 0.95206185
1.28480000 1.23201395 0.95532685
1.28920000 1.23627698 0.95863214
1.29360000 1.23573579 0.95821253
1.29800000 1.24455768 0.96505247
1.30240000 1.24917124 0.96862952
1.30680000 1.25264633 0.97132389
1.31120000 1.25395972 0.97234221
1.31560000 1.26247264 0.97894259
1.32000000 1.26245393 0.97892809
1.32440000 1.26932504 0.98425550
1.32880000 1.27020071 0.98493445
1.33320000 1.27463839 0.98837514
1.33760000 1.27872949 0.99154712
1.34200000 1.27197640 0.98631121
1.34640000 1.27655272 0.98985939
1.35080000 1.28072275 0.99309257
1.35520000 1.28507169 0.99646446
1.35960000 1.28944680 0.99985664
1.36400000 1.29367640 1.00313601
1.36840000 1.29803874 1.00651829
1.37280000 1.30230021 1.00982237
1.37720000 1.30673565 1.01326132
1.38160000 1.31078198 1.01639859
1.38600000 1.31634831 1.02071437
1.39040000 1.31947356 1.02313749
1.39480000 1.32392614 1.02658974
1.39920000 1.32796631 1.02972223
1.40360000 1.33244592 1.03319543
1.40800000 1.33649318 1.03633343
1.41240000 1.34064408 1.03955177
1.41680000 1.34524114 1.04311604
1.42120000 1.34813143 1.04535699
1.42560000 1.35237260 1.04864532
1.43000000 1.35727749 1.05244826
1.43440000 1.36180989 1.05596240
1.43880000 1.36518818 1.05858171
1.44320000 1.37096432 1.06306016
1.44760000 1.37486579 1.06608512
1.45200000 1.37914764 1.06940499
1.45640000 1.38179644 1.07145870
1.46080000 1.38471918 1.07372481
1.46520000 1.39194060 1.07932384
1.46960000 1.39753021 1.08365767
1.47400000 1.40031663 1.08581809
1.47840000 1.40197157 1.08710122
1.48280000 1.41012622 1.09342382
1.48720000 1.41256742 1.09531657
1.49160000 1.41679050 1.09859088
1.49600000 1.42173585 1.10242519
1.50040000 1.42632753 1.10598529
1.50480000 1.42638039 1.10602627
1.50920000 1.43506796 1.11276206
1.51360000 1.43898730 1.11580087
1.51800000 1.43914384 1.11592224
1.52240000 1.44383066 1.11955611
1.52680000 1.45174541 1.12569270
1.53120000 1.45185999 1.12578154
1.53560000 1.45628525 1.12921260
1.54000000 1.46104583 1.13290366
1.54440000 1.46440944 1.13551158
1.54880000 1.46954044 1.13948984
1.55320000 1.47563325 1.14421382
1.55760000 1.48180658 1.14900023
1.56200000 1.48712660 1.15312503
1.56640000 1.48525108 1.15167087
1.57080000 1.49000677 1.15535813
1.57520000 1.49429314 1.15868152
1.57960000 1.50308255 1.16549626
1.58400000 1.50247871 1.16502809
1.58840000 1.50617047 1.16789045
1.59280000 1.51101272 1.17164482
1.59720000 1.50967524 1.17060782
1.60160000 1.50906429 1.17013413
1.60600000 1.51969068 1.17837316
1.61040000 1.52829979 1.18504811
1.61480000 1.53177123 1.18773965
1.61920000 1.53374719 1.18927169
1.62360000 1.54082315 1.19475793
1.62800000 1.54551078 1.19839243
1.63240000 1.54903447 1.20112447
1.63680000 1.55518690 1.20589468
1.64120000 1.56002322 1.20964446
1.64560000 1.56340330 1.21226515
1.65000000 1.56755376 1.21548316
1.65440000 1.57211520 1.21901980
1.65880000 1.57246161 1.21928839
1.66320000 1.57902372 1.22437624
1.66760000 1.58354141 1.22787896
1.67200000 1.58763969 1.23105652
1.67640000 1.59182191 1.23429914
1.68080000 1.59822782 1.23926588
1.68520000 1.60027701 1.24085469
1.68960000 1.60298248 1.24295234
1.69400000 1.60922575 1.24779297
1.69840000 1.61357270 1.25116332
1.70280000 1.61773312 1.25438905
1.70720000 1.62196554 1.25767060
1.71160000 1.63306982 1.26628016
1.71600000 1.62883647 1.26299788
1.72040000 1.62422994 1.25942627
1.72480000 1.62843221 1.26268445
1.72920000 1.63264634 1.26595182
1.73360000 1.63305347 1.26626748
1.73800000 1.64096244 1.27239959
1.74240000 1.64813594 1.27796147
1.74680000 1.65336483 1.28201562
1.75120000 1.65385674 1.28239702
1.75560000 1.65824071 1.28579607
1.76000000 1.66273708 1.28928227
1.76440000 1.66969353 1.29467586
1.76880000 1.67485827 1.29868027
1.77320000 1.67494473 1.29874731
1.77760000 1.67956593 1.30233029
1.78200000 1.68722076 1.30826536
1.78640000 1.68126184 1.30364519
1.79080000 1.68799658 1.30886689
1.79520000 1.69243590 1.31230885
1.79960000 1.70053685 1.31858982
1.80400000 1.70432911 1.32153010
1.80840000 1.70616853 1.32295627
1.81280000 1.70439458 1.32158086
1.81720000 1.71682330 1.33121729
1.82160000 1.71925263 1.33310085
1.82600000 1.71899444 1.33290066
1.83040000 1.72789792 1.33980386
1.83480000 1.73406317 1.34458400
1.83920000 1.73433175 1.34479224
1.84360000 1.73723532 1.34704348
1.84800000 1.74552738 1.35347262
1.85240000 1.74798798 1.35538042
1.85680000 1.75494011 1.36077065
1.86120000 1.76842641 1.37122708
1.86560000 1.77081562 1.37307952
1.87000000 1.77443445 1.37588533
1.87440000 1.78328701 1.38274904
1.87880000 1.78159167 1.38143458
1.88320000 1.78773268 1.38619594
1.88760000 1.78658932 1.38530945
1.89200000 1.79600248 1.39260781
1.89640000 1.80208693 1.39732531
1.90080000 1.80125841 1.39668293
1.90520000 1.80678492 1.40096784
1.90960000 1.81306708 1.40583862
1.91400000 1.81715549 1.40900852
1.91840000 1.82100175 1.41199067
1.92280000 1.82581032 1.41571892
1.92720000 1.82794337 1.41737275
1.93160000 1.83400125 1.42206965
1.93600000 1.83857659 1.42561708
1.94040000 1.82895790 1.41815936
1.94480000 1.83235428 1.42079269
1.94920000 1.83729863 1.42462623
1.95360000 1.84242826 1.42860342
1.95800000 1.84851959 1.43332625
1.96240000 1.84880911 1.43355073
1.96680000 1.85293021 1.43674597
1.97120000 1.85833597 1.44093725
1.97560000 1.86178033 1.44360779
1.98000000 1.87094186 1.45071106
1.98440000 1.86834504 1.44869765
1.98880000 1.87668220 1.45516176
1.99320000 1.88370356 1.46060567
1.99760000 1.88359952 1.46052501
2.00200000 1.88689801 1.46308245
2.00640000 1.89332619 1.46806645
2.01080000 1.89484204 1.46924175
2.01520000 1.90257181 1.47523492
2.01960000 1.89838172 1.47198619
2.02400000 1.90718237 1.47880965
2.02840000 1.91272324 1.48310569
2.03280000 1.91344007 1.48366148
2.03720000 1.91451303 1.48449339
2.04160000 1.91925105 1.48816694
2.04600000 1.93059284 1.49696065
2.05040000 1.93276223 1.49864266
2.05480000 1.94092918 1.50497479
2.05920000 1.93551077 1.50077370
2.06360000 1.94120427 1.50518808
2.06800000 1.94543426 1.50846775
2.07240000 1.94798951 1.51044893
2.07680000 1.95417678 1.51524614
2.08120000 1.95931335 1.51922871
2.08560000 1.96987137 1.52741473
2.09000000 1.97018504 1.52765793
2.09440000 1.97634994 1.53243780
2.09880000 1.97726646 1.53314841
2.10320000 1.98019016 1.53541527
2.10760000 1.98034459 1.53553501
2.11200000 1.98496852 1.53912011
2.11640000 1.98924363 1.54243476
2.12080000 1.99305738 1.54539170
2.12520000 1.99751740 1.54884971
2.12960000 2.00150827 1.55194398
2.13400000 2.00564911 1.55515452
2.13840000 2.00978996 1.55836508
2.14280000 2.01372843 1.56141872
2.14720000 2.01794728 1.56468975
2.15160000 2.02336039 1.56888673
2.15600000 2.02591837 1.57087002
2.16040000 2.02980102 1.57388039
2.16480000 2.03399109 1.57712910
2.16920000 2.03935483 1.58128780
2.17360000 2.04216629 1.58346764
2.17800000 2.04632071 1.58668871
2.18240000 2.05025314 1.58973766
2.18680000 2.05434807 1.59291262
2.19120000 2.05836744 1.59602898
2.19560000 2.06279932 1.59946517
2.20000000 2.06720148 1.60287833
2.20440000 2.07083363 1.60569447
2.20880000 2.07515182 1.60904252
2.21320000 2.07887633 1.61193027
2.21760000 2.08253431 1.61476644
2.22200000 2.08437129 1.61619071
2.22640000 2.09158500 1.62178377
2.23080000 2.09232226 1.62235540
2.23520000 2.09687189 1.62588289
2.23960000 2.10088137 1.62899158
2.24400000 2.10477849 1.63201316
2.24840000 2.11064161 1.63655906
2.25280000 2.11257024 1.63805440
2.25720000 2.11725214 1.64168444
2.26160000 2.12066920 1.64433381
2.26600000 2.12423824 1.64710102
2.27040000 2.13038926 1.65187013
2.27480000 2.13421329 1.65483504
2.27920000 2.13666483 1.65673581
2.28360000 2.14088816 1.66001031
2.28800000 2.14528202 1.66341703
2.29240000 2.14924784 1.66649188
2.29680000 2.15195854 1.66859359
2.30120000 2.14982967 1.66694300
2.30560000 2.15712841 1.67260198
2.31000000 2.15422526 1.67035105
2.31440000 2.15864788 1.67378007
2.31880000 2.16109911 1.67568060
2.32320000 2.16624853 1.67967314
2.32760000 2.17008454 1.68264734
2.33200000 2.17441955 1.68600843
2.33640000 2.18019237 1.69048431
2.34080000 2.18232215 1.69213560
2.34520000 2.18639145 1.69529068
2.34960000 2.19051464 1.69848754
2.35400000 2.19454891 1.70161545
2.35840000 2.19648018 1.70311284
2.36280000 2.20022278 1.70601461
2.36720000 2.20437806 1.70923636
2.37160000 2.21966567 1.72108940
2.37600000 2.22118925 1.72227069
2.38040000 2.22998886 1.72909335
2.38480000 2.23160097 1.73034328
2.38920000 2.23344367 1.73177199
2.39360000 2.23739835 1.73483820
2.39800000 2.24388612 1.73986840
2.40240000 2.24556138 1.74116729
2.40680000 2.24968050 1.74436100
2.41120000 2.25352852 1.74734451
2.41560000 2.25740477 1.75034991
2.42000000 2.26229556 1.75414192
2.42440000 2.26616160 1.75713940
2.42880000 2.26969539 1.75987927
2.43320000 2.27789745 1.76623863
2.43760000 2.27740986 1.76586058
2.44200000 2.28102854 1.76866628
2.44640000 2.28629278 1.77274784
2.45080000 2.29231489 1.77741701
2.45520000 2.28494974 1.77170653
2.45960000 2.29721639 1.78121732
2.46400000 2.30137370 1.78444063
2.46840000 2.30576571 1.78784591
2.47280000 2.28605142 1.77256070
2.47720000 2.30663474 1.78851971
2.48160000 2.30929801 1.79058464
2.48600000 2.30459357 1.78693711
2.49040000 2.31943626 1.79844519
2.49480000 2.32125708 1.79985694
2.49920000 2.32492188 1.80269839
2.50360000 2.32007616 1.79894133
2.50800000 2.34069851 1.81493059
2.51240000 2.34543502 1.81860298
2.51680000 2.34992896 1.82208730
2.52120000 2.33616736 1.81141743
2.52560000 2.34872515 1.82115395
2.53000000 2.35273134 1.82426009
2.53440000 2.35682159 1.82743141
2.53880000 2.36272512 1.83200863
2.54320000 2.36525481 1.83396999
2.54760000 2.36793536 1.83604832
2.55200000 2.37313395 1.84007898
2.55640000 2.37687460 1.84297925
2.56080000 2.38099470 1.84617371
2.56520000 2.37550980 1.84192106
2.56960000 2.38834608 1.85187350
2.57400000 2.39369402 1.85601995
2.57840000 2.39649255 1.85818976
2.58280000 2.39989878 1.86083074
2.58720000 2.40424013 1.86419674
2.59160000 2.39892728 1.86007749
2.59600000 2.40199483 1.86245588
2.60040000 2.41704612 1.87412569
2.60480000 2.41943351 1.87597672
2.60920000 2.41448744 1.87214186
2.61360000 2.42800848 1.88262521
2.61800000 2.43195905 1.88568824
2.62240000 2.42521841 1.88046197
2.62680000 2.44082538 1.89256262
2.63120000 2.44492553 1.89574162
2.63560000 2.43817640 1.89050878
2.64000000 2.44184332 1.89335187
2.64440000 2.45734861 1.90537369
2.64880000 2.46119700 1.90835749
2.65320000 2.45418634 1.90292187
2.65760000 2.45894682 1.90661284
2.66200000 2.46055188 1.90785730
2.66640000 2.46564648 1.91180733
2.67080000 2.46954100 1.91482690
2.67520000 2.47305775 1.91755356
2.67960000 2.47619182 1.91998352
2.68400000 2.47841779 1.92170940
2.68840000 2.48524551 1.92700317
2.69280000 2.47981069 1.92278937
2.69720000 2.49124219 1.93165263
2.70160000 2.49485147 1.93445103
2.70600000 2.49977768 1.93827050
2.71040000 2.52491898 1.95776347
2.71480000 2.50739385 1.94417560
2.71920000 2.50768479 1.94440117
2.72360000 2.51319674 1.94867479
2.72800000 2.51586206 1.95074131
2.73240000 2.52115660 1.95484636
2.73680000 2.52576721 1.95842113
2.74120000 2.52933450 1.96118698
2.74560000 2.53073937 1.96227623
2.75000000 2.53691286 1.96706277
2.75440000 2.54117861 1.97037016
2.75880000 2.54476284 1.97314915
2.76320000 2.55079610 1.97782695
2.76760000 2.55312340 1.97963139
2.77200000 2.55655682 1.98229345
2.77640000 2.56049941 1.98535028
2.78080000 2.56480481 1.98868842
2.78520000 2.56838011 1.99146048
2.78960000 2.57272770 1.99483132
2.79400000 2.57611411 1.99745694
2.79840000 2.58026532 2.00067552
2.80280000 2.58460816 2.00404268
2.80720000 2.58086493 2.00114042
2.81160000 2.60288555 2.01821381
2.81600000 2.59434673 2.01159335
2.82040000 2.59189327 2.00969109
2.82480000 2.59530607 2.01233716
2.82920000 2.60823411 2.02236074
2.83360000 2.60301699 2.01831572
2.83800000 2.60679152 2.02124225
2.84240000 2.61878411 2.03054055
2.84680000 2.61593151 2.02832882
2.85120000 2.62701007 2.03691844
2.85560000 2.63033047 2.03949286
2.86000000 2.62706809 2.03696342
2.86440000 2.63708949 2.04473337
2.86880000 2.63950225 2.04660408
2.87320000 2.64334294 2.04958191
2.87760000 2.64710695 2.05250028
2.88200000 2.65485992 2.05851144
2.88640000 2.65839196 2.06124996
2.89080000 2.65893147 2.06166827
2.89520000 2.66705323 2.06796536
2.89960000 2.66362734 2.06530915
2.90400000 2.67478686 2.07396153
2.90840000 2.67879378 2.07706824
2.91280000 2.67920148 2.07738435
2.91720000 2.68691666 2.08336621
2.92160000 2.68700531 2.08343494
2.92600000 2.69515199 2.08975136
2.93040000 2.68851698 2.08460700
2.93480000 2.70338878 2.09613764
2.93920000 2.70179423 2.09490133
2.94360000 2.70320459 2.09599483
2.94800000 2.69795022 2.09192093
2.95240000 2.69465521 2.08936618
2.95680000 2.70528317 2.09760644
2.96120000 2.70881689 2.10034626
2.96560000 2.70942279 2.10081603
2.97000000 2.71770125 2.10723463
2.97440000 2.71912192 2.10833612
2.97880000 2.72326548 2.11154878
2.98320000 2.72992778 2.11671430
2.98760000 2.72724686 2.11463568
2.99200000 2.73499982 2.12064684
2.99640000 2.73903240 2.12377345
3.00080000 2.74393888 2.12757762
3.00520000 2.74730348 2.13018632
3.00960000 2.75137561 2.13334359
3.01400000 2.74479264 2.12823958
3.01840000 2.75958734 2.13971045
3.02280000 2.75692600 2.13764701
3.02720000 2.76431168 2.14337340
3.03160000 2.76513605 2.14401256
3.03600000 2.76525043 2.14410125
3.04040000 2.77280403 2.14995783
3.04480000 2.78363303 2.15835395
3.04920000 2.78753022 2.16137559
3.05360000 2.78132412 2.15656377
3.05800000 2.79564220 2.16766510
3.06240000 2.79951895 2.17067089
3.06680000 2.80374037 2.17394391
3.07120000 2.80782889 2.17711389
3.07560000 2.80152101 2.17222315
3.08000000 2.81557507 2.18311978
3.08440000 2.81964660 2.18627659
3.08880000 2.82394866 2.18961213
3.09320000 2.82358997 2.18933403
3.09760000 2.82560373 2.19089537
3.10200000 2.83592695 2.19889934
3.10640000 2.83965679 2.20179122
3.11080000 2.84381154 2.20501255
3.11520000 2.83753646 2.20014726
3.11960000 2.85032007 2.21005886
3.12400000 2.84328395 2.20460349
3.12840000 2.85816213 2.21613909
3.13280000 2.85959331 2.21724873
3.13720000 2.86771682 2.22354719
3.14160000 2.87172553 2.22665529
3.14600000 2.87583797 2.22984382
3.15040000 2.87386479 2.22831394
3.15480000 2.88380545 2.23602130
3.15920000 2.88162818 2.23433318
3.16360000 2.85618489 2.21460606
3.16800000 2.86297804 2.21987304
3.17240000 2.87107769 2.22615300
3.17680000 2.87093219 2.22604019
3.18120000 2.87649748 2.23035516
3.18560000 2.88109703 2.23392136
3.19000000 2.88086782 2.23374365
3.19440000 2.88629764 2.23795358
3.19880000 2.89084536 2.24147960
3.20320000 2.88991734 2.24076007
3.20760000 2.90268226 2.25065718
3.21200000 2.90212064 2.25022173
3.21640000 2.90270424 2.25067422
3.22080000 2.90469843 2.25222039
3.22520000 2.91709535 2.26183217
3.22960000 2.91731770 2.26200457
3.23400000 2.92246750 2.26599740
3.23840000 2.92286599 2.26630636
3.24280000 2.92725837 2.26971193
3.24720000 2.92614092 2.26884554
3.25160000 2.93407023 2.27499342
3.25600000 2.94308495 2.28198286
3.26040000 2.94280192 2.28176342
3.26480000 2.94854824 2.28621875
3.26920000 2.94764354 2.28551730
3.27360000 2.95522656 2.29139670
3.27800000 2.96786973 2.30119941
3.28240000 2.96200378 2.29665133
3.28680000 2.96348296 2.29779818
3.29120000 2.97614585 2.30761619
3.29560000 2.97654899 2.30792876
3.29960000 2.97699508 2.30827463
3.29520000 2.97873858 2.30962643
3.29080000 2.97473938 2.30652570
3.28640000 2.96564373 2.29947351
3.28200000 2.95898998 2.29431462
3.27760000 2.95787690 2.29345161
3.27320000 2.95921009 2.29448527
3.26880000 2.94880364 2.28641677
3.26440000 2.95634978 2.29226757
3.26000000 2.94354740 2.28234142
3.25560000 2.93665548 2.27699786
3.25120000 2.93280724 2.27401418
3.24680000 2.92329055 2.26663554
3.24240000 2.93866569 2.27855645
3.23800000 2.92510865 2.26804518
3.23360000 2.91615960 2.26110665
3.22920000 2.91770732 2.26230665
3.22480000 2.91506502 2.26025799
3.22040000 2.90687954 2.25391148
3.21600000 2.91567002 2.26072707
3.21160000 2.90207748 2.25018827
3.20720000 2.90276592 2.25072205
3.20280000 2.89409515 2.24399928
3.19840000 2.88659395 2.23818332
3.19400000 2.88541782 2.23727142
3.18960000 2.88284381 2.23527570
3.18520000 2.87819629 2.23167231
3.18080000 2.87541742 2.22951775
3.17640000 2.87127931 2.22630932
3.17200000 2.87170976 2.22664307
3.16760000 2.86211345 2.21920269
3.16320000 2.86050525 2.21795580
3.15880000 2.86015683 2.21768565
3.15440000 2.85014659 2.20992435
3.15000000 2.84840296 2.20857245
3.14560000 2.84996769 2.20978564
3.14120000 2.84401496 2.20517027
3.13680000 2.83864750 2.20100868
3.13240000 2.83482214 2.19804274
3.12800000 2.82402425 2.18967074
3.12360000 2.82181512 2.18795792
3.11920000 2.81620339 2.18360694
3.11480000 2.81396074 2.18186813
3.11040000 2.81810646 2.18508246
3.10600000 2.80575638 2.17550699
3.10160000 2.81224228 2.18053575
3.09720000 2.79450354 2.16678225
3.09280000 2.79830127 2.16972677
3.08840000 2.78697581 2.16094573
3.08400000 2.78562173 2.15989586
3.07960000 2.78418173 2.15877938
3.07520000 2.77871997 2.15454468
3.07080000 2.78420372 2.15879643
3.06640000 2.77447780 2.15125557
3.06200000 2.76265745 2.14209081
3.05760000 2.76342137 2.14268311
3.05320000 2.76146667 2.14116756
3.04880000 2.76209945 2.14165818
3.04440000 2.75364973 2.13510680
3.04000000 2.75496213 2.13612435
3.03560000 2.75574214 2.13672912
3.03120000 2.74665457 2.12968320
3.02680000 2.73095806 2.11751312
3.02240000 2.72663836 2.11416390
3.01800000 2.73353697 2.11951264
3.01360000 2.72558010 2.11334338
3.00920000 2.72237508 2.11085842
3.00480000 2.72287041 2.11124247
3.00040000 2.71881372 2.10809717
2.99600000 2.71608199 2.10597916
2.99160000 2.71559417 2.10560093
2.98720000 2.71200749 2.10282004
2.98280000 2.69866322 2.09247374
2.97840000 2.69170477 2.08707861
2.97400000 2.68914272 2.08509215
2.96960000 2.68524024 2.08206642
2.96520000 2.68446975 2.08146903
2.96080000 2.68752121 2.08383493
2.95640000 2.67425009 2.07354535
2.95200000 2.67279929 2.07242049
2.94760000 2.67519183 2.07427552
2.94320000 2.67089235 2.07094197
2.93880000 2.65363405 2.05756098
2.93440000 2.65980140 2.06234275
2.93000000 2.66657909 2.06759774
2.92560000 2.66234643 2.06431601
2.92120000 2.65404204 2.05787731
2.91680000 2.65614313 2.05950636
2.91240000 2.63677574 2.04449011
2.90800000 2.63900673 2.04621988
2.90360000 2.62767687 2.03743542
2.89920000 2.63645745 2.04424333
2.89480000 2.62544804 2.03570734
2.89040000 2.63030582 2.03947375
2.88600000 2.62078771 2.03209401
2.88160000 2.61673511 2.02895188
2.87720000 2.61280382 2.02590380
2.87280000 2.61558035 2.02805656
2.86840000 2.61121781 2.02467412
2.86400000 2.60042558 2.01630651
2.85960000 2.60395634 2.01904403
2.85520000 2.59183902 2.00964903
2.85080000 2.59454660 2.01174831
2.84640000 2.58074672 2.00104876
2.84200000 2.58112732 2.00134386
2.83760000 2.57672340 1.99792934
2.83320000 2.57141310 1.99381206
2.82880000 2.56861205 1.99164031
2.82440000 2.57036929 1.99300276
2.82000000 2.56080135 1.98558439
2.81560000 2.56275802 1.98710147
2.81120000 2.55856047 1.98384695
2.80680000 2.54803089 1.97568298
2.80240000 2.55143038 1.97831873
2.79800000 2.53707325 1.96718712
2.79360000 2.53641032 1.96667313
2.78920000 2.53863333 1.96839671
2.78480000 2.52784117 1.96002916
2.78040000 2.52305551 1.95631866
2.77600000 2.52675571 1.95918756
2.77160000 2.51602663 1.95086891
2.76720000 2.51872616 1.95296195
2.76280000 2.51077368 1.94679610
2.75840000 2.50671579 1.94364987
2.75400000 2.49645723 1.93569604
2.74960000 2.49553700 1.93498255
2.74520000 2.49123075 1.93164375
2.74080000 2.49374999 1.93359701
2.73640000 2.48361668 1.92574028
2.73200000 2.50264528 1.94049385
2.72760000 2.47856400 1.92182276
2.72320000 2.46754060 1.91327592
2.71880000 2.47477693 1.91888650
2.71440000 2.46379936 1.91037520
2.71000000 2.46522163 1.91147793
2.70560000 2.46668226 1.91261041
2.70120000 2.46216565 1.90910851
2.69680000 2.45400592 1.90278198
2.69240000 2.44508472 1.89586505
2.68800000 2.43898000 1.89113183
2.68360000 2.44190250 1.89339776
2.67920000 2.43015007 1.88428566
2.67480000 2.42597264 1.88104675
2.67040000 2.42887076 1.88329377
2.66600000 2.41808768 1.87493326
2.66160000 2.41830135 1.87509892
2.65720000 2.41085343 1.86932427
2.65280000 2.40318854 1.86338140
2.64840000 2.41083530 1.86931021
2.64400000 2.39985964 1.86080039
2.63960000 2.40149995 1.86207218
2.63520000 2.39161141 1.85440523
2.63080000 2.39685612 1.85847165
2.62640000 2.39126376 1.85413569
2.62200000 2.40064420 1.86140869
2.61760000 2.38037387 1.84569236
2.61320000 2.38018567 1.84554644
2.60880000 2.38764037 1.85132634
2.60440000 2.38450862 1.84889818
2.60000000 2.36099095 1.83066406
2.59560000 2.36762397 1.83580689
2.59120000 2.37307485 1.84003316
2.58680000 2.36716542 1.83545136
2.58240000 2.35416474 1.82537145
2.57800000 2.34977556 1.82196837
2.57360000 2.34617316 1.81917529
2.56920000 2.34178334 1.81577170
2.56480000 2.33652488 1.81169462
2.56040000 2.34328674 1.81693735
2.55600000 2.33920280 1.81377092
2.55160000 2.31621954 1.79595115
2.54720000 2.32539940 1.80306864
2.54280000 2.32113274 1.79976054
2.53840000 2.31677671 1.79638315
2.53400000 2.31908858 1.79817563
2.52960000 2.31618844 1.79592704
2.52520000 2.31442586 1.79456045
2.52080000 2.30731689 1.78904860
2.51640000 2.30312014 1.78579471
2.51200000 2.30034250 1.78364110
2.50760000 2.29516229 1.77962469
2.50320000 2.28566061 1.77225770
2.49880000 2.28821794 1.77424049
2.49440000 2.28419176 1.77111885
2.49000000 2.28180096 1.76926517
2.48560000 2.27425903 1.76341764
2.48120000 2.27202101 1.76168241
2.47680000 2.27099201 1.76088459
2.47240000 2.25590504 1.74918711
2.46800000 2.26130215 1.75337169
2.46360000 2.25568882 1.74901947
2.45920000 2.25309419 1.74700776
2.45480000 2.24866301 1.74357210
2.45040000 2.24454886 1.74038225
2.44600000 2.24063465 1.73734742
2.44160000 2.23594111 1.73370835
2.43720000 2.23246890 1.73101622
2.43280000 2.22723754 1.72696015
2.42840000 2.22410866 1.72453422
2.42400000 2.21880326 1.72042074
2.41960000 2.21573356 1.71804069
2.41520000 2.21209762 1.71522162
2.41080000 2.20614311 1.71060487
2.40640000 2.20370839 1.70871714
2.40200000 2.19998723 1.70583199
2.39760000 2.19528447 1.70218576
2.39320000 2.19110952 1.69894877
2.38880000 2.18722484 1.69593683
2.38440000 2.18383745 1.69331047
2.38000000 2.17948052 1.68993238
2.37560000 2.17480843 1.68630994
2.37120000 2.17092812 1.68330139
2.36680000 2.16684708 1.68013722
2.36240000 2.16236638 1.67666317
2.35800000 2.15875596 1.67386388
2.35360000 2.15479583 1.67079344
2.34920000 2.15016121 1.66720005
2.34480000 2.14656961 1.66441535
2.34040000 2.14345408 1.66199976
2.33600000 2.13808666 1.65783821
2.33160000 2.13391197 1.65460142
2.32720000 2.13012944 1.65166868
2.32280000 2.12598904 1.64845848
2.31840000 2.12189787 1.64528644
2.31400000 2.11757499 1.64193476
2.30960000 2.11441508 1.63948476
2.30520000 2.10933752 1.63554795
2.30080000 2.10506054 1.63223185
2.29640000 2.10116271 1.62920972
2.29200000 2.09814045 1.62686645
2.28760000 2.09760095 1.62644815
2.28320000 2.08887163 1.61967999
2.27880000 2.08482194 1.61654012
2.27440000 2.08212738 1.61445093
2.27000000 2.07680262 1.61032245
2.26560000 2.07294123 1.60732857
2.26120000 2.06923377 1.60445404
2.25680000 2.06455478 1.60082625
2.25240000 2.06073760 1.59786665
2.24800000 2.05648457 1.59456912
2.24360000 2.05303613 1.59189542
2.23920000 2.04791523 1.58792500
2.23480000 2.04485502 1.58555230
2.23040000 2.04004765 1.58182497
2.22600000 2.03732803 1.57971635
2.22160000 2.03329054 1.57658594
2.21720000 2.02815685 1.57260560
2.21280000 2.02365843 1.56911781
2.20840000 2.02107451 1.56711441
2.20400000 2.01578906 1.56301640
2.19960000 2.01257308 1.56052293
2.19520000 2.00818120 1.55711774
2.19080000 2.00466795 1.55439380
2.18640000 1.99930004 1.55023186
2.18200000 1.99504443 1.54693233
2.17760000 1.99467540 1.54664620
2.17320000 1.98797702 1.54145271
2.16880000 1.98425785 1.53856909
2.16440000 1.98022864 1.53544510
2.16000000 1.97585217 1.53205186
2.15560000 1.97195656 1.52903146
2.15120000 1.96801590 1.52597612
2.14680000 1.96329495 1.52231580
2.14240000 1.95969301 1.51952308
2.13800000 1.95343438 1.51467054
2.13360000 1.95108808 1.51285136
2.12920000 1.94675918 1.50949501
2.12480000 1.94111857 1.50512163
2.12040000 1.93732178 1.50217784
2.11600000 1.93457291 1.50004654
2.11160000 1.92897373 1.49570529
2.10720000 1.92640748 1.49371558
2.10280000 1.92228605 1.49052009
2.09840000 1.91687926 1.48632801
2.09400000 1.91354595 1.48374358
2.08960000 1.90925993 1.48042046
2.08520000 1.90507326 1.47717438
2.08080000 1.90149790 1.47440228
2.07640000 1.89702277 1.47093254
2.07200000 1.89325632 1.46801228
2.06760000 1.88906341 1.46476136
2.06320000 1.88491015 1.46154119
2.05880000 1.88041922 1.45805920
2.05440000 1.87676595 1.45522669
2.05000000 1.87217933 1.45167052
2.04560000 1.87087800 1.45066154
2.04120000 1.86696151 1.44762495
2.03680000 1.86016514 1.44235548
2.03240000 1.85566807 1.43886873
2.02800000 1.85148260 1.43562359
2.02360000 1.84772691 1.43271166
2.01920000 1.84243763 1.42861069
2.01480000 1.83940891 1.42626241
2.01040000 1.83525475 1.42304153
2.00600000 1.82947512 1.41856038
2.00160000 1.82678230 1.41647253
1.99720000 1.82147450 1.41235721
1.99280000 1.81873570 1.41023372
1.98840000 1.81464572 1.40706260
1.98400000 1.80868691 1.40244252
1.97960000 1.80444663 1.39915488
1.97520000 1.80066320 1.39622144
1.97080000 1.79715824 1.39350392
1.96640000 1.79196353 1.38947627
1.96200000 1.78803030 1.38642669
1.95760000 1.78447036 1.38366654
1.95320000 1.78122189 1.38114788
1.94880000 1.77762092 1.37835592
1.94440000 1.77122980 1.37340065
1.94000000 1.76876556 1.37149003
1.93560000 1.76748325 1.37049581
1.93120000 1.76342286 1.36734764
1.92680000 1.75686827 1.36226563
1.92240000 1.75258938 1.35894805
1.91800000 1.74951683 1.35656579
1.91360000 1.74584756 1.35372087
1.90920000 1.74025352 1.34938360
1.90480000 1.73803236 1.34766146
1.90040000 1.72971275 1.34121096
1.89600000 1.73081875 1.34206848
1.89160000 1.72514004 1.33766557
1.88720000 1.72333086 1.33626284
1.88280000 1.72869080 1.34041860
1.87840000 1.72419715 1.33693451
1.87400000 1.72213036 1.33533205
1.86960000 1.71369385 1.32879092
1.86520000 1.71192874 1.32742236
1.86080000 1.70752027 1.32400432
1.85640000 1.70681438 1.32345701
1.85200000 1.68833974 1.30913295
1.84760000 1.68619680 1.30747145
1.84320000 1.68082583 1.30330714
1.83880000 1.68848617 1.30924648
1.83440000 1.68398324 1.30575520
1.83000000 1.68048550 1.30304327
1.82560000 1.67542070 1.29911634
1.82120000 1.66973264 1.29470618
1.81680000 1.66667641 1.29233658
1.81240000 1.66329370 1.28971384
1.80800000 1.65977902 1.28698878
1.80360000 1.65523171 1.28346308
1.79920000 1.65108884 1.28025096
1.79480000 1.64654444 1.27672752
1.79040000 1.64012188 1.27174788
1.78600000 1.64132708 1.27268231
1.78160000 1.63411436 1.26709003
1.77720000 1.62992538 1.26384215
1.77280000 1.62708362 1.26163884
1.76840000 1.62129051 1.25714723
1.76400000 1.61776322 1.25441239
1.75960000 1.61307234 1.25077538
1.75520000 1.61025166 1.24858840
1.75080000 1.60453009 1.24415226
1.74640000 1.60052819 1.24104944
1.74200000 1.59619947 1.23769323
1.73760000 1.59150935 1.23405681
1.73320000 1.58783467 1.23120769
1.72880000 1.58296065 1.22742868
1.72440000 1.56701489 1.21506535
1.72000000 1.56758597 1.21550813
1.71560000 1.56274499 1.21175474
1.71120000 1.56670571 1.21482563
1.70680000 1.56240742 1.21149301
1.70240000 1.55582331 1.20638811
1.69800000 1.55423756 1.20515862
1.69360000 1.54949139 1.20147874
1.68920000 1.54553752 1.19841316
1.68480000 1.54108094 1.19495781
1.68040000 1.53708562 1.19186009
1.67600000 1.53659811 1.19148210
1.67160000 1.53243167 1.18825171
1.66720000 1.52435324 1.18198821
1.66280000 1.52162509 1.17987297
1.65840000 1.51591998 1.17544959
1.65400000 1.51178355 1.17224247
1.64960000 1.50761877 1.16901336
1.64520000 1.50121899 1.16405138
1.64080000 1.49891062 1.16226162
1.63640000 1.49497387 1.15920931
1.63200000 1.49083529 1.15600051
1.62760000 1.51542311 1.17506435
1.62320000 1.51128088 1.17185273
1.61880000 1.50703359 1.16855965
1.61440000 1.50264807 1.16515939
1.61000000 1.49980336 1.16295379
1.60560000 1.49564923 1.15973294
1.60120000 1.49101973 1.15614352
1.59680000 1.48675579 1.15283753
1.59240000 1.48135813 1.14865253
1.58800000 1.47693087 1.14521991
1.58360000 1.47289916 1.14209398
1.57920000 1.46864902 1.13879869
1.57480000 1.46433568 1.13545439
1.57040000 1.45969435 1.13185580
1.56600000 1.45560280 1.12868348
1.56160000 1.45150993 1.12551012
1.55720000 1.44724393 1.12220254
1.55280000 1.44446418 1.12004730
1.54840000 1.43851882 1.11543764
1.54400000 1.43419158 1.11208257
1.53960000 1.43087988 1.10951489
1.53520000 1.42563658 1.10544957
1.53080000 1.42158616 1.10230913
1.52640000 1.41708309 1.09881774
1.52200000 1.41290941 1.09558173
1.51760000 1.40847950 1.09214706
1.51320000 1.40418278 1.08881565
1.50880000 1.39990010 1.08549514
1.50440000 1.39563361 1.08218717
1.50000000 1.39125011 1.07878848
1.49560000 1.38706910 1.07554679
1.49120000 1.38246692 1.07197855
1.48680000 1.38015302 1.07018450
1.48240000 1.37393501 1.06536344
1.47800000 1.37118537 1.06323155
1.47360000 1.36670424 1.05975717
1.46920000 1.36321482 1.05705169
1.46480000 1.35958989 1.05424115
1.46040000 1.35265764 1.04886632
1.45600000 1.35081153 1.04743496
1.45160000 1.34420747 1.04231459
1.44720000 1.33981276 1.03890722
1.44280000 1.33610118 1.03602949
1.43840000 1.33139274 1.03237887
1.43400000 1.32725687 1.02917218
1.42960000 1.32414302 1.02675790
1.42520000 1.32093975 1.02427428
1.42080000 1.31552081 1.02007278
1.41640000 1.31404517 1.01892866
1.41200000 1.30642921 1.01302373
1.40760000 1.30569321 1.01245308
1.40320000 1.30050706 1.00843207
1.39880000 1.29707151 1.00576836
1.39440000 1.29181064 1.00168942
1.39000000 1.28759765 0.99842293
1.38560000 1.28169817 0.99384884
1.38120000 1.27787098 0.99088148
1.37680000 1.27545668 0.98900959
1.37240000 1.26670433 0.98222357
1.36800000 1.26590904 0.98160696
1.36360000 1.25884476 0.97612977
1.35920000 1.25737671 0.97499153
1.35480000 1.25509124 0.97321952
1.35040000 1.24289821 0.96376582
1.34600000 1.24110079 0.96237221
1.34160000 1.24071772 0.96207520
1.33720000 1.23246306 0.95567506
1.33280000 1.23207366 0.95537315
1.32840000 1.22504154 0.94992089
1.32400000 1.22477020 0.94971051
1.31960000 1.22004834 0.94604947
1.31520000 1.21555518 0.94256577
1.31080000 1.21032357 0.93850950
1.30640000 1.20591007 0.93508756
1.30200000 1.20199653 0.93205325
1.29760000 1.19809105 0.92902519
1.29320000 1.19151285 0.92392486
1.28880000 1.19481383 0.92648424
1.28440000 1.18564496 0.91937528
1.28000000 1.18213758 0.91665588
1.27560000 1.17677335 0.91249680
1.27120000 1.17539502 0.91142812
1.26680000 1.16857997 0.90614417
1.26240000 1.16347037 0.90218250
1.25800000 1.15937922 0.89901048
1.25360000 1.15540590 0.89592983
1.24920000 1.15374979 0.89464578
1.24480000 1.14996595 0.89171204
1.24040000 1.14281230 0.88616555
1.23600000 1.14126612 0.88496674
1.23160000 1.13391052 0.87926367
1.22720000 1.13003920 0.87626209
1.22280000 1.12863253 0.87517145
1.21840000 1.12421407 0.87174566
1.21400000 1.11858264 0.86737940
1.20960000 1.11409452 0.86389960
1.20520000 1.11365496 0.86355880
1.20080000 1.10589444 0.85754178
1.19640000 1.10453171 0.85648521
1.19200000 1.09710593 0.85072772
1.18760000 1.09605321 0.84991151
1.18320000 1.08750771 0.84328587
1.17880000 1.08641492 0.84243859
1.17440000 1.07993539 0.83741478
1.17000000 1.07553953 0.83400650
1.16560000 1.07448960 0.83319246
1.16120000 1.07013154 0.82981350
1.15680000 1.06534143 0.82609955
1.15240000 1.06089315 0.82265063
1.14800000 1.05737598 0.81992364
1.14360000 1.05237112 0.81604319
1.13920000 1.04552056 0.81073170
1.13480000 1.04461488 0.81002949
1.13040000 1.03639067 0.80365296
1.12600000 1.03594182 0.80330495
1.12160000 1.02834246 0.79741289
1.11720000 1.02682442 0.79623590
1.11280000 1.02309288 0.79334270
1.10840000 1.01890837 0.79009829
1.10400000 1.01531332 0.78731091
1.09960000 1.01013227 0.78329386
1.09520000 1.00788601 0.78155225
1.09080000 1.00353178 0.77817626
1.08640000 0.99925185 0.77485787
1.08200000 0.99519959 0.77171600
1.07760000 0.99081806 0.76831885
1.07320000 0.98633753 0.76484493
1.06880000 0.98240801 0.76179822
1.06440000 0.97779401 0.75822083
1.06000000 0.97376390 0.75509613
1.05560000 0.96767955 0.75037871
1.05120000 0.96381033 0.74737877
1.04680000 0.96605196 0.74911678
1.04240000 0.96221851 0.74614457
1.03800000 0.95760482 0.74256741
1.03360000 0.95320906 0.73915921
1.02920000 0.94894843 0.73585579
1.02480000 0.94471696 0.73257498
1.02040000 0.93373888 0.72406327
1.01600000 0.92963965 0.72088498
1.01160000 0.92543285 0.71762330
1.00720000 0.92113104 0.71428795
1.00280000 0.91696660 0.71105910
0.99840000 0.91263889 0.70770367
0.99400000 0.90801014 0.70411483
0.98960000 0.91032576 0.70591021
0.98520000 0.90527017 0.70199044
0.98080000 0.90109857 0.69875604
0.97640000 0.89654763 0.69522753
0.97200000 0.89241047 0.69201984
0.96760000 0.89183876 0.69157657
0.96320000 0.88479521 0.68611545
0.95880000 0.87969916 0.68216429
0.95440000 0.87517612 0.67865742
0.95000000 0.87120127 0.67557557
0.94560000 0.86672380 0.67210402
0.94120000 0.86324318 0.66940537
0.93680000 0.85893046 0.66606156
0.93240000 0.85475292 0.66282256
0.92800000 0.85031738 0.65938353
0.92360000 0.84754840 0.65723663
0.91920000 0.84423446 0.65466721
0.91480000 0.83882991 0.65047687
0.91040000 0.83451711 0.64713299
0.90600000 0.83588104 0.64819050
0.90160000 0.82599070 0.64052215
0.89720000 0.82444800 0.63932604
0.89280000 0.81594459 0.63273304
0.88840000 0.81176001 0.62948858
0.88400000 0.80788518 0.62648428
0.87960000 0.80345515 0.62304952
0.87520000 0.79907161 0.61965080
0.87080000 0.79484930 0.61637709
0.86640000 0.78906687 0.61189376
0.86200000 0.77884485 0.60396825
0.85760000 0.77471093 0.60076308
0.85320000 0.77016595 0.59723918
0.84880000 0.77301659 0.59944939
0.84440000 0.76892828 0.59627957
0.84000000 0.76429471 0.59268699
0.83560000 0.76484728 0.59311543
0.83120000 0.75573457 0.58605001
0.82680000 0.76267772 0.59143328
0.82240000 0.74769027 0.57981296
0.81800000 0.74669805 0.57904366
0.81360000 0.74385938 0.57684274
0.80920000 0.74538208 0.57802334
0.80480000 0.73162560 0.56735744
0.80040000 0.73112167 0.56696672
0.79600000 0.72178017 0.55972392
0.79160000 0.72496149 0.56219051
0.78720000 0.71803237 0.55681811
0.78280000 0.71391006 0.55362193
0.77840000 0.71503801 0.55449648
0.77400000 0.69904708 0.54209812
0.76960000 0.69824896 0.54147931
0.76520000 0.69749853 0.54089747
0.76080000 0.68750970 0.53315277
0.75640000 0.69336578 0.53769320
0.75200000 0.68802491 0.53355223
0.74760000 0.67866551 0.52629554
0.74320000 0.67397688 0.52266028
0.73880000 0.66962896 0.51928918
0.73440000 0.66421557 0.51509198
0.73000000 0.66329566 0.51437873
0.72560000 0.66530797 0.51593896
0.72120000 0.65168500 0.50537656
0.71680000 0.66140764 0.51291489
0.71240000 0.65818112 0.51041325
0.70800000 0.64937684 0.50358696
0.70360000 0.64285795 0.49853263
0.69920000 0.64239245 0.49817171
0.69480000 0.63800280 0.49476826
0.69040000 0.62983540 0.48843577
0.68600000 0.62946606 0.48814940
0.68160000 0.62104832 0.48162282
0.67720000 0.62814460 0.48712483
0.67280000 0.61673171 0.47827600
0.66840000 0.60817219 0.47163949
0.66400000 0.61150077 0.47422026
0.65960000 0.60234170 0.46711890
0.65520000 0.59928263 0.46474709
0.65080000 0.60018085 0.46544351
0.64640000 0.59116724 0.45845493
0.64200000 0.58866653 0.45651604
0.63760000 0.58394852 0.45285799
0.63320000 0.57980800 0.44964769
0.62880000 0.58060318 0.45026423
0.62440000 0.57130685 0.44305644
0.62000000 0.57388509 0.44505545
0.61560000 0.56224717 0.43603214
0.61120000 0.55703017 0.43198721
0.60680000 0.55685941 0.43185481
0.60240000 0.54608182 0.42349855
0.59800000 0.54936868 0.42604698
0.59360000 0.53429104 0.41435673
0.58920000 0.53790340 0.41715752
0.58480000 0.52626290 0.40813222
0.58040000 0.53459118 0.41458944
0.57600000 0.53207100 0.41263545
0.57160000 0.53485321 0.41479260
0.56720000 0.52357954 0.40605171
0.56280000 0.51459118 0.39908270
0.55840000 0.50851318 0.39437021
0.55400000 0.51043910 0.39586344
0.54960000 0.49951074 0.38739029
0.54520000 0.49928328 0.38721393
0.54080000 0.50492233 0.39158609
0.53640000 0.48979130 0.37985445
0.53200000 0.48522304 0.37631251
0.52760000 0.48565166 0.37664484
0.52320000 0.49112375 0.38088755
0.51880000 0.48284828 0.37447127
0.51440000 0.47121953 0.36545508
0.51000000 0.46162848 0.35801878
0.50560000 0.46605507 0.36145088
0.50120000 0.45792517 0.35514747
0.49680000 0.45343221 0.35166392
0.49240000 0.44895413 0.34819189
0.48800000 0.45626657 0.35386150
0.48360000 0.44758350 0.34712920
0.47920000 0.43938074 0.34076930
0.47480000 0.43540100 0.33768366
0.47040000 0.42732091 0.33141887
0.46600000 0.42289632 0.32798832
0.46160000 0.42990803 0.33342476
0.45720000 0.42559860 0.33008350
0.45280000 0.42100479 0.32652175
0.44840000 0.40838128 0.31673428
0.44400000 0.40849242 0.31682045
0.43960000 0.40564187 0.31461032
0.43520000 0.39550711 0.30675247
0.43080000 0.39138648 0.30355759
0.42640000 0.38276279 0.29687132
0.42200000 0.37872586 0.29374135
0.41760000 0.37496679 0.29082680
0.41320000 0.37049813 0.28736209
0.40880000 0.37018940 0.28712271
0.40440000 0.36940420 0.28651393
0.40000000 0.36550628 0.28349173
0.39560000 0.36468575 0.28285553
0.39120000 0.35641691 0.27644440
0.38680000 0.35537017 0.27563283
0.38240000 0.34706387 0.26919265
0.37800000 0.33807315 0.26222181
0.37360000 0.33002769 0.25598387
0.36920000 0.32592276 0.25280117
0.36480000 0.33384629 0.25894457
0.36040000 0.32923537 0.25536956
0.35600000 0.32558563 0.25253978
0.35160000 0.32049731 0.24859462
0.34720000 0.31204882 0.24204420
0.34280000 0.31203429 0.24203293
0.33840000 0.30734201 0.23839484
0.33400000 0.30309912 0.23510517
0.32960000 0.29599298 0.22959552
0.32520000 0.29507060 0.22888036
0.32080000 0.29014466 0.22506110
0.31640000 0.28728207 0.22284162
0.31200000 0.27837599 0.21593642
0.30760000 0.27734296 0.21513547
0.30320000 0.26966513 0.20918257
0.29880000 0.26822298 0.20806442
0.29440000 0.26423148 0.20496966
0.29000000 0.25972477 0.20147545
0.28560000 0.25214403 0.19559782
0.28120000 0.24805712 0.19242909
0.27680000 0.24664778 0.19133637
0.27240000 0.24196195 0.18770328
0.26800000 0.23455174 0.18195787
0.26360000 0.23363278 0.18124537
0.25920000 0.22885619 0.17754191
0.25480000 0.22157777 0.17189868
0.25040000 0.21703569 0.16837704
0.24600000 0.21331066 0.16548889
0.24160000 0.19913782 0.15450017
0.23720000 0.19478911 0.15112845
0.23280000 0.19522438 0.15146593
0.22840000 0.18860373 0.14633270
0.22400000 0.18593988 0.14426731
0.21960000 0.17693177 0.13728300
0.21520000 0.18636679 0.14459831
0.21080000 0.17143946 0.13302461
0.20640000 0.16375585 0.12706723
0.20200000 0.16875527 0.13094346
0.19760000 0.16672451 0.12936894
0.19320000 0.16116537 0.12505873
0.18880000 0.15854376 0.12302610
0.18440000 0.15367578 0.11925178
0.18000000 0.14700790 0.11408193
0.17560000 0.14557130 0.11296807
0.17120000 0.14341570 0.11129676
0.16680000 0.14226526 0.11040478
0.16240000 0.13467957 0.10452332
0.15800000 0.12791368 0.09927748
0.15360000 0.12518118 0.09715887
0.14920000 0.11826969 0.09180014
0.14480000 0.11473301 0.08905802
0.14040000 0.11071016 0.08593896
0.13600000 0.10293674 0.07991194
0.13160000 0.10167877 0.07893659
0.12720000 0.09677671 0.07513584
0.12280000 0.09211474 0.07152125
0.11840000 0.08739959 0.06786542
0.11400000 0.08410440 0.06531054
0.10960000 0.08008504 0.06219418
0.10520000 0.08038176 0.06242424
0.10080000 0.07632769 0.05928097
0.09640000 0.06697986 0.05203325
0.09200000 0.06116414 0.04752412
0.08760000 0.05820031 0.04522615
0.08320000 0.05340871 0.04151105
0.07880000 0.05072189 0.03942786
0.07440000 0.05018639 0.03901267
0.07000000 0.03939044 0.03064217
0.06560000 0.03750283 0.02917864
0.06120000 0.03734315 0.02905483
0.05680000 0.02972386 0.02314732
0.05240000 0.02276134 0.01774902
0.04800000 0.02088485 0.01629411
0.04360000 0.01387799 0.01086143
0.03920000 0.01225572 0.00960362
0.03480000 0.00725420 0.00572577
0.03040000 0.00621598 0.00492079
0.02600000 -0.00165589 -0.00118256
0.02160000 -0.00609760 -0.00462637
0.01720000 -0.01020948 -0.00781447
0.01280000 -0.01038433 -0.00795003
0.00840000 -0.01940235 -0.01494203
0.00400000 -0.02335085 -0.01800345
-0.00000000 -0.02975732 -0.02297062