File: plots/rawdata/FigureS5a.txt
# strain(%), strain_el(%), stress(GPa)
0.00000000 -0.00013066 0.00000001
0.00080000 0.00081320 0.00073182
0.00160000 0.00085832 0.00076680
0.00240000 0.00223782 0.00183638
0.00320000 0.00307467 0.00248522
0.00400000 0.00404272 0.00323579
0.00480000 0.00569457 0.00451653
0.00560000 0.00674172 0.00532842
0.00640000 0.00692773 0.00547264
0.00720000 0.00695487 0.00549368
0.00800000 0.00796747 0.00627879
0.00880000 0.00836301 0.00658547
0.00960000 0.00923937 0.00726494
0.01040000 0.01028149 0.00807294
0.01120000 0.01101322 0.00864027
0.01200000 0.01156393 0.00906726
0.01280000 0.01268975 0.00994015
0.01360000 0.01340799 0.01049702
0.01440000 0.01379685 0.01079852
0.01520000 0.01484180 0.01160871
0.01600000 0.01588231 0.01241545
0.01680000 0.01648163 0.01288013
0.01760000 0.01692284 0.01322221
0.01840000 0.01818289 0.01419918
0.01920000 0.01907045 0.01488734
0.02000000 0.01976091 0.01542268
0.02080000 0.02017606 0.01574456
0.02160000 0.02132073 0.01663206
0.02240000 0.02222743 0.01733506
0.02320000 0.02291181 0.01786568
0.02400000 0.02346779 0.01829675
0.02480000 0.02475198 0.01929244
0.02560000 0.02532986 0.01974049
0.02640000 0.02589510 0.02017874
0.02720000 0.02697940 0.02101944
0.02800000 0.02783384 0.02168192
0.02880000 0.02874798 0.02239068
0.02960000 0.03003617 0.02338946
0.03040000 0.03151921 0.02453931
0.03120000 0.03195180 0.02487472
0.03200000 0.03216338 0.02503877
0.03280000 0.03274451 0.02548933
0.03360000 0.03340322 0.02600006
0.03440000 0.03398419 0.02645051
0.03520000 0.03488064 0.02714556
0.03600000 0.03681162 0.02864272
0.03680000 0.03724820 0.02898121
0.03760000 0.03796261 0.02953512
0.03840000 0.03828558 0.02978553
0.03920000 0.03887864 0.03024535
0.04000000 0.03957936 0.03078864
0.04080000 0.04066826 0.03163291
0.04160000 0.04148236 0.03226411
0.04240000 0.04186566 0.03256130
0.04320000 0.04304893 0.03347873
0.04400000 0.04395349 0.03418007
0.04480000 0.04461628 0.03469395
0.04560000 0.04521319 0.03515676
0.04640000 0.04655172 0.03619457
0.04720000 0.04707258 0.03659841
0.04800000 0.04759032 0.03699984
0.04880000 0.04852161 0.03772190
0.04960000 0.04948246 0.03846688
0.05040000 0.05006428 0.03891799
0.05120000 0.05099291 0.03963799
0.05200000 0.05187188 0.04031948
0.05280000 0.05240194 0.04073046
0.05360000 0.05339758 0.04150242
0.05440000 0.05396793 0.04194463
0.05520000 0.05499610 0.04274181
0.05600000 0.05550543 0.04313671
0.05680000 0.05663808 0.04401490
0.05760000 0.05742883 0.04462799
0.05840000 0.05816299 0.04519721
0.05920000 0.05897009 0.04582299
0.06000000 0.05983235 0.04649153
0.06080000 0.06056080 0.04705633
0.06160000 0.06137777 0.04768975
0.06240000 0.06213825 0.04827938
0.06320000 0.06295978 0.04891634
0.06400000 0.06375041 0.04952935
0.06480000 0.06455980 0.05015689
0.06560000 0.06542308 0.05082622
0.06640000 0.06599919 0.05127290
0.06720000 0.06698401 0.05203648
0.06800000 0.06779865 0.05266810
0.06880000 0.06860959 0.05329685
0.06960000 0.06931486 0.05384367
0.07040000 0.07036461 0.05465757
0.07120000 0.07101194 0.05515947
0.07200000 0.07165091 0.05565489
0.07280000 0.07258203 0.05637682
0.07360000 0.07349171 0.05708214
0.07440000 0.07456221 0.05791213
0.07520000 0.07563624 0.05874487
0.07600000 0.07628312 0.05924641
0.07680000 0.07658709 0.05948209
0.07760000 0.07723177 0.05998194
0.07840000 0.07821006 0.06074044
0.07920000 0.07906036 0.06139971
0.08000000 0.08014200 0.06223835
0.08080000 0.08111180 0.06299027
0.08160000 0.08168688 0.06343615
0.08240000 0.08207411 0.06373638
0.08320000 0.08283849 0.06432904
0.08400000 0.08382722 0.06509563
0.08480000 0.08474476 0.06580703
0.08560000 0.08532236 0.06625487
0.08640000 0.08627162 0.06699087
0.08720000 0.08701274 0.06756548
0.08800000 0.08776139 0.06814594
0.08880000 0.08874945 0.06891202
0.08960000 0.08938931 0.06940813
0.09040000 0.09001007 0.06988942
0.09120000 0.09092112 0.07059579
0.09200000 0.09202638 0.07145274
0.09280000 0.09305618 0.07225118
0.09360000 0.09418025 0.07312272
0.09440000 0.09440489 0.07329688
0.09520000 0.09506990 0.07381249
0.09600000 0.09574654 0.07433711
0.09680000 0.09658446 0.07498678
0.09760000 0.09744849 0.07565670
0.09840000 0.09817090 0.07621681
0.09920000 0.09890412 0.07678530
0.10000000 0.09981575 0.07749213
0.10080000 0.10084153 0.07828745
0.10160000 0.10224242 0.07937361
0.10240000 0.10319491 0.08011211
0.10320000 0.10324137 0.08014814
0.10400000 0.10361154 0.08043514
0.10480000 0.10476523 0.08132964
0.10560000 0.10567782 0.08203720
0.10640000 0.10639091 0.08259009
0.10720000 0.10723273 0.08324278
0.10800000 0.10785807 0.08372763
0.10880000 0.10849813 0.08422389
0.10960000 0.10934594 0.08488123
0.11040000 0.11023044 0.08556701
0.11120000 0.11104166 0.08619599
0.11200000 0.11168244 0.08669281
0.11280000 0.11260414 0.08740743
0.11360000 0.11331235 0.08795653
0.11440000 0.11424515 0.08867977
0.11520000 0.11489352 0.08918247
0.11600000 0.11593819 0.08999244
0.11680000 0.11657590 0.09048689
0.11760000 0.11733435 0.09107494
0.11840000 0.11830216 0.09182531
0.11920000 0.11894873 0.09232662
0.12000000 0.11963267 0.09285690
0.12080000 0.12065726 0.09365131
0.12160000 0.12137525 0.09420799
0.12240000 0.12216949 0.09482380
0.12320000 0.12303106 0.09549180
0.12400000 0.12385114 0.09612764
0.12480000 0.12451750 0.09664429
0.12560000 0.12529194 0.09724474
0.12640000 0.12599723 0.09779158
0.12720000 0.12702541 0.09858877
0.12800000 0.12769489 0.09910784
0.12880000 0.12858611 0.09979884
0.12960000 0.12935670 0.10039630
0.13040000 0.13022471 0.10106930
0.13120000 0.13089824 0.10159152
0.13200000 0.13198129 0.10243125
0.13280000 0.13258401 0.10289855
0.13360000 0.13331487 0.10346522
0.13440000 0.13449880 0.10438316
0.13520000 0.13477121 0.10459437
0.13600000 0.13577583 0.10537329
0.13680000 0.13665050 0.10605146
0.13760000 0.13738679 0.10662233
0.13840000 0.13814165 0.10720760
0.13920000 0.13901256 0.10788284
0.14000000 0.13969421 0.10841135
0.14080000 0.14054153 0.10906831
0.14160000 0.14137452 0.10971416
0.14240000 0.14205171 0.11023921
0.14320000 0.14292761 0.11091833
0.14400000 0.14386374 0.11164414
0.14480000 0.14464678 0.11225127
0.14560000 0.14536073 0.11280481
0.14640000 0.14621792 0.11346943
0.14720000 0.14687170 0.11397633
0.14800000 0.14819938 0.11500573
0.14880000 0.14849569 0.11523547
0.14960000 0.14975675 0.11621321
0.15040000 0.15010512 0.11648331
0.15120000 0.15095860 0.11714505
0.15200000 0.15176910 0.11777346
0.15280000 0.15268245 0.11848162
0.15360000 0.15332662 0.11898106
0.15440000 0.15422217 0.11967542
0.15520000 0.15491640 0.12021368
0.15600000 0.15575080 0.12086062
0.15680000 0.15662236 0.12153637
0.15760000 0.15729120 0.12205494
0.15840000 0.15809130 0.12267529
0.15920000 0.15925864 0.12358038
0.16000000 0.15978623 0.12398944
0.16080000 0.16048826 0.12453374
0.16160000 0.16143075 0.12526449
0.16240000 0.16228616 0.12592772
0.16320000 0.16307931 0.12654268
0.16400000 0.16415648 0.12737785
0.16480000 0.16455184 0.12768438
0.16560000 0.16533936 0.12829498
0.16640000 0.16612819 0.12890658
0.16720000 0.16730317 0.12981759
0.16800000 0.16784538 0.13023799
0.16880000 0.16861822 0.13083720
0.16960000 0.16940172 0.13144468
0.17040000 0.17001199 0.13191784
0.17120000 0.17125570 0.13288213
0.17200000 0.17157354 0.13312856
0.17280000 0.17244860 0.13380703
0.17360000 0.17335368 0.13450877
0.17440000 0.17424093 0.13519669
0.17520000 0.17564342 0.13628409
0.17600000 0.17564526 0.13628552
0.17680000 0.17657852 0.13700911
0.17760000 0.17730503 0.13757240
0.17840000 0.17815470 0.13823118
0.17920000 0.17912721 0.13898520
0.18000000 0.17964765 0.13938872
0.18080000 0.18058838 0.14011810
0.18160000 0.18158723 0.14089255
0.18240000 0.18209018 0.14128250
0.18320000 0.18280439 0.14183625
0.18400000 0.18393069 0.14270952
0.18480000 0.18454461 0.14318551
0.18560000 0.18523727 0.14372256
0.18640000 0.18626322 0.14451801
0.18720000 0.18700795 0.14509543
0.18800000 0.18767966 0.14561623
0.18880000 0.18845898 0.14622047
0.18960000 0.18944494 0.14698492
0.19040000 0.19013167 0.14751737
0.19120000 0.19108157 0.14825385
0.19200000 0.19154527 0.14861338
0.19280000 0.19249924 0.14935303
0.19360000 0.19343866 0.15008139
0.19440000 0.19410193 0.15059565
0.19520000 0.19124584 0.14838123
0.19600000 0.19187133 0.14886619
0.19680000 0.19304609 0.14977702
0.19760000 0.19378828 0.15035247
0.19840000 0.19400280 0.15051879
0.19920000 0.19478736 0.15112709
0.20000000 0.19619364 0.15221743
0.20080000 0.19695866 0.15281058
0.20160000 0.19742030 0.15316851
0.20240000 0.19810792 0.15370165
0.20320000 0.19903713 0.15442210
0.20400000 0.20018662 0.15531333
0.20480000 0.20085828 0.15583410
0.20560000 0.20123495 0.15612614
0.20640000 0.20213180 0.15682151
0.20720000 0.20345703 0.15784900
0.20800000 0.20401688 0.15828308
0.20880000 0.20456744 0.15870995
0.20960000 0.20527401 0.15925777
0.21040000 0.20628433 0.16004112
0.21120000 0.20737789 0.16088899
0.21200000 0.20789488 0.16128983
0.21280000 0.20866635 0.16188798
0.21360000 0.20931393 0.16239008
0.21440000 0.21060214 0.16338887
0.21520000 0.21101870 0.16371184
0.21600000 0.21176920 0.16429374
0.21680000 0.21258665 0.16492753
0.21760000 0.21366123 0.16576070
0.21840000 0.21431046 0.16626407
0.21920000 0.21504356 0.16683247
0.22000000 0.21566487 0.16731419
0.22080000 0.21676989 0.16817095
0.22160000 0.21754134 0.16876909
0.22240000 0.21804211 0.16915735
0.22320000 0.21885388 0.16978675
0.22400000 0.21986445 0.17057028
0.22480000 0.22057919 0.17112444
0.22560000 0.22125362 0.17164735
0.22640000 0.22201018 0.17223394
0.22720000 0.22290231 0.17292564
0.22800000 0.22391055 0.17370737
0.22880000 0.22476040 0.17436629
0.22960000 0.22521924 0.17472205
0.23040000 0.22594469 0.17528451
0.23120000 0.22730937 0.17634260
0.23200000 0.22766097 0.17661521
0.23280000 0.22838240 0.17717455
0.23360000 0.22928919 0.17787763
0.23440000 0.23027146 0.17863921
0.23520000 0.23097532 0.17918494
0.23600000 0.23159797 0.17966770
0.23680000 0.23234009 0.18024310
0.23760000 0.23315325 0.18087357
0.23840000 0.23424439 0.18171957
0.23920000 0.23489224 0.18222187
0.24000000 0.23556974 0.18274717
0.24080000 0.23638755 0.18338124
0.24160000 0.23719796 0.18400959
0.24240000 0.23821368 0.18479711
0.24320000 0.23866032 0.18514340
0.24400000 0.23973365 0.18597559
0.24480000 0.24044711 0.18652877
0.24560000 0.24124738 0.18714925
0.24640000 0.24183367 0.18760382
0.24720000 0.24274071 0.18830708
0.24800000 0.24371425 0.18906190
0.24880000 0.24439805 0.18959208
0.24960000 0.24482832 0.18992568
0.25040000 0.24585910 0.19072489
0.25120000 0.24712884 0.19170936
0.25200000 0.24750007 0.19199719
0.25280000 0.24822143 0.19255648
0.25360000 0.24904173 0.19319249
0.25440000 0.25007840 0.19399626
0.25520000 0.25086876 0.19460905
0.25600000 0.25143526 0.19504828
0.25680000 0.25211291 0.19557369
0.25760000 0.25349276 0.19664354
0.25840000 0.25424505 0.19722681
0.25920000 0.25451815 0.19743856
0.26000000 0.25528035 0.19802952
0.26080000 0.25658291 0.19903944
0.26160000 0.25714991 0.19947906
0.26240000 0.25754882 0.19978835
0.26320000 0.25845609 0.20049179
0.26400000 0.25971551 0.20146826
0.26480000 0.26060019 0.20215419
0.26560000 0.26079004 0.20230138
0.26640000 0.26197274 0.20321838
0.26720000 0.26296193 0.20398533
0.26800000 0.26331385 0.20425819
0.26880000 0.26405134 0.20482999
0.26960000 0.26495706 0.20553223
0.27040000 0.26584775 0.20622282
0.27120000 0.26651730 0.20674194
0.27200000 0.26739982 0.20742619
0.27280000 0.26794570 0.20784943
0.27360000 0.26912097 0.20876066
0.27440000 0.27014442 0.20955418
0.27520000 0.27049216 0.20982380
0.27600000 0.27109830 0.21029376
0.27680000 0.27213104 0.21109448
0.27760000 0.27303047 0.21179184
0.27840000 0.27367696 0.21229309
0.27920000 0.27444441 0.21288812
0.28000000 0.27522692 0.21349483
0.28080000 0.27595384 0.21405843
0.28160000 0.27690465 0.21479564
0.28240000 0.27777783 0.21547265
0.28320000 0.27824316 0.21583343
0.28400000 0.27932483 0.21667208
0.28480000 0.28005907 0.21724137
0.28560000 0.28089456 0.21788916
0.28640000 0.28142925 0.21830373
0.28720000 0.28234569 0.21901427
0.28800000 0.28324327 0.21971020
0.28880000 0.28400988 0.22030458
0.28960000 0.28497727 0.22105463
0.29040000 0.28574006 0.22164605
0.29120000 0.28626978 0.22205676
0.29200000 0.28701237 0.22263252
0.29280000 0.28809894 0.22347498
0.29360000 0.28901972 0.22418889
0.29440000 0.28935749 0.22445078
0.29520000 0.29027543 0.22516249
0.29600000 0.29116238 0.22585017
0.29680000 0.29206843 0.22655267
0.29760000 0.29248524 0.22687584
0.29840000 0.29327725 0.22748991
0.29920000 0.29417079 0.22818271
0.30000000 0.29526349 0.22902992
0.30080000 0.29585675 0.22948989
0.30160000 0.29652097 0.23000488
0.30240000 0.29730792 0.23061504
0.30320000 0.29843142 0.23148613
0.30400000 0.29929957 0.23215923
0.30480000 0.29995329 0.23266609
0.30560000 0.30040920 0.23301957
0.30640000 0.30083360 0.23334863
0.30720000 0.30215355 0.23437203
0.30800000 0.30334070 0.23529247
0.30880000 0.30395085 0.23576555
0.30960000 0.30430349 0.23603895
0.31040000 0.30490934 0.23650870
0.31120000 0.30591185 0.23728598
0.31200000 0.30715152 0.23824714
0.31280000 0.30795461 0.23886981
0.31360000 0.30848407 0.23928031
0.31440000 0.30897060 0.23965754
0.31520000 0.31035877 0.24073384
0.31600000 0.31117522 0.24136686
0.31680000 0.31179124 0.24184449
0.31760000 0.31255968 0.24244028
0.31840000 0.31297413 0.24276162
0.31920000 0.31380248 0.24340388
0.32000000 0.31494515 0.24428983
0.32080000 0.31612973 0.24520828
0.32160000 0.31659458 0.24556869
0.32240000 0.31682066 0.24574398
0.32320000 0.31793640 0.24660905
0.32400000 0.31898135 0.24741924
0.32480000 0.31981167 0.24806302
0.32560000 0.32034780 0.24847870
0.32640000 0.32110589 0.24906647
0.32720000 0.32183078 0.24962851
0.32800000 0.32268204 0.25028852
0.32880000 0.32389305 0.25122746
0.32960000 0.32452321 0.25171605
0.33040000 0.32515278 0.25220418
0.33120000 0.32568187 0.25261440
0.33200000 0.32685960 0.25352754
0.33280000 0.32779677 0.25425416
0.33360000 0.32849437 0.25479503
0.33440000 0.32878562 0.25502085
0.33520000 0.32961925 0.25566719
0.33600000 0.33099150 0.25673115
0.33680000 0.33197296 0.25749211
0.33760000 0.33227027 0.25772263
0.33840000 0.33292889 0.25823328
0.33920000 0.33353428 0.25870266
0.34000000 0.33484454 0.25971855
0.34080000 0.33567758 0.26036444
0.34160000 0.33640998 0.26093230
0.34240000 0.33643632 0.26095272
0.34320000 0.33756698 0.26182936
0.34400000 0.33874188 0.26274030
0.34480000 0.33977776 0.26354346
0.34560000 0.34056574 0.26415441
0.34640000 0.34051617 0.26411597
0.34720000 0.34109792 0.26456703
0.34800000 0.34322460 0.26621592
0.34880000 0.34363343 0.26653290
0.34960000 0.34383459 0.26668887
0.35040000 0.34456828 0.26725773
0.35120000 0.34579813 0.26821127
0.35200000 0.34681406 0.26899896
0.35280000 0.34762193 0.26962533
0.35360000 0.34784654 0.26979948
0.35440000 0.34819927 0.27007296
0.35520000 0.34947509 0.27106215
0.35600000 0.35068595 0.27200097
0.35680000 0.35163632 0.27273784
0.35760000 0.35214218 0.27313004
0.35840000 0.35247061 0.27338469
0.35920000 0.35334845 0.27406531
0.36000000 0.35440946 0.27488795
0.36080000 0.35555378 0.27577519
0.36160000 0.35631313 0.27636394
0.36240000 0.35683039 0.27676499
0.36320000 0.35703209 0.27692137
0.36400000 0.35806736 0.27772406
0.36480000 0.35956048 0.27888173
0.36560000 0.36028942 0.27944690
0.36640000 0.36092303 0.27993816
0.36720000 0.36093821 0.27994993
0.36800000 0.36217365 0.28090782
0.36880000 0.36352895 0.28195862
0.36960000 0.36446674 0.28268573
0.37040000 0.36457503 0.28276969
0.37120000 0.36497756 0.28308179
0.37200000 0.36616092 0.28399929
0.37280000 0.36736972 0.28493652
0.37360000 0.36815037 0.28554178
0.37440000 0.36841854 0.28574971
0.37520000 0.36896425 0.28617281
0.37600000 0.37037744 0.28726851
0.37680000 0.37139851 0.28806019
0.37760000 0.37206488 0.28857685
0.37840000 0.37235296 0.28880021
0.37920000 0.37309650 0.28937670
0.38000000 0.37407554 0.29013578
0.38080000 0.37513746 0.29095913
0.38160000 0.37609967 0.29170516
0.38240000 0.37663171 0.29211768
0.38320000 0.37698933 0.29239495
0.38400000 0.37782905 0.29304601
0.38480000 0.37895825 0.29392153
0.38560000 0.38007651 0.29478855
0.38640000 0.38083302 0.29537510
0.38720000 0.38138411 0.29580239
0.38800000 0.38197508 0.29626059
0.38880000 0.38278930 0.29689188
0.38960000 0.38359758 0.29751857
0.39040000 0.38454884 0.29825612
0.39120000 0.38569073 0.29914146
0.39200000 0.38600578 0.29938573
0.39280000 0.38645470 0.29973380
0.39360000 0.38733205 0.30041404
0.39440000 0.38826411 0.30113670
0.39520000 0.38913964 0.30181553
0.39600000 0.39026818 0.30269053
0.39680000 0.39099480 0.30325391
0.39760000 0.39162710 0.30374415
0.39840000 0.39225634 0.30423202
0.39920000 0.39290874 0.30473785
0.40000000 0.39370597 0.30535598
0.39920000 0.39343420 0.30514526
0.39840000 0.39276992 0.30463022
0.39760000 0.39208469 0.30409893
0.39680000 0.39125310 0.30345417
0.39600000 0.39047272 0.30284912
0.39520000 0.38938406 0.30200504
0.39440000 0.38854233 0.30135242
0.39360000 0.38807574 0.30099065
0.39280000 0.38735021 0.30042812
0.39200000 0.38672390 0.29994252
0.39120000 0.38588001 0.29928822
0.39040000 0.38484768 0.29848782
0.38960000 0.38376000 0.29764450
0.38880000 0.38309464 0.29712862
0.38800000 0.38269128 0.29681588
0.38720000 0.38189261 0.29619664
0.38640000 0.38115022 0.29562104
0.38560000 0.37988267 0.29463827
0.38480000 0.37885354 0.29384034
0.38400000 0.37829066 0.29340392
0.38320000 0.37798556 0.29316737
0.38240000 0.37734716 0.29267239
0.38160000 0.37624572 0.29181840
0.38080000 0.37518307 0.29099449
0.38000000 0.37386460 0.28997224
0.37920000 0.37353057 0.28971325
0.37840000 0.37329476 0.28953042
0.37760000 0.37283855 0.28917670
0.37680000 0.37144568 0.28809676
0.37600000 0.37009790 0.28705177
0.37520000 0.36966927 0.28671944
0.37440000 0.36957052 0.28664288
0.37360000 0.36869365 0.28596301
0.37280000 0.36779250 0.28526431
0.37200000 0.36634382 0.28414110
0.37120000 0.36548716 0.28347690
0.37040000 0.36554239 0.28351972
0.36960000 0.36481430 0.28295521
0.36880000 0.36361413 0.28202467
0.36800000 0.36233264 0.28103109
0.36720000 0.36139255 0.28030220
0.36640000 0.36128747 0.28022072
0.36560000 0.36078148 0.27982841
0.36480000 0.36005385 0.27926425
0.36400000 0.35827805 0.27788741
0.36320000 0.35761878 0.27737626
0.36240000 0.35751596 0.27729654
0.36160000 0.35697902 0.27688022
0.36080000 0.35584002 0.27599712
0.36000000 0.35417784 0.27470837
0.35920000 0.35362860 0.27428252
0.35840000 0.35354020 0.27421398
0.35760000 0.35292050 0.27373351
0.35680000 0.35137882 0.27253819
0.35600000 0.35052500 0.27187619
0.35520000 0.34999852 0.27146799
0.35440000 0.34949296 0.27107601
0.35360000 0.34878020 0.27052338
0.35280000 0.34779314 0.26975808
0.35200000 0.34679245 0.26898221
0.35120000 0.34588419 0.26827800
0.35040000 0.34556331 0.26802921
0.34960000 0.34477288 0.26741636
0.34880000 0.34398133 0.26680264
0.34800000 0.34271501 0.26582081
0.34720000 0.34185289 0.26515238
0.34640000 0.34149879 0.26487784
0.34560000 0.34085173 0.26437615
0.34480000 0.33993323 0.26366400
0.34400000 0.33903867 0.26297042
0.34320000 0.33805432 0.26220721
0.34240000 0.33748136 0.26176298
0.34160000 0.33672447 0.26117613
0.34080000 0.33615880 0.26073755
0.34000000 0.33480727 0.25968965
0.33920000 0.33400366 0.25906659
0.33840000 0.33346261 0.25864709
0.33760000 0.33303585 0.25831621
0.33680000 0.33204240 0.25754595
0.33600000 0.33123918 0.25692318
0.33520000 0.33016925 0.25609363
0.33440000 0.32954646 0.25561076
0.33360000 0.32885442 0.25507419
0.33280000 0.32805275 0.25445263
0.33200000 0.32713105 0.25373800
0.33120000 0.32630732 0.25309934
0.33040000 0.32554086 0.25250507
0.32960000 0.32494201 0.25204076
0.32880000 0.32420696 0.25147084
0.32800000 0.32315445 0.25065480
0.32720000 0.32260474 0.25022859
0.32640000 0.32167652 0.24950890
0.32560000 0.32104553 0.24901968
0.32480000 0.32000644 0.24821403
0.32400000 0.31929822 0.24766493
0.32320000 0.31844188 0.24700097
0.32240000 0.31776951 0.24647965
0.32160000 0.31667731 0.24563283
0.32080000 0.31604331 0.24514127
0.32000000 0.31535435 0.24460710
0.31920000 0.31452853 0.24396680
0.31840000 0.31366903 0.24330041
0.31760000 0.31309723 0.24285706
0.31680000 0.31199103 0.24199939
0.31600000 0.31138459 0.24152920
0.31520000 0.31072690 0.24101926
0.31440000 0.30955424 0.24011006
0.31360000 0.30866434 0.23942009
0.31280000 0.30820947 0.23906740
0.31200000 0.30758035 0.23857963
0.31120000 0.30656831 0.23779495
0.31040000 0.30560085 0.23704485
0.30960000 0.30490185 0.23650289
0.30880000 0.30421436 0.23596985
0.30800000 0.30365026 0.23553248
0.30720000 0.30272813 0.23481752
0.30640000 0.30167634 0.23400203
0.30560000 0.30096221 0.23344834
0.30480000 0.30039526 0.23300876
0.30400000 0.29958001 0.23237667
0.30320000 0.29895729 0.23189385
0.30240000 0.29749058 0.23075666
0.30160000 0.29694058 0.23033023
0.30080000 0.29654855 0.23002627
0.30000000 0.29563656 0.22931917
0.29920000 0.29453643 0.22846620
0.29840000 0.29365838 0.22778542
0.29760000 0.29319013 0.22742237
0.29680000 0.29244173 0.22684210
0.29600000 0.29147843 0.22609522
0.29520000 0.29052922 0.22535926
0.29440000 0.29002859 0.22497111
0.29360000 0.28948365 0.22454860
0.29280000 0.28836899 0.22368436
0.29200000 0.28740253 0.22293502
0.29120000 0.28663496 0.22233990
0.29040000 0.28614676 0.22196138
0.28960000 0.28536149 0.22135253
0.28880000 0.28429154 0.22052296
0.28800000 0.28356012 0.21995586
0.28720000 0.28278226 0.21935276
0.28640000 0.28207538 0.21880469
0.28560000 0.28127985 0.21818789
0.28480000 0.28042986 0.21752886
0.28400000 0.27962973 0.21690848
0.28320000 0.27864930 0.21614832
0.28240000 0.27821673 0.21581293
0.28160000 0.27751938 0.21527226
0.28080000 0.27644896 0.21444232
0.28000000 0.27543038 0.21365258
0.27920000 0.27477063 0.21314105
0.27840000 0.27430933 0.21278338
0.27760000 0.27351285 0.21216584
0.27680000 0.27231213 0.21123488
0.27600000 0.27141467 0.21053905
0.27520000 0.27131234 0.21045971
0.27440000 0.27051742 0.20984338
0.27360000 0.26903188 0.20869158
0.27280000 0.26836589 0.20817522
0.27200000 0.26771266 0.20766874
0.27120000 0.26728610 0.20733802
0.27040000 0.26610714 0.20642393
0.26960000 0.26519002 0.20571285
0.26880000 0.26441459 0.20511163
0.26800000 0.26431236 0.20503237
0.26720000 0.26296115 0.20398473
0.26640000 0.26202520 0.20325905
0.26560000 0.26118715 0.20260928
0.26480000 0.26059680 0.20215156
0.26400000 0.25976888 0.20150965
0.26320000 0.25914455 0.20102558
0.26240000 0.25838845 0.20043935
0.26160000 0.25735315 0.19963664
0.26080000 0.25645317 0.19893885
0.26000000 0.25584360 0.19846623
0.25920000 0.25510821 0.19789606
0.25840000 0.25415602 0.19715779
0.25760000 0.25336012 0.19654069
0.25680000 0.25263648 0.19597964
0.25600000 0.25206958 0.19554009
0.25520000 0.25108398 0.19477592
0.25440000 0.25035139 0.19420792
0.25360000 0.24942645 0.19349078
0.25280000 0.24857492 0.19283056
0.25200000 0.24778738 0.19221995
0.25120000 0.24700747 0.19161525
0.25040000 0.24649893 0.19122096
0.24960000 0.24568504 0.19058992
0.24880000 0.24454354 0.18970488
0.24800000 0.24377312 0.18910754
0.24720000 0.24324083 0.18869484
0.24640000 0.24264833 0.18823545
0.24560000 0.24131377 0.18720072
0.24480000 0.24076158 0.18677259
0.24400000 0.24024982 0.18637580
0.24320000 0.23946133 0.18576445
0.24240000 0.23814729 0.18474563
0.24160000 0.23723998 0.18404216
0.24080000 0.23693881 0.18380866
0.24000000 0.23623888 0.18326597
0.23920000 0.23519447 0.18245620
0.23840000 0.23410286 0.18160984
0.23760000 0.23366042 0.18126680
0.23680000 0.23317159 0.18088779
0.23600000 0.23240671 0.18029475
0.23520000 0.23100859 0.17921074
0.23440000 0.23024216 0.17861649
0.23360000 0.23026305 0.17863270
0.23280000 0.22920993 0.17781617
0.23200000 0.22793925 0.17683097
0.23120000 0.22696985 0.17607935
0.23040000 0.22681510 0.17595937
0.22960000 0.22611795 0.17541884
0.22880000 0.22460910 0.17424898
0.22800000 0.22389747 0.17369723
0.22720000 0.22355297 0.17343012
0.22640000 0.22285838 0.17289158
0.22560000 0.22173272 0.17201881
0.22480000 0.22078107 0.17128097
0.22400000 0.22004200 0.17070794
0.22320000 0.21961622 0.17037781
0.22240000 0.21858658 0.16957950
0.22160000 0.21764640 0.16885054
0.22080000 0.21683243 0.16821944
0.22000000 0.21661750 0.16805280
0.21920000 0.21558624 0.16725322
0.21840000 0.21458201 0.16647461
0.21760000 0.21367810 0.16577377
0.21680000 0.21314909 0.16536361
0.21600000 0.21236828 0.16475822
0.21520000 0.21131488 0.16394148
0.21440000 0.21057416 0.16336718
0.21360000 0.20986166 0.16281475
0.21280000 0.20927199 0.16235756
0.21200000 0.20838598 0.16167060
0.21120000 0.20753931 0.16101414
0.21040000 0.20677885 0.16042453
0.20960000 0.20585595 0.15970897
0.20880000 0.20515580 0.15916612
0.20800000 0.20443208 0.15860500
0.20720000 0.20349914 0.15788166
0.20640000 0.20241403 0.15704033
0.20560000 0.20187117 0.15661943
0.20480000 0.20116009 0.15606810
0.20400000 0.20048706 0.15554628
0.20320000 0.19965541 0.15490147
0.20240000 0.19853853 0.15403551
0.20160000 0.19775948 0.15343148
0.20080000 0.19742262 0.15317031
0.20000000 0.19646902 0.15243094
0.19920000 0.19529536 0.15152097
0.19840000 0.19469041 0.15105192
0.19760000 0.19431244 0.15075887
0.19680000 0.19330423 0.14997717
0.19600000 0.19222928 0.14914372
0.19520000 0.19141731 0.14851417
0.19440000 0.19101875 0.14820515
0.19360000 0.19043491 0.14775248
0.19280000 0.18916738 0.14676972
0.19200000 0.18809438 0.14593778
0.19120000 0.18786917 0.14576317
0.19040000 0.18701931 0.14510424
0.18960000 0.18585403 0.14420075
0.18880000 0.18510238 0.14361797
0.18800000 0.18457795 0.14321136
0.18720000 0.18376350 0.14257989
0.18640000 0.18296222 0.14195863
0.18560000 0.18224951 0.14140604
0.18480000 0.18126184 0.14064026
0.18400000 0.18056405 0.14009924
0.18320000 0.17985271 0.13954771
0.18240000 0.17894405 0.13884319
0.18160000 0.17791205 0.13804304
0.18080000 0.17730068 0.13756903
0.18000000 0.17648669 0.13693791
0.17920000 0.17585112 0.13644513
0.17840000 0.17488596 0.13569681
0.17760000 0.17400343 0.13501255
0.17680000 0.17338920 0.13453631
0.17600000 0.17277420 0.13405948
0.17520000 0.17194469 0.13341634
0.17440000 0.17081196 0.13253809
0.17360000 0.17016250 0.13203453
0.17280000 0.16957104 0.13157595
0.17200000 0.16867981 0.13088495
0.17120000 0.16771377 0.13013595
0.17040000 0.16677930 0.12941141
0.16960000 0.16625093 0.12900175
0.16880000 0.16556361 0.12846885
0.16800000 0.16458690 0.12771157
0.16720000 0.16353262 0.12689414
0.16640000 0.16311656 0.12657156
0.16560000 0.16224683 0.12589723
0.16480000 0.16131859 0.12517753
0.16400000 0.16035425 0.12442984
0.16320000 0.15996586 0.12412871
0.16240000 0.15902638 0.12340030
0.16160000 0.15826651 0.12281114
0.16080000 0.15732258 0.12207927
0.16000000 0.15671416 0.12160755
0.15920000 0.15594811 0.12101360
0.15840000 0.15511965 0.12037126
0.15760000 0.15427165 0.11971378
0.15680000 0.15352477 0.11913470
0.15600000 0.15274412 0.11852943
0.15520000 0.15181992 0.11781286
0.15440000 0.15098483 0.11716539
0.15360000 0.15014466 0.11651397
0.15280000 0.14971452 0.11618047
0.15200000 0.14846005 0.11520783
0.15120000 0.14780505 0.11469999
0.15040000 0.14714532 0.11418848
0.14960000 0.14629867 0.11353203
0.14880000 0.14545119 0.11287495
0.14800000 0.14468705 0.11228249
0.14720000 0.14398254 0.11173626
0.14640000 0.14311827 0.11106615
0.14560000 0.14250182 0.11058820
0.14480000 0.14138616 0.10972319
0.14400000 0.14077339 0.10924808
0.14320000 0.14010925 0.10873315
0.14240000 0.13896466 0.10784571
0.14160000 0.13814848 0.10721289
0.14080000 0.13775148 0.10690509
0.14000000 0.13691952 0.10626004
0.13920000 0.13559503 0.10523311
0.13840000 0.13503784 0.10480110
0.13760000 0.13460924 0.10446879
0.13680000 0.13357945 0.10367036
0.13600000 0.13253731 0.10286235
0.13520000 0.13211296 0.10253334
0.13440000 0.13116299 0.10179679
0.13360000 0.13041305 0.10121533
0.13280000 0.12947584 0.10048868
0.13200000 0.12881923 0.09997958
0.13120000 0.12798720 0.09933448
0.13040000 0.12732728 0.09882282
0.12960000 0.12615049 0.09791041
0.12880000 0.12556208 0.09745420
0.12800000 0.12489356 0.09693587
0.12720000 0.12394627 0.09620140
0.12640000 0.12315241 0.09558589
0.12560000 0.12249225 0.09507404
0.12480000 0.12173554 0.09448734
0.12400000 0.12079291 0.09375648
0.12320000 0.11998513 0.09313018
0.12240000 0.11932604 0.09261917
0.12160000 0.11826590 0.09179720
0.12080000 0.11752879 0.09122569
0.12000000 0.11679675 0.09065811
0.11920000 0.11609252 0.09011210
0.11840000 0.11522620 0.08944041
0.11760000 0.11441328 0.08881012
0.11680000 0.11365710 0.08822383
0.11600000 0.11298626 0.08770370
0.11520000 0.11218315 0.08708102
0.11440000 0.11102209 0.08618081
0.11360000 0.11062168 0.08587036
0.11280000 0.10969672 0.08515320
0.11200000 0.10897764 0.08459568
0.11120000 0.10796725 0.08381228
0.11040000 0.10738006 0.08335701
0.10960000 0.10652344 0.08269284
0.10880000 0.10560180 0.08197826
0.10800000 0.10506128 0.08155918
0.10720000 0.10416748 0.08086618
0.10640000 0.10342427 0.08028994
0.10560000 0.10249284 0.07956777
0.10480000 0.10190795 0.07911429
0.10400000 0.10076247 0.07822615
0.10320000 0.09999287 0.07762945
0.10240000 0.09939157 0.07716324
0.10160000 0.09869872 0.07662605
0.10080000 0.09764250 0.07580713
0.10000000 0.09695546 0.07527444
0.09920000 0.09608143 0.07459677
0.09840000 0.09552102 0.07416227
0.09760000 0.09455327 0.07341193
0.09680000 0.09392267 0.07292300
0.09600000 0.09319100 0.07235572
0.09520000 0.09220917 0.07159447
0.09440000 0.09133888 0.07091970
0.09360000 0.09055875 0.07031483
0.09280000 0.08990083 0.06980472
0.09200000 0.08877888 0.06893484
0.09120000 0.08815007 0.06844730
0.09040000 0.08718102 0.06769596
0.08960000 0.08676822 0.06737589
0.08880000 0.08577796 0.06660812
0.08800000 0.08527051 0.06621467
0.08720000 0.08425515 0.06542742
0.08640000 0.08350317 0.06484438
0.08560000 0.08257811 0.06412715
0.08480000 0.08187435 0.06358150
0.08400000 0.08093379 0.06285225
0.08320000 0.08027924 0.06234475
0.08240000 0.07950094 0.06174131
0.08160000 0.07856273 0.06101388
0.08080000 0.07793916 0.06053040
0.08000000 0.07720898 0.05996427
0.07920000 0.07622546 0.05920171
0.07840000 0.07570894 0.05880123
0.07760000 0.07466304 0.05799030
0.07680000 0.07391973 0.05741399
0.07600000 0.07296184 0.05667131
0.07520000 0.07239772 0.05623392
0.07440000 0.07121717 0.05531860
0.07360000 0.07072068 0.05493365
0.07280000 0.06992637 0.05431779
0.07200000 0.06906559 0.05365040
0.07120000 0.06840016 0.05313446
0.07040000 0.06762727 0.05253522
0.06960000 0.06668956 0.05180818
0.06880000 0.06596014 0.05124263
0.06800000 0.06526757 0.05070565
0.06720000 0.06446973 0.05008706
0.06640000 0.06345126 0.04929740
0.06560000 0.06264540 0.04867259
0.06480000 0.06203260 0.04819747
0.06400000 0.06100807 0.04740311
0.06320000 0.06065517 0.04712949
0.06240000 0.05954450 0.04626835
0.06160000 0.05872696 0.04563448
0.06080000 0.05795005 0.04503212
0.06000000 0.05721943 0.04446564
0.05920000 0.05633744 0.04378180
0.05840000 0.05551855 0.04314688
0.05760000 0.05475871 0.04255775
0.05680000 0.05410664 0.04205218
0.05600000 0.05323863 0.04137918
0.05520000 0.05238986 0.04072109
0.05440000 0.05142928 0.03997632
0.05360000 0.05083241 0.03951354
0.05280000 0.04995539 0.03883356
0.05200000 0.04919602 0.03824479
0.05120000 0.04849095 0.03769813
0.05040000 0.04753807 0.03695933
0.04960000 0.04675624 0.03635314
0.04880000 0.04604189 0.03579928
0.04800000 0.04504172 0.03502381
0.04720000 0.04448894 0.03459522
0.04640000 0.04363956 0.03393667
0.04560000 0.04289483 0.03335925
0.04480000 0.04199306 0.03266008
0.04400000 0.04122235 0.03206251
0.04320000 0.04051454 0.03151373
0.04240000 0.03959126 0.03079787
0.04160000 0.03886468 0.03023453
0.04080000 0.03810862 0.02964833
0.04000000 0.03724017 0.02897499
0.03920000 0.03641809 0.02833760
0.03840000 0.03564762 0.02774022
0.03760000 0.03502125 0.02725457
0.03680000 0.03422914 0.02664043
0.03600000 0.03319798 0.02584093
0.03520000 0.03264073 0.02540887
0.03440000 0.03162457 0.02462101
0.03360000 0.03099122 0.02412995
0.03280000 0.02997034 0.02333842
0.03200000 0.02935361 0.02286024
0.03120000 0.02871030 0.02236146
0.03040000 0.02739861 0.02134447
0.02960000 0.02703816 0.02106499
0.02880000 0.02603922 0.02029048
0.02800000 0.02525738 0.01968429
0.02720000 0.02451386 0.01910781
0.02640000 0.02370103 0.01847760
0.02560000 0.02295924 0.01790245
0.02480000 0.02212459 0.01725532
0.02400000 0.02138178 0.01667939
0.02320000 0.02052454 0.01601475
0.02240000 0.01954663 0.01525654
0.02160000 0.01911250 0.01491994
0.02080000 0.01862416 0.01454131
0.02000000 0.01754322 0.01370322
0.01920000 0.01653010 0.01291771
0.01840000 0.01567903 0.01225784
0.01760000 0.01521649 0.01189922
0.01680000 0.01407193 0.01101180
0.01600000 0.01342613 0.01051109
0.01520000 0.01299812 0.01017923
0.01440000 0.01172582 0.00919278
0.01360000 0.01097571 0.00861119
0.01280000 0.01041726 0.00817820
0.01200000 0.00958412 0.00753224
0.01120000 0.00840238 0.00661599
0.01040000 0.00782972 0.00617198
0.00960000 0.00715666 0.00565014
0.00880000 0.00623099 0.00493243
0.00800000 0.00538062 0.00427311
0.00720000 0.00464480 0.00370260
0.00640000 0.00387589 0.00310644
0.00560000 0.00292913 0.00237238
0.00480000 0.00223058 0.00183076
0.00400000 0.00171543 0.00143136