File: plots/rawdata/Figure2-2K.txt
# strain(%), strain_el(%), stress(GPa)
0.00000000 -0.00013066 0.00000001
0.00040000 0.00041218 0.00042089
0.00080000 0.00081320 0.00073182
0.00120000 0.00073968 0.00067482
0.00160000 0.00085832 0.00076680
0.00200000 0.00144074 0.00121837
0.00240000 0.00223782 0.00183638
0.00280000 0.00273387 0.00222099
0.00320000 0.00307467 0.00248522
0.00360000 0.00343385 0.00276371
0.00400000 0.00404272 0.00323579
0.00440000 0.00483567 0.00385059
0.00480000 0.00569457 0.00451653
0.00520000 0.00618070 0.00489344
0.00560000 0.00674172 0.00532842
0.00600000 0.00709919 0.00560558
0.00640000 0.00692773 0.00547264
0.00680000 0.00702659 0.00554929
0.00720000 0.00695487 0.00549368
0.00760000 0.00746129 0.00588633
0.00800000 0.00796747 0.00627879
0.00840000 0.00845981 0.00666052
0.00880000 0.00836301 0.00658547
0.00920000 0.00858165 0.00675498
0.00960000 0.00923937 0.00726494
0.01000000 0.00983672 0.00772809
0.01040000 0.01028149 0.00807294
0.01080000 0.01076264 0.00844599
0.01120000 0.01101322 0.00864027
0.01160000 0.01117958 0.00876926
0.01200000 0.01156393 0.00906726
0.01240000 0.01172413 0.00919147
0.01280000 0.01268975 0.00994015
0.01320000 0.01322285 0.01035347
0.01360000 0.01340799 0.01049702
0.01400000 0.01360699 0.01065131
0.01440000 0.01379685 0.01079852
0.01480000 0.01437249 0.01124484
0.01520000 0.01484180 0.01160871
0.01560000 0.01552022 0.01213471
0.01600000 0.01588231 0.01241545
0.01640000 0.01626963 0.01271576
0.01680000 0.01648163 0.01288013
0.01720000 0.01672682 0.01307023
0.01760000 0.01692284 0.01322221
0.01800000 0.01765104 0.01378681
0.01840000 0.01818289 0.01419918
0.01880000 0.01863033 0.01454609
0.01920000 0.01907045 0.01488734
0.01960000 0.01949070 0.01521317
0.02000000 0.01976091 0.01542268
0.02040000 0.01996192 0.01557852
0.02080000 0.02017606 0.01574456
0.02120000 0.02084435 0.01626271
0.02160000 0.02132073 0.01663206
0.02200000 0.02185482 0.01704616
0.02240000 0.02222743 0.01733506
0.02280000 0.02244077 0.01750047
0.02320000 0.02291181 0.01786568
0.02360000 0.02320537 0.01809329
0.02400000 0.02346779 0.01829675
0.02440000 0.02419508 0.01886065
0.02480000 0.02475198 0.01929244
0.02520000 0.02522222 0.01965703
0.02560000 0.02532986 0.01974049
0.02600000 0.02563783 0.01997927
0.02640000 0.02589510 0.02017874
0.02680000 0.02639494 0.02056628
0.02720000 0.02697940 0.02101944
0.02760000 0.02748986 0.02141522
0.02800000 0.02783384 0.02168192
0.02840000 0.02803772 0.02183999
0.02880000 0.02874798 0.02239068
0.02920000 0.02910155 0.02266482
0.02960000 0.03003617 0.02338946
0.03000000 0.03069752 0.02390223
0.03040000 0.03151921 0.02453931
0.03080000 0.03171180 0.02468864
0.03120000 0.03195180 0.02487472
0.03160000 0.03212454 0.02500865
0.03200000 0.03216338 0.02503877
0.03240000 0.03240888 0.02522911
0.03280000 0.03274451 0.02548933
0.03320000 0.03315548 0.02580797
0.03360000 0.03340322 0.02600006
0.03400000 0.03353758 0.02610423
0.03440000 0.03398419 0.02645051
0.03480000 0.03443575 0.02680062
0.03520000 0.03488064 0.02714556
0.03560000 0.03563732 0.02773224
0.03600000 0.03681162 0.02864272
0.03640000 0.03702756 0.02881014
0.03680000 0.03724820 0.02898121
0.03720000 0.03752365 0.02919478
0.03760000 0.03796261 0.02953512
0.03800000 0.03830469 0.02980035
0.03840000 0.03828558 0.02978553
0.03880000 0.03861751 0.03004289
0.03920000 0.03887864 0.03024535
0.03960000 0.03907480 0.03039744
0.04000000 0.03957936 0.03078864
0.04040000 0.04013951 0.03122295
0.04080000 0.04066826 0.03163291
0.04120000 0.04105365 0.03193172
0.04160000 0.04148236 0.03226411
0.04200000 0.04179516 0.03250663
0.04240000 0.04186566 0.03256130
0.04280000 0.04237206 0.03295393
0.04320000 0.04304893 0.03347873
0.04360000 0.04338786 0.03374151
0.04400000 0.04395349 0.03418007
0.04440000 0.04419674 0.03436867
0.04480000 0.04461628 0.03469395
0.04520000 0.04486958 0.03489035
0.04560000 0.04521319 0.03515676
0.04600000 0.04572033 0.03554996
0.04640000 0.04655172 0.03619457
0.04680000 0.04670181 0.03631094
0.04720000 0.04707258 0.03659841
0.04760000 0.04735495 0.03681735
0.04800000 0.04759032 0.03699984
0.04840000 0.04805252 0.03735820
0.04880000 0.04852161 0.03772190
0.04920000 0.04890673 0.03802049
0.04960000 0.04948246 0.03846688
0.05000000 0.04944339 0.03843659
0.05040000 0.05006428 0.03891799
0.05080000 0.05042028 0.03919401
0.05120000 0.05099291 0.03963799
0.05160000 0.05142339 0.03997175
0.05200000 0.05187188 0.04031948
0.05240000 0.05211417 0.04050734
0.05280000 0.05240194 0.04073046
0.05320000 0.05287452 0.04109687
0.05360000 0.05339758 0.04150242
0.05400000 0.05381475 0.04182586
0.05440000 0.05396793 0.04194463
0.05480000 0.05457198 0.04241297
0.05520000 0.05499610 0.04274181
0.05560000 0.05526840 0.04295293
0.05600000 0.05550543 0.04313671
0.05640000 0.05611189 0.04360692
0.05680000 0.05663808 0.04401490
0.05720000 0.05691324 0.04422824
0.05760000 0.05742883 0.04462799
0.05800000 0.05783436 0.04494242
0.05840000 0.05816299 0.04519721
0.05880000 0.05852257 0.04547601
0.05920000 0.05897009 0.04582299
0.05960000 0.05936665 0.04613046
0.06000000 0.05983235 0.04649153
0.06040000 0.06014181 0.04673147
0.06080000 0.06056080 0.04705633
0.06120000 0.06094932 0.04735756
0.06160000 0.06137777 0.04768975
0.06200000 0.06162257 0.04787956
0.06240000 0.06213825 0.04827938
0.06280000 0.06268146 0.04870055
0.06320000 0.06295978 0.04891634
0.06360000 0.06334640 0.04921610
0.06400000 0.06375041 0.04952935
0.06440000 0.06408932 0.04979212
0.06480000 0.06455980 0.05015689
0.06520000 0.06494921 0.05045882
0.06560000 0.06542308 0.05082622
0.06600000 0.06582266 0.05113604
0.06640000 0.06599919 0.05127290
0.06680000 0.06633636 0.05153433
0.06720000 0.06698401 0.05203648
0.06760000 0.06746184 0.05240696
0.06800000 0.06779865 0.05266810
0.06840000 0.06816655 0.05295334
0.06880000 0.06860959 0.05329685
0.06920000 0.06869621 0.05336401
0.06960000 0.06931486 0.05384367
0.07000000 0.06959893 0.05406392
0.07040000 0.07036461 0.05465757
0.07080000 0.07083770 0.05502438
0.07120000 0.07101194 0.05515947
0.07160000 0.07127832 0.05536601
0.07200000 0.07165091 0.05565489
0.07240000 0.07207715 0.05598537
0.07280000 0.07258203 0.05637682
0.07320000 0.07303080 0.05672477
0.07360000 0.07349171 0.05708214
0.07400000 0.07396249 0.05744714
0.07440000 0.07456221 0.05791213
0.07480000 0.07515563 0.05837223
0.07520000 0.07563624 0.05874487
0.07560000 0.07604987 0.05906557
0.07600000 0.07628312 0.05924641
0.07640000 0.07652988 0.05943774
0.07680000 0.07658709 0.05948209
0.07720000 0.07686040 0.05969400
0.07760000 0.07723177 0.05998194
0.07800000 0.07771235 0.06035455
0.07840000 0.07821006 0.06074044
0.07880000 0.07857359 0.06102230
0.07920000 0.07906036 0.06139971
0.07960000 0.07967073 0.06187295
0.08000000 0.08014200 0.06223835
0.08040000 0.08073117 0.06269515
0.08080000 0.08111180 0.06299027
0.08120000 0.08155084 0.06333067
0.08160000 0.08168688 0.06343615
0.08200000 0.08173841 0.06347610
0.08240000 0.08207411 0.06373638
0.08280000 0.08248732 0.06405676
0.08320000 0.08283849 0.06432904
0.08360000 0.08337157 0.06474235
0.08400000 0.08382722 0.06509563
0.08440000 0.08431870 0.06547670
0.08480000 0.08474476 0.06580703
0.08520000 0.08495291 0.06596842
0.08560000 0.08532236 0.06625487
0.08600000 0.08571930 0.06656263
0.08640000 0.08627162 0.06699087
0.08680000 0.08667758 0.06730562
0.08720000 0.08701274 0.06756548
0.08760000 0.08729610 0.06778518
0.08800000 0.08776139 0.06814594
0.08840000 0.08815328 0.06844979
0.08880000 0.08874945 0.06891202
0.08920000 0.08921211 0.06927074
0.08960000 0.08938931 0.06940813
0.09000000 0.08988664 0.06979372
0.09040000 0.09001007 0.06988942
0.09080000 0.09043626 0.07021986
0.09120000 0.09092112 0.07059579
0.09160000 0.09134613 0.07092532
0.09200000 0.09202638 0.07145274
0.09240000 0.09285783 0.07209740
0.09280000 0.09305618 0.07225118
0.09320000 0.09385386 0.07286965
0.09360000 0.09418025 0.07312272
0.09400000 0.09422316 0.07315599
0.09440000 0.09440489 0.07329688
0.09480000 0.09472813 0.07354750
0.09520000 0.09506990 0.07381249
0.09560000 0.09544246 0.07410136
0.09600000 0.09574654 0.07433711
0.09640000 0.09613340 0.07463706
0.09680000 0.09658446 0.07498678
0.09720000 0.09710411 0.07538969
0.09760000 0.09744849 0.07565670
0.09800000 0.09769676 0.07584919
0.09840000 0.09817090 0.07621681
0.09880000 0.09852306 0.07648985
0.09920000 0.09890412 0.07678530
0.09960000 0.09931626 0.07710485
0.10000000 0.09981575 0.07749213
0.10040000 0.10026270 0.07783866
0.10080000 0.10084153 0.07828745
0.10120000 0.10141285 0.07873042
0.10160000 0.10224242 0.07937361
0.10200000 0.10283503 0.07983308
0.10240000 0.10319491 0.08011211
0.10280000 0.10338052 0.08025602
0.10320000 0.10324137 0.08014814
0.10360000 0.10333924 0.08022402
0.10400000 0.10361154 0.08043514
0.10440000 0.10409677 0.08081136
0.10480000 0.10476523 0.08132964
0.10520000 0.10492351 0.08145236
0.10560000 0.10567782 0.08203720
0.10600000 0.10615439 0.08240670
0.10640000 0.10639091 0.08259009
0.10680000 0.10673676 0.08285824
0.10720000 0.10723273 0.08324278
0.10760000 0.10777940 0.08366663
0.10800000 0.10785807 0.08372763
0.10840000 0.10807976 0.08389952
0.10880000 0.10849813 0.08422389
0.10920000 0.10899805 0.08461149
0.10960000 0.10934594 0.08488123
0.11000000 0.10964625 0.08511407
0.11040000 0.11023044 0.08556701
0.11080000 0.11072718 0.08595215
0.11120000 0.11104166 0.08619599
0.11160000 0.11131933 0.08641127
0.11200000 0.11168244 0.08669281
0.11240000 0.11214915 0.08705466
0.11280000 0.11260414 0.08740743
0.11320000 0.11305228 0.08775489
0.11360000 0.11331235 0.08795653
0.11400000 0.11424627 0.08868064
0.11440000 0.11424515 0.08867977
0.11480000 0.11459892 0.08895406
0.11520000 0.11489352 0.08918247
0.11560000 0.11543354 0.08960117
0.11600000 0.11593819 0.08999244
0.11640000 0.11624310 0.09022885
0.11680000 0.11657590 0.09048689
0.11720000 0.11681378 0.09067132
0.11760000 0.11733435 0.09107494
0.11800000 0.11774899 0.09139642
0.11840000 0.11830216 0.09182531
0.11880000 0.11869085 0.09212668
0.11920000 0.11894873 0.09232662
0.11960000 0.11911390 0.09245469
0.12000000 0.11963267 0.09285690
0.12040000 0.12023157 0.09332126
0.12080000 0.12065726 0.09365131
0.12120000 0.12105033 0.09395607
0.12160000 0.12137525 0.09420799
0.12200000 0.12175515 0.09450254
0.12240000 0.12216949 0.09482380
0.12280000 0.12251743 0.09509357
0.12320000 0.12303106 0.09549180
0.12360000 0.12343653 0.09580618
0.12400000 0.12385114 0.09612764
0.12440000 0.12417931 0.09638208
0.12480000 0.12451750 0.09664429
0.12520000 0.12503676 0.09704690
0.12560000 0.12529194 0.09724474
0.12600000 0.12566193 0.09753161
0.12640000 0.12599723 0.09779158
0.12680000 0.12660670 0.09826413
0.12720000 0.12702541 0.09858877
0.12760000 0.12736983 0.09885581
0.12800000 0.12769489 0.09910784
0.12840000 0.12813430 0.09944854
0.12880000 0.12858611 0.09979884
0.12920000 0.12895067 0.10008149
0.12960000 0.12935670 0.10039630
0.13000000 0.12992391 0.10083609
0.13040000 0.13022471 0.10106930
0.13080000 0.13045680 0.10124925
0.13120000 0.13089824 0.10159152
0.13160000 0.13140126 0.10198153
0.13200000 0.13198129 0.10243125
0.13240000 0.13221309 0.10261097
0.13280000 0.13258401 0.10289855
0.13320000 0.13292281 0.10316124
0.13360000 0.13331487 0.10346522
0.13400000 0.13382905 0.10386388
0.13440000 0.13449880 0.10438316
0.13480000 0.13461534 0.10447352
0.13520000 0.13477121 0.10459437
0.13560000 0.13537865 0.10506534
0.13600000 0.13577583 0.10537329
0.13640000 0.13619725 0.10570003
0.13680000 0.13665050 0.10605146
0.13720000 0.13713729 0.10642888
0.13760000 0.13738679 0.10662233
0.13800000 0.13768304 0.10685202
0.13840000 0.13814165 0.10720760
0.13880000 0.13869894 0.10763969
0.13920000 0.13901256 0.10788284
0.13960000 0.13915235 0.10799123
0.14000000 0.13969421 0.10841135
0.14040000 0.14015068 0.10876527
0.14080000 0.14054153 0.10906831
0.14120000 0.14100631 0.10942867
0.14160000 0.14137452 0.10971416
0.14200000 0.14183057 0.11006775
0.14240000 0.14205171 0.11023921
0.14280000 0.14228861 0.11042288
0.14320000 0.14292761 0.11091833
0.14360000 0.14362194 0.11145667
0.14400000 0.14386374 0.11164414
0.14440000 0.14421668 0.11191779
0.14480000 0.14464678 0.11225127
0.14520000 0.14504728 0.11256179
0.14560000 0.14536073 0.11280481
0.14600000 0.14581362 0.11315596
0.14640000 0.14621792 0.11346943
0.14680000 0.14649626 0.11368523
0.14720000 0.14687170 0.11397633
0.14760000 0.14732870 0.11433065
0.14800000 0.14819938 0.11500573
0.14840000 0.14803310 0.11487680
0.14880000 0.14849569 0.11523547
0.14920000 0.14886656 0.11552301
0.14960000 0.14975675 0.11621321
0.15000000 0.14974952 0.11620761
0.15040000 0.15010512 0.11648331
0.15080000 0.15066839 0.11692004
0.15120000 0.15095860 0.11714505
0.15160000 0.15129940 0.11740928
0.15200000 0.15176910 0.11777346
0.15240000 0.15220101 0.11810833
0.15280000 0.15268245 0.11848162
0.15320000 0.15299568 0.11872447
0.15360000 0.15332662 0.11898106
0.15400000 0.15378276 0.11933472
0.15440000 0.15422217 0.11967542
0.15480000 0.15456265 0.11993940
0.15520000 0.15491640 0.12021368
0.15560000 0.15534648 0.12054713
0.15600000 0.15575080 0.12086062
0.15640000 0.15623598 0.12123680
0.15680000 0.15662236 0.12153637
0.15720000 0.15699685 0.12182673
0.15760000 0.15729120 0.12205494
0.15800000 0.15762703 0.12231533
0.15840000 0.15809130 0.12267529
0.15880000 0.15860436 0.12307309
0.15920000 0.15925864 0.12358038
0.15960000 0.15940158 0.12369120
0.16000000 0.15978623 0.12398944
0.16040000 0.16008263 0.12421924
0.16080000 0.16048826 0.12453374
0.16120000 0.16084962 0.12481392
0.16160000 0.16143075 0.12526449
0.16200000 0.16188518 0.12561682
0.16240000 0.16228616 0.12592772
0.16280000 0.16274583 0.12628412
0.16320000 0.16307931 0.12654268
0.16360000 0.16341894 0.12680601
0.16400000 0.16415648 0.12737785
0.16440000 0.16442952 0.12758955
0.16480000 0.16455184 0.12768438
0.16520000 0.16484203 0.12790938
0.16560000 0.16533936 0.12829498
0.16600000 0.16569377 0.12856976
0.16640000 0.16612819 0.12890658
0.16680000 0.16639536 0.12911373
0.16720000 0.16730317 0.12981759
0.16760000 0.16785242 0.13024344
0.16800000 0.16784538 0.13023799
0.16840000 0.16848360 0.13073282
0.16880000 0.16861822 0.13083720
0.16920000 0.16912433 0.13122961
0.16960000 0.16940172 0.13144468
0.17000000 0.16970612 0.13168069
0.17040000 0.17001199 0.13191784
0.17080000 0.17062292 0.13239152
0.17120000 0.17125570 0.13288213
0.17160000 0.17152122 0.13308800
0.17200000 0.17157354 0.13312856
0.17240000 0.17218717 0.13360434
0.17280000 0.17244860 0.13380703
0.17320000 0.17282681 0.13410027
0.17360000 0.17335368 0.13450877
0.17400000 0.17386149 0.13490250
0.17440000 0.17424093 0.13519669
0.17480000 0.17447348 0.13537699
0.17520000 0.17564342 0.13628409
0.17560000 0.17500007 0.13578528
0.17600000 0.17564526 0.13628552
0.17640000 0.17610870 0.13664484
0.17680000 0.17657852 0.13700911
0.17720000 0.17713591 0.13744128
0.17760000 0.17730503 0.13757240
0.17800000 0.17778049 0.13794104
0.17840000 0.17815470 0.13823118
0.17880000 0.17881801 0.13874547
0.17920000 0.17912721 0.13898520
0.17960000 0.17924929 0.13907986
0.18000000 0.17964765 0.13938872
0.18040000 0.18008794 0.13973009
0.18080000 0.18058838 0.14011810
0.18120000 0.18102556 0.14045706
0.18160000 0.18158723 0.14089255
0.18200000 0.18188942 0.14112685
0.18240000 0.18209018 0.14128250
0.18280000 0.18237491 0.14150326
0.18320000 0.18280439 0.14183625
0.18360000 0.18345866 0.14234353
0.18400000 0.18393069 0.14270952
0.18440000 0.18419118 0.14291149
0.18480000 0.18454461 0.14318551
0.18520000 0.18485487 0.14342607
0.18560000 0.18523727 0.14372256
0.18600000 0.18549352 0.14392124
0.18640000 0.18626322 0.14451801
0.18680000 0.18684781 0.14497127
0.18720000 0.18700795 0.14509543
0.18760000 0.18735150 0.14536180
0.18800000 0.18767966 0.14561623
0.18840000 0.18803359 0.14589065
0.18880000 0.18845898 0.14622047
0.18920000 0.18889445 0.14655811
0.18960000 0.18944494 0.14698492
0.19000000 0.18982854 0.14728234
0.19040000 0.19013167 0.14751737
0.19080000 0.19054322 0.14783645
0.19120000 0.19108157 0.14825385
0.19160000 0.19130805 0.14842945
0.19200000 0.19154527 0.14861338
0.19240000 0.19203224 0.14899095
0.19280000 0.19249924 0.14935303
0.19320000 0.19295839 0.14970902
0.19360000 0.19343866 0.15008139
0.19400000 0.19390346 0.15044177
0.19440000 0.19410193 0.15059565
0.19480000 0.19352105 0.15014528
0.19520000 0.19124584 0.14838123
0.19520000 0.19124584 0.14838123
0.19480000 0.19099595 0.14818747
0.19440000 0.19084728 0.14807221
0.19400000 0.19052195 0.14781996
0.19360000 0.19026345 0.14761954
0.19320000 0.18965587 0.14714846
0.19280000 0.18899592 0.14663677
0.19240000 0.18846750 0.14622707
0.19200000 0.18792291 0.14580483
0.19160000 0.18780888 0.14571642
0.19120000 0.18769770 0.14563022
0.19080000 0.18740023 0.14539958
0.19040000 0.18684784 0.14497129
0.19000000 0.18625699 0.14451318
0.18960000 0.18568256 0.14406781
0.18920000 0.18535061 0.14381043
0.18880000 0.18493091 0.14348503
0.18840000 0.18469685 0.14330355
0.18800000 0.18440648 0.14307842
0.18760000 0.18400615 0.14276802
0.18720000 0.18359204 0.14244695
0.18680000 0.18319849 0.14214181
0.18640000 0.18279075 0.14182568
0.18600000 0.18234379 0.14147914
0.18560000 0.18207805 0.14127310
0.18520000 0.18141281 0.14075732
0.18480000 0.18109037 0.14050731
0.18440000 0.18061850 0.14014145
0.18400000 0.18039259 0.13996630
0.18360000 0.18009987 0.13973935
0.18320000 0.17968125 0.13941477
0.18280000 0.17934418 0.13915343
0.18240000 0.17877259 0.13871025
0.18200000 0.17817797 0.13824923
0.18160000 0.17774058 0.13791010
0.18120000 0.17743517 0.13767330
0.18080000 0.17712922 0.13743609
0.18040000 0.17677284 0.13715978
0.18000000 0.17631522 0.13680497
0.17960000 0.17606267 0.13660915
0.17920000 0.17567965 0.13631219
0.17880000 0.17522280 0.13595798
0.17840000 0.17471450 0.13556387
0.17800000 0.17434524 0.13527757
0.17760000 0.17383196 0.13487960
0.17720000 0.17346363 0.13459402
0.17680000 0.17321773 0.13440337
0.17640000 0.17297597 0.13421592
0.17600000 0.17260273 0.13392654
0.17560000 0.17235178 0.13373196
0.17520000 0.17177323 0.13328339
0.17480000 0.17103584 0.13271167
0.17440000 0.17064050 0.13240514
0.17400000 0.17013865 0.13201605
0.17360000 0.16999103 0.13190159
0.17320000 0.16973416 0.13170243
0.17280000 0.16939957 0.13144301
0.17240000 0.16895629 0.13109932
0.17200000 0.16850835 0.13075201
0.17160000 0.16798067 0.13034288
0.17120000 0.16754231 0.13000300
0.17080000 0.16706024 0.12962924
0.17040000 0.16660783 0.12927847
0.17000000 0.16638641 0.12910679
0.16960000 0.16607946 0.12886881
0.16920000 0.16578154 0.12863782
0.16880000 0.16539214 0.12833590
0.16840000 0.16491053 0.12796249
0.16800000 0.16441543 0.12757862
0.16760000 0.16383804 0.12713095
0.16720000 0.16336115 0.12676120
0.16680000 0.16303286 0.12650667
0.16640000 0.16294510 0.12643862
0.16600000 0.16261936 0.12618607
0.16560000 0.16207537 0.12576428
0.16520000 0.16182528 0.12557039
0.16480000 0.16114713 0.12504459
0.16440000 0.16059304 0.12461498
0.16400000 0.16018279 0.12429690
0.16360000 0.16001176 0.12416430
0.16320000 0.15979440 0.12399577
0.16280000 0.15937987 0.12367437
0.16240000 0.15885491 0.12326735
0.16200000 0.15859536 0.12306611
0.16160000 0.15809505 0.12267820
0.16120000 0.15754625 0.12225269
0.16080000 0.15715111 0.12194633
0.16040000 0.15676566 0.12164748
0.16000000 0.15654269 0.12147460
0.15960000 0.15615085 0.12117079
0.15920000 0.15577664 0.12088065
0.15880000 0.15532214 0.12052826
0.15840000 0.15494818 0.12023832
0.15800000 0.15440813 0.11981959
0.15760000 0.15410018 0.11958083
0.15720000 0.15378092 0.11933330
0.15680000 0.15335331 0.11900175
0.15640000 0.15294759 0.11868719
0.15600000 0.15257265 0.11839648
0.15560000 0.15216555 0.11808084
0.15520000 0.15164845 0.11767992
0.15480000 0.15108916 0.11724627
0.15440000 0.15081337 0.11703244
0.15400000 0.15035704 0.11667863
0.15360000 0.14997319 0.11638103
0.15320000 0.14987492 0.11630483
0.15280000 0.14954305 0.11604752
0.15240000 0.14892007 0.11556451
0.15200000 0.14828858 0.11507489
0.15160000 0.14797267 0.11482995
0.15120000 0.14763359 0.11456704
0.15080000 0.14723122 0.11425507
0.15040000 0.14697386 0.11405553
0.15000000 0.14655215 0.11372856
0.14960000 0.14612720 0.11339909
0.14920000 0.14550598 0.11291743
0.14880000 0.14527972 0.11274201
0.14840000 0.14484370 0.11240394
0.14800000 0.14451558 0.11214954
0.14760000 0.14413090 0.11185129
0.14720000 0.14381108 0.11160331
0.14680000 0.14338564 0.11127345
0.14640000 0.14294680 0.11093321
0.14600000 0.14267584 0.11072312
0.14560000 0.14233035 0.11045525
0.14520000 0.14174329 0.11000008
0.14480000 0.14121469 0.10959024
0.14440000 0.14082960 0.10929166
0.14400000 0.14060192 0.10911514
0.14360000 0.14030173 0.10888239
0.14320000 0.13993779 0.10860021
0.14280000 0.13933039 0.10812927
0.14240000 0.13879319 0.10771276
0.14200000 0.13854724 0.10752207
0.14160000 0.13797701 0.10707995
0.14120000 0.13759475 0.10678357
0.14080000 0.13758002 0.10677214
0.14040000 0.13717310 0.10645665
0.14000000 0.13674805 0.10612709
0.13960000 0.13612094 0.10564087
0.13920000 0.13542356 0.10510016
0.13880000 0.13530798 0.10501055
0.13840000 0.13486637 0.10466815
0.13800000 0.13474838 0.10457667
0.13760000 0.13443777 0.10433585
0.13720000 0.13399632 0.10399357
0.13680000 0.13340799 0.10353742
0.13640000 0.13290025 0.10314375
0.13600000 0.13236584 0.10272940
0.13560000 0.13199273 0.10244012
0.13520000 0.13194150 0.10240039
0.13480000 0.13148302 0.10204492
0.13440000 0.13099153 0.10166385
0.13400000 0.13068172 0.10142364
0.13360000 0.13024158 0.10108239
0.13320000 0.12966676 0.10063671
0.13280000 0.12930437 0.10035573
0.13240000 0.12899880 0.10011882
0.13200000 0.12864776 0.09984664
0.13160000 0.12827061 0.09955422
0.13120000 0.12781573 0.09920154
0.13080000 0.12750736 0.09896244
0.13040000 0.12715582 0.09868988
0.13000000 0.12656194 0.09822943
0.12960000 0.12597902 0.09777747
0.12920000 0.12570203 0.09756271
0.12880000 0.12539061 0.09732125
0.12840000 0.12511878 0.09711049
0.12800000 0.12472209 0.09680292
0.12760000 0.12438052 0.09653809
0.12720000 0.12377480 0.09606845
0.12680000 0.12335060 0.09573956
0.12640000 0.12298095 0.09545295
0.12600000 0.12247635 0.09506172
0.12560000 0.12232078 0.09494110
0.12520000 0.12195171 0.09465494
0.12480000 0.12156408 0.09435440
0.12440000 0.12094649 0.09387556
0.12400000 0.12062144 0.09362354
0.12360000 0.12013671 0.09324771
0.12320000 0.11981366 0.09299724
0.12280000 0.11946307 0.09272541
0.12240000 0.11915457 0.09248622
0.12200000 0.11875639 0.09217750
0.12160000 0.11809443 0.09166426
0.12120000 0.11778151 0.09142164
0.12080000 0.11735732 0.09109275
0.12040000 0.11703356 0.09084172
0.12000000 0.11662528 0.09052517
0.11960000 0.11625491 0.09023801
0.11920000 0.11592105 0.08997915
0.11880000 0.11547985 0.08963707
0.11840000 0.11505473 0.08930746
0.11800000 0.11456234 0.08892570
0.11760000 0.11424181 0.08867718
0.11720000 0.11389504 0.08840831
0.11680000 0.11348564 0.08809089
0.11640000 0.11300457 0.08771790
0.11600000 0.11281479 0.08757076
0.11560000 0.11246214 0.08729733
0.11520000 0.11201168 0.08694808
0.11480000 0.11140214 0.08647548
0.11440000 0.11085062 0.08604787
0.11400000 0.11072368 0.08594944
0.11360000 0.11045021 0.08573741
0.11320000 0.11012854 0.08548801
0.11280000 0.10952525 0.08502025
0.11240000 0.10919386 0.08476332
0.11200000 0.10880618 0.08446273
0.11160000 0.10828628 0.08405964
0.11120000 0.10779579 0.08367934
0.11080000 0.10759214 0.08352145
0.11040000 0.10720860 0.08322407
0.11000000 0.10669509 0.08282593
0.10960000 0.10635198 0.08255990
0.10920000 0.10571495 0.08206599
0.10880000 0.10543033 0.08184531
0.10840000 0.10522862 0.08168892
0.10800000 0.10488982 0.08142623
0.10760000 0.10444231 0.08107927
0.10720000 0.10399601 0.08073323
0.10680000 0.10352316 0.08036662
0.10640000 0.10325281 0.08015700
0.10600000 0.10277434 0.07978603
0.10560000 0.10232138 0.07943483
0.10520000 0.10205507 0.07922835
0.10480000 0.10173649 0.07898134
0.10440000 0.10124656 0.07860148
0.10400000 0.10059100 0.07809321
0.10360000 0.10027365 0.07784715
0.10320000 0.09982141 0.07749651
0.10280000 0.09954456 0.07728186
0.10240000 0.09922010 0.07703030
0.10200000 0.09882471 0.07672373
0.10160000 0.09852725 0.07649311
0.10120000 0.09798133 0.07606983
0.10080000 0.09747104 0.07567418
0.10040000 0.09725248 0.07550472
0.10000000 0.09678400 0.07514150
0.09960000 0.09636590 0.07481733
0.09920000 0.09590996 0.07446383
0.09880000 0.09567457 0.07428132
0.09840000 0.09534956 0.07402932
0.09800000 0.09484340 0.07363688
0.09760000 0.09438180 0.07327898
0.09720000 0.09408798 0.07305117
0.09680000 0.09375120 0.07279006
0.09640000 0.09330827 0.07244664
0.09600000 0.09301954 0.07222277
0.09560000 0.09254058 0.07185142
0.09520000 0.09203771 0.07146152
0.09480000 0.09152517 0.07106414
0.09440000 0.09116742 0.07078675
0.09400000 0.09076870 0.07047761
0.09360000 0.09038728 0.07018189
0.09320000 0.09002064 0.06989762
0.09280000 0.08972936 0.06967178
0.09240000 0.08921124 0.06927006
0.09200000 0.08860742 0.06880189
0.09160000 0.08832602 0.06858371
0.09120000 0.08797860 0.06831435
0.09080000 0.08752416 0.06796201
0.09040000 0.08700956 0.06756301
0.09000000 0.08729589 0.06778502
0.08960000 0.08659675 0.06724295
0.08920000 0.08624569 0.06697076
0.08880000 0.08560650 0.06647517
0.08840000 0.08538085 0.06630022
0.08800000 0.08509904 0.06608172
0.08760000 0.08455728 0.06566167
0.08720000 0.08408369 0.06529448
0.08680000 0.08379486 0.06507054
0.08640000 0.08333170 0.06471144
0.08600000 0.08281476 0.06431063
0.08560000 0.08240664 0.06399421
0.08520000 0.08224178 0.06386638
0.08480000 0.08170288 0.06344856
0.08440000 0.08109345 0.06297604
0.08400000 0.08076232 0.06271930
0.08360000 0.08053638 0.06254412
0.08320000 0.08010777 0.06221181
0.08280000 0.07982117 0.06198959
0.08240000 0.07932948 0.06160837
0.08200000 0.07882703 0.06121880
0.08160000 0.07839126 0.06088094
0.08120000 0.07814375 0.06068903
0.08080000 0.07776769 0.06039746
0.08040000 0.07740552 0.06011665
0.08000000 0.07703751 0.05983132
0.07960000 0.07653627 0.05944269
0.07920000 0.07605399 0.05906876
0.07880000 0.07575255 0.05883504
0.07840000 0.07553747 0.05866829
0.07800000 0.07490743 0.05817979
0.07760000 0.07449157 0.05785736
0.07720000 0.07421329 0.05764160
0.07680000 0.07374827 0.05728105
0.07640000 0.07333396 0.05695982
0.07600000 0.07279038 0.05653836
0.07560000 0.07253192 0.05633797
0.07520000 0.07222625 0.05610098
0.07480000 0.07160935 0.05562267
0.07440000 0.07104570 0.05518565
0.07400000 0.07082185 0.05501209
0.07360000 0.07054922 0.05480071
0.07320000 0.07006060 0.05442187
0.07280000 0.06975490 0.05418485
0.07240000 0.06945054 0.05394886
0.07200000 0.06889413 0.05351746
0.07160000 0.06849674 0.05320935
0.07120000 0.06822869 0.05300152
0.07080000 0.06774195 0.05262414
0.07040000 0.06745580 0.05240227
0.07000000 0.06698075 0.05203394
0.06960000 0.06651809 0.05167523
0.06920000 0.06602364 0.05129187
0.06880000 0.06578868 0.05110969
0.06840000 0.06515155 0.05061570
0.06800000 0.06509610 0.05057271
0.06760000 0.06472523 0.05028516
0.06720000 0.06429827 0.04995412
0.06680000 0.06369525 0.04948658
0.06640000 0.06327979 0.04916446
0.06600000 0.06278959 0.04878439
0.06560000 0.06247393 0.04853964
0.06520000 0.06232690 0.04842565
0.06480000 0.06186114 0.04806452
0.06440000 0.06127074 0.04760677
0.06400000 0.06083660 0.04727016
0.06360000 0.06043478 0.04695861
0.06320000 0.06048370 0.04699655
0.06280000 0.06004453 0.04665604
0.06240000 0.05937304 0.04613541
0.06200000 0.05896975 0.04582272
0.06160000 0.05855549 0.04550154
0.06120000 0.05818771 0.04521638
0.06080000 0.05777859 0.04489917
0.06040000 0.05752789 0.04470480
0.06000000 0.05704797 0.04433270
0.05960000 0.05664496 0.04402023
0.05920000 0.05616597 0.04364885
0.05880000 0.05588437 0.04343051
0.05840000 0.05534708 0.04301394
0.05800000 0.05484303 0.04262313
0.05760000 0.05458725 0.04242481
0.05720000 0.05440376 0.04228255
0.05680000 0.05393517 0.04191923
0.05640000 0.05335573 0.04146997
0.05600000 0.05306717 0.04124623
0.05560000 0.05293722 0.04114548
0.05520000 0.05221839 0.04058815
0.05480000 0.05181305 0.04027388
0.05440000 0.05125781 0.03984338
0.05400000 0.05115722 0.03976539
0.05360000 0.05066094 0.03938060
0.05320000 0.05009669 0.03894312
0.05280000 0.04978393 0.03870062
0.05240000 0.04943445 0.03842966
0.05200000 0.04902455 0.03811185
0.05160000 0.04865320 0.03782393
0.05120000 0.04831948 0.03756518
0.05080000 0.04790553 0.03724423
0.05040000 0.04736661 0.03682638
0.05000000 0.04684908 0.03642513
0.04960000 0.04658478 0.03622020
0.04920000 0.04623176 0.03594649
0.04880000 0.04587043 0.03566634
0.04840000 0.04528821 0.03521492
0.04800000 0.04487025 0.03489087
0.04760000 0.04462345 0.03469951
0.04720000 0.04431747 0.03446228
0.04680000 0.04377626 0.03404266
0.04640000 0.04346809 0.03380372
0.04600000 0.04308890 0.03350972
0.04560000 0.04272336 0.03322631
0.04520000 0.04218279 0.03280718
0.04480000 0.04182160 0.03252713
0.04440000 0.04146575 0.03225123
0.04400000 0.04105088 0.03192957
0.04360000 0.04077246 0.03171370
0.04320000 0.04034308 0.03138078
0.04280000 0.03993551 0.03106478
0.04240000 0.03941979 0.03066493
0.04200000 0.03894001 0.03029293
0.04160000 0.03869322 0.03010159
0.04120000 0.03834485 0.02983149
0.04080000 0.03793715 0.02951538
0.04040000 0.03753021 0.02919986
0.04000000 0.03706870 0.02884204
0.03960000 0.03669888 0.02855531
0.03920000 0.03624662 0.02820465
0.03880000 0.03573574 0.02780855
0.03840000 0.03547615 0.02760728
0.03800000 0.03517895 0.02737685
0.03760000 0.03484978 0.02712163
0.03720000 0.03449295 0.02684496
0.03680000 0.03405768 0.02650748
0.03640000 0.03347159 0.02605307
0.03600000 0.03302652 0.02570799
0.03560000 0.03285264 0.02557318
0.03520000 0.03246926 0.02527593
0.03480000 0.03213147 0.02501402
0.03440000 0.03145311 0.02448806
0.03400000 0.03114171 0.02424663
0.03360000 0.03081976 0.02399700
0.03320000 0.03033815 0.02362359
0.03280000 0.02979887 0.02320547
0.03240000 0.02940193 0.02289771
0.03200000 0.02918214 0.02272730
0.03160000 0.02906216 0.02263427
0.03120000 0.02853883 0.02222852
0.03080000 0.02783444 0.02168238
0.03040000 0.02722715 0.02121152
0.03000000 0.02698925 0.02102707
0.02960000 0.02686669 0.02093205
0.02920000 0.02638985 0.02056234
0.02880000 0.02586775 0.02015753
0.02840000 0.02549233 0.01986646
0.02800000 0.02508592 0.01955135
0.02760000 0.02471423 0.01926316
0.02720000 0.02434239 0.01897486
0.02680000 0.02392533 0.01865151
0.02640000 0.02352957 0.01834465
0.02600000 0.02321504 0.01810079
0.02560000 0.02278777 0.01776951
0.02520000 0.02237974 0.01745315
0.02480000 0.02195312 0.01712238
0.02440000 0.02153518 0.01679833
0.02400000 0.02121031 0.01654645
0.02360000 0.02087817 0.01628893
0.02320000 0.02035308 0.01588180
0.02280000 0.01990527 0.01553460
0.02240000 0.01937517 0.01512359
0.02200000 0.01910571 0.01491467
0.02160000 0.01894103 0.01478699
0.02120000 0.01843896 0.01439772
0.02080000 0.01845269 0.01440837
0.02040000 0.01787020 0.01395674
0.02000000 0.01737175 0.01357027
0.01960000 0.01691265 0.01321432
0.01920000 0.01635864 0.01278477
0.01880000 0.01590896 0.01243612
0.01840000 0.01550756 0.01212490
0.01800000 0.01537585 0.01202278
0.01760000 0.01504503 0.01176628
0.01720000 0.01443529 0.01129352
0.01680000 0.01390046 0.01087886
0.01640000 0.01356220 0.01061659
0.01600000 0.01325466 0.01037814
0.01560000 0.01300503 0.01018459
0.01520000 0.01282665 0.01004629
0.01480000 0.01205301 0.00944645
0.01440000 0.01155435 0.00905983
0.01400000 0.01104952 0.00866841
0.01360000 0.01080424 0.00847824
0.01320000 0.01035740 0.00813179
0.01280000 0.01024579 0.00804526
0.01240000 0.00990907 0.00778418
0.01200000 0.00941265 0.00739929
0.01160000 0.00869736 0.00684470
0.01120000 0.00823092 0.00648305
0.01080000 0.00789109 0.00621957
0.01040000 0.00765825 0.00603904
0.01000000 0.00736115 0.00580868
0.00960000 0.00698519 0.00551719
0.00920000 0.00661550 0.00523056
0.00880000 0.00605952 0.00479949
0.00840000 0.00559820 0.00444181
0.00800000 0.00520915 0.00414017
0.00760000 0.00494873 0.00393825
0.00720000 0.00447334 0.00356966
0.00680000 0.00419833 0.00335644
0.00640000 0.00370442 0.00297349
0.00600000 0.00330782 0.00266599
0.00560000 0.00275766 0.00223943
0.00520000 0.00231731 0.00189801
0.00480000 0.00205911 0.00169782
0.00440000 0.00172230 0.00143668
0.00400000 0.00154397 0.00129841