File: plots/rawdata/Figure1c_full.txt
# strain (%), stress (GPa)
0.00000000 0.05467558
0.01360000 0.06347798
0.02720000 0.07278568
0.04080000 0.08198218
0.05440000 0.09120320
0.06800000 0.09998374
0.08160000 0.10910907
0.09520000 0.11816867
0.10880000 0.12750085
0.12240000 0.13662849
0.13600000 0.14603494
0.14960000 0.15530773
0.16320000 0.16454425
0.17680000 0.17366450
0.19040000 0.18284161
0.20400000 0.19208170
0.21760000 0.20112277
0.23120000 0.21025870
0.24480000 0.21934917
0.25840000 0.22862366
0.27200000 0.23772613
0.28560000 0.24705739
0.29920000 0.25646632
0.31280000 0.26587155
0.32640000 0.27505679
0.34000000 0.28420448
0.35360000 0.29313422
0.36720000 0.30194759
0.38080000 0.31125855
0.39440000 0.32048568
0.40800000 0.33000681
0.42160000 0.33904268
0.43520000 0.34850091
0.44880000 0.35771609
0.46240000 0.36720049
0.47600000 0.37652219
0.48960000 0.38603748
0.50320000 0.39536606
0.51680000 0.40452357
0.53040000 0.41374530
0.54400000 0.42301453
0.55760000 0.43225976
0.57120000 0.44164235
0.58480000 0.45079430
0.59840000 0.46042312
0.61200000 0.46927548
0.62560000 0.47850307
0.63920000 0.48753859
0.65280000 0.49708214
0.66640000 0.50633761
0.68000000 0.51545332
0.69360000 0.52505467
0.70720000 0.53512901
0.72080000 0.54459947
0.73440000 0.55350975
0.74800000 0.56210178
0.76160000 0.57127878
0.77520000 0.58060841
0.78880000 0.59010326
0.80240000 0.59965639
0.81600000 0.60913208
0.82960000 0.61864570
0.84320000 0.62782360
0.85680000 0.63676409
0.87040000 0.64585396
0.88400000 0.65514607
0.89760000 0.66424199
0.91120000 0.67356032
0.92480000 0.68286309
0.93840000 0.69247240
0.95200000 0.70160223
0.96560000 0.71111579
0.97920000 0.72023168
0.99280000 0.72938233
1.00640000 0.73845103
1.02000000 0.74809894
1.03360000 0.75752866
1.04720000 0.76677524
1.06080000 0.77632412
1.07440000 0.78580148
1.08800000 0.79526414
1.10160000 0.80416664
1.11520000 0.81323135
1.12880000 0.82255750
1.14240000 0.83180014
1.15600000 0.84073861
1.16960000 0.84956530
1.18320000 0.85869049
1.19680000 0.86776505
1.21040000 0.87701077
1.22400000 0.88640877
1.23760000 0.89556468
1.25120000 0.90423838
1.26480000 0.91334404
1.27840000 0.92286852
1.29200000 0.93190658
1.30560000 0.94094329
1.31920000 0.95007952
1.33280000 0.95965281
1.34640000 0.96867449
1.36000000 0.97725620
1.37360000 0.98645905
1.38720000 0.99556766
1.40080000 1.00549866
1.41440000 1.01436109
1.42800000 1.02389194
1.44160000 1.03280221
1.45520000 1.04174157
1.46880000 1.05006182
1.48240000 1.05844601
1.49600000 1.06774978
1.50960000 1.07724758
1.52320000 1.08701980
1.53680000 1.09612293
1.55040000 1.10556763
1.56400000 1.11471881
1.57760000 1.12348517
1.59120000 1.13300932
1.60480000 1.14237745
1.61840000 1.15203849
1.63200000 1.16108334
1.64560000 1.17009979
1.65920000 1.17891498
1.67280000 1.18806655
1.68640000 1.19651618
1.70000000 1.20535978
1.71360000 1.21441538
1.72720000 1.22407933
1.74080000 1.23345931
1.75440000 1.24250054
1.76800000 1.25189255
1.78160000 1.26172695
1.79520000 1.27082484
1.80880000 1.28000515
1.82240000 1.28926806
1.83600000 1.29894215
1.84960000 1.30713000
1.86320000 1.31538822
1.87680000 1.32382809
1.89040000 1.33328506
1.90400000 1.34282724
1.91760000 1.35221861
1.93120000 1.36188374
1.94480000 1.37102813
1.95840000 1.38050764
1.97200000 1.38973900
1.98560000 1.39910926
1.99920000 1.40822725
2.01280000 1.41755970
2.02640000 1.42724240
2.04000000 1.43675847
2.05360000 1.44609653
2.06720000 1.45525474
2.08080000 1.46456841
2.09440000 1.47381982
2.10800000 1.48300841
2.12160000 1.49237660
2.13520000 1.50136222
2.14880000 1.51007155
2.16240000 1.51900060
2.17600000 1.52820578
2.18960000 1.53772024
2.20320000 1.54682173
2.21680000 1.55581963
2.23040000 1.56489348
2.24400000 1.57399483
2.25760000 1.58340649
2.27120000 1.59268915
2.28480000 1.60212222
2.29840000 1.61125725
2.31200000 1.62090567
2.32560000 1.63036687
2.33920000 1.63978068
2.35280000 1.64912011
2.36640000 1.65799095
2.38000000 1.66754445
2.39360000 1.67678423
2.40720000 1.68658209
2.42080000 1.69582648
2.43440000 1.70533822
2.44800000 1.71462991
2.46160000 1.72418052
2.47520000 1.73342193
2.48880000 1.74323296
2.50240000 1.75296973
2.51600000 1.76220074
2.52960000 1.77127023
2.54320000 1.78032438
2.55680000 1.78949198
2.57040000 1.79870153
2.58400000 1.80846976
2.59760000 1.81805420
2.61120000 1.82792037
2.62480000 1.83768442
2.63840000 1.84746721
2.65200000 1.85644022
2.66560000 1.86595729
2.67920000 1.87572699
2.69280000 1.88530522
2.70640000 1.89474304
2.72000000 1.90412247
2.73360000 1.91364805
2.74720000 1.92290532
2.76080000 1.93211536
2.77440000 1.94165452
2.78800000 1.95143334
2.80160000 1.96123033
2.81520000 1.97051987
2.82880000 1.97943407
2.84240000 1.98877146
2.85600000 1.99828188
2.86960000 2.00774793
2.88320000 2.01664306
2.89680000 2.02558417
2.91040000 2.03427612
2.92400000 2.04334769
2.93760000 2.05228161
2.95120000 2.06166584
2.96480000 2.07119021
2.97840000 2.08083592
2.99200000 2.09021608
3.00560000 2.09955653
3.01920000 2.10976067
3.03280000 2.11924127
3.04640000 2.12864726
3.06000000 2.13779896
3.07360000 2.14746896
3.08720000 2.15685243
3.10080000 2.16505162
3.11440000 2.17457457
3.12800000 2.18370350
3.14160000 2.19392747
3.15520000 2.20320906
3.16880000 2.21321338
3.18240000 2.22265844
3.19600000 2.23223058
3.20960000 2.24209727
3.22320000 2.25175856
3.23680000 2.26141313
3.25040000 2.27074492
3.26400000 2.28098688
3.27760000 2.29057426
3.29120000 2.29965822
3.30480000 2.30872923
3.31840000 2.31846500
3.33200000 2.32827953
3.34560000 2.33789051
3.35920000 2.34784885
3.37280000 2.35713618
3.38640000 2.36698359
3.40000000 2.37618984
3.41360000 2.38538801
3.42720000 2.39408340
3.44080000 2.40296729
3.45440000 2.41259807
3.46800000 2.42228645
3.48160000 2.43097687
3.49520000 2.44068267
3.50880000 2.45025779
3.52240000 2.46103654
3.53600000 2.47042120
3.54960000 2.47934757
3.56320000 2.48850430
3.57680000 2.49783178
3.59040000 2.50717748
3.60400000 2.51623525
3.61760000 2.52576791
3.63120000 2.53541127
3.64480000 2.54465627
3.65840000 2.55477968
3.67200000 2.56524140
3.68560000 2.57515846
3.69920000 2.58510152
3.71280000 2.59315039
3.72640000 2.60241488
3.74000000 2.61112444
3.75360000 2.62108166
3.76720000 2.63123101
3.78080000 2.64123874
3.79440000 2.65095666
3.80800000 2.66026203
3.82160000 2.66853678
3.83520000 2.67831738
3.84880000 2.68775523
3.86240000 2.69827760
3.87600000 2.70756030
3.88960000 2.71673143
3.90320000 2.72525467
3.91680000 2.73378410
3.93040000 2.74344730
3.94400000 2.75152671
3.95760000 2.75974179
3.97120000 2.76868384
3.98480000 2.77911840
3.99840000 2.78940357
4.01200000 2.79839195
4.02560000 2.80827839
4.03920000 2.81808261
4.05280000 2.82821879
4.06640000 2.83857596
4.08000000 2.84864549
4.09360000 2.85752976
4.10720000 2.86491714
4.12080000 2.87225582
4.13440000 2.88068741
4.14800000 2.88990651
4.16160000 2.89860595
4.17520000 2.90740609
4.18880000 2.91721583
4.20240000 2.92657873
4.21600000 2.93630433
4.22960000 2.94565422
4.24320000 2.95699185
4.25680000 2.96709999
4.27040000 2.97633087
4.28400000 2.98454619
4.29760000 2.99390106
4.31120000 3.00343210
4.32480000 3.01262907
4.33840000 3.02218733
4.35200000 3.03111495
4.36560000 3.03863966
4.37920000 3.04586864
4.39280000 3.05500219
4.40640000 3.06495822
4.42000000 3.07414458
4.43360000 3.08223592
4.44720000 3.09138342
4.46080000 3.10156730
4.47440000 3.11189356
4.48800000 3.12219193
4.50160000 3.13084642
4.51520000 3.14082477
4.52880000 3.14923308
4.54240000 3.15874512
4.55600000 3.16404493
4.56960000 3.17044735
4.58320000 3.17712826
4.59680000 3.18685996
4.61040000 3.19627076
4.62400000 3.20628205
4.63760000 3.21614577
4.65120000 3.22622014
4.66480000 3.23603418
4.67840000 3.24433688
4.69200000 3.25340924
4.70560000 3.26026059
4.71920000 3.26978104
4.73280000 3.27884681
4.74640000 3.28986803
4.76000000 3.30061199
4.77360000 3.31062279
4.78720000 3.31927507
4.80080000 3.32756351
4.81440000 3.33663692
4.82800000 3.34549679
4.84160000 3.35463927
4.85520000 3.36325679
4.86880000 3.37165068
4.88240000 3.37984814
4.89600000 3.38704451
4.90960000 3.39517416
4.92320000 3.40381708
4.93680000 3.41291960
4.95040000 3.42162976
4.96400000 3.42987202
4.97760000 3.43866490
4.99120000 3.44847258
5.00480000 3.45682220
5.01840000 3.46592010
5.03200000 3.47472892
5.04560000 3.48494938
5.05920000 3.49441601
5.07280000 3.50350236
5.08640000 3.51173684
5.10000000 3.52074369
5.11360000 3.52967231
5.12720000 3.53918971
5.14080000 3.54767344
5.15440000 3.55649145
5.16800000 3.56481630
5.18160000 3.57346197
5.19520000 3.58191172
5.20880000 3.59050214
5.22240000 3.60043011
5.23600000 3.61048302
5.24960000 3.61902768
5.26320000 3.62626227
5.27680000 3.63478982
5.29040000 3.64444700
5.30400000 3.65375296
5.31760000 3.66137873
5.33120000 3.66961326
5.34480000 3.67740909
5.35840000 3.68424114
5.37200000 3.68962056
5.38560000 3.69673993
5.39920000 3.70590446
5.41280000 3.71555556
5.42640000 3.72387878
5.44000000 3.73045743
5.45360000 3.73829681
5.46720000 3.74574832
5.48080000 3.75488593
5.49440000 3.76328180
5.50800000 3.77159543
5.52160000 3.77997982
5.53520000 3.78867280
5.54880000 3.79611008
5.56240000 3.80290406
5.57600000 3.81065514
5.58960000 3.81954303
5.60320000 3.82706566
5.61680000 3.83634701
5.63040000 3.84621399
5.64400000 3.85705449
5.65760000 3.86380730
5.67120000 3.87016173
5.68480000 3.87689037
5.69840000 3.88550400
5.71200000 3.89440062
5.72560000 3.90353812
5.73920000 3.91157237
5.75280000 3.92096774
5.76640000 3.93044886
5.78000000 3.93974207
5.79360000 3.94651967
5.80720000 3.95126900
5.82080000 3.95597614
5.83440000 3.96263372
5.84800000 3.97016317
5.86160000 3.98032552
5.87520000 3.98981124
5.88880000 3.99955111
5.90240000 4.00687534
5.91600000 4.01410772
5.92960000 4.02187743
5.94320000 4.03006647
5.95680000 4.03798829
5.97040000 4.04671150
5.98400000 4.05621466
5.99760000 4.06601720
6.01120000 4.07522486
6.02480000 4.08543629
6.03840000 4.09384538
6.05200000 4.10019986
6.06560000 4.10663217
6.07920000 4.11438621
6.09280000 4.12444517
6.10640000 4.13547724
6.12000000 4.14702536
6.13360000 4.15722208
6.14720000 4.16418760
6.16080000 4.17031705
6.17440000 4.17763155
6.18800000 4.18464599
6.20160000 4.19242030
6.21520000 4.20027949
6.22880000 4.20935432
6.24240000 4.21729548
6.25600000 4.22600566
6.26960000 4.23379480
6.28320000 4.24141111
6.29680000 4.24748043
6.31040000 4.25480251
6.32400000 4.26311006
6.33760000 4.27198948
6.35120000 4.28158878
6.36480000 4.28997930
6.37840000 4.29797873
6.39200000 4.30415770
6.40560000 4.31125539
6.41920000 4.31924726
6.43280000 4.32782138
6.44640000 4.33773479
6.46000000 4.34748656
6.47360000 4.35598473
6.48720000 4.36373353
6.50080000 4.37186723
6.51440000 4.37973957
6.52800000 4.38739877
6.54160000 4.39426538
6.55520000 4.40246466
6.56880000 4.41135008
6.58240000 4.41931506
6.59600000 4.42496817
6.60960000 4.42815676
6.62320000 4.43242877
6.63680000 4.43826464
6.65040000 4.44582221
6.66400000 4.45406220
6.67760000 4.46136953
6.69120000 4.46769709
6.70480000 4.47103014
6.71840000 4.47733853
6.73200000 4.48520024
6.74560000 4.49419412
6.75920000 4.50279292
6.77280000 4.50985125
6.78640000 4.51835677
6.80000000 4.52552411
6.81360000 4.53390545
6.82720000 4.54126411
6.84080000 4.54813680
6.85440000 4.55482138
6.86800000 4.56171501
6.88160000 4.56984517
6.89520000 4.57861711
6.90880000 4.58713978
6.92240000 4.59270352
6.93600000 4.59838737
6.94960000 4.60447891
6.96320000 4.61160384
6.97680000 4.61814434
6.99040000 4.62487746
7.00400000 4.63262820
7.01760000 4.63695512
7.03120000 4.64125299
7.04480000 4.64477425
7.05840000 4.65254106
7.07200000 4.65960658
7.08560000 4.66648639
7.09920000 4.67199207
7.11280000 4.67731850
7.12640000 4.68447460
7.14000000 4.69267335
7.15360000 4.70134559
7.16720000 4.70765664
7.18080000 4.71579644
7.19440000 4.72370593
7.20800000 4.73214518
7.22160000 4.73888488
7.23520000 4.74739933
7.24880000 4.75486645
7.26240000 4.76223368
7.27600000 4.76796819
7.28960000 4.77409350
7.30320000 4.78163466
7.31680000 4.79008906
7.33040000 4.79674656
7.34400000 4.80140036
7.35760000 4.80606043
7.37120000 4.81146271
7.38480000 4.81737407
7.39840000 4.82330594
7.41200000 4.83021720
7.42560000 4.83760748
7.43920000 4.84427643
7.45280000 4.84750265
7.46640000 4.84866183
7.48000000 4.84520121
7.49360000 4.84363150
7.50720000 4.84379272
7.52080000 4.84805743
7.53440000 4.85541705
7.54800000 4.86242297
7.56160000 4.86876388
7.57520000 4.87482615
7.58880000 4.87444568
7.60240000 4.87513697
7.61600000 4.87337179
7.62960000 4.87786163
7.64320000 4.88565111
7.65680000 4.89286019
7.67040000 4.90092839
7.68400000 4.90506556
7.69760000 4.91087296
7.71120000 4.91427426
7.72480000 4.91798758
7.73840000 4.92293300
7.75200000 4.92777746
7.76560000 4.93406920
7.77920000 4.93808532
7.79280000 4.94285890
7.80640000 4.94941916
7.82000000 4.95675032
7.83360000 4.96209976
7.84720000 4.95937724
7.86080000 4.95897570
7.87440000 4.95886572
7.88800000 4.96084694
7.90160000 4.96069593
7.91520000 4.96498970
7.92880000 4.97209575
7.94240000 4.98023869
7.95600000 4.98578731
7.96960000 4.98946908
7.98320000 4.99273738
7.99680000 4.99725632
8.01040000 5.00398334
8.02400000 5.00897656
8.03760000 5.01509039
8.05120000 5.01983433
8.06480000 5.02332890
8.07840000 5.02644302
8.09200000 5.03079605
8.10560000 5.03411159
8.11920000 5.03830773
8.13280000 5.03473283
8.14640000 5.03310715
8.16000000 5.03039253
8.17360000 5.03427044
8.18720000 5.03338154
8.20080000 5.03166107
8.21440000 5.02942357
8.22800000 5.02539739
8.24160000 5.02290874
8.25520000 5.02261255
8.26880000 5.03071412
8.28240000 5.03757518
8.29600000 5.04192145
8.30960000 5.04344495
8.32320000 5.04576543
8.33680000 5.05221318
8.35040000 5.05576715
8.36400000 5.05571154
8.37760000 5.05095766
8.39120000 5.04918485
8.40480000 5.05014820
8.41840000 5.05104087
8.43200000 5.05162037
8.44560000 5.05013079
8.45920000 5.05296952
8.47280000 5.05834725
8.48640000 5.06602521
8.50000000 5.07393820
8.51360000 5.08210524
8.52720000 5.09013540
8.54080000 5.09532854
8.55440000 5.09938779
8.56800000 5.10440184
8.58160000 5.11152393
8.59520000 5.11693899
8.60880000 5.12449593
8.62240000 5.12971924
8.63600000 5.13654853
8.64960000 5.14252615
8.66320000 5.14623664
8.67680000 5.15065476
8.69040000 5.15277339
8.70400000 5.15849695
8.71760000 5.16345546
8.73120000 5.16922835
8.74480000 5.17611438
8.75840000 5.18346433
8.77200000 5.18735767
8.78560000 5.17965927
8.79920000 5.16534614
8.81280000 5.15336239
8.82640000 5.15240629
8.84000000 5.15646056
8.85360000 5.16371029
8.86720000 5.17106307
8.88080000 5.17874768
8.89440000 5.18128905
8.90800000 5.18478984
8.92160000 5.18821790
8.93520000 5.19473862
8.94880000 5.20027152
8.96240000 5.20359203
8.97600000 5.20750005
8.98960000 5.21031832
9.00320000 5.21617905
9.01680000 5.22297264
9.03040000 5.22927870
9.04400000 5.23096680
9.05760000 5.23270197
9.07120000 5.22776442
9.08480000 5.21822255
9.09840000 5.20350012
9.11200000 5.19356440
9.12560000 5.18834904
9.13920000 5.17761250
9.15280000 5.17278553
9.16640000 5.16620700
9.18000000 5.16419034
9.19360000 5.15447247
9.20720000 5.14872243
9.22080000 5.14770238
9.23440000 5.15488327
9.24800000 5.16231149
9.26160000 5.16630351
9.27520000 5.15521314
9.28880000 5.14286380
9.30240000 5.12596943
9.31600000 5.10837885
9.32960000 5.08625148
9.34320000 5.07116671
9.35680000 5.07142263
9.37040000 5.07408949
9.38400000 5.07468641
9.39760000 5.07321358
9.41120000 5.07504041
9.42480000 5.08046747
9.43840000 5.08817430
9.45200000 5.09572950
9.46560000 5.10022035
9.47920000 5.09852997
9.49280000 5.08534610
9.50640000 5.07155471
9.52000000 5.06057585
9.53360000 5.06187439
9.54720000 5.05637477
9.56080000 5.04766077
9.57440000 5.02637106
9.58800000 5.01591547
9.60160000 5.01110490
9.61520000 5.01756067
9.62880000 5.02365435
9.64240000 5.02923168
9.65600000 5.03183332
9.66960000 5.03170307
9.68320000 5.02616485
9.69680000 5.02167005
9.71040000 5.01895759
9.72400000 5.02149581
9.73760000 5.02855965
9.75120000 5.02766688
9.76480000 5.02224562
9.77840000 4.99741594
9.79200000 4.97172244
9.80560000 4.94195978
9.81920000 4.92238950
9.83280000 4.91129124
9.84640000 4.90788643
9.86000000 4.90416336
9.87360000 4.89865349
9.88720000 4.89487229
9.90080000 4.89850284
9.91440000 4.90410542
9.92800000 4.90846820
9.94160000 4.90869285
9.95520000 4.90860149
9.96880000 4.90887307
9.98240000 4.91336171
9.99600000 4.91943286
10.00960000 4.92656797
10.02320000 4.93484475
10.03680000 4.94259552
10.05040000 4.94858013
10.06400000 4.95199495
10.07760000 4.95815682
10.09120000 4.96611499
10.10480000 4.97623445
10.11840000 4.98340159
10.13200000 4.98908733
10.14560000 4.99545891
10.15920000 5.00247382
10.17280000 5.01045973
10.18640000 5.01754503
10.20000000 5.02549710
10.21360000 5.03178710
10.22720000 5.03909200
10.24080000 5.04624346
10.25440000 5.05409367
10.26800000 5.06038351
10.28160000 5.06097722
10.29520000 5.05908209
10.30880000 5.05772683
10.32240000 5.06084344
10.33600000 5.06524254
10.34960000 5.07066684
10.36320000 5.07608817
10.37680000 5.07272082
10.39040000 5.06052188
10.40400000 5.04667915
10.41760000 5.03671946
10.43120000 5.02188250
10.44480000 4.98972723
10.45840000 4.95209525
10.47200000 4.91852628
10.48560000 4.88595685
10.49920000 4.86179577
10.51280000 4.84198302
10.52640000 4.80411900
10.54000000 4.73172897
10.55360000 4.64498342
10.56720000 4.59123161
10.58080000 4.56284105
10.59440000 4.54867048
10.60800000 4.54274399
10.62160000 4.54077404
10.63520000 4.53141977
10.64880000 4.50618206
10.66240000 4.48435739
10.67600000 4.46494349
10.68960000 4.45543268
10.70320000 4.45254064
10.71680000 4.46326597
10.73040000 4.47220324
10.74400000 4.48287040
10.75760000 4.48738933
10.77120000 4.49510753
10.78480000 4.49752089
10.79840000 4.50210110
10.81200000 4.50714588
10.82560000 4.51509385
10.83920000 4.52405503
10.85280000 4.52770341
10.86640000 4.53281181
10.88000000 4.53977734
10.89360000 4.54913372
10.90720000 4.55678806
10.92080000 4.56055873
10.93440000 4.56665172
10.94800000 4.57180904
10.96160000 4.57438764
10.97520000 4.57342011
10.98880000 4.57254654
11.00240000 4.57602806
11.01600000 4.58201241
11.02960000 4.58642511
11.04320000 4.58845866
11.05680000 4.59105735
11.07040000 4.59614303
11.08400000 4.60158273
11.09760000 4.60612083
11.11120000 4.60994628
11.12480000 4.61480899
11.13840000 4.60669459
11.15200000 4.59372146
11.16560000 4.57775164
11.17920000 4.56299068
11.19280000 4.53924539
11.20640000 4.51381573
11.22000000 4.50318326
11.23360000 4.50792837
11.24720000 4.51495552
11.26080000 4.52239239
11.27440000 4.52773734
11.28800000 4.53214597
11.30160000 4.53799298
11.31520000 4.54355233
11.32880000 4.54935808
11.34240000 4.55061265
11.35600000 4.55068601
11.36960000 4.54869742
11.38320000 4.53659977
11.39680000 4.52176338
11.41040000 4.50361896
11.42400000 4.49923040
11.43760000 4.49946776
11.45120000 4.50879608
11.46480000 4.51336783
11.47840000 4.51241117
11.49200000 4.50852099
11.50560000 4.50641411
11.51920000 4.50563994
11.53280000 4.50478980
11.54640000 4.50016143
11.56000000 4.50112042
11.57360000 4.50104089
11.58720000 4.50196954
11.60080000 4.49637510
11.61440000 4.49624209
11.62800000 4.49627195
11.64160000 4.49002792
11.65520000 4.48055549
11.66880000 4.47676015
11.68240000 4.47960484
11.69600000 4.48217095
11.70960000 4.48283702
11.72320000 4.48357832
11.73680000 4.48043353
11.75040000 4.47700712
11.76400000 4.47695900
11.77760000 4.47366578
11.79120000 4.47312678
11.80480000 4.47419765
11.81840000 4.48034364
11.83200000 4.48156994
11.84560000 4.48076359
11.85920000 4.47934853
11.87280000 4.48094195
11.88640000 4.48019452
11.90000000 4.47728773
11.91360000 4.46961479
11.92720000 4.45232169
11.94080000 4.44181409
11.95440000 4.43751708
11.96800000 4.44152344
11.98160000 4.43634406
11.99520000 4.42510665
12.00880000 4.41711556
12.02240000 4.41261919
12.03600000 4.41109270
12.04960000 4.41332153
12.06320000 4.41857381
12.07680000 4.42778828
12.09040000 4.43653222
12.10400000 4.44608357
12.11760000 4.45184427
12.13120000 4.45453006
12.14480000 4.45360964
12.15840000 4.45701217
12.17200000 4.46205219
12.18560000 4.46763101
12.19920000 4.47133205
12.21280000 4.47725013
12.22640000 4.48157002
12.24000000 4.48774878
12.25360000 4.49359495
12.26720000 4.50047100
12.28080000 4.50500617
12.29440000 4.50755984
12.30800000 4.51000542
12.32160000 4.51285802
12.33520000 4.51632098
12.34880000 4.51132008
12.36240000 4.50113330
12.37600000 4.48773342
12.38960000 4.47713333
12.40320000 4.46443063
12.41680000 4.45097515
12.43040000 4.43164673
12.44400000 4.42038161
12.45760000 4.41540439
12.47120000 4.42154040
12.48480000 4.42337701
12.49840000 4.42567946
12.51200000 4.42859640
12.52560000 4.41754658
12.53920000 4.40350058
12.55280000 4.38995233
12.56640000 4.39332777
12.58000000 4.39378619
12.59360000 4.38274706
12.60720000 4.37188070
12.62080000 4.37003823
12.63440000 4.37986360
12.64800000 4.38928044
12.66160000 4.39468743
12.67520000 4.39506300
12.68880000 4.39411503
12.70240000 4.39425299
12.71600000 4.39199275
12.72960000 4.38874679
12.74320000 4.38564358
12.75680000 4.38400614
12.77040000 4.38458013
12.78400000 4.38535972
12.79760000 4.39154923
12.81120000 4.39385270
12.82480000 4.39734346
12.83840000 4.39947518
12.85200000 4.39972183
12.86560000 4.39389741
12.87920000 4.37624828
12.89280000 4.35041833
12.90640000 4.32831367
12.92000000 4.32065488
12.93360000 4.32607433
12.94720000 4.33143551
12.96080000 4.33747850
12.97440000 4.34095906
12.98800000 4.34471707
13.00160000 4.35005332
13.01520000 4.35651020
13.02880000 4.36497066
13.04240000 4.37109573
13.05600000 4.37652334
13.06960000 4.38240988
13.08320000 4.38837781
13.09680000 4.39588788
13.11040000 4.40344666
13.12400000 4.41072130
13.13760000 4.40321134
13.15120000 4.38319329
13.16480000 4.36016748
13.17840000 4.35008543
13.19200000 4.35118870
13.20560000 4.35639847
13.21920000 4.35706916
13.23280000 4.35089634
13.24640000 4.34275975
13.26000000 4.34301188
13.27360000 4.34738595
13.28720000 4.35531965
13.30080000 4.36266999
13.31440000 4.36864785
13.32800000 4.37252135
13.34160000 4.37819574
13.35520000 4.38579656
13.36880000 4.39464416
13.38240000 4.40299115
13.39600000 4.41249236
13.40960000 4.42236496
13.42320000 4.42610039
13.43680000 4.42902248
13.45040000 4.42809267
13.46400000 4.43447413
13.47760000 4.44105273
13.49120000 4.45111679
13.50480000 4.45855286
13.51840000 4.46479261
13.53200000 4.46931897
13.54560000 4.47197387
13.55920000 4.47239835
13.57280000 4.47351014
13.58640000 4.47732340
13.60000000 4.48459827
13.61360000 4.49242093
13.62720000 4.49319781
13.64080000 4.49235637
13.65440000 4.49363201
13.66800000 4.50179479
13.68160000 4.50850046
13.69520000 4.51089987
13.70880000 4.51226459
13.72240000 4.51339538
13.73600000 4.51180229
13.74960000 4.50461436
13.76320000 4.49301796
13.77680000 4.47773150
13.79040000 4.46676183
13.80400000 4.46311900
13.81760000 4.46682703
13.83120000 4.47202682
13.84480000 4.47774197
13.85840000 4.48521837
13.87200000 4.49174312
13.88560000 4.49387073
13.89920000 4.49540993
13.91280000 4.49775580
13.92640000 4.50309535
13.94000000 4.50763631
13.95360000 4.51206218
13.96720000 4.51467843
13.98080000 4.51277386
13.99440000 4.50754498
14.00800000 4.50419390
14.02160000 4.50651458
14.03520000 4.51358965
14.04880000 4.52325419
14.06240000 4.53134061
14.07600000 4.53884703
14.08960000 4.54670190
14.10320000 4.55504708
14.11680000 4.56503690
14.13040000 4.57271132
14.14400000 4.58360237
14.15760000 4.59054711
14.17120000 4.59886249
14.18480000 4.60587903
14.19840000 4.61643220
14.21200000 4.62490736
14.22560000 4.63313555
14.23920000 4.64082614
14.25280000 4.64816945
14.26640000 4.65347867
14.28000000 4.65858627
14.29360000 4.66980800
14.30720000 4.68037696
14.32080000 4.68764266
14.33440000 4.68688081
14.34800000 4.68246698
14.36160000 4.67984273
14.37520000 4.68017152
14.38880000 4.68475023
14.40240000 4.69064330
14.41600000 4.69907507
14.42960000 4.70920362
14.44320000 4.71826953
14.45680000 4.72728815
14.47040000 4.73091677
14.48400000 4.73467341
14.49760000 4.73155947
14.51120000 4.72922204
14.52480000 4.72701641
14.53840000 4.73233442
14.55200000 4.74001927
14.56560000 4.74822950
14.57920000 4.75523818
14.59280000 4.76176794
14.60640000 4.76732007
14.62000000 4.77055369
14.63360000 4.77390577
14.64720000 4.77922618
14.66080000 4.78693449
14.67440000 4.79458777
14.68800000 4.79957996
14.70160000 4.80559641
14.71520000 4.81328509
14.72880000 4.82264659
14.74240000 4.83063456
14.75600000 4.83576070
14.76960000 4.84088960
14.78320000 4.84254369
14.79680000 4.84262524
14.81040000 4.83420092
14.82400000 4.82052781
14.83760000 4.80774637
14.85120000 4.80271548
14.86480000 4.80805900
14.87840000 4.81882987
14.89200000 4.82943999
14.90560000 4.83519898
14.91920000 4.83737493
14.93280000 4.84209238
14.94640000 4.84866517
14.96000000 4.85675845
14.97360000 4.86023964
14.98720000 4.86236442
15.00080000 4.86370868
15.01440000 4.86897630
15.02800000 4.87643655
15.04160000 4.87573890
15.05520000 4.86484881
15.06880000 4.85441713
15.08240000 4.84630858
15.09600000 4.83371057
15.10960000 4.82204134
15.12320000 4.81545235
15.13680000 4.81677000
15.15040000 4.81854363
15.16400000 4.82249557
15.17760000 4.82852508
15.19120000 4.83211695
15.20480000 4.83354901
15.21840000 4.83521094
15.23200000 4.83846828
15.24560000 4.84358283
15.25920000 4.84485577
15.27280000 4.82950351
15.28640000 4.81394251
15.30000000 4.80647648
15.31360000 4.81450912
15.32720000 4.82132704
15.34080000 4.82405840
15.35440000 4.82743044
15.36800000 4.83221144
15.38160000 4.83824178
15.39520000 4.84374590
15.40880000 4.85111180
15.42240000 4.85946621
15.43600000 4.86789739
15.44960000 4.87182384
15.46320000 4.87159733
15.47680000 4.87032942
15.49040000 4.87272862
15.50400000 4.87930250
15.51760000 4.88586096
15.53120000 4.88417620
15.54480000 4.87971376
15.55840000 4.87207791
15.57200000 4.86773307
15.58560000 4.86283153
15.59920000 4.86110991
15.61280000 4.86142320
15.62640000 4.85231500
15.64000000 4.83344145
15.65360000 4.80645600
15.66720000 4.79328320
15.68080000 4.78895521
15.69440000 4.78838268
15.70800000 4.78597719
15.72160000 4.78656222
15.73520000 4.78821848
15.74880000 4.78390058
15.76240000 4.77209144
15.77600000 4.75944285
15.78960000 4.75423082
15.80320000 4.75960876
15.81680000 4.76320564
15.83040000 4.75033718
15.84400000 4.71873276
15.85760000 4.68929096
15.87120000 4.67531996
15.88480000 4.67023468
15.89840000 4.67269218
15.91200000 4.67538924
15.92560000 4.68628387
15.93920000 4.69381095
15.95280000 4.69491811
15.96640000 4.69056230
15.98000000 4.68697428
15.99360000 4.68753857
16.00720000 4.69081010
16.02080000 4.69394826
16.03440000 4.69573048
16.04800000 4.69583825
16.06160000 4.69750910
16.07520000 4.69849279
16.08880000 4.70329287
16.10240000 4.70677718
16.11600000 4.71289660
16.12960000 4.71655495
16.14320000 4.72111983
16.15680000 4.72755764
16.17040000 4.73485391
16.18400000 4.74376602
16.19760000 4.75231215
16.21120000 4.75976300
16.22480000 4.76607443
16.23840000 4.77430798
16.25200000 4.78234479
16.26560000 4.79023184
16.27920000 4.79547987
16.29280000 4.79823209
16.30640000 4.80219305
16.32000000 4.80793796
16.33360000 4.81773714
16.34720000 4.82607665
16.36080000 4.82883746
16.37440000 4.82617993
16.38800000 4.81938936
16.40160000 4.81577410
16.41520000 4.81648835
16.42880000 4.82214403
16.44240000 4.82953966
16.45600000 4.83688511
16.46960000 4.84397819
16.48320000 4.85012455
16.49680000 4.85438317
16.51040000 4.85855243
16.52400000 4.85987907
16.53760000 4.86039651
16.55120000 4.85910575
16.56480000 4.86300904
16.57840000 4.86833173
16.59200000 4.87630327
16.60560000 4.88079034
16.61920000 4.88873291
16.63280000 4.89476176
16.64640000 4.90088575
16.66000000 4.90430181
16.67360000 4.90692472
16.68720000 4.91057040
16.70080000 4.91596098
16.71440000 4.92281306
16.72800000 4.92357483
16.74160000 4.91708431
16.75520000 4.90851763
16.76880000 4.90506087
16.78240000 4.90981707
16.79600000 4.91752624
16.80960000 4.92597972
16.82320000 4.93387628
16.83680000 4.94096817
16.85040000 4.94896441
16.86400000 4.95048468
16.87760000 4.95248863
16.89120000 4.95475793
16.90480000 4.96135391
16.91840000 4.96768759
16.93200000 4.97553327
16.94560000 4.98333276
16.95920000 4.99128796
16.97280000 4.99887541
16.98640000 5.00654724
17.00000000 5.01594802
17.01360000 5.02534018
17.02720000 5.03502387
17.04080000 5.04300766
17.05440000 5.04766739
17.06800000 5.04187938
17.08160000 5.02683030
17.09520000 5.00741170
17.10880000 4.98762647
17.12240000 4.96065757
17.13600000 4.92891453
17.14960000 4.89845256
17.16320000 4.87626372
17.17680000 4.85188491
17.19040000 4.82842568
17.20400000 4.81111185
17.21760000 4.80703398
17.23120000 4.80623535
17.24480000 4.80639802
17.25840000 4.80778994
17.27200000 4.81244446
17.28560000 4.81870956
17.29920000 4.82318773
17.31280000 4.82744544
17.32640000 4.83148689
17.34000000 4.83863444
17.35360000 4.84513669
17.36720000 4.85145454
17.38080000 4.85633482
17.39440000 4.86185812
17.40800000 4.86459140
17.42160000 4.86635981
17.43520000 4.86647330
17.44880000 4.86213909
17.46240000 4.85138911
17.47600000 4.84686650
17.48960000 4.84842426
17.50320000 4.85547716
17.51680000 4.85558358
17.53040000 4.85779476
17.54400000 4.85913998
17.55760000 4.85953464
17.57120000 4.85562210
17.58480000 4.84774385
17.59840000 4.84160203
17.61200000 4.83586051
17.62560000 4.82864201
17.63920000 4.82389497
17.65280000 4.82258561
17.66640000 4.82931382
17.68000000 4.83576081
17.69360000 4.84263988
17.70720000 4.85028904
17.72080000 4.85798954
17.73440000 4.85955728
17.74800000 4.85872517
17.76160000 4.85940081
17.77520000 4.86716058
17.78880000 4.87363851
17.80240000 4.87780264
17.81600000 4.88043170
17.82960000 4.88306078
17.84320000 4.88410626
17.85680000 4.88584468
17.87040000 4.89034711
17.88400000 4.89829907
17.89760000 4.90496783
17.91120000 4.90948054
17.92480000 4.91305159
17.93840000 4.91846104
17.95200000 4.92543000
17.96560000 4.93214869
17.97920000 4.93788466
17.99280000 4.94050415
18.00640000 4.94287639
18.02000000 4.94520527
18.03360000 4.95291652
18.04720000 4.96348391
18.06080000 4.96695883
18.07440000 4.96203119
18.08800000 4.94383729
18.10160000 4.93022783
18.11520000 4.91804362
18.12880000 4.91237872
18.14240000 4.88961622
18.15600000 4.87033345
18.16960000 4.85763383
18.18320000 4.86415332
18.19680000 4.87439576
18.21040000 4.88268586
18.22400000 4.89188566
18.23760000 4.89808989
18.25120000 4.90569614
18.26480000 4.91227617
18.27840000 4.91923924
18.29200000 4.92383564
18.30560000 4.92963611
18.31920000 4.93503212
18.33280000 4.94260274
18.34640000 4.95064869
18.36000000 4.95807336
18.37360000 4.96509290
18.38720000 4.97295102
18.40080000 4.98502227
18.41440000 4.99678735
18.42800000 5.00631481
18.44160000 5.00644435
18.45520000 5.00266973
18.46880000 4.99708123
18.48240000 4.99296552
18.49600000 4.99256636
18.50960000 4.99340783
18.52320000 4.99474093
18.53680000 4.98737731
18.55040000 4.97727589
18.56400000 4.96788307
18.57760000 4.95879153
18.59120000 4.94097144
18.60480000 4.92384015
18.61840000 4.89913852
18.63200000 4.87405553
18.64560000 4.84168281
18.65920000 4.81777490
18.67280000 4.79721156
18.68640000 4.78626859
18.70000000 4.78336349
18.71360000 4.78828081
18.72720000 4.79428762
18.74080000 4.79992307
18.75440000 4.80622736
18.76800000 4.80976169
18.78160000 4.81349125
18.79520000 4.81601042
18.80880000 4.82236998
18.82240000 4.82995956
18.83600000 4.83873857
18.84960000 4.84750179
18.86320000 4.85817787
18.87680000 4.86870646
18.89040000 4.87888216
18.90400000 4.88662466
18.91760000 4.89499927
18.93120000 4.90463739
18.94480000 4.91349840
18.95840000 4.92137462
18.97200000 4.92816612
18.98560000 4.93584891
18.99920000 4.94358360
19.01280000 4.94830401
19.02640000 4.95296242
19.04000000 4.95763483
19.05360000 4.96413976
19.06720000 4.96947728
19.08080000 4.97594281
19.09440000 4.98255126
19.10800000 4.99004301
19.12160000 4.99712856
19.13520000 5.00601691
19.14880000 5.01347650
19.16240000 5.01959193
19.17600000 5.02400184
19.18960000 5.02928213
19.20320000 5.03582468
19.21680000 5.04341304
19.23040000 5.04879481
19.24400000 5.05472701
19.25760000 5.06326160
19.27120000 5.07257762
19.28480000 5.06718023
19.29840000 5.05596351
19.31200000 5.04727592
19.32560000 5.05020175
19.33920000 5.05219581
19.35280000 5.05338143
19.36640000 5.05638644
19.38000000 5.06143062
19.39360000 5.06802958
19.40720000 5.07443160
19.42080000 5.08177042
19.43440000 5.08868828
19.44800000 5.09501953
19.46160000 5.09926746
19.47520000 5.10094689
19.48880000 5.10837329
19.50240000 5.11764885
19.51600000 5.13085833
19.52960000 5.13820718
19.54320000 5.14277244
19.55680000 5.14691783
19.57040000 5.15193925
19.58400000 5.16004487
19.59760000 5.16773018
19.61120000 5.17472662
19.62480000 5.18293243
19.63840000 5.18609019
19.65200000 5.18489119
19.66560000 5.18094122
19.67920000 5.18092637
19.69280000 5.18620406
19.70640000 5.18935779
19.72000000 5.19278940
19.73360000 5.19049823
19.74720000 5.18650215
19.76080000 5.18137967
19.77440000 5.18197841
19.78800000 5.18877353
19.80160000 5.19554695
19.81520000 5.20187034
19.82880000 5.20736765
19.84240000 5.21547456
19.85600000 5.22227303
19.86960000 5.22628531
19.88320000 5.22869584
19.89680000 5.23365967
19.91040000 5.24132976
19.92400000 5.24983696
19.93760000 5.25879101
19.95120000 5.26549439
19.96040000 5.26760434