File: plots/rawdata/FigureS6d-1.txt
# strain(%), strain_el(%), stress(GPa)
0.00000000 -0.00013068 0.00000000
0.00440000 0.00426156 0.00340546
0.00880000 0.00611449 0.00484211
0.01320000 0.01357399 0.01062573
0.01760000 0.01755852 0.01371508
0.02200000 0.01881472 0.01468906
0.02640000 0.02333804 0.01819615
0.03080000 0.03048827 0.02373999
0.03520000 0.03211876 0.02500417
0.03960000 0.03658015 0.02846324
0.04400000 0.04504368 0.03502533
0.04840000 0.04856138 0.03775273
0.05280000 0.05258921 0.04087566
0.05720000 0.05419769 0.04212277
0.06160000 0.05971919 0.04640379
0.06600000 0.06318505 0.04909100
0.07040000 0.06688346 0.05195851
0.07480000 0.07149592 0.05553472
0.07920000 0.07607477 0.05908487
0.08360000 0.08358311 0.06490636
0.08800000 0.08450262 0.06561929
0.09240000 0.08917801 0.06924429
0.09680000 0.09680116 0.07515481
0.10120000 0.09780828 0.07593566
0.10560000 0.10213384 0.07928942
0.11000000 0.10993373 0.08533697
0.11440000 0.11099182 0.08615734
0.11880000 0.11544668 0.08961136
0.12320000 0.12310798 0.09555144
0.12760000 0.12406182 0.09629099
0.13200000 0.12854239 0.09976494
0.13640000 0.13641008 0.10586505
0.14080000 0.13720583 0.10648202
0.14520000 0.14157240 0.10986758
0.14960000 0.14579624 0.11314248
0.15400000 0.15417343 0.11963763
0.15840000 0.15470349 0.12004860
0.16280000 0.15916837 0.12351039
0.16720000 0.15486985 0.12017758
0.17160000 0.15903557 0.12340742
0.17600000 0.16335249 0.12675449
0.18040000 0.17651870 0.13696273
0.18480000 0.18095066 0.14039899
0.18920000 0.18891137 0.14657122
0.19360000 0.18930579 0.14687703
0.19800000 0.19402041 0.15053245
0.20240000 0.19825386 0.15381480
0.20680000 0.20282159 0.15735633
0.21120000 0.20720431 0.16075441
0.21560000 0.21163681 0.16419109
0.22000000 0.21916686 0.17002941
0.22440000 0.22392823 0.17372108
0.22880000 0.22842002 0.17720372
0.23320000 0.22875080 0.17746019
0.23760000 0.23700918 0.18386321
0.24200000 0.23745744 0.18421077
0.24640000 0.24183658 0.18760607
0.25080000 0.24632442 0.19108567
0.25520000 0.25052586 0.19434319
0.25960000 0.25465014 0.19754090
0.26400000 0.25929982 0.20114596
0.26840000 0.26372912 0.20458016
0.27280000 0.26777559 0.20771754
0.27720000 0.27263153 0.21148252
0.28160000 0.27675430 0.21467906
0.28600000 0.28102230 0.21798820
0.29040000 0.28894054 0.22412750
0.29480000 0.28992801 0.22489312
0.29920000 0.29430280 0.22828506
0.30360000 0.29864320 0.23165033
0.30800000 0.30322229 0.23520066
0.31240000 0.30740775 0.23844581
0.31680000 0.31153426 0.24164524
0.32120000 0.31612180 0.24520212
0.32560000 0.32042286 0.24853690
0.33000000 0.32449976 0.25169786
0.33440000 0.32917515 0.25532286
0.33880000 0.32586321 0.25275500
0.34320000 0.33004091 0.25599412
0.34760000 0.33476181 0.25965441
0.35200000 0.33854343 0.26258644
0.35640000 0.34328950 0.26626624
0.36080000 0.34759723 0.26960618
0.36520000 0.35207365 0.27307691
0.36960000 0.35631072 0.27636207
0.37400000 0.36064242 0.27972059
0.37840000 0.36476394 0.28291616
0.38280000 0.36556717 0.28353893
0.38720000 0.37390851 0.29000628
0.39160000 0.37807954 0.29324023
0.39600000 0.38273094 0.29684663
0.40040000 0.38254541 0.29670278
0.40480000 0.39166471 0.30377331
0.40920000 0.39161475 0.30373457
0.41360000 0.39378505 0.30541729
0.41800000 0.40473150 0.31390447
0.42240000 0.40914967 0.31733004
0.42680000 0.40798560 0.31642750
0.43120000 0.41136005 0.31904383
0.43560000 0.41754854 0.32384199
0.44000000 0.42660581 0.33086443
0.44440000 0.42695686 0.33113661
0.44880000 0.43570799 0.33792168
0.45320000 0.44000784 0.34125551
0.45760000 0.43667358 0.33867034
0.46200000 0.44892316 0.34816788
0.46640000 0.45015879 0.34912592
0.47080000 0.45170914 0.35032796
0.47520000 0.45372313 0.35188948
0.47960000 0.45925400 0.35617776
0.48400000 0.46983877 0.36438452
0.48840000 0.46874782 0.36353867
0.49280000 0.47654292 0.36958249
0.49720000 0.47338429 0.36713349
0.50160000 0.48127631 0.37325246
0.50600000 0.48124052 0.37322472
0.51040000 0.48945447 0.37959329
0.51480000 0.48958176 0.37969199
0.51920000 0.49915804 0.38711683
0.52360000 0.50116386 0.38867201
0.52800000 0.50918022 0.39488739
0.53240000 0.51034552 0.39579089
0.53680000 0.51489327 0.39931693
0.54120000 0.52164831 0.40455436
0.54560000 0.52364892 0.40610550
0.55000000 0.52702751 0.40872504
0.55440000 0.52811777 0.40957037
0.55880000 0.53717986 0.41659654
0.56320000 0.54208760 0.42040169
0.56760000 0.53903068 0.41803155
0.57200000 0.53629751 0.41591241
0.57640000 0.54249917 0.42072079
0.58080000 0.54490454 0.42258576
0.58520000 0.55003323 0.42656222
0.58960000 0.55349822 0.42924876
0.59400000 0.55916434 0.43364191
0.59840000 0.56219092 0.43598853
0.60280000 0.56631585 0.43918674
0.60720000 0.57065311 0.44254957
0.61160000 0.57507143 0.44597526
0.61600000 0.58080047 0.45041719
0.62040000 0.58564977 0.45417703
0.62480000 0.58799859 0.45599816
0.62920000 0.59385168 0.46053627
0.63360000 0.59835842 0.46403051
0.63800000 0.60078871 0.46591481
0.64240000 0.60548841 0.46955865
0.64680000 0.60948366 0.47265632
0.65120000 0.61533178 0.47719058
0.65560000 0.61973256 0.48060267
0.66000000 0.62237186 0.48264902
0.66440000 0.62683768 0.48611153
0.66880000 0.63109604 0.48941319
0.67320000 0.63340631 0.49120443
0.67760000 0.64140206 0.49740382
0.68200000 0.64410062 0.49949612
0.68640000 0.64847167 0.50288515
0.69080000 0.65257576 0.50606721
0.69520000 0.65744030 0.50983886
0.69960000 0.66135075 0.51287077
0.70400000 0.66620007 0.51663063
0.70840000 0.66986627 0.51947317
0.71280000 0.67236909 0.52141370
0.71720000 0.67860484 0.52624851
0.72160000 0.68316394 0.52978334
0.72600000 0.68756114 0.53319265
0.73040000 0.69172615 0.53642193
0.73480000 0.69564154 0.53945768
0.73920000 0.70061064 0.54331041
0.74360000 0.70407239 0.54599443
0.74800000 0.70891922 0.54975235
0.75240000 0.71482685 0.55433275
0.75680000 0.71699019 0.55601007
0.76120000 0.72166858 0.55963740
0.76560000 0.72614666 0.56310942
0.77000000 0.73009347 0.56616953
0.77440000 0.73451637 0.56959876
0.77880000 0.73887427 0.57297760
0.78320000 0.74306649 0.57622798
0.78760000 0.74710242 0.57935718
0.79200000 0.75146088 0.58273646
0.79640000 0.75603320 0.58628154
0.80080000 0.76060231 0.58982414
0.80520000 0.76446913 0.59282223
0.80960000 0.76874946 0.59614092
0.81400000 0.77327252 0.59964782
0.81840000 0.77768313 0.60306753
0.82280000 0.77945801 0.60444366
0.82720000 0.78586532 0.60941148
0.83160000 0.78997717 0.61259955
0.83600000 0.79440497 0.61603259
0.84040000 0.79655919 0.61770283
0.84480000 0.80081168 0.62099994
0.84920000 0.80499376 0.62424246
0.85360000 0.81207864 0.62973563
0.85800000 0.81611771 0.63286727
0.86240000 0.82027947 0.63609403
0.86680000 0.82187678 0.63733249
0.87120000 0.82672555 0.64109192
0.87560000 0.83089742 0.64432652
0.88000000 0.83792318 0.64977385
0.88440000 0.84191430 0.65286831
0.88880000 0.84608484 0.65610188
0.89320000 0.85048605 0.65951430
0.89760000 0.85479713 0.66285683
0.90200000 0.85694279 0.66452045
0.90640000 0.86081213 0.66752049
0.91080000 0.86775903 0.67290667
0.91520000 0.87207247 0.67625104
0.91960000 0.87631359 0.67953934
0.92400000 0.88065249 0.68290345
0.92840000 0.88494627 0.68623257
0.93280000 0.88918957 0.68952256
0.93720000 0.89114158 0.69103602
0.94160000 0.89532178 0.69427708
0.94600000 0.89955895 0.69756232
0.95040000 0.90370617 0.70077781
0.95480000 0.90831770 0.70435329
0.95920000 0.91242539 0.70753814
0.96360000 0.91937723 0.71292815
0.96800000 0.92117611 0.71432289
0.97240000 0.92632189 0.71831260
0.97680000 0.93196789 0.72269016
0.98120000 0.93514314 0.72515204
0.98560000 0.93952694 0.72855096
0.99000000 0.94394235 0.73197439
0.99440000 0.95091982 0.73738428
0.99880000 0.95243649 0.73856021
1.00320000 0.95941017 0.74396716
1.00760000 0.96146053 0.74555688
1.01200000 0.96533036 0.74855730
1.01640000 0.97232046 0.75397698
1.02080000 0.97351767 0.75490522
1.02520000 0.97881028 0.75900877
1.02960000 0.98220223 0.76163867
1.03400000 0.98663750 0.76507750
1.03840000 0.99107863 0.76852088
1.04280000 0.99519006 0.77170862
1.04720000 0.99951403 0.77506115
1.05160000 1.00670989 0.78064037
1.05600000 1.00785709 0.78152983
1.06040000 1.01218578 0.78488602
1.06480000 1.01653052 0.78825466
1.06920000 1.02061840 0.79142414
1.07360000 1.02481702 0.79467948
1.07800000 1.02904889 0.79796061
1.08240000 1.03663576 0.80384299
1.08680000 1.03851253 0.80529812
1.09120000 1.04199832 0.80800077
1.09560000 1.04624991 0.81129719
1.10000000 1.05035150 0.81447730
1.10440000 1.05490385 0.81800690
1.10880000 1.05934557 0.82145074
1.11320000 1.06230968 0.82374892
1.11760000 1.06691047 0.82731608
1.12200000 1.07119317 0.83063661
1.12640000 1.07554134 0.83400791
1.13080000 1.07972628 0.83725264
1.13520000 1.08833574 0.84392788
1.13960000 1.08899808 0.84444141
1.14400000 1.09301567 0.84755640
1.14840000 1.09671425 0.85042404
1.15280000 1.10099804 0.85374542
1.15720000 1.10533418 0.85710739
1.16160000 1.10969534 0.86048876
1.16600000 1.11389769 0.86374699
1.17040000 1.11827183 0.86713842
1.17480000 1.12168477 0.86978460
1.17920000 1.12757908 0.87435467
1.18360000 1.12949769 0.87584224
1.18800000 1.13175838 0.87759504
1.19240000 1.13588941 0.88079797
1.19680000 1.14012851 0.88408470
1.20120000 1.14532485 0.88811362
1.20560000 1.15348874 0.89444338
1.21000000 1.15750316 0.89755591
1.21440000 1.16204591 0.90107807
1.21880000 1.16638519 0.90444247
1.22320000 1.17018239 0.90738658
1.22760000 1.17473235 0.91091433
1.23200000 1.17893852 0.91417553
1.23640000 1.18321006 0.91748741
1.24080000 1.18751152 0.92082249
1.24520000 1.19161083 0.92400083
1.24960000 1.19631412 0.92764747
1.25400000 1.20045424 0.93085746
1.25840000 1.20460097 0.93407256
1.26280000 1.20531186 0.93462375
1.26720000 1.21311569 0.94067434
1.27160000 1.21383738 0.94123389
1.27600000 1.21697941 0.94367002
1.28040000 1.22428559 0.94933477
1.28480000 1.22866281 0.95272859
1.28920000 1.23003884 0.95379548
1.29360000 1.23852211 0.96037287
1.29800000 1.23923286 0.96092394
1.30240000 1.24392536 0.96456220
1.30680000 1.25205032 0.97086178
1.31120000 1.25572535 0.97371117
1.31560000 1.25446161 0.97273135
1.32000000 1.25998127 0.97701094
1.32440000 1.26451412 0.98052542
1.32880000 1.26860913 0.98370044
1.33320000 1.27302019 0.98712049
1.33760000 1.27739743 0.99051433
1.34200000 1.28162066 0.99378875
1.34640000 1.29084578 1.00094133
1.35080000 1.29506387 1.00421177
1.35520000 1.29832093 1.00673708
1.35960000 1.30364316 1.01086360
1.36400000 1.30814928 1.01435736
1.36840000 1.31238956 1.01764501
1.37280000 1.31254031 1.01776189
1.37720000 1.31685373 1.02110624
1.38160000 1.31853528 1.02241001
1.38600000 1.32510788 1.02750599
1.39040000 1.32739977 1.02928297
1.39480000 1.33305150 1.03366497
1.39920000 1.33711355 1.03681442
1.40360000 1.34151047 1.04022351
1.40800000 1.34605643 1.04374816
1.41240000 1.35018582 1.04694983
1.41680000 1.35412780 1.05000619
1.42120000 1.35698791 1.05222374
1.42560000 1.36159439 1.05579531
1.43000000 1.36729376 1.06021424
1.43440000 1.36778745 1.06059702
1.43880000 1.37567268 1.06671073
1.44320000 1.37658485 1.06741797
1.44760000 1.38427129 1.07337754
1.45200000 1.38513802 1.07404956
1.45640000 1.39285869 1.08003567
1.46080000 1.39328723 1.08036793
1.46520000 1.40155084 1.08677501
1.46960000 1.40560579 1.08991896
1.47400000 1.40898071 1.09253566
1.47840000 1.41434004 1.09669095
1.48280000 1.41837046 1.09981588
1.48720000 1.41904937 1.10034226
1.49160000 1.42294210 1.10336044
1.49600000 1.42939021 1.10835989
1.50040000 1.43209943 1.11046045
1.50480000 1.43576182 1.11330004
1.50920000 1.44432524 1.11993957
1.51360000 1.44425205 1.11988283
1.51800000 1.44828197 1.12300737
1.52240000 1.45335707 1.12694228
1.52680000 1.46088341 1.13277772
1.53120000 1.46215802 1.13376598
1.53560000 1.46457527 1.13564016
1.54000000 1.47390525 1.14287403
1.54440000 1.47405403 1.14298939
1.54880000 1.48228234 1.14936910
1.55320000 1.48632106 1.15250047
1.55760000 1.48622892 1.15242903
1.56200000 1.49363742 1.15817311
1.56640000 1.49506509 1.15928004
1.57080000 1.49932151 1.16258019
1.57520000 1.50346511 1.16579288
1.57960000 1.50750858 1.16892793
1.58400000 1.51278523 1.17301911
1.58840000 1.51690581 1.17621395
1.59280000 1.52121767 1.17955709
1.59720000 1.52881493 1.18544752
1.60160000 1.53158461 1.18759496
1.60600000 1.53362602 1.18917773
1.61040000 1.53838428 1.19286699
1.61480000 1.54263731 1.19616452
1.61920000 1.54669601 1.19931138
1.62360000 1.55069967 1.20241556
1.62800000 1.55533819 1.20601198
1.63240000 1.55868850 1.20860960
1.63680000 1.56254263 1.21159785
1.64120000 1.56703436 1.21508045
1.64560000 1.57109785 1.21823102
1.65000000 1.57560133 1.22172273
1.65440000 1.57948576 1.22473447
1.65880000 1.58374549 1.22803719
1.66320000 1.58795279 1.23129927
1.66760000 1.59045448 1.23323892
1.67200000 1.59695487 1.23827892
1.67640000 1.60124004 1.24160137
1.68080000 1.60495395 1.24448089
1.68520000 1.61035718 1.24867021
1.68960000 1.61080430 1.24901688
1.69400000 1.61895360 1.25533534
1.69840000 1.62317613 1.25860922
1.70280000 1.62673603 1.26136933
1.70720000 1.62225495 1.25789499
1.71160000 1.61701419 1.25383164
1.71600000 1.61457437 1.25193995
1.72040000 1.62016649 1.25627573
1.72480000 1.62682268 1.26143652
1.72920000 1.63348351 1.26660091
1.73360000 1.63792761 1.27004658
1.73800000 1.64232723 1.27345777
1.74240000 1.64636998 1.27659226
1.74680000 1.64684007 1.27695674
1.75120000 1.65507835 1.28334417
1.75560000 1.65522916 1.28346111
1.76000000 1.66067737 1.28768530
1.76440000 1.66488624 1.29094859
1.76880000 1.66947022 1.29450272
1.77320000 1.66681902 1.29244715
1.77760000 1.67781043 1.30096919
1.78200000 1.67521292 1.29895524
1.78640000 1.68239042 1.30452023
1.79080000 1.68416679 1.30589750
1.79520000 1.69468285 1.31405099
1.79960000 1.69523112 1.31447609
1.80400000 1.69636096 1.31535209
1.80840000 1.70360957 1.32097220
1.81280000 1.71114947 1.32681817
1.81720000 1.71305664 1.32829686
1.82160000 1.71612224 1.33067374
1.82600000 1.72377906 1.33661035
1.83040000 1.72491435 1.33749058
1.83480000 1.72823472 1.34006499
1.83920000 1.73094766 1.34216843
1.84360000 1.73705670 1.34690499
1.84800000 1.74138276 1.35025914
1.85240000 1.74555624 1.35349500
1.85680000 1.75358866 1.35972283
1.86120000 1.75156859 1.35815659
1.86560000 1.75592877 1.36153720
1.87000000 1.76215087 1.36636142
1.87440000 1.76660055 1.36981142
1.87880000 1.76898254 1.37165827
1.88320000 1.77457884 1.37599729
1.88760000 1.77861897 1.37912975
1.89200000 1.78303996 1.38255750
1.89640000 1.78333948 1.38278973
1.90080000 1.79113007 1.38883005
1.90520000 1.79644955 1.39295444
1.90960000 1.79685486 1.39326869
1.91400000 1.80404078 1.39884020
1.91840000 1.80613843 1.40046659
1.92280000 1.81067138 1.40398115
1.92720000 1.81473098 1.40712871
1.93160000 1.81912523 1.41053573
1.93600000 1.82422381 1.41448885
1.94040000 1.82579546 1.41570740
1.94480000 1.83071874 1.41952460
1.94920000 1.83724119 1.42458170
1.95360000 1.84159750 1.42795930
1.95800000 1.84234045 1.42853534
1.96240000 1.84814247 1.43303386
1.96680000 1.85077555 1.43507538
1.97120000 1.85509069 1.43842106
1.97560000 1.86120348 1.44316054
1.98000000 1.86138926 1.44330458
1.98440000 1.86750595 1.44804708
1.98880000 1.86973145 1.44977259
1.99320000 1.87996004 1.45770319
1.99760000 1.88191302 1.45921741
2.00200000 1.88517870 1.46174941
2.00640000 1.88702842 1.46318356
2.01080000 1.89340561 1.46812803
2.01520000 1.89494972 1.46932523
2.01960000 1.89949084 1.47284613
2.02400000 1.90739937 1.47897790
2.02840000 1.90892571 1.48016133
2.03280000 1.91235445 1.48281976
2.03720000 1.91553562 1.48528624
2.04160000 1.92107843 1.48958378
2.04600000 1.92477434 1.49244936
2.05040000 1.92815119 1.49506755
2.05480000 1.92977731 1.49632834
2.05920000 1.93678647 1.50176280
2.06360000 1.94135441 1.50530449
2.06800000 1.94504081 1.50816269
2.07240000 1.95442955 1.51544212
2.07680000 1.95189113 1.51347400
2.08120000 1.95454867 1.51553448
2.08560000 1.95851719 1.51861142
2.09000000 1.96254190 1.52173193
2.09440000 1.96786953 1.52586263
2.09880000 1.97223327 1.52924600
2.10320000 1.97528870 1.53161499
2.10760000 1.97945100 1.53484217
2.11200000 1.98361923 1.53807396
2.11640000 1.98887393 1.54214811
2.12080000 1.99127082 1.54400651
2.12520000 1.99571227 1.54745013
2.12960000 1.99952546 1.55040664
2.13400000 2.00342630 1.55343110
2.13840000 2.00805083 1.55701667
2.14280000 2.01214668 1.56019233
2.14720000 2.01616022 1.56330417
2.15160000 2.02057867 1.56672996
2.15600000 2.02383359 1.56925362
2.16040000 2.02794197 1.57243900
2.16480000 2.03238948 1.57588731
2.16920000 2.03653789 1.57910373
2.17360000 2.04089398 1.58248116
2.17800000 2.04476164 1.58547990
2.18240000 2.04965450 1.58927352
2.18680000 2.05290022 1.59179004
2.19120000 2.05678854 1.59480480
2.19560000 2.06081244 1.59792467
2.20000000 2.06453529 1.60081114
2.20440000 2.06886215 1.60416591
2.20880000 2.07332663 1.60762738
2.21320000 2.07680353 1.61032315
2.21760000 2.08073618 1.61337228
2.22200000 2.08300064 1.61512800
2.22640000 2.08927834 1.61999533
2.23080000 2.08977089 1.62037723
2.23520000 2.09414247 1.62376667
2.23960000 2.09843331 1.62709351
2.24400000 2.10255991 1.63029302
2.24840000 2.10615340 1.63307918
2.25280000 2.10939226 1.63559039
2.25720000 2.11509032 1.64000831
2.26160000 2.11833861 1.64252682
2.26600000 2.12188327 1.64527513
2.27040000 2.12773639 1.64981326
2.27480000 2.12977656 1.65139509
2.27920000 2.13337302 1.65418355
2.28360000 2.13796203 1.65774157
2.28800000 2.14219075 1.66102026
2.29240000 2.14651694 1.66437451
2.29680000 2.15009286 1.66714705
2.30120000 2.15381246 1.67003100
2.30560000 2.15774868 1.67308289
2.31000000 2.16323106 1.67733358
2.31440000 2.16600496 1.67948429
2.31880000 2.16974617 1.68238499
2.32320000 2.17374654 1.68548661
2.32760000 2.17776691 1.68860376
2.33200000 2.18259490 1.69234708
2.33640000 2.18595184 1.69494983
2.34080000 2.19051667 1.69848911
2.34520000 2.19162941 1.69935186
2.34960000 2.19817337 1.70442563
2.35400000 2.20214783 1.70750718
2.35840000 2.20370447 1.70871410
2.36280000 2.20731863 1.71151629
2.36720000 2.21432179 1.71694610
2.37160000 2.21598788 1.71823788
2.37600000 2.22267061 1.72341924
2.38040000 2.22351216 1.72407173
2.38480000 2.22804310 1.72758473
2.38920000 2.23385741 1.73209278
2.39360000 2.23529657 1.73320861
2.39800000 2.24005873 1.73690088
2.40240000 2.24364761 1.73968348
2.40680000 2.24770091 1.74282615
2.41120000 2.25430915 1.74794976
2.41560000 2.25516920 1.74861659
2.42000000 2.26212430 1.75400913
2.42440000 2.26649268 1.75739610
2.42880000 2.26811426 1.75865337
2.43320000 2.27189245 1.76158274
2.43760000 2.27606126 1.76481497
2.44200000 2.28000972 1.76787635
2.44640000 2.28333364 1.77045351
2.45080000 2.28738335 1.77359340
2.45520000 2.29258493 1.77762637
2.45960000 2.29627066 1.78048406
2.46400000 2.30131115 1.78439213
2.46840000 2.30406398 1.78652651
2.47280000 2.30806810 1.78963104
2.47720000 2.31236111 1.79295957
2.48160000 2.31669233 1.79631773
2.48600000 2.32048580 1.79925894
2.49040000 2.32467627 1.80250797
2.49480000 2.32790610 1.80501217
2.49920000 2.33188436 1.80809666
2.50360000 2.33672672 1.81185112
2.50800000 2.33940440 1.81392723
2.51240000 2.34424503 1.81768034
2.51680000 2.34755101 1.82024359
2.52120000 2.35250188 1.82408218
2.52560000 2.35632057 1.82704295
2.53000000 2.36009547 1.82996977
2.53440000 2.36258914 1.83190320
2.53880000 2.36748431 1.83569860
2.54320000 2.37321795 1.84014411
2.54760000 2.37620486 1.84245997
2.55200000 2.37889748 1.84454765
2.55640000 2.38292335 1.84766906
2.56080000 2.37866274 1.84436565
2.56520000 2.38129913 1.84640974
2.56960000 2.38573462 1.84984874
2.57400000 2.38200564 1.84695752
2.57840000 2.39520027 1.85718780
2.58280000 2.39831735 1.85960459
2.58720000 2.40387729 1.86391541
2.59160000 2.40732629 1.86658955
2.59600000 2.41048900 1.86904172
2.60040000 2.41397924 1.87174783
2.60480000 2.41951374 1.87603893
2.60920000 2.42168530 1.87772262
2.61360000 2.42692193 1.88178277
2.61800000 2.43166506 1.88546029
2.62240000 2.43367291 1.88701705
2.62680000 2.43860559 1.89084154
2.63120000 2.44143744 1.89303718
2.63560000 2.44370288 1.89479366
2.64000000 2.45009486 1.89974960
2.64440000 2.45427002 1.90298675
2.64880000 2.45911493 1.90674318
2.65320000 2.46331076 1.90999636
2.65760000 2.46655803 1.91251409
2.66200000 2.45789176 1.90579481
2.66640000 2.46456539 1.91096912
2.67080000 2.46575186 1.91188903
2.67520000 2.47160925 1.91643049
2.67960000 2.47197689 1.91671553
2.68400000 2.47409196 1.91835543
2.68840000 2.47643888 1.92017508
2.69280000 2.48572446 1.92737452
2.69720000 2.49035302 1.93096322
2.70160000 2.48613540 1.92769314
2.70600000 2.49603603 1.93536946
2.71040000 2.50071838 1.93899986
2.71480000 2.50519986 1.94247452
2.71920000 2.51087256 1.94687277
2.72360000 2.51057712 1.94664370
2.72800000 2.51665424 1.95135552
2.73240000 2.51964516 1.95367449
2.73680000 2.52371158 1.95682733
2.74120000 2.52759541 1.95983860
2.74560000 2.53176417 1.96307080
2.75000000 2.53378303 1.96463609
2.75440000 2.53882290 1.96854369
2.75880000 2.54353778 1.97219931
2.76320000 2.54734422 1.97515058
2.76760000 2.55124604 1.97817581
2.77200000 2.55561776 1.98156536
2.77640000 2.55918693 1.98433267
2.78080000 2.56376483 1.98788208
2.78520000 2.56720096 1.99054624
2.78960000 2.57154802 1.99391667
2.79400000 2.57529867 1.99682469
2.79840000 2.57863279 1.99940975
2.80280000 2.58385681 2.00346013
2.80720000 2.58673509 2.00569176
2.81160000 2.59147766 2.00936885
2.81600000 2.59431261 2.01156689
2.82040000 2.59903756 2.01523032
2.82480000 2.60227130 2.01773756
2.82920000 2.60566486 2.02036871
2.83360000 2.61011299 2.02381751
2.83800000 2.61333366 2.02631461
2.84240000 2.61440934 2.02714862
2.84680000 2.62165167 2.03276387
2.85120000 2.61785317 2.02981875
2.85560000 2.62901157 2.03847027
2.86000000 2.62587798 2.03604068
2.86440000 2.63790274 2.04536392
2.86880000 2.64133950 2.04802857
2.87320000 2.64645483 2.05199467
2.87760000 2.64203240 2.04856579
2.88200000 2.65017139 2.05487625
2.88640000 2.65777924 2.06077490
2.89080000 2.66109271 2.06334395
2.89520000 2.66176378 2.06386426
2.89960000 2.66936752 2.06975972
2.90400000 2.66627533 2.06736223
2.90840000 2.67718324 2.07581953
2.91280000 2.68134549 2.07904667
2.91720000 2.67845276 2.07680383
2.92160000 2.68236874 2.07984004
2.92600000 2.68797619 2.08418770
2.93040000 2.69762898 2.09167186
2.93480000 2.70150913 2.09468028
2.93920000 2.70554824 2.09781195
2.94360000 2.70955127 2.10091565
2.94800000 2.71390315 2.10428982
2.95240000 2.71042371 2.10159208
2.95680000 2.71458686 2.10481992
2.96120000 2.72280633 2.11119278
2.96560000 2.72952011 2.11639822
2.97000000 2.73388849 2.11978518
2.97440000 2.73789232 2.12288950
2.97880000 2.73464852 2.12037446
2.98320000 2.74208352 2.12613909
2.98760000 2.74257571 2.12652071
2.99200000 2.75441390 2.13569928
2.99640000 2.75395824 2.13534600
2.99920000 2.76057910 2.14047939
2.99480000 2.75196032 2.13379694
2.99040000 2.74574944 2.12898141
2.98600000 2.74899352 2.13149667
2.98160000 2.74471727 2.12818113
2.97720000 2.74075947 2.12511251
2.97280000 2.73669156 2.12195851
2.96840000 2.72256468 2.11100542
2.96400000 2.72879335 2.11583474
2.95960000 2.72070009 2.10955973
2.95520000 2.72036106 2.10929687
2.95080000 2.71197510 2.10279493
2.94640000 2.71225858 2.10301473
2.94200000 2.70359354 2.09629640
2.93760000 2.70442111 2.09693805
2.93320000 2.70077436 2.09411059
2.92880000 2.69688391 2.09109418
2.92440000 2.68856723 2.08464595
2.92000000 2.68115265 2.07889716
2.91560000 2.68109910 2.07885564
2.91120000 2.67316759 2.07270605
2.90680000 2.66866599 2.06921579
2.90240000 2.67238634 2.07210032
2.89800000 2.66878443 2.06930763
2.89360000 2.66418212 2.06573928
2.88920000 2.66006805 2.06254950
2.88480000 2.65646220 2.05975375
2.88040000 2.65277343 2.05689371
2.87600000 2.64818117 2.05333316
2.87160000 2.64439750 2.05039954
2.86720000 2.64089422 2.04768333
2.86280000 2.63635865 2.04416673
2.85840000 2.62471744 2.03514087
2.85400000 2.62798867 2.03767717
2.84960000 2.62469785 2.03512568
2.84520000 2.61270318 2.02582577
2.84080000 2.61633391 2.02864082
2.83640000 2.60490150 2.01977685
2.83200000 2.60846182 2.02253730
2.82760000 2.60403304 2.01910350
2.82320000 2.60120636 2.01691187
2.81880000 2.59633050 2.01313144
2.81440000 2.59261083 2.01024744
2.81000000 2.58809156 2.00674349
2.80560000 2.57516483 1.99672092
2.80120000 2.58153543 2.00166028
2.79680000 2.57188959 1.99418151
2.79240000 2.57384195 1.99569524
2.78800000 2.56188872 1.98642746
2.78360000 2.56615099 1.98973216
2.77920000 2.55505826 1.98113156
2.77480000 2.55805659 1.98345627
2.77040000 2.55125798 1.97818507
2.76600000 2.55033360 1.97746836
2.76160000 2.54698090 1.97486888
2.75720000 2.53645904 1.96671091
2.75280000 2.53954981 1.96910729
2.74840000 2.53525181 1.96577490
2.74400000 2.52986162 1.96159568
2.73960000 2.52703212 1.95940187
2.73520000 2.52245280 1.95585135
2.73080000 2.51885746 1.95306376
2.72640000 2.51467036 1.94981734
2.72200000 2.51117047 1.94710375
2.71760000 2.50538564 1.94261856
2.71320000 2.50286341 1.94066298
2.70880000 2.49987841 1.93834860
2.70440000 2.48839073 1.92944178
2.70000000 2.49293284 1.93296344
2.69560000 2.48899505 1.92991033
2.69120000 2.48592621 1.92753095
2.68680000 2.47963238 1.92265112
2.68240000 2.47753784 1.92102714
2.67800000 2.47378732 1.91811922
2.67360000 2.46832343 1.91388287
2.66920000 2.46688737 1.91276944
2.66480000 2.45399551 1.90277391
2.66040000 2.46757860 1.91330537
2.65600000 2.45430652 1.90301504
2.65160000 2.45164395 1.90095066
2.64720000 2.43816796 1.89050223
2.64280000 2.45386872 1.90267560
2.63840000 2.44912143 1.89899486
2.63400000 2.44605510 1.89661742
2.62960000 2.44256482 1.89391128
2.62520000 2.43670893 1.88937099
2.62080000 2.42408209 1.87958094
2.61640000 2.41979920 1.87626026
2.61200000 2.42461594 1.87999485
2.60760000 2.42069021 1.87695109
2.60320000 2.41822606 1.87504055
2.59880000 2.41324641 1.87117964
2.59440000 2.41025185 1.86885784
2.59000000 2.40547812 1.86515660
2.58560000 2.40119441 1.86183529
2.58120000 2.39711621 1.85867331
2.57680000 2.39305565 1.85552500
2.57240000 2.39036632 1.85343987
2.56800000 2.37656693 1.84274070
2.56360000 2.37237313 1.83948909
2.55920000 2.36889362 1.83679129
2.55480000 2.37312922 1.84007531
2.55040000 2.37014296 1.83775996
2.54600000 2.36644678 1.83489417
2.54160000 2.35278198 1.82429935
2.53720000 2.34860598 1.82106154
2.53280000 2.34550457 1.81865691
2.52840000 2.33970171 1.81415774
2.52400000 2.34655463 1.81947106
2.51960000 2.34203437 1.81596634
2.51520000 2.33774816 1.81264308
2.51080000 2.33417185 1.80987023
2.50640000 2.33071846 1.80719270
2.50200000 2.32620639 1.80369433
2.49760000 2.32219749 1.80058608
2.49320000 2.31777307 1.79715566
2.48880000 2.31428990 1.79445503
2.48440000 2.31037220 1.79141749
2.48000000 2.30666098 1.78854005
2.47560000 2.30179677 1.78476865
2.47120000 2.29749557 1.78143377
2.46680000 2.29450284 1.77911340
2.46240000 2.29039010 1.77592464
2.45800000 2.28566310 1.77225963
2.45360000 2.28407318 1.77102691
2.44920000 2.28022794 1.76804555
2.44480000 2.27318360 1.76258381
2.44040000 2.27421947 1.76338696
2.43600000 2.26771897 1.75834689
2.43160000 2.26468281 1.75599284
2.42720000 2.25712059 1.75012957
2.42280000 2.25328844 1.74715837
2.41840000 2.24913761 1.74394008
2.41400000 2.24846055 1.74341512
2.40960000 2.24417589 1.74009308
2.40520000 2.23699361 1.73452439
2.40080000 2.23606617 1.73380531
2.39640000 2.23161121 1.73035122
2.39200000 2.22556868 1.72566622
2.38760000 2.22396462 1.72442254
2.38320000 2.21970916 1.72112312
2.37880000 2.21374810 1.71650129
2.37440000 2.21186007 1.71503743
2.37000000 2.20585842 1.71038413
2.36560000 2.20158413 1.70707012
2.36120000 2.19957632 1.70551339
2.35680000 2.19363921 1.70091013
2.35240000 2.19171020 1.69941450
2.34800000 2.18562887 1.69469942
2.34360000 2.18169740 1.69165121
2.33920000 2.17963053 1.69004869
2.33480000 2.17558333 1.68691075
2.33040000 2.17170835 1.68390634
2.32600000 2.17471312 1.68623604
2.32160000 2.17206416 1.68418221
2.31720000 2.16797720 1.68101343
2.31280000 2.16454640 1.67835341
2.30840000 2.16060061 1.67529409
2.30400000 2.15673281 1.67229525
2.29960000 2.15343602 1.66973913
2.29520000 2.15054784 1.66749982
2.29080000 2.14454906 1.66284874
2.28640000 2.14226403 1.66107708
2.28200000 2.13819835 1.65792481
2.27760000 2.13371969 1.65445234
2.27320000 2.13228316 1.65333854
2.26880000 2.12576931 1.64828811
2.26440000 2.12096242 1.64456116
2.26000000 2.11904099 1.64307140
2.25560000 2.11338550 1.63868650
2.25120000 2.11218037 1.63775211
2.24680000 2.10751013 1.63413111
2.24240000 2.10478073 1.63201490
2.23800000 2.09817266 1.62689142
2.23360000 2.09341395 1.62320182
2.22920000 2.09183081 1.62197435
2.22480000 2.08666627 1.61797010
2.22040000 2.08393947 1.61585591
2.21600000 2.07734079 1.61073971
2.21160000 2.07588476 1.60961080
2.20720000 2.07161998 1.60630416
2.20280000 2.06778659 1.60333199
2.19840000 2.06298406 1.59960841
2.19400000 2.05985629 1.59718334
2.18960000 2.05579596 1.59403521
2.18520000 2.05270431 1.59163814
2.18080000 2.04743223 1.58755050
2.17640000 2.04358589 1.58456830
2.17200000 2.04012481 1.58188480
2.16760000 2.03702652 1.57948258
2.16320000 2.03129888 1.57504173
2.15880000 2.02703301 1.57173425
2.15440000 2.02295069 1.56856907
2.15000000 2.01894930 1.56546665
2.14560000 2.01499351 1.56239958
2.14120000 2.01067399 1.55905049
2.13680000 2.00674497 1.55600419
2.13240000 2.00249521 1.55270919
2.12800000 1.99875023 1.54980557
2.12360000 1.99430845 1.54636170
2.11920000 1.99021539 1.54318819
2.11480000 1.98596004 1.53988887
2.11040000 1.98393982 1.53832252
2.10600000 1.97824137 1.53390430
2.10160000 1.97370306 1.53038558
2.09720000 1.96968640 1.52727132
2.09280000 1.96719038 1.52533606
2.08840000 1.96147579 1.52090533
2.08400000 1.95752368 1.51784112
2.07960000 1.95476227 1.51570010
2.07520000 1.95084794 1.51266517
2.07080000 1.94899416 1.51122787
2.06640000 1.94238122 1.50610061
2.06200000 1.93692430 1.50186966
2.05760000 1.93282291 1.49868971
2.05320000 1.93809808 1.50277974
2.04880000 1.93168694 1.49780894
2.04440000 1.92756494 1.49461300
2.04000000 1.92084692 1.48940428
2.03560000 1.91950730 1.48836563
2.03120000 1.91531196 1.48511282
2.02680000 1.91259813 1.48300869
2.02240000 1.90287707 1.47547160
2.01800000 1.89554062 1.46978338
2.01360000 1.89333031 1.46806964
2.00920000 1.89222582 1.46721329
2.00480000 1.88972327 1.46527298
2.00040000 1.88418035 1.46097535
1.99600000 1.87966250 1.45747249
1.99160000 1.87719795 1.45556163
1.98720000 1.87117177 1.45088932
1.98280000 1.87079180 1.45059471
1.97840000 1.86039595 1.44253443
1.97400000 1.86018771 1.44237298
1.96960000 1.85327881 1.43701625
1.96520000 1.85271691 1.43658059
1.96080000 1.84783197 1.43279312
1.95640000 1.84316158 1.42917199
1.95200000 1.83989853 1.42664203
1.94760000 1.83553952 1.42326233
1.94320000 1.83086990 1.41964180
1.93880000 1.82439362 1.41462051
1.93440000 1.82016320 1.41134051
1.93000000 1.82212995 1.41286540
1.92560000 1.81425768 1.40676174
1.92120000 1.80947086 1.40305034
1.91680000 1.80502898 1.39960639
1.91240000 1.80090695 1.39641043
1.90800000 1.79665729 1.39311551
1.90360000 1.79451548 1.39145489
1.89920000 1.78839749 1.38671138
1.89480000 1.78601789 1.38486639
1.89040000 1.78244555 1.38209663
1.88600000 1.77804535 1.37868500
1.88160000 1.77165867 1.37373317
1.87720000 1.76957220 1.37211545
1.87280000 1.76523958 1.36875621
1.86840000 1.76425997 1.36799669
1.86400000 1.75844919 1.36349137
1.85960000 1.75267743 1.35901632
1.85520000 1.74935940 1.35644372
1.85080000 1.74177712 1.35056491
1.84640000 1.73995088 1.34914896
1.84200000 1.73634714 1.34635484
1.83760000 1.73169598 1.34274863
1.83320000 1.72537805 1.33785011
1.82880000 1.72328464 1.33622701
1.82440000 1.71693796 1.33130620
1.82000000 1.71764138 1.33185158
1.81560000 1.71752286 1.33175969
1.81120000 1.70782551 1.32424098
1.80680000 1.70593969 1.32277884
1.80240000 1.69791598 1.31655776
1.79800000 1.69798697 1.31661280
1.79360000 1.68982205 1.31028224
1.78920000 1.68510007 1.30662111
1.78480000 1.68515782 1.30666589
1.78040000 1.67533444 1.29904947
1.77600000 1.67647901 1.29993689
1.77160000 1.67214375 1.29657561
1.76720000 1.66819787 1.29351622
1.76280000 1.65976359 1.28697682
1.75840000 1.65388540 1.28241924
1.75400000 1.64879035 1.27846886
1.74960000 1.64782784 1.27772259
1.74520000 1.64969997 1.27917412
1.74080000 1.63882815 1.27074480
1.73640000 1.63841576 1.27042506
1.73200000 1.63077076 1.26449761
1.72760000 1.62978097 1.26373019
1.72320000 1.62549488 1.26040703
1.71880000 1.61788507 1.25450686
1.71440000 1.61707359 1.25387770
1.71000000 1.61313665 1.25082524
1.70560000 1.60894802 1.24757764
1.70120000 1.60466012 1.24425308
1.69680000 1.59668169 1.23806711
1.69240000 1.59373721 1.23578414
1.68800000 1.59173081 1.23422851
1.68360000 1.58731986 1.23080854
1.67920000 1.58307761 1.22751937
1.67480000 1.57918038 1.22449770
1.67040000 1.57452375 1.22088725
1.66600000 1.58243143 1.22701836
1.66160000 1.57513146 1.22135842
1.65720000 1.57211138 1.21901684
1.65280000 1.56502820 1.21352500
1.64840000 1.56537919 1.21379713
1.64400000 1.56030094 1.20985978
1.63960000 1.55638396 1.20682280
1.63520000 1.55207568 1.20348243
1.63080000 1.54471690 1.19777690
1.62640000 1.54406848 1.19727416
1.62200000 1.53958274 1.19379620
1.61760000 1.53515980 1.19036693
1.61320000 1.52976723 1.18618587
1.60880000 1.52504327 1.18252322
1.60440000 1.52302907 1.18096153
1.60000000 1.51721893 1.17645672
1.59560000 1.51241552 1.17273246
1.59120000 1.50624721 1.16794995
1.58680000 1.50385834 1.16609776
1.58240000 1.50146530 1.16424235
1.57800000 1.49557548 1.15967576
1.57360000 1.49349791 1.15806495
1.56920000 1.48725716 1.15322626
1.56480000 1.48250592 1.14954245
1.56040000 1.47918170 1.14696506
1.55600000 1.47396998 1.14292422
1.55160000 1.47511075 1.14380870
1.54720000 1.46915564 1.13919149
1.54280000 1.46749210 1.13790169
1.53840000 1.45872786 1.13110645
1.53400000 1.45467696 1.12796564
1.52960000 1.45448931 1.12782014
1.52520000 1.44582977 1.12110609
1.52080000 1.44069875 1.11712782
1.51640000 1.44210652 1.11821931
1.51200000 1.43300294 1.11116098
1.50760000 1.43223038 1.11056198
1.50320000 1.42359598 1.10386742
1.49880000 1.42304068 1.10343687
1.49440000 1.41570836 1.09775186
1.49000000 1.41472369 1.09698841
1.48560000 1.40727170 1.09121061
1.48120000 1.40638635 1.09052416
1.47680000 1.40184502 1.08700310
1.47240000 1.39801355 1.08403242
1.46800000 1.39185699 1.07925902
1.46360000 1.38943727 1.07738292
1.45920000 1.38527772 1.07415787
1.45480000 1.37927628 1.06950473
1.45040000 1.37261811 1.06434241
1.44600000 1.37203110 1.06388728
1.44160000 1.36342451 1.05721428
1.43720000 1.36364398 1.05738443
1.43280000 1.35958366 1.05423632
1.42840000 1.35520463 1.05084110
1.42400000 1.35053059 1.04721714
1.41960000 1.34387601 1.04205761
1.41520000 1.34236861 1.04088886
1.41080000 1.33828467 1.03772243
1.40640000 1.33366605 1.03414145
1.40200000 1.32955570 1.03095454
1.39760000 1.32394351 1.02660321
1.39320000 1.31948443 1.02314592
1.38880000 1.31597809 1.02042732
1.38440000 1.31191586 1.01727773
1.38000000 1.30796217 1.01421229
1.37560000 1.30374507 1.01094262
1.37120000 1.29965190 1.00776903
1.36680000 1.29485916 1.00405305
1.36240000 1.29080469 1.00090946
1.35800000 1.28689494 0.99787809
1.35360000 1.28227054 0.99429263
1.34920000 1.27820159 0.99113782
1.34480000 1.27346814 0.98746780
1.34040000 1.26956451 0.98444118
1.33600000 1.26493581 0.98085238
1.33160000 1.26092654 0.97774384
1.32720000 1.25651582 0.97432405
1.32280000 1.25255367 0.97125205
1.31840000 1.24781906 0.96758113
1.31400000 1.24352010 0.96424799
1.30960000 1.23966590 0.96125969
1.30520000 1.23511033 0.95772759
1.30080000 1.23110287 0.95462046
1.29640000 1.22645346 0.95101560
1.29200000 1.22253768 0.94797955
1.28760000 1.21792085 0.94439996
1.28320000 1.21388815 0.94127325
1.27880000 1.20935539 0.93775884
1.27440000 1.20512988 0.93448265
1.27000000 1.20113004 0.93138143
1.26560000 1.19551410 0.92702718
1.26120000 1.19260000 0.92476777
1.25680000 1.18775281 0.92100957
1.25240000 1.18801720 0.92121456
1.24800000 1.18396585 0.91807340
1.24360000 1.17992159 0.91493774
1.23920000 1.17541631 0.91144463
1.23480000 1.17112882 0.90812038
1.23040000 1.16680493 0.90476791
1.22600000 1.16256513 0.90148064
1.22160000 1.15815443 0.89806086
1.21720000 1.15381353 0.89469521
1.21280000 1.14967930 0.89148978
1.20840000 1.14538771 0.88816236
1.20400000 1.14104550 0.88479569
1.19960000 1.13226130 0.87798497
1.19520000 1.13109481 0.87708055
1.19080000 1.12346835 0.87116748
1.18640000 1.11952412 0.86810937
1.18200000 1.11528270 0.86482084
1.17760000 1.11412740 0.86392509
1.17320000 1.10673130 0.85819063
1.16880000 1.10241522 0.85484421
1.16440000 1.10143408 0.85408349
1.16000000 1.09366044 0.84805631
1.15560000 1.09250314 0.84715901
1.15120000 1.08527645 0.84155590
1.14680000 1.08105137 0.83828004
1.14240000 1.07998120 0.83745029
1.13800000 1.07633178 0.83462077
1.13360000 1.07166492 0.83100238
1.12920000 1.06393158 0.82500644
1.12480000 1.06300001 0.82428416
1.12040000 1.05907450 0.82124056
1.11600000 1.05113645 0.81508591
1.11160000 1.05080384 0.81482802
1.10720000 1.04730547 0.81211560
1.10280000 1.03818772 0.80504628
1.09840000 1.03654673 0.80377396
1.09400000 1.03314518 0.80113661
1.08960000 1.02917405 0.79805765
1.08520000 1.02537498 0.79511209
1.08080000 1.02014729 0.79105887
1.07640000 1.01602006 0.78785888
1.07200000 1.01229702 0.78497227
1.06760000 1.00740548 0.78117968
1.06320000 1.00404447 0.77857377
1.05880000 0.99937190 0.77495095
1.05440000 0.99541158 0.77188037
1.05000000 0.99108303 0.76852429
1.04560000 0.98613531 0.76468814
1.04120000 0.98235182 0.76175466
1.03680000 0.97801248 0.75839021
1.03240000 0.97528528 0.75627571
1.02800000 0.97117454 0.75308850
1.02360000 0.96718533 0.74999552
1.01920000 0.96086516 0.74509526
1.01480000 0.95633418 0.74158223
1.01040000 0.95288470 0.73890772
1.00600000 0.94786591 0.73501647
1.00160000 0.94636559 0.73385322
0.99720000 0.93925135 0.72833729
0.99280000 0.93519261 0.72519040
0.98840000 0.93336997 0.72377724
0.98400000 0.92635313 0.71833682
0.97960000 0.92206546 0.71501243
0.97520000 0.91779446 0.71170098
0.97080000 0.91601639 0.71032237
0.96640000 0.90893815 0.70483435
0.96200000 0.90478519 0.70161441
0.95760000 0.90059070 0.69836227
0.95320000 0.89612991 0.69490366
0.94880000 0.89203712 0.69173037
0.94440000 0.88788711 0.68851271
0.94000000 0.88343268 0.68505903
0.93560000 0.88145897 0.68352873
0.93120000 0.87739770 0.68037989
0.92680000 0.87302599 0.67699034
0.92240000 0.86632433 0.67179429
0.91800000 0.86324664 0.66940806
0.91360000 0.85746773 0.66492745
0.90920000 0.85314615 0.66157677
0.90480000 0.84870799 0.65813570
0.90040000 0.84471893 0.65504284
0.89600000 0.84028196 0.65160270
0.89160000 0.83614081 0.64839191
0.88720000 0.83145569 0.64475936
0.88280000 0.82992495 0.64357252
0.87840000 0.82293214 0.63815075
0.87400000 0.82128799 0.63687597
0.86960000 0.81683707 0.63342502
0.86520000 0.81261648 0.63015263
0.86080000 0.80606750 0.62507497
0.85640000 0.80156820 0.62158650
0.85200000 0.79964637 0.62009643
0.84760000 0.79330079 0.61517648
0.84320000 0.78820758 0.61122752
0.83880000 0.78587373 0.60941800
0.83440000 0.78219591 0.60656645
0.83000000 0.77719125 0.60268616
0.82560000 0.77273819 0.59923354
0.82120000 0.76908461 0.59640078
0.81680000 0.76678585 0.59461847
0.81240000 0.76084006 0.59000848
0.80800000 0.75579466 0.58609660
0.80360000 0.75395290 0.58466861
0.79920000 0.74721766 0.57944654
0.79480000 0.74514807 0.57784190
0.79040000 0.73875817 0.57288758
0.78600000 0.73654191 0.57116924
0.78160000 0.73600835 0.57075554
0.77720000 0.73439731 0.56950645
0.77280000 0.72239594 0.56020135
0.76840000 0.71795579 0.55675874
0.76400000 0.71371530 0.55347093
0.75960000 0.70931577 0.55005981
0.75520000 0.70541261 0.54703355
0.75080000 0.71170491 0.55191220
0.74640000 0.70772563 0.54882692
0.74200000 0.70093974 0.54356557
0.73760000 0.69916845 0.54219223
0.73320000 0.69462084 0.53866630
0.72880000 0.69062882 0.53557114
0.72440000 0.68336862 0.52994204
0.72000000 0.67909426 0.52662797
0.71560000 0.67540026 0.52376388
0.71120000 0.67326563 0.52210882
0.70680000 0.66878527 0.51863503
0.70240000 0.66458062 0.51537501
0.69800000 0.66032527 0.51207568
0.69360000 0.65587178 0.50862273
0.68920000 0.65171301 0.50539828
0.68480000 0.64720738 0.50190490
0.68040000 0.64245918 0.49822345
0.67600000 0.63878842 0.49537737
0.67160000 0.63432285 0.49191505
0.66720000 0.62996002 0.48853239
0.66280000 0.62553650 0.48510267
0.65840000 0.62241766 0.48268452
0.65400000 0.61687292 0.47838548
0.64960000 0.61268509 0.47513850
0.64520000 0.60837276 0.47179500
0.64080000 0.60585345 0.46984168
0.63640000 0.59964654 0.46502924
0.63200000 0.59535979 0.46170557
0.62760000 0.59124742 0.45851710
0.62320000 0.58813445 0.45610350
0.61880000 0.58286461 0.45201759
0.61440000 0.57787076 0.44814568
0.61000000 0.57588195 0.44660368
0.60560000 0.56963334 0.44175891
0.60120000 0.56514860 0.43828172
0.59680000 0.56895688 0.44123442
0.59240000 0.55700143 0.43196493
0.58800000 0.55196911 0.42806318
0.58360000 0.54919052 0.42590884
0.57920000 0.54531694 0.42290551
0.57480000 0.53966004 0.41851951
0.57040000 0.53515712 0.41502823
0.56600000 0.53055819 0.41146252
0.56160000 0.52808493 0.40954490
0.55720000 0.52182731 0.40469314
0.55280000 0.51766004 0.40146211
0.54840000 0.51632976 0.40043069
0.54400000 0.51505429 0.39944177
0.53960000 0.51352960 0.39825962
0.53520000 0.50884600 0.39462826
0.53080000 0.50273508 0.38989024
0.52640000 0.49820870 0.38638077
0.52200000 0.49552108 0.38429696
0.51760000 0.49107773 0.38085187
0.51320000 0.48603320 0.37694066
0.50880000 0.48171668 0.37359390
0.50440000 0.47801306 0.37072235
0.50000000 0.47126381 0.36548940
0.49560000 0.47718250 0.37007839
0.49120000 0.46502269 0.36065044
0.48680000 0.46039316 0.35706100
0.48240000 0.45438022 0.35239894
0.47800000 0.44922620 0.34840284
0.47360000 0.44740652 0.34699198
0.46920000 0.44300312 0.34357786
0.46480000 0.43837865 0.33999234
0.46040000 0.43444139 0.33693964
0.45600000 0.43029436 0.33372429
0.45160000 0.42107186 0.32657375
0.44720000 0.42252211 0.32769818
0.44280000 0.41801568 0.32420418
0.43840000 0.42545019 0.32996843
0.43400000 0.42137615 0.32680968
0.42960000 0.41181157 0.31939391
0.42520000 0.40780663 0.31628873
0.42080000 0.40747347 0.31603042
0.41640000 0.39886046 0.30935244
0.41200000 0.39891293 0.30939312
0.40760000 0.39129192 0.30348427
0.40320000 0.39059360 0.30294284
0.39880000 0.38161329 0.29598008
0.39440000 0.37828023 0.29339583
0.39000000 0.37759443 0.29286411
0.38560000 0.37282043 0.28916265
0.38120000 0.36814663 0.28553889
0.37680000 0.36040021 0.27953280
0.37240000 0.35997189 0.27920070
0.36800000 0.35173711 0.27281598
0.36360000 0.35080567 0.27209380
0.35920000 0.34636993 0.26865461
0.35480000 0.34205950 0.26531257
0.35040000 0.33770021 0.26193266
0.34600000 0.33362368 0.25877198
0.34160000 0.32923077 0.25536599
0.33720000 0.32461243 0.25178522
0.33280000 0.32016432 0.24833644
0.32840000 0.31579782 0.24495093
0.32400000 0.31140610 0.24154587
0.31960000 0.30689270 0.23804647
0.31520000 0.30249839 0.23463940
0.31080000 0.29813772 0.23125841
0.30640000 0.29396865 0.22802598
0.30200000 0.28982950 0.22481674
0.29760000 0.28508707 0.22113977
0.29320000 0.28060569 0.21766519
0.28880000 0.27656771 0.21453439
0.28440000 0.27139388 0.21052293
0.28000000 0.26779279 0.20773088
0.27560000 0.26314235 0.20412522
0.27120000 0.25918532 0.20105719
0.26680000 0.25432236 0.19728676
0.26240000 0.25004138 0.19396756
0.25800000 0.24537171 0.19034699
0.25360000 0.24142844 0.18728963
0.24920000 0.23677944 0.18368509
0.24480000 0.23244552 0.18032485
0.24040000 0.22816457 0.17700566
0.23600000 0.22383365 0.17364775
0.23160000 0.21937484 0.17019067
0.22720000 0.21799319 0.16911942
0.22280000 0.21069366 0.16345983
0.21840000 0.20608360 0.15988548
0.21400000 0.20552038 0.15944879
0.20960000 0.19726765 0.15305015
0.20520000 0.19666914 0.15258611
0.20080000 0.18865120 0.14636951
0.19640000 0.18453525 0.14317826
0.19200000 0.17957505 0.13933243
0.18760000 0.18419977 0.14291815
0.18320000 0.18343663 0.14232646
0.17880000 0.17911134 0.13897290
0.17440000 0.17093056 0.13263004
0.17000000 0.16688031 0.12948973
0.16560000 0.16221069 0.12586920
0.16120000 0.15784752 0.12248628
0.15680000 0.15334802 0.11899765
0.15240000 0.14905518 0.11566926
0.14800000 0.14480154 0.11237125
0.14360000 0.14023397 0.10882985
0.13920000 0.13614653 0.10566071
0.13480000 0.13170341 0.10221580
0.13040000 0.12745050 0.09891836
0.12600000 0.12634199 0.09805889
0.12160000 0.11855112 0.09201834
0.11720000 0.11435135 0.08876211
0.11280000 0.10984444 0.08526773
0.10840000 0.10556956 0.08195326
0.10400000 0.10091964 0.07834801
0.09960000 0.09697744 0.07529148
0.09520000 0.09561215 0.07423292
0.09080000 0.08795683 0.06829747
0.08640000 0.08329880 0.06468593
0.08200000 0.07893570 0.06130305
0.07760000 0.07788698 0.06048995
0.07320000 0.07414611 0.05758951
0.06880000 0.06958670 0.05405443
0.06440000 0.06161929 0.04787701
0.06000000 0.06041664 0.04694456
0.05560000 0.05282165 0.04105588
0.05120000 0.05191189 0.04035051
0.04680000 0.04703849 0.03657198
0.04240000 0.04011848 0.03120665
0.03800000 0.03820700 0.02972461
0.03360000 0.03133382 0.02439557
0.02920000 0.02613330 0.02036342
0.02480000 0.02434383 0.01897598
0.02040000 0.01665549 0.01301493
0.01600000 0.01219939 0.00955995
0.01160000 0.00789672 0.00622393
0.00720000 0.00374060 0.00300155
0.00280000 0.00216508 0.00177998
-0.00000000 0.00055527 0.00053184