File: plots/rawdata/Figure2-10K.txt
# strain(%), strain_el(%), stress(GPa)
0.00000000 -0.00013068 0.00000000
0.00080000 0.00380554 0.00305189
0.00160000 0.00497062 0.00395522
0.00240000 0.00564692 0.00447958
0.00320000 0.00553051 0.00438933
0.00400000 0.00646032 0.00511024
0.00480000 0.00721308 0.00569388
0.00560000 0.00772833 0.00609337
0.00640000 0.00865893 0.00681490
0.00720000 0.00682507 0.00539304
0.00800000 0.00875284 0.00688772
0.00880000 0.00917663 0.00721630
0.00960000 0.00925063 0.00727367
0.01040000 0.00971253 0.00763179
0.01120000 0.01162512 0.00911470
0.01200000 0.01475744 0.01154331
0.01280000 0.01626727 0.01271393
0.01360000 0.01591612 0.01244167
0.01440000 0.01653297 0.01291993
0.01520000 0.01745822 0.01363732
0.01600000 0.01837068 0.01434478
0.01680000 0.02003412 0.01563450
0.01760000 0.02059427 0.01606881
0.01840000 0.01783559 0.01392990
0.01920000 0.01849020 0.01443745
0.02000000 0.01993958 0.01556120
0.02080000 0.02126750 0.01659079
0.02160000 0.02388689 0.01862170
0.02240000 0.02438806 0.01901028
0.02320000 0.02657530 0.02070612
0.02400000 0.02640397 0.02057329
0.02480000 0.02683269 0.02090568
0.02560000 0.02779397 0.02165100
0.02640000 0.02925925 0.02278709
0.02720000 0.03066399 0.02387624
0.02800000 0.03056583 0.02380013
0.02880000 0.03097748 0.02411929
0.02960000 0.03174400 0.02471360
0.03040000 0.03263016 0.02540067
0.03120000 0.03383003 0.02633098
0.03200000 0.03564398 0.02773740
0.03280000 0.03619136 0.02816181
0.03360000 0.03613081 0.02811486
0.03440000 0.03643959 0.02835427
0.03520000 0.03741633 0.02911157
0.03600000 0.03936838 0.03062506
0.03680000 0.03994346 0.03107095
0.03760000 0.03982873 0.03098199
0.03840000 0.04065542 0.03162295
0.03920000 0.04136842 0.03217577
0.04000000 0.04207534 0.03272387
0.04080000 0.04307671 0.03350027
0.04160000 0.04377611 0.03404254
0.04240000 0.04175095 0.03247236
0.04320000 0.04238333 0.03296267
0.04400000 0.04301221 0.03345026
0.04480000 0.04526319 0.03519552
0.04560000 0.04590770 0.03569524
0.04640000 0.04578343 0.03559889
0.04720000 0.04621825 0.03593602
0.04800000 0.04716595 0.03667081
0.04880000 0.04803558 0.03734507
0.04960000 0.05251661 0.04081937
0.05040000 0.05265284 0.04092499
0.05120000 0.05331561 0.04143886
0.05200000 0.05419367 0.04211965
0.05280000 0.05611661 0.04361058
0.05360000 0.05660314 0.04398781
0.05440000 0.05705305 0.04433663
0.05520000 0.05740583 0.04461016
0.05600000 0.05507396 0.04280218
0.05680000 0.05608271 0.04358430
0.05760000 0.06063749 0.04711578
0.05840000 0.06174037 0.04797089
0.05920000 0.06161510 0.04787376
0.06000000 0.06218796 0.04831792
0.06080000 0.06322634 0.04912301
0.06160000 0.06465493 0.05023065
0.06240000 0.06549958 0.05088554
0.06320000 0.06562030 0.05097914
0.06400000 0.06617669 0.05141053
0.06480000 0.06731810 0.05229550
0.06560000 0.06885295 0.05348553
0.06640000 0.06545530 0.05085121
0.06720000 0.06644023 0.05161486
0.06800000 0.06699659 0.05204623
0.06880000 0.06778587 0.05265818
0.06960000 0.06873655 0.05339528
0.07040000 0.07340423 0.05701431
0.07120000 0.07358498 0.05715444
0.07200000 0.07382955 0.05734408
0.07280000 0.07203037 0.05594910
0.07360000 0.07268445 0.05645623
0.07440000 0.07367538 0.05722454
0.07520000 0.07457324 0.05792068
0.07600000 0.07513066 0.05835287
0.07680000 0.07716944 0.05993361
0.07760000 0.07684238 0.05968003
0.07840000 0.07737098 0.06008987
0.07920000 0.07810668 0.06066029
0.08000000 0.07921880 0.06152255
0.08080000 0.07974722 0.06193226
0.08160000 0.08070513 0.06267496
0.08240000 0.08157025 0.06334572
0.08320000 0.08228437 0.06389940
0.08400000 0.08616835 0.06691079
0.08480000 0.08703352 0.06758159
0.08560000 0.08780837 0.06818236
0.08640000 0.08546666 0.06636675
0.08720000 0.08638950 0.06708226
0.08800000 0.08810839 0.06841498
0.08880000 0.08790963 0.06826087
0.08960000 0.08854848 0.06875620
0.09040000 0.08918774 0.06925184
0.09120000 0.09019234 0.07003074
0.09200000 0.09114999 0.07077325
0.09280000 0.09182718 0.07129829
0.09360000 0.09666513 0.07504934
0.09440000 0.09732291 0.07555934
0.09520000 0.09739575 0.07561581
0.09600000 0.09831849 0.07633124
0.09680000 0.09583371 0.07440470
0.09760000 0.09661690 0.07501194
0.09840000 0.10068541 0.07816640
0.09920000 0.09817084 0.07621676
0.10000000 0.09890215 0.07678378
0.10080000 0.09992915 0.07758005
0.10160000 0.10053881 0.07805274
0.10240000 0.10141660 0.07873333
0.10320000 0.10210089 0.07926388
0.10400000 0.10293971 0.07991424
0.10480000 0.10381270 0.08059111
0.10560000 0.10453874 0.08115403
0.10640000 0.10546345 0.08187100
0.10720000 0.10616723 0.08241666
0.10800000 0.10692811 0.08300660
0.10880000 0.10760310 0.08352994
0.10960000 0.10856791 0.08427799
0.11040000 0.10920814 0.08477439
0.11120000 0.11013329 0.08549169
0.11200000 0.11098833 0.08615464
0.11280000 0.11166496 0.08667925
0.11360000 0.11252256 0.08734418
0.11440000 0.11334015 0.08797809
0.11520000 0.11424009 0.08867584
0.11600000 0.11476587 0.08908350
0.11680000 0.11574577 0.08984325
0.11760000 0.11989859 0.09306309
0.11840000 0.12061163 0.09361593
0.11920000 0.12146286 0.09427592
0.12000000 0.12240790 0.09500864
0.12080000 0.12362234 0.09595025
0.12160000 0.12452541 0.09665043
0.12240000 0.12511869 0.09711042
0.12320000 0.12543523 0.09735584
0.12400000 0.12627903 0.09801008
0.12480000 0.12375640 0.09605419
0.12560000 0.12448174 0.09661657
0.12640000 0.12598940 0.09778551
0.12720000 0.12607156 0.09784921
0.12800000 0.12655172 0.09822150
0.12880000 0.12791290 0.09927687
0.12960000 0.12818648 0.09948899
0.13040000 0.12923501 0.10030195
0.13120000 0.13024621 0.10108597
0.13200000 0.13071664 0.10145072
0.13280000 0.13179763 0.10228885
0.13360000 0.13241342 0.10276629
0.13440000 0.13323991 0.10340710
0.13520000 0.13424879 0.10418932
0.13600000 0.13501226 0.10478127
0.13680000 0.13569448 0.10531022
0.13760000 0.13628060 0.10576466
0.13840000 0.13741542 0.10664453
0.13920000 0.13815563 0.10721844
0.14000000 0.13883910 0.10774835
0.14080000 0.13924797 0.10806537
0.14160000 0.14044675 0.10899483
0.14240000 0.14117225 0.10955734
0.14320000 0.14204203 0.11023170
0.14400000 0.14292162 0.11091368
0.14480000 0.14352933 0.11138487
0.14560000 0.14438940 0.11205171
0.14640000 0.14520152 0.11268137
0.14720000 0.14581371 0.11315603
0.14800000 0.14680145 0.11392185
0.14880000 0.14747351 0.11444293
0.14960000 0.14847631 0.11522044
0.15040000 0.14908617 0.11569329
0.15120000 0.14980140 0.11624783
0.15200000 0.15066258 0.11691553
0.15280000 0.15152727 0.11758596
0.15360000 0.15248572 0.11832908
0.15440000 0.15298430 0.11871565
0.15520000 0.15411213 0.11959009
0.15600000 0.15456027 0.11993756
0.15680000 0.15536154 0.12055881
0.15760000 0.15617024 0.12118583
0.15840000 0.15707499 0.12188731
0.15920000 0.15786371 0.12249884
0.16000000 0.15848947 0.12298401
0.16080000 0.15949138 0.12376083
0.16160000 0.16043009 0.12448864
0.16240000 0.16117747 0.12506811
0.16320000 0.16189629 0.12562544
0.16400000 0.16620914 0.12896935
0.16480000 0.16706744 0.12963482
0.16560000 0.16766606 0.13009895
0.16640000 0.16854709 0.13078205
0.16720000 0.16921120 0.13129696
0.16800000 0.17028899 0.13213261
0.16880000 0.16718363 0.12972491
0.16960000 0.16812781 0.13045697
0.17040000 0.17253613 0.13387490
0.17120000 0.17343892 0.13457487
0.17200000 0.17061455 0.13238503
0.17280000 0.17156051 0.13311846
0.17360000 0.17206075 0.13350632
0.17440000 0.17278420 0.13406724
0.17520000 0.17379355 0.13484982
0.17600000 0.17462857 0.13549724
0.17680000 0.17885377 0.13877319
0.17760000 0.17602293 0.13657835
0.17840000 0.17674443 0.13713775
0.17920000 0.17740471 0.13764969
0.18000000 0.17857563 0.13855754
0.18080000 0.17946386 0.13924622
0.18160000 0.18019189 0.13981069
0.18240000 0.18094211 0.14039236
0.18320000 0.18530058 0.14377164
0.18400000 0.18272534 0.14177497
0.18480000 0.18337838 0.14228129
0.18560000 0.18381967 0.14262344
0.18640000 0.18775592 0.14567536
0.18720000 0.18914939 0.14675577
0.18800000 0.19019101 0.14756337
0.18880000 0.19081324 0.14804581
0.18960000 0.18788314 0.14577400
0.19040000 0.18887903 0.14654615
0.19120000 0.18968675 0.14717240
0.19200000 0.19025818 0.14761545
0.19280000 0.19150601 0.14858294
0.19360000 0.19202487 0.14898523
0.19440000 0.19262033 0.14944691
0.19520000 0.19372087 0.15030020
0.19600000 0.19434686 0.15078555
0.19680000 0.19540444 0.15160554
0.19760000 0.19592847 0.15201183
0.19840000 0.19656695 0.15250688
0.19920000 0.19761086 0.15331625
0.20000000 0.19845997 0.15397460
0.20080000 0.19927700 0.15460808
0.20160000 0.20004012 0.15519975
0.20240000 0.20065746 0.15567840
0.20320000 0.20160777 0.15641521
0.20400000 0.20260086 0.15718519
0.20480000 0.20323046 0.15767333
0.20560000 0.20410518 0.15835154
0.20640000 0.20450094 0.15865838
0.20720000 0.20580393 0.15966864
0.20800000 0.20652216 0.16022551
0.20880000 0.20689932 0.16051794
0.20960000 0.20810361 0.16145167
0.21040000 0.20876236 0.16196242
0.21120000 0.20939283 0.16245125
0.21200000 0.21018572 0.16306601
0.21280000 0.21121511 0.16386413
0.21360000 0.21139606 0.16400443
0.21440000 0.21243060 0.16480654
0.21520000 0.21364802 0.16575045
0.21600000 0.21414541 0.16613610
0.21680000 0.21496749 0.16677348
0.21760000 0.21565182 0.16730407
0.21840000 0.21673036 0.16814031
0.21920000 0.21742231 0.16867680
0.22000000 0.21839774 0.16943308
0.22080000 0.22220345 0.17238379
0.22160000 0.22387199 0.17367747
0.22240000 0.22453207 0.17418926
0.22320000 0.22556149 0.17498740
0.22400000 0.22588289 0.17523660
0.22480000 0.22697104 0.17608028
0.22560000 0.22749733 0.17648833
0.22640000 0.22413958 0.17388494
0.22720000 0.22535661 0.17482855
0.22800000 0.22633804 0.17558949
0.22880000 0.22718690 0.17624764
0.22960000 0.22751441 0.17650157
0.23040000 0.22856633 0.17731716
0.23120000 0.22959147 0.17811199
0.23200000 0.22985580 0.17831694
0.23280000 0.23083749 0.17907808
0.23360000 0.23150897 0.17959870
0.23440000 0.23238544 0.18027826
0.23520000 0.23326434 0.18095970
0.23600000 0.23406043 0.18157694
0.23680000 0.23468860 0.18206399
0.23760000 0.23544693 0.18265194
0.23840000 0.23624940 0.18327413
0.23920000 0.23735855 0.18413410
0.24000000 0.23823087 0.18481044
0.24080000 0.23866619 0.18514796
0.24160000 0.23904751 0.18544360
0.24240000 0.24423357 0.18946455
0.24320000 0.24516981 0.19019045
0.24400000 0.24568119 0.19058695
0.24480000 0.24628081 0.19105185
0.24560000 0.24752850 0.19201923
0.24640000 0.24832584 0.19263743
0.24720000 0.24809243 0.19245647
0.24800000 0.24986820 0.19383328
0.24880000 0.25076013 0.19452483
0.24960000 0.24761774 0.19208842
0.25040000 0.24851333 0.19278280
0.25120000 0.24877024 0.19298199
0.25200000 0.24976403 0.19375251
0.25280000 0.25072933 0.19450095
0.25360000 0.25140296 0.19502324
0.25440000 0.25233371 0.19574488
0.25520000 0.25319442 0.19641222
0.25600000 0.25380929 0.19688896
0.25680000 0.25481901 0.19767183
0.25760000 0.25548818 0.19819066
0.25840000 0.25651300 0.19898524
0.25920000 0.25712071 0.19945642
0.26000000 0.25773824 0.19993522
0.26080000 0.25868923 0.20067255
0.26160000 0.25957138 0.20135651
0.26240000 0.26012979 0.20178947
0.26320000 0.26092094 0.20240288
0.26400000 0.26207838 0.20330029
0.26480000 0.26221616 0.20340711
0.26560000 0.26327464 0.20422779
0.26640000 0.26431317 0.20503300
0.26720000 0.26496286 0.20553673
0.26800000 0.26561956 0.20604589
0.26880000 0.26646190 0.20669899
0.26960000 0.26732287 0.20736653
0.27040000 0.26831495 0.20813573
0.27120000 0.26875893 0.20847996
0.27200000 0.26971663 0.20922250
0.27280000 0.27426082 0.21274577
0.27360000 0.27520007 0.21347401
0.27440000 0.27151231 0.21061475
0.27520000 0.27280941 0.21162045
0.27600000 0.27357949 0.21221752
0.27680000 0.27423517 0.21272589
0.27760000 0.27504880 0.21335673
0.27840000 0.27618669 0.21423897
0.27920000 0.27692258 0.21480953
0.28000000 0.27742992 0.21520289
0.28080000 0.27847283 0.21601150
0.28160000 0.27905039 0.21645930
0.28240000 0.28022362 0.21736896
0.28320000 0.28078994 0.21780804
0.28400000 0.28131229 0.21821304
0.28480000 0.28258726 0.21920157
0.28560000 0.28329568 0.21975083
0.28640000 0.28392530 0.22023900
0.28720000 0.28483222 0.22094217
0.28800000 0.28543975 0.22141321
0.28880000 0.28642228 0.22217500
0.28960000 0.28731610 0.22286801
0.29040000 0.28805521 0.22344107
0.29120000 0.28872902 0.22396350
0.29200000 0.28953084 0.22458518
0.29280000 0.29039650 0.22525636
0.29360000 0.29132651 0.22597743
0.29440000 0.29175801 0.22631199
0.29520000 0.29257771 0.22694753
0.29600000 0.29392352 0.22799099
0.29680000 0.29436657 0.22833450
0.29760000 0.29506952 0.22887952
0.29840000 0.29567186 0.22934654
0.29920000 0.29681737 0.23023469
0.30000000 0.29751686 0.23077703
0.30080000 0.29844516 0.23149678
0.30160000 0.29912553 0.23202430
0.30240000 0.29966614 0.23244345
0.30320000 0.30048440 0.23307788
0.30400000 0.30142125 0.23380425
0.30480000 0.30211947 0.23434561
0.30560000 0.30316958 0.23515980
0.30640000 0.30387403 0.23570598
0.30720000 0.30455322 0.23623259
0.30800000 0.30531724 0.23682495
0.30880000 0.30606541 0.23740504
0.30960000 0.30704261 0.23816269
0.31040000 0.30744884 0.23847766
0.31120000 0.30873095 0.23947173
0.31200000 0.30959718 0.24014335
0.31280000 0.30963654 0.24017387
0.31360000 0.31060156 0.24092208
0.31440000 0.31192799 0.24195051
0.31520000 0.31278310 0.24261351
0.31600000 0.31313764 0.24288840
0.31680000 0.31397417 0.24353699
0.31760000 0.31520553 0.24449171
0.31840000 0.31590377 0.24503308
0.31920000 0.31637029 0.24539479
0.32000000 0.31700740 0.24588877
0.32080000 0.31847667 0.24702794
0.32160000 0.31903420 0.24746021
0.32240000 0.31981706 0.24806720
0.32320000 0.32031448 0.24845287
0.32400000 0.32113704 0.24909063
0.32480000 0.32192236 0.24969952
0.32560000 0.32283429 0.25040656
0.32640000 0.32341600 0.25085759
0.32720000 0.32417769 0.25144816
0.32800000 0.32537003 0.25237262
0.32880000 0.32619773 0.25301437
0.32960000 0.32695647 0.25360264
0.33040000 0.32783152 0.25428110
0.33120000 0.32840274 0.25472399
0.33200000 0.32927792 0.25540255
0.33280000 0.32998247 0.25594881
0.33360000 0.33048646 0.25633957
0.33440000 0.33143305 0.25707350
0.33520000 0.33242844 0.25784526
0.33600000 0.33314021 0.25839713
0.33680000 0.33309765 0.25836413
0.33760000 0.33488142 0.25974715
0.33840000 0.33568991 0.26037400
0.33920000 0.33627630 0.26082865
0.34000000 0.33672888 0.26117955
0.34080000 0.33768191 0.26191847
0.34160000 0.33909988 0.26301788
0.34240000 0.33922524 0.26311507
0.34320000 0.33977527 0.26354153
0.34400000 0.34141569 0.26481341
0.34480000 0.34210260 0.26534599
0.34560000 0.34295126 0.26600399
0.34640000 0.34304781 0.26607885
0.34720000 0.34398767 0.26680755
0.34800000 0.34876703 0.27051317
0.34880000 0.34932519 0.27094593
0.34960000 0.34653764 0.26878464
0.35040000 0.34706087 0.26919032
0.35120000 0.34824888 0.27011143
0.35200000 0.34867750 0.27044375
0.35280000 0.34967736 0.27121898
0.35360000 0.35090822 0.27217331
0.35440000 0.35137113 0.27253222
0.35520000 0.35161935 0.27272468
0.35600000 0.35248870 0.27339871
0.35680000 0.35380904 0.27442242
0.35760000 0.34979113 0.27130719
0.35840000 0.35077549 0.27207040
0.35920000 0.35637278 0.27641018
0.36000000 0.35698717 0.27688655
0.36080000 0.35750664 0.27728931
0.36160000 0.35447294 0.27493717
0.36240000 0.35447605 0.27493958
0.36320000 0.36004489 0.27925731
0.36400000 0.36093228 0.27994533
0.36480000 0.36193196 0.28072042
0.36560000 0.36237394 0.28106310
0.36640000 0.36303286 0.28157399
0.36720000 0.36395971 0.28229261
0.36800000 0.36484659 0.28298024
0.36880000 0.36582536 0.28373912
0.36960000 0.36665339 0.28438112
0.37040000 0.36742699 0.28498092
0.37120000 0.36732844 0.28490451
0.37200000 0.36838979 0.28572741
0.37280000 0.36965597 0.28670913
0.37360000 0.37042919 0.28730864
0.37440000 0.37151246 0.28814854
0.37520000 0.37160830 0.28822284
0.37600000 0.37260123 0.28899270
0.37680000 0.37362840 0.28978910
0.37760000 0.37453438 0.29049154
0.37840000 0.37508602 0.29091925
0.37920000 0.37542838 0.29118469
0.38000000 0.37679799 0.29224660
0.38080000 0.37743721 0.29274221
0.38160000 0.37830934 0.29341840
0.38240000 0.37835017 0.29345006
0.38320000 0.37977336 0.29455351
0.38400000 0.38118882 0.29565097
0.38480000 0.38159107 0.29596285
0.38560000 0.38124882 0.29569749
0.38640000 0.38295994 0.29702419
0.38720000 0.38391922 0.29776795
0.38800000 0.38435496 0.29810579
0.38880000 0.38476419 0.29842309
0.38960000 0.38641436 0.29970252
0.39040000 0.38744265 0.30049980
0.39120000 0.38717620 0.30029320
0.39200000 0.38778465 0.30076496
0.39280000 0.38928815 0.30193068
0.39360000 0.38994271 0.30243818
0.39440000 0.39034554 0.30275051
0.39520000 0.39112000 0.30335098
0.39600000 0.39298176 0.30479447
0.39680000 0.39286333 0.30470264
0.39760000 0.38746231 0.30051504
0.39840000 0.38900663 0.30171241
0.39920000 0.39596575 0.30710807
0.40000000 0.39659773 0.30759806
0.40080000 0.39104840 0.30329547
0.40160000 0.39166047 0.30377002
0.40240000 0.39320658 0.30496878
0.40320000 0.39958172 0.30991166
0.40400000 0.40049519 0.31061991
0.40480000 0.40066807 0.31075394
0.40560000 0.40150028 0.31139919
0.40640000 0.40280850 0.31241350
0.40720000 0.40411796 0.31342877
0.40800000 0.40378288 0.31316898
0.40880000 0.40103446 0.31103802
0.40960000 0.40029181 0.31046222
0.41040000 0.40132626 0.31126427
0.41120000 0.40747364 0.31603055
0.41200000 0.40760839 0.31613503
0.41280000 0.40569681 0.31465291
0.41360000 0.40405696 0.31338147
0.41440000 0.40455228 0.31376552
0.41520000 0.41111266 0.31885202
0.41600000 0.41167335 0.31928674
0.41680000 0.41315706 0.32043712
0.41760000 0.40823687 0.31662232
0.41840000 0.41137938 0.31905881
0.41920000 0.41505129 0.32190578
0.42000000 0.41615353 0.32276039
0.42080000 0.41192055 0.31947841
0.42160000 0.41099561 0.31876127
0.42240000 0.41197141 0.31951784
0.42320000 0.41402713 0.32111172
0.42400000 0.42051176 0.32613949
0.42480000 0.42031525 0.32598712
0.42560000 0.41581101 0.32249482
0.42640000 0.41637715 0.32293377
0.42720000 0.41747133 0.32378213
0.42800000 0.41779867 0.32403593
0.42880000 0.41835487 0.32446717
0.42960000 0.41940423 0.32528078
0.43040000 0.42006234 0.32579103
0.43120000 0.42055068 0.32616966
0.43200000 0.42222879 0.32747077
0.43280000 0.42923023 0.33289924
0.43360000 0.43006848 0.33354916
0.43440000 0.42993085 0.33344245
0.43520000 0.43068135 0.33402434
0.43600000 0.43173952 0.33484478
0.43680000 0.43297140 0.33579990
0.43760000 0.43368555 0.33635361
0.43840000 0.42843614 0.33228355
0.43880000 0.42245600 0.32764692
0.43800000 0.42247259 0.32765979
0.43720000 0.42127264 0.32672942
0.43640000 0.42249931 0.32768051
0.43560000 0.41643992 0.32298244
0.43480000 0.41571190 0.32241798
0.43400000 0.41546390 0.32222570
0.43320000 0.41944899 0.32531548
0.43240000 0.41825365 0.32438869
0.43160000 0.41233681 0.31980115
0.43080000 0.41208562 0.31960639
0.43000000 0.41626909 0.32284999
0.42920000 0.41528578 0.32208759
0.42840000 0.40931702 0.31745980
0.42760000 0.40902113 0.31723038
0.42680000 0.41299260 0.32030960
0.42600000 0.40609705 0.31496324
0.42520000 0.40463363 0.31382859
0.42440000 0.40579670 0.31473036
0.42360000 0.41004115 0.31802124
0.42280000 0.40891138 0.31714529
0.42200000 0.40197499 0.31176725
0.42120000 0.40292134 0.31250099
0.42040000 0.40209148 0.31185757
0.41960000 0.40611865 0.31497998
0.41880000 0.40497990 0.31409706
0.41800000 0.40404872 0.31337509
0.41720000 0.39929116 0.30968638
0.41640000 0.39821938 0.30885539
0.41560000 0.40190115 0.31171000
0.41480000 0.40068520 0.31076723
0.41400000 0.39992583 0.31017846
0.41320000 0.39504308 0.30639269
0.41240000 0.39873564 0.30925566
0.41160000 0.39746312 0.30826903
0.41080000 0.39720639 0.30806998
0.41000000 0.39166205 0.30377125
0.40920000 0.39248185 0.30440687
0.40840000 0.39473454 0.30615346
0.40760000 0.39389976 0.30550623
0.40680000 0.39301973 0.30482391
0.40600000 0.39228366 0.30425321
0.40520000 0.39178915 0.30386980
0.40440000 0.39077428 0.30308293
0.40360000 0.38979857 0.30232642
0.40280000 0.38914826 0.30182222
0.40200000 0.38834521 0.30119958
0.40120000 0.38747424 0.30052429
0.40040000 0.38643196 0.29971617
0.39960000 0.38578880 0.29921751
0.39880000 0.38500995 0.29861363
0.39800000 0.37833442 0.29343785
0.39720000 0.38359165 0.29751397
0.39640000 0.38298096 0.29704048
0.39560000 0.38185332 0.29616618
0.39480000 0.38130907 0.29574420
0.39400000 0.38035071 0.29500115
0.39320000 0.37952729 0.29436272
0.39240000 0.37870151 0.29372246
0.39160000 0.37790481 0.29310475
0.39080000 0.37716093 0.29252800
0.39000000 0.37657087 0.29207050
0.38920000 0.37581865 0.29148728
0.38840000 0.37088162 0.28765942
0.38760000 0.36962570 0.28668566
0.38680000 0.37339754 0.28961011
0.38600000 0.37227186 0.28873732
0.38520000 0.37137332 0.28804066
0.38440000 0.37077287 0.28757510
0.38360000 0.37009793 0.28705180
0.38280000 0.36533852 0.28336165
0.38200000 0.36472769 0.28288805
0.38120000 0.36759023 0.28510749
0.38040000 0.36677541 0.28447572
0.37960000 0.36594487 0.28383177
0.37880000 0.36525633 0.28329793
0.37800000 0.36453704 0.28274023
0.37720000 0.35956058 0.27888180
0.37640000 0.35929873 0.27867878
0.37560000 0.36206562 0.28082405
0.37480000 0.36116154 0.28012309
0.37400000 0.36024343 0.27941124
0.37320000 0.35959777 0.27891064
0.37240000 0.35871909 0.27822937
0.37160000 0.35810266 0.27775142
0.37080000 0.35736754 0.27718146
0.37000000 0.35657797 0.27656927
0.36920000 0.35575789 0.27593344
0.36840000 0.35508104 0.27540866
0.36760000 0.35433312 0.27482876
0.36680000 0.35337081 0.27408265
0.36600000 0.35257673 0.27346697
0.36520000 0.35139215 0.27254852
0.36440000 0.35104942 0.27228279
0.36360000 0.34664774 0.26887001
0.36280000 0.34939663 0.27100132
0.36200000 0.34832743 0.27017233
0.36120000 0.34783369 0.26978952
0.36040000 0.34713465 0.26924752
0.35960000 0.34588932 0.26828198
0.35880000 0.34540023 0.26790277
0.35800000 0.34450941 0.26721208
0.35720000 0.34385336 0.26670342
0.35640000 0.34291885 0.26597886
0.35560000 0.34195960 0.26523512
0.35480000 0.34098765 0.26448153
0.35400000 0.34055433 0.26414556
0.35320000 0.33622531 0.26078911
0.35240000 0.33891114 0.26287154
0.35160000 0.33804070 0.26219666
0.35080000 0.33720817 0.26155116
0.35000000 0.33590259 0.26053890
0.34920000 0.33546079 0.26019636
0.34840000 0.33477951 0.25966813
0.34760000 0.33386621 0.25896002
0.34680000 0.33337589 0.25857986
0.34600000 0.33234060 0.25777716
0.34520000 0.33173860 0.25731040
0.34440000 0.33101528 0.25674959
0.34360000 0.33027117 0.25617265
0.34280000 0.32923486 0.25536916
0.34200000 0.32903242 0.25521220
0.34120000 0.32797501 0.25439235
0.34040000 0.32704676 0.25367265
0.33960000 0.32598581 0.25285006
0.33880000 0.32524811 0.25227809
0.33800000 0.32435028 0.25158197
0.33720000 0.32385615 0.25119885
0.33640000 0.32327896 0.25075134
0.33560000 0.32224264 0.24994784
0.33480000 0.32110850 0.24906850
0.33400000 0.32075588 0.24879510
0.33320000 0.31976885 0.24802982
0.33240000 0.31884089 0.24731033
0.33160000 0.31820156 0.24681464
0.33080000 0.31733247 0.24614080
0.33000000 0.31669364 0.24564549
0.32920000 0.31582176 0.24496949
0.32840000 0.31512458 0.24442894
0.32760000 0.31415066 0.24367383
0.32680000 0.31367089 0.24330185
0.32600000 0.31252892 0.24241644
0.32520000 0.31171318 0.24178396
0.32440000 0.31080107 0.24107677
0.32360000 0.31028674 0.24067799
0.32280000 0.30929901 0.23991217
0.32200000 0.30875501 0.23949038
0.32120000 0.30751375 0.23852799
0.32040000 0.30715044 0.23824630
0.31960000 0.30589622 0.23727386
0.31880000 0.30521848 0.23674838
0.31800000 0.30510940 0.23666381
0.31720000 0.30338253 0.23532490
0.31640000 0.30298906 0.23501983
0.31560000 0.30222225 0.23442530
0.31480000 0.30176387 0.23406990
0.31400000 0.30043682 0.23304099
0.31320000 0.29959570 0.23238883
0.31240000 0.29956673 0.23236638
0.31160000 0.29833553 0.23141178
0.31080000 0.29727731 0.23059130
0.31000000 0.29674684 0.23018001
0.30920000 0.29598512 0.22958942
0.30840000 0.29475198 0.22863332
0.30760000 0.29428944 0.22827470
0.30680000 0.29350713 0.22766814
0.30600000 0.29275741 0.22708686
0.30520000 0.29191910 0.22643688
0.30440000 0.29097270 0.22570311
0.30360000 0.29036419 0.22523131
0.30280000 0.28929746 0.22440424
0.30200000 0.28851035 0.22379396
0.30120000 0.28789701 0.22331841
0.30040000 0.28706256 0.22267144
0.29960000 0.28626804 0.22205542
0.29880000 0.28556822 0.22151281
0.29800000 0.28430370 0.22053239
0.29720000 0.28381769 0.22015557
0.29640000 0.28301919 0.21953646
0.29560000 0.28254904 0.21917193
0.29480000 0.28154683 0.21839489
0.29400000 0.28070280 0.21774048
0.29320000 0.27999381 0.21719077
0.29240000 0.27920876 0.21658209
0.29160000 0.27810144 0.21572355
0.29080000 0.27724712 0.21506116
0.29000000 0.27683748 0.21474356
0.28920000 0.27598842 0.21408525
0.28840000 0.27477157 0.21314178
0.28760000 0.27413832 0.21265080
0.28680000 0.27342397 0.21209693
0.28600000 0.27243789 0.21133239
0.28520000 0.27188031 0.21090008
0.28440000 0.27107484 0.21027557
0.28360000 0.27030199 0.20967635
0.28280000 0.26928118 0.20888488
0.28200000 0.26839814 0.20820022
0.28120000 0.26819490 0.20804265
0.28040000 0.26711843 0.20720802
0.27960000 0.26616244 0.20646680
0.27880000 0.26530870 0.20580487
0.27800000 0.26496033 0.20553477
0.27720000 0.26418204 0.20493133
0.27640000 0.26290903 0.20394432
0.27560000 0.26221939 0.20340962
0.27480000 0.26170694 0.20301230
0.27400000 0.26053681 0.20210505
0.27320000 0.25991029 0.20161929
0.27240000 0.25910426 0.20099434
0.27160000 0.25814637 0.20025165
0.27080000 0.25713893 0.19947055
0.27000000 0.25662601 0.19907286
0.26920000 0.25589725 0.19850783
0.26840000 0.25544571 0.19815773
0.26760000 0.25410717 0.19711991
0.26680000 0.25338075 0.19655669
0.26600000 0.25296711 0.19623598
0.26520000 0.25208845 0.19555473
0.26440000 0.25107602 0.19476975
0.26360000 0.25024916 0.19412865
0.26280000 0.24954343 0.19358148
0.26200000 0.24881993 0.19302052
0.26120000 0.24786800 0.19228246
0.26040000 0.24716199 0.19173506
0.25960000 0.24641915 0.19115911
0.25880000 0.24575434 0.19064366
0.25800000 0.24464769 0.18978563
0.25720000 0.24366248 0.18902176
0.25640000 0.24311241 0.18859527
0.25560000 0.24254233 0.18815327
0.25480000 0.24142069 0.18728362
0.25400000 0.24061004 0.18665509
0.25320000 0.23994388 0.18613859
0.25240000 0.23923744 0.18559087
0.25160000 0.23848478 0.18500730
0.25080000 0.23747971 0.18422803
0.25000000 0.23692284 0.18379627
0.24920000 0.23600259 0.18308277
0.24840000 0.23496633 0.18227932
0.24760000 0.23443267 0.18186555
0.24680000 0.23380920 0.18138216
0.24600000 0.23265451 0.18048688
0.24520000 0.23203186 0.18000411
0.24440000 0.23126586 0.17941021
0.24360000 0.23031133 0.17867013
0.24280000 0.22936438 0.17793592
0.24200000 0.22893571 0.17760356
0.24120000 0.22835635 0.17715436
0.24040000 0.22688321 0.17601218
0.23960000 0.22634302 0.17559335
0.23880000 0.22598115 0.17531278
0.23800000 0.22471524 0.17433127
0.23720000 0.22381609 0.17363413
0.23640000 0.22352455 0.17340809
0.23560000 0.22226159 0.17242887
0.23480000 0.22132034 0.17169908
0.23400000 0.22070221 0.17121983
0.23320000 0.22009095 0.17074589
0.23240000 0.21890232 0.16982430
0.23160000 0.21860522 0.16959395
0.23080000 0.21771188 0.16890131
0.23000000 0.21659276 0.16803362
0.22920000 0.21616209 0.16769970
0.22840000 0.21536478 0.16708152
0.22760000 0.21422843 0.16620046
0.22680000 0.21347874 0.16561920
0.22600000 0.21328983 0.16547273
0.22520000 0.21198117 0.16445808
0.22440000 0.21141245 0.16401713
0.22360000 0.21070004 0.16346478
0.22280000 0.20945675 0.16250081
0.22200000 0.20858072 0.16182159
0.22120000 0.20821290 0.16153640
0.22040000 0.20711041 0.16068161
0.21960000 0.20633510 0.16008048
0.21880000 0.20578561 0.15965444
0.21800000 0.20490782 0.15897386
0.21720000 0.20401542 0.15828195
0.21640000 0.20324612 0.15768548
0.21560000 0.20243835 0.15705919
0.21480000 0.20191999 0.15665728
0.21400000 0.20090061 0.15586692
0.21320000 0.20002197 0.15518568
0.21240000 0.19936168 0.15467373
0.21160000 0.19885332 0.15427958
0.21080000 0.19745728 0.15319717
0.21000000 0.19678265 0.15267411
0.20920000 0.19612930 0.15216755
0.20840000 0.19532017 0.15154020
0.20760000 0.19431770 0.15076295
0.20680000 0.19369905 0.15028328
0.20600000 0.19313215 0.14984374
0.20520000 0.19210930 0.14905069
0.20440000 0.19116095 0.14831540
0.20360000 0.19060407 0.14788364
0.20280000 0.18963265 0.14713046
0.20200000 0.18889021 0.14655481
0.20120000 0.18832265 0.14611477
0.20040000 0.18737363 0.14537896
0.19960000 0.18643070 0.14464787
0.19880000 0.18570223 0.14408305
0.19800000 0.18511320 0.14362636
0.19720000 0.18415808 0.14288582
0.19640000 0.18331573 0.14223272
0.19560000 0.18240674 0.14152794
0.19480000 0.18174165 0.14101228
0.19400000 0.18106631 0.14048866
0.19320000 0.18016688 0.13979130
0.19240000 0.17902504 0.13890599
0.19160000 0.17932381 0.13913764
0.19080000 0.17794719 0.13807029
0.19000000 0.17678118 0.13716624
0.18920000 0.17973555 0.13945687
0.18840000 0.17826140 0.13831391
0.18760000 0.17449917 0.13539691
0.18680000 0.17364265 0.13473283
0.18600000 0.17308684 0.13430188
0.18520000 0.17208427 0.13352456
0.18440000 0.17149500 0.13306767
0.18360000 0.17060222 0.13237547
0.18280000 0.16954857 0.13155853
0.18200000 0.16908703 0.13120068
0.18120000 0.16838423 0.13065578
0.18040000 0.16735633 0.12985881
0.17960000 0.16645728 0.12916174
0.17880000 0.16585656 0.12869598
0.17800000 0.16512444 0.12812835
0.17720000 0.16416594 0.12738518
0.17640000 0.16334394 0.12674786
0.17560000 0.16264721 0.12620766
0.17480000 0.16538833 0.12833295
0.17400000 0.16441990 0.12758209
0.17320000 0.16027588 0.12436908
0.17240000 0.15946328 0.12373904
0.17160000 0.15844950 0.12295302
0.17080000 0.15774804 0.12240915
0.17000000 0.16045873 0.12451085
0.16920000 0.15980968 0.12400761
0.16840000 0.15514889 0.12039393
0.16760000 0.15451618 0.11990337
0.16680000 0.15381905 0.11936286
0.16600000 0.15285612 0.11861627
0.16520000 0.15221187 0.11811675
0.16440000 0.15136869 0.11746301
0.16360000 0.15062985 0.11689016
0.16280000 0.14996843 0.11637733
0.16200000 0.14888972 0.11554097
0.16120000 0.14814081 0.11496031
0.16040000 0.14752756 0.11448484
0.15960000 0.14694109 0.11403012
0.15880000 0.14570972 0.11307540
0.15800000 0.14498354 0.11251237
0.15720000 0.14401703 0.11176300
0.15640000 0.14342372 0.11130298
0.15560000 0.14273410 0.11076829
0.15480000 0.14170096 0.10996726
0.15400000 0.14076583 0.10924222
0.15320000 0.14036919 0.10893469
0.15240000 0.13935996 0.10815220
0.15160000 0.13872696 0.10766141
0.15080000 0.13789148 0.10701363
0.15000000 0.13694682 0.10628120
0.14920000 0.13619530 0.10569852
0.14840000 0.13539326 0.10507667
0.14760000 0.13450517 0.10438810
0.14680000 0.13374916 0.10380194
0.14600000 0.13302575 0.10324105
0.14520000 0.13199767 0.10244395
0.14440000 0.13137092 0.10195800
0.14360000 0.13060925 0.10136745
0.14280000 0.12989264 0.10081184
0.14200000 0.13246114 0.10280329
0.14120000 0.13172938 0.10223593
0.14040000 0.12749574 0.09895344
0.13960000 0.12658429 0.09824675
0.13880000 0.12567615 0.09754264
0.13800000 0.12516825 0.09714885
0.13720000 0.12401347 0.09625350
0.13640000 0.12336240 0.09574870
0.13560000 0.12260327 0.09516013
0.13480000 0.12192490 0.09463416
0.13400000 0.12077809 0.09374499
0.13320000 0.12016351 0.09326849
0.13240000 0.11953697 0.09278270
0.13160000 0.11854467 0.09201334
0.13080000 0.11727276 0.09102718
0.13000000 0.11681105 0.09066921
0.12920000 0.11611684 0.09013096
0.12840000 0.11556680 0.08970449
0.12760000 0.11463009 0.08897822
0.12680000 0.11400681 0.08849497
0.12600000 0.11295871 0.08768235
0.12520000 0.11194639 0.08689745
0.12440000 0.11136680 0.08644808
0.12360000 0.11050228 0.08577778
0.12280000 0.10978959 0.08522521
0.12200000 0.10949787 0.08499902
0.12120000 0.10824885 0.08403062
0.12040000 0.10732910 0.08331750
0.11960000 0.10716593 0.08319099
0.11880000 0.10565258 0.08201763
0.11800000 0.10524854 0.08170437
0.11720000 0.10445577 0.08108970
0.11640000 0.10360713 0.08043172
0.11560000 0.10250091 0.07957403
0.11480000 0.10180338 0.07903321
0.11400000 0.10198152 0.07917132
0.11320000 0.10056006 0.07806921
0.11240000 0.09945018 0.07720869
0.11160000 0.09876635 0.07667848
0.11080000 0.09793859 0.07603670
0.11000000 0.09714693 0.07542289
0.10920000 0.09938521 0.07715831
0.10840000 0.09875443 0.07666924
0.10760000 0.09455671 0.07341460
0.10680000 0.09365922 0.07271874
0.10600000 0.09308832 0.07227610
0.10520000 0.09550154 0.07414716
0.10440000 0.09552599 0.07416612
0.10360000 0.09411019 0.07306840
0.10280000 0.09303803 0.07223711
0.10200000 0.08910864 0.06919051
0.10120000 0.08817042 0.06846307
0.10040000 0.08737250 0.06784441
0.09960000 0.08642000 0.06710591
0.09880000 0.08559962 0.06646984
0.09800000 0.08473275 0.06579772
0.09720000 0.08782915 0.06819847
0.09640000 0.08664978 0.06728407
0.09560000 0.08250806 0.06407284
0.09480000 0.08192858 0.06362355
0.09400000 0.08094365 0.06285989
0.09320000 0.08027686 0.06234291
0.09240000 0.07947844 0.06172386
0.09160000 0.07859922 0.06104217
0.09080000 0.07951346 0.06175101
0.09000000 0.07689583 0.05972147
0.08920000 0.07620723 0.05918758
0.08840000 0.07550924 0.05864640
0.08760000 0.07480838 0.05810300
0.08680000 0.07391966 0.05741394
0.08600000 0.07297718 0.05668320
0.08520000 0.07216323 0.05605211
0.08440000 0.07146579 0.05551136
0.08360000 0.07072407 0.05493628
0.08280000 0.07427779 0.05769161
0.08200000 0.07279918 0.05654519
0.08120000 0.06838258 0.05312083
0.08040000 0.06777154 0.05264708
0.07960000 0.06643787 0.05161303
0.07880000 0.06585754 0.05116308
0.07800000 0.06492707 0.05044165
0.07720000 0.06535681 0.05077485
0.07640000 0.06348842 0.04932621
0.07560000 0.06274558 0.04875026
0.07480000 0.06216454 0.04829977
0.07400000 0.06080040 0.04724210
0.07320000 0.06048076 0.04699426
0.07240000 0.05926395 0.04605083
0.07160000 0.05852593 0.04547861
0.07080000 0.05768501 0.04482662
0.07000000 0.05693125 0.04424220
0.06920000 0.05913259 0.04594898
0.06840000 0.05895693 0.04581278
0.06760000 0.05828326 0.04529046
0.06680000 0.05816826 0.04520130
0.06600000 0.05734023 0.04455930
0.06520000 0.05248816 0.04079731
0.06440000 0.05146730 0.04000580
0.06360000 0.05496742 0.04271957
0.06280000 0.05408811 0.04203781
0.06200000 0.04899787 0.03809116
0.06120000 0.04824407 0.03750671
0.06040000 0.04997570 0.03884931
0.05960000 0.05058554 0.03932214
0.05880000 0.04617328 0.03590115
0.05800000 0.04527941 0.03520810
0.05720000 0.04437709 0.03450850
0.05640000 0.04347084 0.03380585
0.05560000 0.04545701 0.03534580
0.05480000 0.04512070 0.03508505
0.05400000 0.04206260 0.03271399
0.05320000 0.04135263 0.03216353
0.05240000 0.04237579 0.03295682
0.05160000 0.04179233 0.03250444
0.05080000 0.03820797 0.02972536
0.05000000 0.03733836 0.02905112
0.04920000 0.04063396 0.03160631
0.04840000 0.03989963 0.03103697
0.04760000 0.03476546 0.02705625
0.04680000 0.03386969 0.02636173
0.04600000 0.03286244 0.02558077
0.04520000 0.03240146 0.02522336
0.04440000 0.03169312 0.02467416
0.04360000 0.03071979 0.02391949
0.04280000 0.02988695 0.02327376
0.04200000 0.02923160 0.02276565
0.04120000 0.02808943 0.02188008
0.04040000 0.03029774 0.02359226
0.03960000 0.02964809 0.02308857
0.03880000 0.02915739 0.02270811
0.03800000 0.02814081 0.02191992
0.03720000 0.02737570 0.02132670
0.03640000 0.02402612 0.01872965
0.03560000 0.02223636 0.01734198
0.03480000 0.02235260 0.01743210
0.03400000 0.02099231 0.01637743
0.03320000 0.02357320 0.01837848
0.03240000 0.02260725 0.01762955
0.03160000 0.02180130 0.01700467
0.03080000 0.02159405 0.01684398
0.03000000 0.02064376 0.01610718
0.02920000 0.01689662 0.01320189
0.02840000 0.01607359 0.01256376
0.02760000 0.01488584 0.01164285
0.02680000 0.01753622 0.01369779
0.02600000 0.01642059 0.01283280
0.02520000 0.01269497 0.00994420
0.02440000 0.01270668 0.00995327
0.02360000 0.01152146 0.00903433
0.02280000 0.01271329 0.00995840
0.02200000 0.01180252 0.00925225
0.02120000 0.00840595 0.00661876
0.02040000 0.00786771 0.00620144
0.01960000 0.00657139 0.00519636
0.01880000 0.00903577 0.00710708
0.01800000 0.00835068 0.00657591
0.01720000 0.00404507 0.00323761
0.01640000 0.00340258 0.00273946
0.01560000 0.00305738 0.00247182
0.01480000 0.00261177 0.00212632
0.01400000 0.00215465 0.00177190
0.01320000 0.00053357 0.00051502
0.01240000 -0.00043428 -0.00023540
0.01160000 -0.00007744 0.00004128
0.01080000 -0.00214705 -0.00156336
0.01000000 -0.00282728 -0.00209077
0.00920000 -0.00358850 -0.00268098
0.00840000 -0.00227048 -0.00165907
0.00760000 -0.00407510 -0.00305826
0.00680000 -0.00623739 -0.00473476
0.00600000 -0.00556370 -0.00421242
0.00520000 -0.00588034 -0.00445793
0.00440000 -0.00699757 -0.00532416
0.00360000 -0.00821799 -0.00627039
0.00280000 -0.00702805 -0.00534778
0.00200000 -0.00786069 -0.00599336
0.00120000 -0.00871033 -0.00665212
0.00040000 -0.00819007 -0.00624874
-0.00000000 -0.00872226 -0.00666137