File: plots/rawdata/FigureS6d-2.txt
# strain(%), strain_el(%), stress(GPa)
0.00000000 -0.00013068 0.00000000
0.00480000 0.00474387 0.00377942
0.00960000 0.00982439 0.00771853
0.01440000 0.01142179 0.00895705
0.01920000 0.01605531 0.01254959
0.02400000 0.02369063 0.01846953
0.02880000 0.02703888 0.02106555
0.03360000 0.03021449 0.02352772
0.03840000 0.03864671 0.03006553
0.04320000 0.04313881 0.03354841
0.04800000 0.04863431 0.03780928
0.05280000 0.05258921 0.04087566
0.05760000 0.05394085 0.04192364
0.06240000 0.05922317 0.04601921
0.06720000 0.06397230 0.04970138
0.07200000 0.06871075 0.05337528
0.07680000 0.07661338 0.05950248
0.08160000 0.07843118 0.06091189
0.08640000 0.08416207 0.06535525
0.09120000 0.09193086 0.07137868
0.09600000 0.09240556 0.07174673
0.10080000 0.10063784 0.07812952
0.10560000 0.10213384 0.07928942
0.11040000 0.11026845 0.08559648
0.11520000 0.11158383 0.08661635
0.12000000 0.11640880 0.09035732
0.12480000 0.12132311 0.09416757
0.12960000 0.12603221 0.09781871
0.13440000 0.13113987 0.10177886
0.13920000 0.13918827 0.10801908
0.14400000 0.14036451 0.10893106
0.14880000 0.14528702 0.11274766
0.15360000 0.15013004 0.11650264
0.15840000 0.15470349 0.12004860
0.16320000 0.15937083 0.12366736
0.16800000 0.15548306 0.12065302
0.17280000 0.16018507 0.12429867
0.17760000 0.16495884 0.12799995
0.18240000 0.17846267 0.13846996
0.18720000 0.18337367 0.14227764
0.19200000 0.18799918 0.14586396
0.19680000 0.19657093 0.15250996
0.20160000 0.19787962 0.15352463
0.20640000 0.20214292 0.15683013
0.21120000 0.20720431 0.16075441
0.21600000 0.21162163 0.16417932
0.22080000 0.21631925 0.16782156
0.22560000 0.22145588 0.17180417
0.23040000 0.22594196 0.17528240
0.23520000 0.23068087 0.17895664
0.24000000 0.23562806 0.18279238
0.24480000 0.24035934 0.18646072
0.24960000 0.24508888 0.19012770
0.25440000 0.24998537 0.19392413
0.25920000 0.25424765 0.19722883
0.26400000 0.25929982 0.20114596
0.26880000 0.26407312 0.20484688
0.27360000 0.26888582 0.20857834
0.27840000 0.27375955 0.21235713
0.28320000 0.27832769 0.21589897
0.28800000 0.28341382 0.21984243
0.29280000 0.28806577 0.22344926
0.29760000 0.29608613 0.22966774
0.30240000 0.29731970 0.23062417
0.30720000 0.30212978 0.23435360
0.31200000 0.30705661 0.23817355
0.31680000 0.31153426 0.24164524
0.32160000 0.32008932 0.24827829
0.32640000 0.32102766 0.24900582
0.33120000 0.32617085 0.25299353
0.33600000 0.33024309 0.25615088
0.34080000 0.32782056 0.25427260
0.34560000 0.33251955 0.25791590
0.35040000 0.33734894 0.26166031
0.35520000 0.34236605 0.26555026
0.36000000 0.34682266 0.26900562
0.36480000 0.34792805 0.26986268
0.36960000 0.35631072 0.27636207
0.37440000 0.35889191 0.27836336
0.37920000 0.36625510 0.28407231
0.38400000 0.37068404 0.28750623
0.38880000 0.37573321 0.29142104
0.39360000 0.38034608 0.29499756
0.39840000 0.38347383 0.29742262
0.40320000 0.38601688 0.29939435
0.40800000 0.39481029 0.30621219
0.41280000 0.39354594 0.30523190
0.41760000 0.40051559 0.31063572
0.42240000 0.40914967 0.31733004
0.42720000 0.40814757 0.31655308
0.43200000 0.41663819 0.32313617
0.43680000 0.41729567 0.32364593
0.44160000 0.42754399 0.33159183
0.44640000 0.42815477 0.33206539
0.45120000 0.43279493 0.33566307
0.45600000 0.44273850 0.34337269
0.46080000 0.44177940 0.34262906
0.46560000 0.44459032 0.34480848
0.47040000 0.45700156 0.35443137
0.47520000 0.45372313 0.35188948
0.48000000 0.46570672 0.36118080
0.48480000 0.47117332 0.36541925
0.48960000 0.46787579 0.36286255
0.49440000 0.46852834 0.36336850
0.49920000 0.48305263 0.37462971
0.50400000 0.48968908 0.37977520
0.50880000 0.48826402 0.37867029
0.51360000 0.49505979 0.38393930
0.51840000 0.49206704 0.38161892
0.52320000 0.50097678 0.38852696
0.52800000 0.50918022 0.39488739
0.53280000 0.51154719 0.39672259
0.53760000 0.51604112 0.40020690
0.54240000 0.51990646 0.40320384
0.54720000 0.52636206 0.40820910
0.55200000 0.52953946 0.41067265
0.55680000 0.53382407 0.41399467
0.56160000 0.53672897 0.41624695
0.56640000 0.53825026 0.41742646
0.57120000 0.54179505 0.42017486
0.57600000 0.54184983 0.42021734
0.58080000 0.54490454 0.42258576
0.58560000 0.54931814 0.42600779
0.59040000 0.55411216 0.42972477
0.59520000 0.55888771 0.43342743
0.60000000 0.56406842 0.43744422
0.60480000 0.57052449 0.44244985
0.60960000 0.57287370 0.44427128
0.61440000 0.57779770 0.44808904
0.61920000 0.58227464 0.45156017
0.62400000 0.58721864 0.45539344
0.62880000 0.59343315 0.46021177
0.63360000 0.59835842 0.46403051
0.63840000 0.60132530 0.46633084
0.64320000 0.60594895 0.46991573
0.64800000 0.61229315 0.47483462
0.65280000 0.61548855 0.47731213
0.65760000 0.62043013 0.48114352
0.66240000 0.62479175 0.48452524
0.66720000 0.62970234 0.48833261
0.67200000 0.63224865 0.49030685
0.67680000 0.63896703 0.49551585
0.68160000 0.64357912 0.49909178
0.68640000 0.64847167 0.50288515
0.69120000 0.65300876 0.50640292
0.69600000 0.65771776 0.51005399
0.70080000 0.66261773 0.51385311
0.70560000 0.66729835 0.51748217
0.71040000 0.67230551 0.52136440
0.71520000 0.67461914 0.52315824
0.72000000 0.68153191 0.52851797
0.72480000 0.68632351 0.53223307
0.72960000 0.69077802 0.53568682
0.73440000 0.69572002 0.53951853
0.73920000 0.70061064 0.54331041
0.74400000 0.70459504 0.54639966
0.74880000 0.70983655 0.55046359
0.75360000 0.71534746 0.55473640
0.75840000 0.71908296 0.55763267
0.76320000 0.72368436 0.56120030
0.76800000 0.72835699 0.56482316
0.77280000 0.72993142 0.56604388
0.77760000 0.73784405 0.57217883
0.78240000 0.74228611 0.57562292
0.78720000 0.74678107 0.57910803
0.79200000 0.75146088 0.58273646
0.79680000 0.75622248 0.58642830
0.80160000 0.76086418 0.59002718
0.80640000 0.76567904 0.59376032
0.81120000 0.77027599 0.59732451
0.81600000 0.77497331 0.60096650
0.82080000 0.77755676 0.60296955
0.82560000 0.78454783 0.60838998
0.83040000 0.78898439 0.61182981
0.83520000 0.79387711 0.61562331
0.84000000 0.79646280 0.61762809
0.84480000 0.80081168 0.62099994
0.84960000 0.80556910 0.62468854
0.85440000 0.81252720 0.63008342
0.85920000 0.81713758 0.63365801
0.86400000 0.82187249 0.63732916
0.86880000 0.82436811 0.63926410
0.87360000 0.82866152 0.64259294
0.87840000 0.83595922 0.64825112
0.88320000 0.84068127 0.65191230
0.88800000 0.84555866 0.65569392
0.89280000 0.85000170 0.65913877
0.89760000 0.85479713 0.66285683
0.90240000 0.85703304 0.66459042
0.90720000 0.86196204 0.66841205
0.91200000 0.86900050 0.67386923
0.91680000 0.87092808 0.67536375
0.92160000 0.87851360 0.68124509
0.92640000 0.88059940 0.68286228
0.93120000 0.88770959 0.68837507
0.93600000 0.89213339 0.69180501
0.94080000 0.89450266 0.69364199
0.94560000 0.89914840 0.69724400
0.95040000 0.90370617 0.70077781
0.95520000 0.90868797 0.70464038
0.96000000 0.91328527 0.70820484
0.96480000 0.91795328 0.71182412
0.96960000 0.92436376 0.71679439
0.97440000 0.92874134 0.72018849
0.97920000 0.93305046 0.72352951
0.98400000 0.93811638 0.72745730
0.98880000 0.94257721 0.73091595
0.99360000 0.95020090 0.73682687
0.99840000 0.95209042 0.73829189
1.00320000 0.95941017 0.74396716
1.00800000 0.96108288 0.74526407
1.01280000 0.96642103 0.74940293
1.01760000 0.97364166 0.75500136
1.02240000 0.97548943 0.75643400
1.02720000 0.98265191 0.76198733
1.03200000 0.98442560 0.76336254
1.03680000 0.98926848 0.76711740
1.04160000 0.99424572 0.77097644
1.04640000 0.99856175 0.77432281
1.05120000 1.00646698 0.78045203
1.05600000 1.00785709 0.78152983
1.06080000 1.01264829 0.78524462
1.06560000 1.01729271 0.78884561
1.07040000 1.02181738 0.79235376
1.07520000 1.02971087 0.79847387
1.08000000 1.03427804 0.80201496
1.08480000 1.03569599 0.80311435
1.08960000 1.04027518 0.80666476
1.09440000 1.04487338 0.81022992
1.09920000 1.04983320 0.81407544
1.10400000 1.05456309 0.81774270
1.10880000 1.05934557 0.82145074
1.11360000 1.06285192 0.82416934
1.11840000 1.06768383 0.82791569
1.12320000 1.07223015 0.83144062
1.12800000 1.07679572 0.83498048
1.13280000 1.08203372 0.83904169
1.13760000 1.08707843 0.84295304
1.14240000 1.09176303 0.84658518
1.14720000 1.09588428 0.84978053
1.15200000 1.10035983 0.85325059
1.15680000 1.10468137 0.85660124
1.16160000 1.10969534 0.86048876
1.16640000 1.11434040 0.86409024
1.17120000 1.11895364 0.86766706
1.17600000 1.11991308 0.86841094
1.18080000 1.12356636 0.87124346
1.18560000 1.12934082 0.87572061
1.19040000 1.13843685 0.88277310
1.19520000 1.13859302 0.88289418
1.20000000 1.14413885 0.88719407
1.20480000 1.15253031 0.89370028
1.20960000 1.15716632 0.89729475
1.21440000 1.16204591 0.90107807
1.21920000 1.16662229 0.90462630
1.22400000 1.17169174 0.90855683
1.22880000 1.17595803 0.91186465
1.23360000 1.18080546 0.91562303
1.23840000 1.18515304 0.91899387
1.24320000 1.19017650 0.92288875
1.24800000 1.19451472 0.92625233
1.25280000 1.19952543 0.93013731
1.25760000 1.20396261 0.93357762
1.26240000 1.20830484 0.93694431
1.26720000 1.21311569 0.94067434
1.27200000 1.21737242 0.94397474
1.27680000 1.21795670 0.94442775
1.28160000 1.22666184 0.95117717
1.28640000 1.22755137 0.95186685
1.29120000 1.23192666 0.95525918
1.29600000 1.23771740 0.95974895
1.30080000 1.24200792 0.96307554
1.30560000 1.24684261 0.96682406
1.31040000 1.25577727 0.97375142
1.31520000 1.25407076 0.97242830
1.32000000 1.25998127 0.97701094
1.32480000 1.26478003 0.98073159
1.32960000 1.26968783 0.98453679
1.33440000 1.27407529 0.98793855
1.33920000 1.27852916 0.99139180
1.34400000 1.28637284 0.99747329
1.34880000 1.29333959 1.00287487
1.35360000 1.29800705 1.00649372
1.35840000 1.30267775 1.01011509
1.36320000 1.30744590 1.01381201
1.36800000 1.31243110 1.01767721
1.37280000 1.31254031 1.01776189
1.37760000 1.31276072 1.01793278
1.38240000 1.32052641 1.02395381
1.38720000 1.32589002 1.02811241
1.39200000 1.33015393 1.03141837
1.39680000 1.33498905 1.03516722
1.40160000 1.33962970 1.03876528
1.40640000 1.34287801 1.04128382
1.41120000 1.34904633 1.04606634
1.41600000 1.35373301 1.04970010
1.42080000 1.35682749 1.05209936
1.42560000 1.36159439 1.05579531
1.43040000 1.36757093 1.06042915
1.43520000 1.37219348 1.06401317
1.44000000 1.37673799 1.06753670
1.44480000 1.37979093 1.06990375
1.44960000 1.38614211 1.07482806
1.45440000 1.39113379 1.07869829
1.45920000 1.39523199 1.08187577
1.46400000 1.39846001 1.08437858
1.46880000 1.40505802 1.08949426
1.47360000 1.40856632 1.09221437
1.47840000 1.41434004 1.09669095
1.48320000 1.41496313 1.09717406
1.48800000 1.42368791 1.10393869
1.49280000 1.42420554 1.10434003
1.49760000 1.42920382 1.10821538
1.50240000 1.43742202 1.11458725
1.50720000 1.44194448 1.11809368
1.51200000 1.44248969 1.11851640
1.51680000 1.44927943 1.12378073
1.52160000 1.45182199 1.12575208
1.52640000 1.46066157 1.13260572
1.53120000 1.46215802 1.13376598
1.53600000 1.46569676 1.13650969
1.54080000 1.47050026 1.14023403
1.54560000 1.47906274 1.14687282
1.55040000 1.48038144 1.14789527
1.55520000 1.48575513 1.15206169
1.56000000 1.48885326 1.15446377
1.56480000 1.49345765 1.15803373
1.56960000 1.49821053 1.16171881
1.57440000 1.50232874 1.16491181
1.57920000 1.50703168 1.16855817
1.58400000 1.51278523 1.17301911
1.58880000 1.51805277 1.17710322
1.59360000 1.52206476 1.18021387
1.59840000 1.52705226 1.18408086
1.60320000 1.53103249 1.18716688
1.60800000 1.53566354 1.19075750
1.61280000 1.54048834 1.19449834
1.61760000 1.54546176 1.19835442
1.62240000 1.54972022 1.20165616
1.62720000 1.55520770 1.20591080
1.63200000 1.55864224 1.20857372
1.63680000 1.56254263 1.21159785
1.64160000 1.56919959 1.21675923
1.64640000 1.57165586 1.21866366
1.65120000 1.58087344 1.22581039
1.65600000 1.58081500 1.22576508
1.66080000 1.58594027 1.22973889
1.66560000 1.59068064 1.23341427
1.67040000 1.59460273 1.23645521
1.67520000 1.60046863 1.24100326
1.68000000 1.60449177 1.24412255
1.68480000 1.61024562 1.24858371
1.68960000 1.61080430 1.24901688
1.69440000 1.61954121 1.25579093
1.69920000 1.62404270 1.25928110
1.70400000 1.62873355 1.26291808
1.70880000 1.62357295 1.25891689
1.71360000 1.61588226 1.25295402
1.71840000 1.62044836 1.25649428
1.72320000 1.62538224 1.26031970
1.72800000 1.63290937 1.26615575
1.73280000 1.63710608 1.26940962
1.73760000 1.64176501 1.27302185
1.74240000 1.64636998 1.27659226
1.74720000 1.64748949 1.27746025
1.75200000 1.65190492 1.28088370
1.75680000 1.65136623 1.28046603
1.76160000 1.65851275 1.28600699
1.76640000 1.66295626 1.28945221
1.77120000 1.66593325 1.29176038
1.77600000 1.67025502 1.29511120
1.78080000 1.68097815 1.30342524
1.78560000 1.68500164 1.30654480
1.79040000 1.68617234 1.30745249
1.79520000 1.69468285 1.31405099
1.80000000 1.69520851 1.31445856
1.80480000 1.70393219 1.32122234
1.80960000 1.70820939 1.32453862
1.81440000 1.71292269 1.32819301
1.81920000 1.71743253 1.33168966
1.82400000 1.71836034 1.33240902
1.82880000 1.72288268 1.33591536
1.83360000 1.73045702 1.34178802
1.83840000 1.73150561 1.34260103
1.84320000 1.73683841 1.34673574
1.84800000 1.74138276 1.35025914
1.85280000 1.74967037 1.35668483
1.85760000 1.74779940 1.35523420
1.86240000 1.75428644 1.36026384
1.86720000 1.75711816 1.36245938
1.87200000 1.76171366 1.36602244
1.87680000 1.76636388 1.36962792
1.88160000 1.76913052 1.37177300
1.88640000 1.77778447 1.37848272
1.89120000 1.78190165 1.38167493
1.89600000 1.78286523 1.38242202
1.90080000 1.79113007 1.38883005
1.90560000 1.79427088 1.39126524
1.91040000 1.79910957 1.39501685
1.91520000 1.80466087 1.39932098
1.92000000 1.80591541 1.40029367
1.92480000 1.81189925 1.40493316
1.92960000 1.81714303 1.40899886
1.93440000 1.82174793 1.41256920
1.93920000 1.82722838 1.41681840
1.94400000 1.82899058 1.41818470
1.94880000 1.83551662 1.42324457
1.95360000 1.84159750 1.42795930
1.95840000 1.84276126 1.42886161
1.96320000 1.85298058 1.43678502
1.96800000 1.85400609 1.43758014
1.97280000 1.85900328 1.44145464
1.97760000 1.86354567 1.44497652
1.98240000 1.86161071 1.44347628
1.98720000 1.87311566 1.45239648
1.99200000 1.87495358 1.45382149
1.99680000 1.87967908 1.45748535
2.00160000 1.88452971 1.46124622
2.00640000 1.88702842 1.46318356
2.01120000 1.89216482 1.46716600
2.01600000 1.89558220 1.46981562
2.02080000 1.90044407 1.47358521
2.02560000 1.90570286 1.47766254
2.03040000 1.90973653 1.48078999
2.03520000 1.91391636 1.48403076
2.04000000 1.91829656 1.48742689
2.04480000 1.92310250 1.49115311
2.04960000 1.92795081 1.49491219
2.05440000 1.93195678 1.49801816
2.05920000 1.93678647 1.50176280
2.06400000 1.94173955 1.50560310
2.06880000 1.94642947 1.50923937
2.07360000 1.94833474 1.51071660
2.07840000 1.95188438 1.51346876
2.08320000 1.95799272 1.51820478
2.08800000 1.96192120 1.52125068
2.09280000 1.96525355 1.52383437
2.09760000 1.96955441 1.52716898
2.10240000 1.97452421 1.53102225
2.10720000 1.97901834 1.53450671
2.11200000 1.98361923 1.53807396
2.11680000 1.98916894 1.54237685
2.12160000 1.99207187 1.54462759
2.12640000 1.99658488 1.54812669
2.13120000 2.00247608 1.55269436
2.13600000 2.00738430 1.55649988
2.14080000 2.01012342 1.55862362
2.14560000 2.01493098 1.56235110
2.15040000 2.01909880 1.56558256
2.15520000 2.02346165 1.56896524
2.16000000 2.02858343 1.57293634
2.16480000 2.03238948 1.57588731
2.16960000 2.03625450 1.57888400
2.17440000 2.04189831 1.58325986
2.17920000 2.04393752 1.58484093
2.18400000 2.04997825 1.58952453
2.18880000 2.05443573 1.59298058
2.19360000 2.05892693 1.59646277
2.19840000 2.06336009 1.59989996
2.20320000 2.06774592 1.60330046
2.20800000 2.06908891 1.60434172
2.21280000 2.07634315 1.60996620
2.21760000 2.08073618 1.61337228
2.22240000 2.08537209 1.61696667
2.22720000 2.08650561 1.61784553
2.23200000 2.09161626 1.62180801
2.23680000 2.09800506 1.62676148
2.24160000 2.10003601 1.62833615
2.24640000 2.10436346 1.63169138
2.25120000 2.11199416 1.63760774
2.25600000 2.11295887 1.63835571
2.26080000 2.11736253 1.64177003
2.26560000 2.12201543 1.64537759
2.27040000 2.12773639 1.64981326
2.27520000 2.13328639 1.65411638
2.28000000 2.13460617 1.65513966
2.28480000 2.13850683 1.65816398
2.28960000 2.14328068 1.66186532
2.29440000 2.14724248 1.66493705
2.29920000 2.15201842 1.66864001
2.30400000 2.15424099 1.67036325
2.30880000 2.16055719 1.67526043
2.31360000 2.16285710 1.67704364
2.31840000 2.16728339 1.68047550
2.32320000 2.17374654 1.68548661
2.32800000 2.17828451 1.68900507
2.33280000 2.18238240 1.69218232
2.33760000 2.18452137 1.69384074
2.34240000 2.18915793 1.69743563
2.34720000 2.19583243 1.70261062
2.35200000 2.20073830 1.70641432
2.35680000 2.20458560 1.70939727
2.36160000 2.20660900 1.71096609
2.36640000 2.21050795 1.71398909
2.37120000 2.21544161 1.71781433
2.37600000 2.22267061 1.72341924
2.38080000 2.22629139 1.72622657
2.38560000 2.23096772 1.72985230
2.39040000 2.23328557 1.73164941
2.39520000 2.23764440 1.73502897
2.40000000 2.24156340 1.73806752
2.40480000 2.24623307 1.74168808
2.40960000 2.25074581 1.74518697
2.41440000 2.25505601 1.74852883
2.41920000 2.26139061 1.75344027
2.42400000 2.26384447 1.75534284
2.42880000 2.26811426 1.75865337
2.43360000 2.27267281 1.76218778
2.43840000 2.27675281 1.76535115
2.44320000 2.28166901 1.76916286
2.44800000 2.28507782 1.77180584
2.45280000 2.29002419 1.77564094
2.45760000 2.29437027 1.77901061
2.46240000 2.29887601 1.78250408
2.46720000 2.30233646 1.78518710
2.47200000 2.30661397 1.78850361
2.47680000 2.31186455 1.79257457
2.48160000 2.31669233 1.79631773
2.48640000 2.32084867 1.79954029
2.49120000 2.32395516 1.80194886
2.49600000 2.32958414 1.80631321
2.50080000 2.32435870 1.80226175
2.50560000 2.33808115 1.81290126
2.51040000 2.34222294 1.81611254
2.51520000 2.34639695 1.81934881
2.52000000 2.35014414 1.82225414
2.52480000 2.35607658 1.82685378
2.52960000 2.35981591 1.82975301
2.53440000 2.36258914 1.83190320
2.53920000 2.36681494 1.83517962
2.54400000 2.37273542 1.83976998
2.54880000 2.37610964 1.84238614
2.55360000 2.38176378 1.84677000
2.55840000 2.38605035 1.85009354
2.56320000 2.37990880 1.84533177
2.56800000 2.39422158 1.85642899
2.57280000 2.37923488 1.84480925
2.57760000 2.39421058 1.85642046
2.58240000 2.39790872 1.85928777
2.58720000 2.40387729 1.86391541
2.59200000 2.40766108 1.86684912
2.59680000 2.41148122 1.86981102
2.60160000 2.41670213 1.87385898
2.60640000 2.41980464 1.87626447
2.61120000 2.42364807 1.87924443
2.61600000 2.42866371 1.88313324
2.62080000 2.43370382 1.88704102
2.62560000 2.43725003 1.88979052
2.63040000 2.44237858 1.89376687
2.63520000 2.44371231 1.89480096
2.64000000 2.45009486 1.89974960
2.64480000 2.45496744 1.90352748
2.64960000 2.45928852 1.90687777
2.65440000 2.46307727 1.90981533
2.65920000 2.46337829 1.91004872
2.66400000 2.46181009 1.90883284
2.66880000 2.46513554 1.91141118
2.67360000 2.47011149 1.91526922
2.67840000 2.46489703 1.91122626
2.68320000 2.47844533 1.92173075
2.68800000 2.48288542 1.92517331
2.69280000 2.48572446 1.92737452
2.69760000 2.49152396 1.93187109
2.70240000 2.48418667 1.92618222
2.70720000 2.49929049 1.93789276
2.71200000 2.50092336 1.93915879
2.71680000 2.50585113 1.94297947
2.72160000 2.51140420 1.94728497
2.72640000 2.51427461 1.94951050
2.73120000 2.51872064 1.95295767
2.73600000 2.52308615 1.95634241
2.74080000 2.52729825 1.95960821
2.74560000 2.53176417 1.96307080
2.75040000 2.53201088 1.96326208
2.75520000 2.54129650 1.97046156
2.76000000 2.54428878 1.97278159
2.76480000 2.54910960 1.97651935
2.76960000 2.55350433 1.97992674
2.77440000 2.55751240 1.98303435
2.77920000 2.55264707 1.97926208
2.78400000 2.56701653 1.99040324
2.78880000 2.57060219 1.99318334
2.79360000 2.57577241 1.99719200
2.79840000 2.57863279 1.99940975
2.80320000 2.58254916 2.00244626
2.80800000 2.58739598 2.00620418
2.81280000 2.59052476 2.00863004
2.81760000 2.58693316 2.00584534
2.82240000 2.60096896 2.01672781
2.82720000 2.60322352 2.01847585
2.83200000 2.60810547 2.02226100
2.83680000 2.60477526 2.01967897
2.84160000 2.61675373 2.02896631
2.84640000 2.62110504 2.03234005
2.85120000 2.61785317 2.02981875
2.85600000 2.62975809 2.03904908
2.86080000 2.63444015 2.04267925
2.86560000 2.63079012 2.03984925
2.87040000 2.63560681 2.04358380
2.87520000 2.64692613 2.05236008
2.88000000 2.64123530 2.04794778
2.88480000 2.65580654 2.05924539
2.88960000 2.66066222 2.06301017
2.89440000 2.65742660 2.06050148
2.89920000 2.66171270 2.06382465
2.90400000 2.66627533 2.06736223
2.90880000 2.67733697 2.07593873
2.91360000 2.68214696 2.07966808
2.91840000 2.67936530 2.07751136
2.92320000 2.68222223 2.07972644
2.92800000 2.68493105 2.08182669
2.93280000 2.69732456 2.09143583
2.93760000 2.70435119 2.09688383
2.94240000 2.70454297 2.09703253
2.94720000 2.70841277 2.10003293
2.95200000 2.71027305 2.10147527
2.95680000 2.71458686 2.10481992
2.96160000 2.72579662 2.11351127
2.96640000 2.73029531 2.11699926
2.97120000 2.73472840 2.12043640
2.97600000 2.73905406 2.12379024
2.98080000 2.73674752 2.12200189
2.98560000 2.74776678 2.13054553
2.99040000 2.74604937 2.12921396
2.99520000 2.75324531 2.13479324
3.00000000 2.76130803 2.14104456
3.00480000 2.76077849 2.14063399
3.00960000 2.76610696 2.14476535
3.01440000 2.76725951 2.14565896
3.01920000 2.77500987 2.15166810
3.02400000 2.78285768 2.15775280
3.02880000 2.78763519 2.16145697
3.03360000 2.79168842 2.16459959
3.03840000 2.79604849 2.16798011
3.04320000 2.79703005 2.16874115
3.04800000 2.79494977 2.16712823
3.05280000 2.79905740 2.17031303
3.05760000 2.80385305 2.17403128
3.06240000 2.81805911 2.18504575
3.06720000 2.82251313 2.18849912
3.07200000 2.82675188 2.19178557
3.07680000 2.82757024 2.19242007
3.08160000 2.81259382 2.18080831
3.08640000 2.82028292 2.18676995
3.09120000 2.82462919 2.19013977
3.09600000 2.82494117 2.19038166
3.10080000 2.83336562 2.19691345
3.10560000 2.83789415 2.20042459
3.11040000 2.84239274 2.20391250
3.11520000 2.84638517 2.20700798
3.12000000 2.85092903 2.21053100
3.12480000 2.85529995 2.21391994
3.12960000 2.85340840 2.21245335
3.13440000 2.85383092 2.21278094
3.13920000 2.86240199 2.21942641
3.14400000 2.86824577 2.22395731
3.14880000 2.87567263 2.22971562
3.15360000 2.88142733 2.23417745
3.15840000 2.88578389 2.23755525
3.16320000 2.89018703 2.24096917
3.16800000 2.89030465 2.24106036
3.17280000 2.89463770 2.24441993
3.17760000 2.89328600 2.24337191
3.18240000 2.89734362 2.24651793
3.18720000 2.90185462 2.25001548
3.19200000 2.91043321 2.25666678
3.19680000 2.91032555 2.25658330
3.20160000 2.92027470 2.26429724
3.20640000 2.91656110 2.26141795
3.21120000 2.92361401 2.26688633
3.21600000 2.92509434 2.26803408
3.22080000 2.93717169 2.27739809
3.22560000 2.93649157 2.27687077
3.23040000 2.91783359 2.26240456
3.23520000 2.92099122 2.26485278
3.24000000 2.92513089 2.26806242
3.24480000 2.93579925 2.27633399
3.24960000 2.93200369 2.27339116
3.25440000 2.93285848 2.27405391
3.25920000 2.93941665 2.27913869
3.26400000 2.94422357 2.28286568
3.26880000 2.94897898 2.28655272
3.27360000 2.95470678 2.29099370
3.27840000 2.96167524 2.29639659
3.28320000 2.97110384 2.30370694
3.28800000 2.96591261 2.29968198
3.29280000 2.97435709 2.30622930
3.29760000 2.97411933 2.30604495
3.30240000 2.97819577 2.30920556
3.30720000 2.98247812 2.31252583
3.31200000 2.99127704 2.31934795
3.31680000 2.99070313 2.31890298
3.32160000 2.99525109 2.32242918
3.32640000 2.99910371 2.32541626
3.33120000 3.00355003 2.32886366
3.33600000 3.00768580 2.33207027
3.34080000 3.00035766 2.32638849
3.34560000 2.99871438 2.32511440
3.35040000 3.02008664 2.34168510
3.35520000 3.01548838 2.33811989
3.36000000 3.01502040 2.33775705
3.36480000 3.02508134 2.34555767
3.36960000 3.03186872 2.35082017
3.37440000 3.04126535 2.35810572
3.37920000 3.04538862 2.36130264
3.38400000 3.04982088 2.36473914
3.38880000 3.04762040 2.36303302
3.39360000 3.05818475 2.37122395
3.39840000 3.06225894 2.37438282
3.40320000 3.06437294 2.37602188
3.40800000 3.07042682 2.38071568
3.41280000 3.07527387 2.38447378
3.41760000 3.07725112 2.38600680
3.42240000 3.08352838 2.39087380
3.42720000 3.08802842 2.39436285
3.43200000 3.09182013 2.39730269
3.43680000 3.09570326 2.40031343
3.44160000 3.10545643 2.40787541
3.44640000 3.09877943 2.40269850
3.45120000 3.10916950 2.41075430
3.45600000 3.10746170 2.40943017
3.46080000 3.11768500 2.41735667
3.46560000 3.11404944 2.41453790
3.47040000 3.11381008 2.41435231
3.47520000 3.12224332 2.42089091
3.48000000 3.12652491 2.42421058
3.48480000 3.13535272 2.43105511
3.48960000 3.13658727 2.43201230
3.49440000 3.14561217 2.43900964
3.49920000 3.14189860 2.43613037
3.49600000 3.13463246 2.43049666
3.49120000 3.14368008 2.43751161
3.48640000 3.12542118 2.42335482
3.48160000 3.12203862 2.42073220
3.47680000 3.12251429 2.42110100
3.47200000 3.12022565 2.41932653
3.46720000 3.11315958 2.41384796
3.46240000 3.11784614 2.41748161
3.45760000 3.11373327 2.41429275
3.45280000 3.10956013 2.41105717
3.44800000 3.09757873 2.40176755
3.44320000 3.09433015 2.39924881
3.43840000 3.08292585 2.39040664
3.43360000 3.08620854 2.39295182
3.42880000 3.08170839 2.38946269
3.42400000 3.07152452 2.38156677
3.41920000 3.06601589 2.37729573
3.41440000 3.06834082 2.37909832
3.40960000 3.06486051 2.37639992
3.40480000 3.05782945 2.37094848
3.40000000 3.05723125 2.37048467
3.39520000 3.05850888 2.37147526
3.39040000 3.05220168 2.36658506
3.38560000 3.04999662 2.36487540
3.38080000 3.03403740 2.35250163
3.37600000 3.03671859 2.35458045
3.37120000 3.02221273 2.34333353
3.36640000 3.02174361 2.34296980
3.36160000 3.02182034 2.34302930
3.35680000 3.02431949 2.34496698
3.35200000 3.01379372 2.33680596
3.34720000 3.01590405 2.33844218
3.34240000 3.00708364 2.33160339
3.33760000 3.00130325 2.32712164
3.33280000 2.99900022 2.32533602
3.32800000 2.99240253 2.32022059
3.32320000 2.99361462 2.32116037
3.31840000 2.99067353 2.31888003
3.31360000 2.98629134 2.31548236
3.30880000 2.97610576 2.30758511
3.30400000 2.97858601 2.30950813
3.29920000 2.97438147 2.30624820
3.29440000 2.97084308 2.30350475
3.28960000 2.96621504 2.29991647
3.28480000 2.96602623 2.29977008
3.28000000 2.95873901 2.29412003
3.27520000 2.95469057 2.29098112
3.27040000 2.95104977 2.28815828
3.26560000 2.94518002 2.28360725
3.26080000 2.94253940 2.28155988
3.25600000 2.93841852 2.27836481
3.25120000 2.93214446 2.27350030
3.24640000 2.93002186 2.27185457
3.24160000 2.92150332 2.26524984
3.23680000 2.91985045 2.26396831
3.23200000 2.91733239 2.26201596
3.22720000 2.91065768 2.25684081
3.22240000 2.90319420 2.25105410
3.21760000 2.90654752 2.25365406
3.21280000 2.89800944 2.24703417
3.20800000 2.89626616 2.24568254
3.20320000 2.88942855 2.24038109
3.19840000 2.88359328 2.23585679
3.19360000 2.88084615 2.23372685
3.18880000 2.87687332 2.23064656
3.18400000 2.87505150 2.22923404
3.17920000 2.87060980 2.22579022
3.17440000 2.86662746 2.22270257
3.16960000 2.86623635 2.22239933
3.16480000 2.85794555 2.21597116
3.16000000 2.85332065 2.21238531
3.15520000 2.84917746 2.20917295
3.15040000 2.84466597 2.20567502
3.14560000 2.85026897 2.21001923
3.14080000 2.84012736 2.20215607
3.13600000 2.83590581 2.19888295
3.13120000 2.83135264 2.19535271
3.12640000 2.82695625 2.19194403
3.12160000 2.82860478 2.19322219
3.11680000 2.82439485 2.18995808
3.11200000 2.80990006 2.17871974
3.10720000 2.80625510 2.17589367
3.10240000 2.80147689 2.17218895
3.09760000 2.80082817 2.17168597
3.09280000 2.80245857 2.17295008
3.08800000 2.79197065 2.16481841
3.08320000 2.78864927 2.16224323
3.07840000 2.78334663 2.15813189
3.07360000 2.77885239 2.15464735
3.06880000 2.77437483 2.15117573
3.06400000 2.77623018 2.15261425
3.05920000 2.76513606 2.14401257
3.05440000 2.76117046 2.14093789
3.04960000 2.76619586 2.14483427
3.04480000 2.75246124 2.13418532
3.04000000 2.74806043 2.13077321
3.03520000 2.74361338 2.12732525
3.03040000 2.74432915 2.12788022
3.02560000 2.73987264 2.12442492
3.02080000 2.73042407 2.11709909
3.01600000 2.73277730 2.11892364
3.01120000 2.72557199 2.11333710
3.00640000 2.72750147 2.11483309
3.00160000 2.71971461 2.10879566
2.99680000 2.71224257 2.10300231
2.99200000 2.70416728 2.09674124
2.98720000 2.69927055 2.09294463
2.98240000 2.69935983 2.09301385
2.97760000 2.69475248 2.08944160
2.97280000 2.69150725 2.08692546
2.96800000 2.69278433 2.08791563
2.96320000 2.68775581 2.08401683
2.95840000 2.67731710 2.07592331
2.95360000 2.66901203 2.06948409
2.94880000 2.67218360 2.07194312
2.94400000 2.66524656 2.06656458
2.93920000 2.65937925 2.06201544
2.93440000 2.65488542 2.05853122
2.92960000 2.65663992 2.05989154
2.92480000 2.65641822 2.05971965
2.92000000 2.64486782 2.05076420
2.91520000 2.63974824 2.04679480
2.91040000 2.64303884 2.04934612
2.90560000 2.62995481 2.03920160
2.90080000 2.62532439 2.03561146
2.89600000 2.62030400 2.03171897
2.89120000 2.62472675 2.03514809
2.88640000 2.61798185 2.02991852
2.88160000 2.60623855 2.02081352
2.87680000 2.60620966 2.02079112
2.87200000 2.60720740 2.02156470
2.86720000 2.60302277 2.01832020
2.86240000 2.59871680 2.01498163
2.85760000 2.58788166 2.00658075
2.85280000 2.58112882 2.00134502
2.84800000 2.58516272 2.00447265
2.84320000 2.58153324 2.00165858
2.83840000 2.57618214 1.99750967
2.83360000 2.56607583 1.98967389
2.82880000 2.56699576 1.99038714
2.82400000 2.56279241 1.98712813
2.81920000 2.55393900 1.98026375
2.81440000 2.54773916 1.97545680
2.80960000 2.54972871 1.97699936
2.80480000 2.54491880 1.97327006
2.80000000 2.54086987 1.97013078
2.79520000 2.52876582 1.96074607
2.79040000 2.52444415 1.95739532
2.78560000 2.52746669 1.95973881
2.78080000 2.51640764 1.95116432
2.77600000 2.51188621 1.94765869
2.77120000 2.51409112 1.94936823
2.76640000 2.50913491 1.94552550
2.76160000 2.49737902 1.93641073
2.75680000 2.50036278 1.93872415
2.75200000 2.49268697 1.93277282
2.74720000 2.49169404 1.93200296
2.74240000 2.48706909 1.92841706
2.73760000 2.47487221 1.91896038
2.73280000 2.47162480 1.91644255
2.72800000 2.46694235 1.91281207
2.72320000 2.46940207 1.91471918
2.71840000 2.46444451 1.91087540
2.71360000 2.45997966 1.90741364
2.70880000 2.44882739 1.89876688
2.70400000 2.44434430 1.89529097
2.69920000 2.43996063 1.89189216
2.69440000 2.43537178 1.88833425
2.68960000 2.43918984 1.89129453
2.68480000 2.43377794 1.88709848
2.68000000 2.42900063 1.88339446
2.67520000 2.42489638 1.88021229
2.67040000 2.41237419 1.87050338
2.66560000 2.41582019 1.87317519
2.66080000 2.41146063 1.86979506
2.65600000 2.40655377 1.86599059
2.65120000 2.40232373 1.86271089
2.64640000 2.39786913 1.85925707
2.64160000 2.39368444 1.85601253
2.63680000 2.38059536 1.84586409
2.63200000 2.37945165 1.84497733
2.62720000 2.38004001 1.84543350
2.62240000 2.37593005 1.84224690
2.61760000 2.38246246 1.84731171
2.61280000 2.37795138 1.84381411
2.60800000 2.37335885 1.84025335
2.60320000 2.35832948 1.82860053
2.59840000 2.36442175 1.83332409
2.59360000 2.36011964 1.82998851
2.58880000 2.35531848 1.82626599
2.58400000 2.34047938 1.81476070
2.57920000 2.33673101 1.81185445
2.57440000 2.33092868 1.80735569
2.56960000 2.32804190 1.80511746
2.56480000 2.33496307 1.81048370
2.56000000 2.32930086 1.80609358
2.55520000 2.32392713 1.80192713
2.55040000 2.31984373 1.79876112
2.54560000 2.31577490 1.79560640
2.54080000 2.31085844 1.79179449
2.53600000 2.30582760 1.78789390
2.53120000 2.30222877 1.78510360
2.52640000 2.28009586 1.76794314
2.52160000 2.29470479 1.77926998
2.51680000 2.29014542 1.77573493
2.51200000 2.26784808 1.75844699
2.50720000 2.27108194 1.76095432
2.50240000 2.26781437 1.75842085
2.49760000 2.26196275 1.75388388
2.49280000 2.25647582 1.74962966
2.48800000 2.26235656 1.75418921
2.48320000 2.25777785 1.75063917
2.47840000 2.25422490 1.74788444
2.47360000 2.24858507 1.74351167
2.46880000 2.24399495 1.73995279
2.46400000 2.24172819 1.73819528
2.45920000 2.23530034 1.73321153
2.45440000 2.23098861 1.72986849
2.44960000 2.23490846 1.73290769
2.44480000 2.22876391 1.72814360
2.44000000 2.22404387 1.72448398
2.43520000 2.22227937 1.72311590
2.43040000 2.21559139 1.71793046
2.42560000 2.21356751 1.71636128
2.42080000 2.20668911 1.71102820
2.41600000 2.20381289 1.70879816
2.41120000 2.19793631 1.70424184
2.40640000 2.19497377 1.70194487
2.40160000 2.19177142 1.69946197
2.39680000 2.18720433 1.69592094
2.39200000 2.18122690 1.69128642
2.38720000 2.17696190 1.68797960
2.38240000 2.17492971 1.68640397
2.37760000 2.16779379 1.68087123
2.37280000 2.16407087 1.67798472
2.36800000 2.16170762 1.67615240
2.36320000 2.15620952 1.67188953
2.35840000 2.15153837 1.66826781
2.35360000 2.14565448 1.66370581
2.34880000 2.14124359 1.66028589
2.34400000 2.13848370 1.65814605
2.33920000 2.13225440 1.65331625
2.33440000 2.12920397 1.65095114
2.32960000 2.12528443 1.64791217
2.32480000 2.11969075 1.64357518
2.32000000 2.11648742 1.64109153
2.31520000 2.11175624 1.63742327
2.31040000 2.10664373 1.63345935
2.30560000 2.10280592 1.63048376
2.30080000 2.09885177 1.62741796
2.29600000 2.09429868 1.62388778
2.29120000 2.08947588 1.62014849
2.28640000 2.08629434 1.61768172
2.28160000 2.08098011 1.61356141
2.27680000 2.07633575 1.60996047
2.27200000 2.07214801 1.60671356
2.26720000 2.06740404 1.60303538
2.26240000 2.06336882 1.59990673
2.25760000 2.05912079 1.59661307
2.25280000 2.05446440 1.59300281
2.24800000 2.04946405 1.58912585
2.24320000 2.04525728 1.58586419
2.23840000 2.04119735 1.58271638
2.23360000 2.03694054 1.57941592
2.22880000 2.03227774 1.57580068
2.22400000 2.02626432 1.57113825
2.21920000 2.02286130 1.56849976
2.21440000 2.01834597 1.56499886
2.20960000 2.01794621 1.56468891
2.20480000 2.00978606 1.55836205
2.20000000 2.00550551 1.55504319
2.19520000 2.00159643 1.55201233
2.19040000 1.99747685 1.54881828
2.18560000 1.99556078 1.54733267
2.18080000 1.98822299 1.54164341
2.17600000 1.98311471 1.53768278
2.17120000 1.97855218 1.53414528
2.16640000 1.97513380 1.53149489
2.16160000 1.97355675 1.53027214
2.15680000 1.96823126 1.52614310
2.15200000 1.96469584 1.52340196
2.14720000 1.95864796 1.51871282
2.14240000 1.95395782 1.51507638
2.13760000 1.94920108 1.51138830
2.13280000 1.94508471 1.50819672
2.12800000 1.94260358 1.50627302
2.12320000 1.93774943 1.50250941
2.11840000 1.93224156 1.49823896
2.11360000 1.92905273 1.49576654
2.10880000 1.92464730 1.49235085
2.10400000 1.91848272 1.48757123
2.09920000 1.91442574 1.48442571
2.09440000 1.90816403 1.47957078
2.08960000 1.90471483 1.47689648
2.08480000 1.90263858 1.47528669
2.08000000 1.89644657 1.47048580
2.07520000 1.89203256 1.46706345
2.07040000 1.88828931 1.46416117
2.06560000 1.88452243 1.46124058
2.06080000 1.87999446 1.45772987
2.05600000 1.87408908 1.45315121
2.05120000 1.87115763 1.45087835
2.04640000 1.86668308 1.44740908
2.04160000 1.86066436 1.44274254
2.03680000 1.85761041 1.44037470
2.03200000 1.85199204 1.43601857
2.02720000 1.84834959 1.43319445
2.02240000 1.84487014 1.43049670
2.01760000 1.83955123 1.42637276
2.01280000 1.83587786 1.42352466
2.00800000 1.83203084 1.42054192
2.00320000 1.82667240 1.41638733
1.99840000 1.82350328 1.41393020
1.99360000 1.81600886 1.40811949
1.98880000 1.81290909 1.40571613
1.98400000 1.80816832 1.40204044
1.97920000 1.80939404 1.40299078
1.97440000 1.80464889 1.39931169
1.96960000 1.80076230 1.39629827
1.96480000 1.79059676 1.38841656
1.96000000 1.78560302 1.38454473
1.95520000 1.78672757 1.38541664
1.95040000 1.77935532 1.37970066
1.94560000 1.77314649 1.37488673
1.94080000 1.77250218 1.37438717
1.93600000 1.76371108 1.36757111
1.93120000 1.76463366 1.36828642
1.92640000 1.75983194 1.36456347
1.92160000 1.75554356 1.36123853
1.91680000 1.75023827 1.35712515
1.91200000 1.74530435 1.35329970
1.90720000 1.73966722 1.34892903
1.90240000 1.73315144 1.34387710
1.89760000 1.72841538 1.34020506
1.89280000 1.72726658 1.33931435
1.88800000 1.71931533 1.33314946
1.88320000 1.71866608 1.33264607
1.87840000 1.71030395 1.32616261
1.87360000 1.70933822 1.32541384
1.86880000 1.70114541 1.31906165
1.86400000 1.69713139 1.31594943
1.85920000 1.69458518 1.31397527
1.85440000 1.69379285 1.31336095
1.84960000 1.68710712 1.30817725
1.84480000 1.68179486 1.30405846
1.84000000 1.67999068 1.30265962
1.83520000 1.68067993 1.30319402
1.83040000 1.67165280 1.29619495
1.82560000 1.66643447 1.29214899
1.82080000 1.65569803 1.28382464
1.81600000 1.65406821 1.28256098
1.81120000 1.64944033 1.27897281
1.80640000 1.64491263 1.27546232
1.80160000 1.64027957 1.27187014
1.79680000 1.64428696 1.27497722
1.79200000 1.63126891 1.26488384
1.78720000 1.62528533 1.26024456
1.78240000 1.62036260 1.25642779
1.77760000 1.63111035 1.26476091
1.77280000 1.62550969 1.26041851
1.76800000 1.62403834 1.25927772
1.76320000 1.61793746 1.25454748
1.75840000 1.61277572 1.25054540
1.75360000 1.60791587 1.24677738
1.74880000 1.60123528 1.24159767
1.74400000 1.59779215 1.23892808
1.73920000 1.59312321 1.23530809
1.73440000 1.58852009 1.23173912
1.72960000 1.58517519 1.22914569
1.72480000 1.58032031 1.22538153
1.72000000 1.57361682 1.22018407
1.71520000 1.57101111 1.21816376
1.71040000 1.56653900 1.21469638
1.70560000 1.56205010 1.21121596
1.70080000 1.55729133 1.20752631
1.69600000 1.55242762 1.20375531
1.69120000 1.54838071 1.20061759
1.68640000 1.54393669 1.19717198
1.68160000 1.53897111 1.19332198
1.67680000 1.53414290 1.18957849
1.67200000 1.53000103 1.18636715
1.66720000 1.52534009 1.18275335
1.66240000 1.52036750 1.17889792
1.65760000 1.51579588 1.17535337
1.65280000 1.51125928 1.17183598
1.64800000 1.50643186 1.16809311
1.64320000 1.50176631 1.16447574
1.63840000 1.49733801 1.16104231
1.63360000 1.49943862 1.16267099
1.62880000 1.49257501 1.15734938
1.62400000 1.48714736 1.15314113
1.61920000 1.48540406 1.15178949
1.61440000 1.50164671 1.16438301
1.60960000 1.49730098 1.16101360
1.60480000 1.49107034 1.15618276
1.60000000 1.48618093 1.15239182
1.59520000 1.48163685 1.14886863
1.59040000 1.48356497 1.15036357
1.58560000 1.47449972 1.14333495
1.58080000 1.46936246 1.13935185
1.57600000 1.46631777 1.13699119
1.57120000 1.46132970 1.13312375
1.56640000 1.45793992 1.13049553
1.56160000 1.45260379 1.12635823
1.55680000 1.44891234 1.12349611
1.55200000 1.44486589 1.12035876
1.54720000 1.43929179 1.11603695
1.54240000 1.43437806 1.11222715
1.53760000 1.42900839 1.10806386
1.53280000 1.42519220 1.10510503
1.52800000 1.42462306 1.10466375
1.52320000 1.41508336 1.09726727
1.51840000 1.41403241 1.09645243
1.51360000 1.40794413 1.09173196
1.50880000 1.40508425 1.08951459
1.50400000 1.40068584 1.08610435
1.49920000 1.39114941 1.07871040
1.49440000 1.39141424 1.07891573
1.48960000 1.38266322 1.07213075
1.48480000 1.37972967 1.06985626
1.48000000 1.37465554 1.06592210
1.47520000 1.37055746 1.06274471
1.47040000 1.36426249 1.05786399
1.46560000 1.36201256 1.05611954
1.46080000 1.35867896 1.05353488
1.45600000 1.35403110 1.04993122
1.45120000 1.34658349 1.04415681
1.44640000 1.34485573 1.04281721
1.44160000 1.34009535 1.03912632
1.43680000 1.33519037 1.03532331
1.43200000 1.33041640 1.03162187
1.42720000 1.32598471 1.02818582
1.42240000 1.32113073 1.02442236
1.41760000 1.31635544 1.02071990
1.41280000 1.31202121 1.01735941
1.40800000 1.30569799 1.01245679
1.40320000 1.30241538 1.00991166
1.39840000 1.29625155 1.00513262
1.39360000 1.29321222 1.00277612
1.38880000 1.28870665 0.99928278
1.38400000 1.28426115 0.99583602
1.37920000 1.27887117 0.99165697
1.37440000 1.27320016 0.98726003
1.36960000 1.26902369 0.98402186
1.36480000 1.26335296 0.97962513
1.36000000 1.26039798 0.97733403
1.35520000 1.25558532 0.97360260
1.35040000 1.25080159 0.96989359
1.34560000 1.24529085 0.96562092
1.34080000 1.24166169 0.96280710
1.33600000 1.23770646 0.95974047
1.33120000 1.23219270 0.95546544
1.32640000 1.22843349 0.95255079
1.32160000 1.22363047 0.94882683
1.31680000 1.21896923 0.94521280
1.31200000 1.21452040 0.94176347
1.30720000 1.20919407 0.93763377
1.30240000 1.20408444 0.93367208
1.29760000 1.20021701 0.93067352
1.29280000 1.19452513 0.92626040
1.28800000 1.19089791 0.92344808
1.28320000 1.18546295 0.91923416
1.27840000 1.18182180 0.91641104
1.27360000 1.17652716 0.91230591
1.26880000 1.17133376 0.90827928
1.26400000 1.16785057 0.90557863
1.25920000 1.16291074 0.90174860
1.25440000 1.15838922 0.89824290
1.24960000 1.15338309 0.89436147
1.24480000 1.14825853 0.89038821
1.24000000 1.14432114 0.88733540
1.23520000 1.13969791 0.88375084
1.23040000 1.13360848 0.87902949
1.22560000 1.13121208 0.87717147
1.22080000 1.12686145 0.87379827
1.21600000 1.12217319 0.87016329
1.21120000 1.11594388 0.86533348
1.20640000 1.11295586 0.86301676
1.20160000 1.10943073 0.86028359
1.19680000 1.10137485 0.85403758
1.19200000 1.10104047 0.85377832
1.18720000 1.09329222 0.84777082
1.18240000 1.08827496 0.84388075
1.17760000 1.08347415 0.84015851
1.17280000 1.08224491 0.83920543
1.16800000 1.07421092 0.83297638
1.16320000 1.06970760 0.82948480
1.15840000 1.06504999 0.82587358
1.15360000 1.06406098 0.82510677
1.14880000 1.06349774 0.82467007
1.14400000 1.05084411 0.81485924
1.13920000 1.04639406 0.81140896
1.13440000 1.04597412 0.81108336
1.12960000 1.04165156 0.80773192
1.12480000 1.03629610 0.80357964
1.12000000 1.02801435 0.79715849
1.11520000 1.02769471 0.79691067
1.11040000 1.02255371 0.79292465
1.10560000 1.01415966 0.78641644
1.10080000 1.01351053 0.78591315
1.09600000 1.00866172 0.78215369
1.09120000 1.00116041 0.77633765
1.08640000 0.99968784 0.77519591
1.08160000 0.99096618 0.76843369
1.07680000 0.98754835 0.76578372
1.07200000 0.98417394 0.76316741
1.06720000 0.98210865 0.76156613
1.06240000 0.97868293 0.75891003
1.05760000 0.97282107 0.75436512
1.05280000 0.96800592 0.75063176
1.04800000 0.96365257 0.74725645
1.04320000 0.95881464 0.74350542
1.03840000 0.95397201 0.73975076
1.03360000 0.94937128 0.73618364
1.02880000 0.94753801 0.73476224
1.02400000 0.94021857 0.72908721
1.01920000 0.93386912 0.72416425
1.01440000 0.92713313 0.71894159
1.00960000 0.92497719 0.71727000
1.00480000 0.91987619 0.71331501
1.00000000 0.91549083 0.70991489
0.99520000 0.91078667 0.70626758
0.99040000 0.90610800 0.70264004
0.98560000 0.90121824 0.69884883
0.98080000 0.89673121 0.69536987
0.97600000 0.89218851 0.69184774
0.97120000 0.88734617 0.68809330
0.96640000 0.88283298 0.68459406
0.96160000 0.87809644 0.68092164
0.95680000 0.87333322 0.67722855
0.95200000 0.86878416 0.67370149
0.94720000 0.86415500 0.67011234
0.94240000 0.85932430 0.66636692
0.93760000 0.85472875 0.66280382
0.93280000 0.85217778 0.66082596
0.92800000 0.84545623 0.65561449
0.92320000 0.84082384 0.65202283
0.91840000 0.83593612 0.64823321
0.91360000 0.83113613 0.64451160
0.90880000 0.82667408 0.64105201
0.90400000 0.82283294 0.63807383
0.89920000 0.81808524 0.63439277
0.89440000 0.81392662 0.63116843
0.88960000 0.81136672 0.62918365
0.88480000 0.80433121 0.62372876
0.88000000 0.79958761 0.62005087
0.87520000 0.80228456 0.62214192
0.87040000 0.79470711 0.61626685
0.86560000 0.79478022 0.61632353
0.86080000 0.78151462 0.60603823
0.85600000 0.78195503 0.60637969
0.85120000 0.77234433 0.59892816
0.84640000 0.77499255 0.60098142
0.84160000 0.76273456 0.59147736
0.83680000 0.75819152 0.58795497
0.83200000 0.75380949 0.58455742
0.82720000 0.74878526 0.58066195
0.82240000 0.74210580 0.57548312
0.81760000 0.73786920 0.57219833
0.81280000 0.73271380 0.56820116
0.80800000 0.72859197 0.56500536
0.80320000 0.72382847 0.56131204
0.79840000 0.71861908 0.55727301
0.79360000 0.71386945 0.55359044
0.78880000 0.70970120 0.55035865
0.78400000 0.70478620 0.54654787
0.77920000 0.70013289 0.54293999
0.77440000 0.69541745 0.53928394
0.76960000 0.69060093 0.53554951
0.76480000 0.68615418 0.53210179
0.76000000 0.68367441 0.53017913
0.75520000 0.67888674 0.52646707
0.75040000 0.67451319 0.52307610
0.74560000 0.67555076 0.52388056
0.74080000 0.66637473 0.51676605
0.73600000 0.66612246 0.51657046
0.73120000 0.66166151 0.51311171
0.72640000 0.65097804 0.50482843
0.72160000 0.64618270 0.50111043
0.71680000 0.63927398 0.49575384
0.71200000 0.63505508 0.49248278
0.70720000 0.63750785 0.49438450
0.70240000 0.63297093 0.49086686
0.69760000 0.62255933 0.48279437
0.69280000 0.62346575 0.48349715
0.68800000 0.61497571 0.47691451
0.68320000 0.61402091 0.47617421
0.67840000 0.60938962 0.47258341
0.67360000 0.59918282 0.46466970
0.66880000 0.59949374 0.46491077
0.66400000 0.59329556 0.46010509
0.65920000 0.59048325 0.45792461
0.65440000 0.58590733 0.45437673
0.64960000 0.59343730 0.46021499
0.64480000 0.58454338 0.45331920
0.64000000 0.57538866 0.44622122
0.63520000 0.57324612 0.44456003
0.63040000 0.56853643 0.44090843
0.62560000 0.55817829 0.43287738
0.62080000 0.56078349 0.43489730
0.61600000 0.55318865 0.42900874
0.61120000 0.55032450 0.42678806
0.60640000 0.54130396 0.41979410
0.60160000 0.54750590 0.42460269
0.59680000 0.53518317 0.41504843
0.59200000 0.53656838 0.41612243
0.58720000 0.53175567 0.41239096
0.58240000 0.53482151 0.41476802
0.57760000 0.53414209 0.41424124
0.57280000 0.52561986 0.40763364
0.56800000 0.52442924 0.40671052
0.56320000 0.51740064 0.40126099
0.55840000 0.51091151 0.39622972
0.55360000 0.50821785 0.39414123
0.54880000 0.50391458 0.39080475
0.54400000 0.50279125 0.38993379
0.53920000 0.49311690 0.38243291
0.53440000 0.48732713 0.37794389
0.52960000 0.48876770 0.37906082
0.52480000 0.48403407 0.37539066
0.52000000 0.47705142 0.36997676
0.51520000 0.47532117 0.36863523
0.51040000 0.46778420 0.36279154
0.50560000 0.45707324 0.35448694
0.50080000 0.45821966 0.35537580
0.49600000 0.44921223 0.34839201
0.49120000 0.45089459 0.34969640
0.48640000 0.44637026 0.34618853
0.48160000 0.44085711 0.34191398
0.47680000 0.43048399 0.33387132
0.47200000 0.43387596 0.33650124
0.46720000 0.43690307 0.33884827
0.46240000 0.43196980 0.33502333
0.45760000 0.41216653 0.31966912
0.45280000 0.40903452 0.31724076
0.44800000 0.40768115 0.31619144
0.44320000 0.40078339 0.31084336
0.43840000 0.39611170 0.30722123
0.43360000 0.38732470 0.30040834
0.42880000 0.38925657 0.30190619
0.42400000 0.38274729 0.29685931
0.41920000 0.37942495 0.29428338
0.41440000 0.37622288 0.29180070
0.40960000 0.36921816 0.28636968
0.40480000 0.36349410 0.28193161
0.40000000 0.36447065 0.28268876
0.39520000 0.35461657 0.27504853
0.39040000 0.35168761 0.27277760
0.38560000 0.34106137 0.26453869
0.38080000 0.34234275 0.26553219
0.37600000 0.34119924 0.26464558
0.37120000 0.33399212 0.25905764
0.36640000 0.33123504 0.25691997
0.36160000 0.32369160 0.25107127
0.35680000 0.31870040 0.24720141
0.35200000 0.31701206 0.24589238
0.34720000 0.31204853 0.24204397
0.34240000 0.30409901 0.23588041
0.33760000 0.29954792 0.23235179
0.33280000 0.29465199 0.22855580
0.32800000 0.29305480 0.22731744
0.32320000 0.28964046 0.22467017
0.31840000 0.27998267 0.21718214
0.31360000 0.27558551 0.21377285
0.30880000 0.27468187 0.21307223
0.30400000 0.26919024 0.20881437
0.29920000 0.26357560 0.20446114
0.29440000 0.25993466 0.20163818
0.28960000 0.25147842 0.19508174
0.28480000 0.24704191 0.19164195
0.28000000 0.24587951 0.19074071
0.27520000 0.23717347 0.18399059
0.27040000 0.23668048 0.18360836
0.26560000 0.23181532 0.17983623
0.26080000 0.22717397 0.17623762
0.25600000 0.21803481 0.16915169
0.25120000 0.21971319 0.17045300
0.24640000 0.21844655 0.16947093
0.24160000 0.21017337 0.16305643
0.23680000 0.20194016 0.15667292
0.23200000 0.19625154 0.15226232
0.22720000 0.18886614 0.14653616
0.22240000 0.18750176 0.14547830
0.21760000 0.18232544 0.14146491
0.21280000 0.17708520 0.13740196
0.20800000 0.17323485 0.13441664
0.20320000 0.16470977 0.12780684
0.19840000 0.16312761 0.12658013
0.19360000 0.15580694 0.12090415
0.18880000 0.15398434 0.11949102
0.18400000 0.14906317 0.11567545
0.17920000 0.14438671 0.11204962
0.17440000 0.13676637 0.10614130
0.16960000 0.13137708 0.10196278
0.16480000 0.12889608 0.10003917
0.16000000 0.12483591 0.09689117
0.15520000 0.12017171 0.09327484
0.15040000 0.11268851 0.08747285
0.14560000 0.11049631 0.08577315
0.14080000 0.10705947 0.08310845
0.13600000 0.10211118 0.07927186
0.13120000 0.09736929 0.07559529
0.12640000 0.09215337 0.07155120
0.12160000 0.08740269 0.06786782
0.11680000 0.08244318 0.06402253
0.11200000 0.07764032 0.06029870
0.10720000 0.07283220 0.05657079
0.10240000 0.06698448 0.05203684
0.09760000 0.06337961 0.04924185
0.09280000 0.05855138 0.04549835
0.08800000 0.05389717 0.04188977
0.08320000 0.04886892 0.03799118
0.07840000 0.05187836 0.04032451
0.07360000 0.04703720 0.03657098
0.06880000 0.04223808 0.03285005
0.06400000 0.03772225 0.02934876
0.05920000 0.03242952 0.02524511
0.05440000 0.02792589 0.02175328
0.04960000 0.02296911 0.01791011
0.04480000 0.01814100 0.01416670
0.04000000 0.01333399 0.01043965
0.03520000 0.00850603 0.00669635
0.03040000 0.00431840 0.00344954
0.02560000 -0.00071851 -0.00045577
0.02080000 -0.00499404 -0.00377075
0.01600000 -0.01017561 -0.00778821
0.01120000 -0.01450015 -0.01114118
0.00640000 -0.01977481 -0.01523081
0.00160000 -0.02454334 -0.01892803
-0.00000000 -0.02620243 -0.02021438